Workbook

Sheet 목차
B2: E2E검증_방식2
B3: 재무모델 (Financial Model) — 재생E AI Agent 자동생성 · 2026-10-02
B6: No | C6: 시트 | D6: 내용
B7: 1 | C7: Assum | D7: 모든 입력 가정 — 노란 셀(파란 글씨)만 수정하면 전 시트 재계산
B8: 2 | C8: TIC_Funding | D8: 총투자비 · 건설이자 · 재원조달 · 감가상각 기준
B9: 3 | C9: Revenue | D9: 발전량 · 판매단가 · 영업수익 추정
B10: 4 | C10: Opex | D10: 운영비용 추정 (물가상승 반영)
B11: 5 | C11: Debt | D11: 차입금 인출/상환 스케줄 · 이자 · DSRA
B12: 6 | C12: IS(Y) | D12: 추정 손익계산서 (이월결손금·법인세 포함)
B13: 7 | C13: CF(Y) | D13: 추정 현금흐름표 · 배당 · 현금계정
B14: 8 | C14: DSCR | D14: 원리금 상환능력 (단순 DSCR, 최소/평균)
B15: 9 | C15: IRR | D15: Project IRR / Equity IRR / NPV
B16: 10 | C16: Report | D16: Executive Summary + 연도별 요약
B17: 11 | C17: Sensitivity | D17: 민감도 분석 (산출값)
B19: 색상 규칙
C20: 파란 글씨 + 노란 배경 | D20: 직접 입력하는 가정값 (Assum 시트)
C21: 검정 글씨 | D21: 해당 시트 내 수식
C22: 초록 글씨 | D22: 다른 시트를 참조하는 수식
C23: 단위 | D23: 별도 표기가 없는 금액은 모두 백만원(KRWm)

Sheet Report
A1: E2E검증_방식2
A2: Executive Summary
B4: 사업 개요
B6: 사업명 | D6: E2E검증_방식2
B7: 설비용량 [MW] | D7: =Assum!$F$7 -> 45.5
B8: 이용률 [%] | D8: =Assum!$F$8 -> 0.148
B9: 준공(COD) | D9: 2028-04
B10: 운영기간 [Year] | D10: =Assum!$F$18 -> 20
B12: 재원조달
B14: 총투자비(TIC) [KRWm] | D14: =Assum!$F$27 -> 63400.366
B15: 건설이자(IDC) [KRWm] | D15: =Assum!$F$26 -> 1400.3662
B16: 자기자본 [KRWm] | D16: ='TIC_Funding'!$D$15 -> 11610
B17: 선순위 차입금 [KRWm] | D17: ='TIC_Funding'!$D$16 -> 54290.366
B18: 차입비율 [%] | D18: =Assum!$F$24 -> 0.82
B20: 수익성 지표
B22: Project IRR (세후) [%] | D22: ='IRR'!$D$15 -> 0.10364197
B23: Equity IRR (FCFE) [%] | D23: ='IRR'!$D$26 -> 0.2697522
B24: Equity IRR (배당) [%] | D24: ='IRR'!$D$27 -> 0.21462725
B25: NPV [KRWm] | D25: ='IRR'!$D$16 -> 23642.556
B26: 최소 DSCR [x] | D26: ='DSCR'!$D$13 -> 1.3755525
B27: 평균 DSCR [x] | D27: ='DSCR'!$D$14 -> 1.518567
B28: LCOE [KRW/kWh] | D28: 141.88541
B29: 투자비 회수기간 [Year] | D29: 8.2101506
B30: 연평균 EBITDA [KRWm] | D30: 8223.7647
B31: EBITDA Margin [%] | D31: 0.75837774
B33: 연도별 요약
B35: 구 분 | C35: unit | D35: 합 계 | E35: 건설기간 | F35: 1년차 | G35: 2년차 | H35: 3년차 | I35: 4년차 | J35: 5년차 | K35: 6년차 | L35: 7년차 | M35: 8년차 | N35: 9년차 | O35: 10년차 | P35: 11년차 | Q35: 12년차 | R35: 13년차 | S35: 14년차 | T35: 15년차 | U35: 16년차 | V35: 17년차 | W35: 18년차 | X35: 19년차 | Y35: 20년차
E36: 2027 | F36: 2028 | G36: 2029 | H36: 2030 | I36: 2031 | J36: 2032 | K36: 2033 | L36: 2034 | M36: 2035 | N36: 2036 | O36: 2037 | P36: 2038 | Q36: 2039 | R36: 2040 | S36: 2041 | T36: 2042 | U36: 2043 | V36: 2044 | W36: 2045 | X36: 2046 | Y36: 2047
B38: 영업수익 | F38: ='Revenue'!F16 | G38: ='Revenue'!G16 | H38: ='Revenue'!H16 | I38: ='Revenue'!I16 | J38: ='Revenue'!J16 | K38: ='Revenue'!K16 | L38: ='Revenue'!L16 | M38: ='Revenue'!M16 | ... Y38: ='Revenue'!Y16
B39: 영업비용 | F39: ='Opex'!F12 -> 2200 | G39: ='Opex'!G12 -> 2239.6 | H39: ='Opex'!H12 -> 2279.9128 | I39: ='Opex'!I12 -> 2320.9512 | J39: ='Opex'!J12 -> 2362.7284 | K39: ='Opex'!K12 -> 2405.2575 | L39: ='Opex'!L12 -> 2448.5521 | M39: ='Opex'!M12 -> 2492.626 | ... Y39: ='Opex'!Y12 -> 3087.667
B40: EBITDA | F40: ='IS(Y)'!F11 -> 7946.2525 | G40: ='IS(Y)'!G11 -> 7977.0675 | H40: ='IS(Y)'!H11 -> 8007.6583 | I40: ='IS(Y)'!I11 -> 8038.0157 | J40: ='IS(Y)'!J11 -> 8068.1298 | K40: ='IS(Y)'!K11 -> 8097.9908 | L40: ='IS(Y)'!L11 -> 8127.5887 | M40: ='IS(Y)'!M11 -> 8156.9132 | ... Y40: ='IS(Y)'!Y11 -> 8483.414
B41: 당기순이익 | F41: ='IS(Y)'!F21 -> 1173.5498 | G41: ='IS(Y)'!G21 -> 1198.51 | H41: ='IS(Y)'!H21 -> 1251.2368 | I41: ='IS(Y)'!I21 -> 1389.2539 | J41: ='IS(Y)'!J21 -> 1533.7096 | K41: ='IS(Y)'!K21 -> 1684.9839 | L41: ='IS(Y)'!L21 -> 1843.4798 | M41: ='IS(Y)'!M21 -> 2009.6236 | ... Y41: ='IS(Y)'!Y21 -> 6891.5654
B42: CFADS | F42: ='CF(Y)'!F11 -> 7695.6667 | G42: ='CF(Y)'!G11 -> 7720.6269 | H42: ='CF(Y)'!H11 -> 7738.8497 | I42: ='CF(Y)'!I11 -> 7736.8326 | J42: ='CF(Y)'!J11 -> 7733.0621 | K42: ='CF(Y)'!K11 -> 7727.439 | L42: ='CF(Y)'!L11 -> 7719.8589 | M42: ='CF(Y)'!M11 -> 7710.2114 | ... Y42: ='CF(Y)'!Y11 -> 6891.5654
B43: 원리금(DS) | F43: ='Debt'!F13 -> 3175.9864 | G43: ='Debt'!G13 -> 3175.9864 | H43: ='Debt'!H13 -> 5500.7256 | I43: ='Debt'!I13 -> 5498.7072 | J43: ='Debt'!J13 -> 5496.5706 | K43: ='Debt'!K13 -> 5494.3091 | L43: ='Debt'!L13 -> 5491.9152 | M43: ='Debt'!M13 -> 5489.3813 | ... Y43: ='Debt'!Y13 -> 0
B44: DSCR | F44: ='DSCR'!F11 -> 2.4230792 | G44: ='DSCR'!G11 -> 2.4309382 | H44: ='DSCR'!H11 -> 1.406878 | I44: ='DSCR'!I11 -> 1.4070276 | J44: ='DSCR'!J11 -> 1.4068885 | K44: ='DSCR'!K11 -> 1.4064442 | L44: ='DSCR'!L11 -> 1.405677 | M44: ='DSCR'!M11 -> 1.4045684 | ... Y44: ='DSCR'!Y11 -> -
B45: 배당금 | F45: ='CF(Y)'!F19 -> 0 | G45: ='CF(Y)'!G19 -> 0 | H45: ='CF(Y)'!H19 -> 10053.091 | I45: ='CF(Y)'!I19 -> 2239.1938 | J45: ='CF(Y)'!J19 -> 2237.6223 | K45: ='CF(Y)'!K19 -> 2234.3269 | L45: ='CF(Y)'!L19 -> 2229.2106 | M45: ='CF(Y)'!M19 -> 2222.1711 | ... Y45: ='CF(Y)'!Y19 -> 6291.5654
B46: Project FCF | F46: ='IRR'!F13 -> 7695.6667 | G46: ='IRR'!G13 -> 7720.6269 | H46: ='IRR'!H13 -> 7738.8497 | I46: ='IRR'!I13 -> 7736.8326 | J46: ='IRR'!J13 -> 7733.0621 | K46: ='IRR'!K13 -> 7727.439 | L46: ='IRR'!L13 -> 7719.8589 | M46: ='IRR'!M13 -> 7710.2114 | ... Y46: ='IRR'!Y13 -> 5291.5654

Sheet Assum
A1: E2E검증_방식2
A2: Assumption — 파란색 셀만 수정하면 전 시트가 재계산됩니다
B3: 노랑 배경 + 파란 글씨 = 직접 입력값 / 회색 = 수식
B4: General
B6: 사업명 | D6: [text] | F6: E2E검증_방식2
B7: 설비용량 | D7: [MW] | F7: 45.5
B8: 이용률 | D8: [%] | F8: 0.148 | G8: 일일발전시간 ÷ 24
B9: 일일 발전시간(환산) | D9: [h/day] | F9: =$F$8*24 -> 3.552
B10: Degradation | D10: [%/yr] | F10: 0.005
B11: 소내 소비율 | D11: [%] | F11: 0
B13: Timing
B15: 착공시점 | D15: [Date] | F15: 2027-04
B16: 공사기간 | D16: [Month] | F16: 12
B17: 준공(COD) | D17: [Date] | F17: 2028-04
B18: 운영기간 | D18: [Year] | F18: 20
B20: TIC & Funding
B22: 총사업비(건설이자 제외) | D22: [KRWm] | F22: 62000
B23: 최초 DSRA | D23: [KRWm] | F23: 2500
B24: 차입비율(Gearing) | D24: [%] | F24: 0.82 | G24: 기준: 총사업비 + 최초DSRA (건설이자는 전액 차입 조달)
B25: 자기자본 | D25: [KRWm] | F25: =($F$22+$F$23)*(1-$F$24) -> 11610
B26: 건설이자(IDC) | D26: [KRWm] | F26: ='Construction'!$D$13 -> 1400.3662 | G26: Construction 시트에서 월단위 산출
B27: 총투자비(TIC) | D27: [KRWm] | F27: =$F$22+$F$26 -> 63400.366
B28: 소요자금 합계 | D28: [KRWm] | F28: =$F$27+$F$23 -> 65900.366
B29: 차입금 | D29: [KRWm] | F29: =$F$28-$F$25 -> 54290.366
B30: 실질 차입비율(TIC 기준) | D30: [%] | F30: =$F$29/$F$28 -> 0.82382495
B32: Debt
B34: 이자율(건설기간) | D34: [%] | F34: 0.061
B35: 이자율(운영기간) | D35: [%] | F35: 0.0585
B36: 거치기간 | D36: [Year] | F36: 2
B37: 상환기간 | D37: [Year] | F37: 15
B38: 상환방식 | D38: [1/2/3] | F38: 2 | G38: 1: 원금균등 2: 원리금균등 3: DSCR 스컬프팅(수동 스케줄)
B39: 연간 상환횟수 | D39: [회/년] | F39: 2 | G39: 이자는 연중 평균잔액 기준으로 계산
B40: 스컬프팅 균등 DSCR(산출) | D40: [x] | F40: 1.2 | G40: 상환방식 3 선택 시 완전상환되는 균등 DSCR
B42: Revenue
B44: 판매단가 | D44: [KRW/kWh] | F44: 172 | G44: PPA 또는 SMP+REC 가중평균
B45: 단가 상승률 | D45: [%/yr] | F45: 0.012
B47: Cost
B49: 운영비(연간, 1년차) | D49: [KRWm/yr] | F49: 2200
B50: 운영비 상승률 | D50: [%/yr] | F50: 0.018
B51: 철거·복구비(만기) | D51: [KRWm] | F51: 1600
...

Sheet Construction
A1: E2E검증_방식2
A2: 건설기간 자금인출 및 건설이자(IDC)
B4: 월별 인출 스케줄
B6: 구 분 | C6: unit | D6: 합 계 | E6: 1 | F6: 2 | G6: 3 | H6: 4 | I6: 5 | J6: 6 | K6: 7 | L6: 8 | M6: 9 | N6: 10 | O6: 11 | P6: 12 | Q6: 13 | R6: 14 | S6: 15 | T6: 16 | U6: 17 | V6: 18 | W6: 19 | X6: 20 | Y6: 21 | Z6: 22 | AA6: 23 | AB6: 24
B8: 사업비 인출 | C8: [KRWm] | D8: =SUM(E8:AB8) | E8: =IF(1<=Assum!$F$16,Assum!$F$22/Assum!$F$16,0) -> 5166.6667 | F8: =IF(2<=Assum!$F$16,Assum!$F$22/Assum!$F$16,0) -> 5166.6667 | G8: =IF(3<=Assum!$F$16,Assum!$F$22/Assum!$F$16,0) -> 5166.6667 | H8: =IF(4<=Assum!$F$16,Assum!$F$22/Assum!$F$16,0) -> 5166.6667 | I8: =IF(5<=Assum!$F$16,Assum!$F$22/Assum!$F$16,0) -> 5166.6667 | J8: =IF(6<=Assum!$F$16,Assum!$F$22/Assum!$F$16,0) -> 5166.6667 | K8: =IF(7<=Assum!$F$16,Assum!$F$22/Assum!$F$16,0) -> 5166.6667 | L8: =IF(8<=Assum!$F$16,Assum!$F$22/Assum!$F$16,0) -> 5166.6667 | M8: =IF(9<=Assum!$F$16,Assum!$F$22/Assum!$F$16,0) -> 5166.6667 | N8: =IF(10<=Assum!$F$16,Assum!$F$22/Assum!$F$16,0) -> 5166.6667 | O8: =IF(11<=Assum!$F$16,Assum!$F$22/Assum!$F$16,0) -> 5166.6667 | P8: =IF(12<=Assum!$F$16,Assum!$F$22/Assum!$F$16,0) -> 5166.6667 | Q8: =IF(13<=Assum!$F$16,Assum!$F$22/Assum!$F$16,0) -> 0 | R8: =IF(14<=Assum!$F$16,Assum!$F$22/Assum!$F$16,0) -> 0 | S8: =IF(15<=Assum!$F$16,Assum!$F$22/Assum!$F$16,0) -> 0 | T8: =IF(16<=Assum!$F$16,Assum!$F$22/Assum!$F$16,0) -> 0 | U8: =IF(17<=Assum!$F$16,Assum!$F$22/Assum!$F$16,0) -> 0 | V8: =IF(18<=Assum!$F$16,Assum!$F$22/Assum!$F$16,0) -> 0 | W8: =IF(19<=Assum!$F$16,Assum!$F$22/Assum!$F$16,0) -> 0 | X8: =IF(20<=Assum!$F$16,Assum!$F$22/Assum!$F$16,0) -> 0 | Y8: =IF(21<=Assum!$F$16,Assum!$F$22/Assum!$F$16,0) -> 0 | Z8: =IF(22<=Assum!$F$16,Assum!$F$22/Assum!$F$16,0) -> 0 | AA8: =IF(23<=Assum!$F$16,Assum!$F$22/Assum!$F$16,0) -> 0 | AB8: =IF(24<=Assum!$F$16,Assum!$F$22/Assum!$F$16,0) -> 0
B9: 자기자본 인출 | C9: [KRWm] | D9: =SUM(E9:AB9) | E9: =MIN(MAX(0,Assum!$F$25-0),E8) -> 5166.6667 | F9: =MIN(MAX(0,Assum!$F$25-SUM($E$9:E9)),F8) -> 5166.6667 | G9: =MIN(MAX(0,Assum!$F$25-SUM($E$9:F9)),G8) -> 1276.6667 | H9: =MIN(MAX(0,Assum!$F$25-SUM($E$9:G9)),H8) -> 0 | I9: =MIN(MAX(0,Assum!$F$25-SUM($E$9:H9)),I8) -> 0 | J9: =MIN(MAX(0,Assum!$F$25-SUM($E$9:I9)),J8) -> 0 | K9: =MIN(MAX(0,Assum!$F$25-SUM($E$9:J9)),K8) -> 0 | L9: =MIN(MAX(0,Assum!$F$25-SUM($E$9:K9)),L8) -> 0 | M9: =MIN(MAX(0,Assum!$F$25-SUM($E$9:L9)),M8) -> 0 | ... AB9: =MIN(MAX(0,Assum!$F$25-SUM($E$9:AA9)),AB8) -> 0
B10: 차입금 인출 | C10: [KRWm] | D10: =SUM(E10:AB10) | E10: =E8-E9 -> 0 | F10: =F8-F9 -> 0 | G10: =G8-G9 -> 3890 | H10: =H8-H9 -> 5166.6667 | I10: =I8-I9 -> 5166.6667 | J10: =J8-J9 -> 5166.6667 | K10: =K8-K9 -> 5166.6667 | L10: =L8-L9 -> 5166.6667 | ... AB10: =AB8-AB9 -> 0
B11: 기초 차입잔액 | C11: [KRWm] | E11: 0 | F11: =E13 -> 0 | G11: =F13 -> 0 | H11: =G13 -> 3909.7742 | I11: =H13 -> 9122.5794 | J11: =I13 -> 14361.883 | K11: =J13 -> 19627.82 | L11: =K13 -> 24920.525 | M11: =L13 -> 30240.135 | ... AB11: =AA13 -> 0
B12: 건설이자(월) | C12: [KRWm] | D12: =SUM(E12:AB12) | E12: =IF(1<=Assum!$F$16,(E11+E10)*Assum!$F$34/12,0) -> 0 | F12: =IF(2<=Assum!$F$16,(F11+F10)*Assum!$F$34/12,0) -> 0 | G12: =IF(3<=Assum!$F$16,(G11+G10)*Assum!$F$34/12,0) -> 19.774167 | H12: =IF(4<=Assum!$F$16,(H11+H10)*Assum!$F$34/12,0) -> 46.138574 | I12: =IF(5<=Assum!$F$16,(I11+I10)*Assum!$F$34/12,0) -> 72.637001 | J12: =IF(6<=Assum!$F$16,(J11+J10)*Assum!$F$34/12,0) -> 99.270128 | K12: =IF(7<=Assum!$F$16,(K11+K10)*Assum!$F$34/12,0) -> 126.03864 | L12: =IF(8<=Assum!$F$16,(L11+L10)*Assum!$F$34/12,0) -> 152.94323 | M12: =IF(9<=Assum!$F$16,(M11+M10)*Assum!$F$34/12,0) -> 179.98458 | N12: =IF(10<=Assum!$F$16,(N11+N10)*Assum!$F$34/12,0) -> 207.16339 | O12: =IF(11<=Assum!$F$16,(O11+O10)*Assum!$F$34/12,0) -> 234.48036 | P12: =IF(12<=Assum!$F$16,(P11+P10)*Assum!$F$34/12,0) -> 261.93619 | Q12: =IF(13<=Assum!$F$16,(Q11+Q10)*Assum!$F$34/12,0) -> 0 | R12: =IF(14<=Assum!$F$16,(R11+R10)*Assum!$F$34/12,0) -> 0 | S12: =IF(15<=Assum!$F$16,(S11+S10)*Assum!$F$34/12,0) -> 0 | T12: =IF(16<=Assum!$F$16,(T11+T10)*Assum!$F$34/12,0) -> 0 | U12: =IF(17<=Assum!$F$16,(U11+U10)*Assum!$F$34/12,0) -> 0 | V12: =IF(18<=Assum!$F$16,(V11+V10)*Assum!$F$34/12,0) -> 0 | W12: =IF(19<=Assum!$F$16,(W11+W10)*Assum!$F$34/12,0) -> 0 | X12: =IF(20<=Assum!$F$16,(X11+X10)*Assum!$F$34/12,0) -> 0 | Y12: =IF(21<=Assum!$F$16,(Y11+Y10)*Assum!$F$34/12,0) -> 0 | Z12: =IF(22<=Assum!$F$16,(Z11+Z10)*Assum!$F$34/12,0) -> 0 | AA12: =IF(23<=Assum!$F$16,(AA11+AA10)*Assum!$F$34/12,0) -> 0 | AB12: =IF(24<=Assum!$F$16,(AB11+AB10)*Assum!$F$34/12,0) -> 0
B13: 기말 차입잔액 | C13: [IDC 합계] | D13: =SUM(E12:AB12) -> 1400.3662 | E13: =E11+E10+E12 -> 0 | F13: =F11+F10+F12 -> 0 | G13: =G11+G10+G12 -> 3909.7742 | H13: =H11+H10+H12 -> 9122.5794 | I13: =I11+I10+I12 -> 14361.883 | J13: =J11+J10+J12 -> 19627.82 | K13: =K11+K10+K12 -> 24920.525 | L13: =L11+L10+L12 -> 30240.135 | ... AB13: =AB11+AB10+AB12 -> 0
B15: 준공시점 정산
B17: 기말 차입잔액(사업비) | C17: [KRWm] | D17: =AB13 -> 51790.366
B18: DSRA — 자기자본 조달 | C18: [KRWm] | D18: =MIN(MAX(0,Assum!$F$25-SUM(E9:AB9)),Assum!$F$23) -> 0
B19: DSRA — 차입 조달 | C19: [KRWm] | D19: =Assum!$F$23-D18 -> 2500
B20: 차입금 합계(운영개시) | C20: [KRWm] | D20: =D17+D19 -> 54290.366
B21: Check (Assum 차입금과 일치) | C21: [KRWm] | D21: =D20-Assum!$F$29 -> 0
B23: ※ 자기자본을 먼저 인출하고 잔여 소요액을 차입하는 구조이며, 건설이자는 매월 자본화(원금가산)됩니다.
B24: ※ 공사기간을 24개월 이상으로 늘리려면 열을 추가하거나 생성기에서 다시 만들어 주세요.

Sheet TIC_Funding
A1: E2E검증_방식2
A2: 총투자비 및 재원조달
B4: 총투자비
B6: 구 분 | D6: 금액 | E6: 비중
B7: 총사업비(건설이자 제외) | C7: [KRWm] | D7: =Assum!$F$22 -> 62000 | E7: =D7/$D$10 -> 0.94081419
B8: 건설이자(IDC) | C8: [KRWm] | D8: =Assum!$F$26 -> 1400.3662 | E8: =D8/$D$10 -> 0.021249749
B9: 최초 DSRA | C9: [KRWm] | D9: =Assum!$F$23 -> 2500 | E9: =D9/$D$10 -> 0.037936056
B10: 소요자금 합계 | C10: [KRWm] | D10: =SUM(D7:D9) -> 65900.366 | E10: =D10/$D$10 -> 1
B13: 재원조달
B15: 자기자본 | C15: [KRWm] | D15: =Assum!$F$25 -> 11610 | E15: =D15/$D$17 -> 0.17617505
B16: 선순위 차입금 | C16: [KRWm] | D16: =Assum!$F$29 -> 54290.366 | E16: =D16/$D$17 -> 0.82382495
B17: 합계 | C17: [KRWm] | D17: =SUM(D15:D16) -> 65900.366 | E17: =D17/$D$17 -> 1
B18: Check (소요 - 조달) | C18: [KRWm] | D18: =D10-D17 -> 0
B21: 감가상각
B23: 감가상각 대상자산 | C23: [KRWm] | D23: =Assum!$F$56 -> 60230.348
B24: 내용연수 | C24: [Year] | D24: =Assum!$F$57 -> 18
B25: 연간 상각비 | C25: [KRWm/yr] | D25: =D23/D24 -> 3346.1304
B27: ※ 건설이자는 자기자본 우선인출 가정 하에 월단위로 자본화하여 산출한 값입니다.

Sheet Revenue
A1: E2E검증_방식2
A2: 영업수익 추정
B4: 발전량 및 매출
B6: 구 분 | C6: unit | D6: 합 계 | E6: 건설기간 | F6: 1년차 | G6: 2년차 | H6: 3년차 | I6: 4년차 | J6: 5년차 | K6: 6년차 | L6: 7년차 | M6: 8년차 | N6: 9년차 | O6: 10년차 | P6: 11년차 | Q6: 12년차 | R6: 13년차 | S6: 14년차 | T6: 15년차 | U6: 16년차 | V6: 17년차 | W6: 18년차 | X6: 19년차 | Y6: 20년차
E7: 2027 | F7: 2028 | G7: 2029 | H7: 2030 | I7: 2031 | J7: 2032 | K7: 2033 | L7: 2034 | M7: 2035 | N7: 2036 | O7: 2037 | P7: 2038 | Q7: 2039 | R7: 2040 | S7: 2041 | T7: 2042 | U7: 2043 | V7: 2044 | W7: 2045 | X7: 2046 | Y7: 2047
B9: 설비용량 | C9: [MW] | F9: =Assum!$F$7 -> 45.5 | G9: =Assum!$F$7 -> 45.5 | H9: =Assum!$F$7 -> 45.5 | I9: =Assum!$F$7 -> 45.5 | J9: =Assum!$F$7 -> 45.5 | K9: =Assum!$F$7 -> 45.5 | L9: =Assum!$F$7 -> 45.5 | M9: =Assum!$F$7 -> 45.5 | ... Y9: =Assum!$F$7 -> 45.5
B10: 이용률 | C10: [%] | F10: =Assum!$F$8 -> 0.148 | G10: =Assum!$F$8 -> 0.148 | H10: =Assum!$F$8 -> 0.148 | I10: =Assum!$F$8 -> 0.148 | J10: =Assum!$F$8 -> 0.148 | K10: =Assum!$F$8 -> 0.148 | L10: =Assum!$F$8 -> 0.148 | M10: =Assum!$F$8 -> 0.148 | ... Y10: =Assum!$F$8 -> 0.148
B11: Degradation 계수 | C11: [%] | F11: =(1-Assum!$F$10)^(1-1) -> 1 | G11: =(1-Assum!$F$10)^(2-1) -> 0.995 | H11: =(1-Assum!$F$10)^(3-1) -> 0.990025 | I11: =(1-Assum!$F$10)^(4-1) -> 0.98507488 | J11: =(1-Assum!$F$10)^(5-1) -> 0.9801495 | K11: =(1-Assum!$F$10)^(6-1) -> 0.97524875 | L11: =(1-Assum!$F$10)^(7-1) -> 0.97037251 | M11: =(1-Assum!$F$10)^(8-1) -> 0.96552065 | N11: =(1-Assum!$F$10)^(9-1) -> 0.96069304 | O11: =(1-Assum!$F$10)^(10-1) -> 0.95588958 | P11: =(1-Assum!$F$10)^(11-1) -> 0.95111013 | Q11: =(1-Assum!$F$10)^(12-1) -> 0.94635458 | R11: =(1-Assum!$F$10)^(13-1) -> 0.94162281 | S11: =(1-Assum!$F$10)^(14-1) -> 0.93691469 | T11: =(1-Assum!$F$10)^(15-1) -> 0.93223012 | U11: =(1-Assum!$F$10)^(16-1) -> 0.92756897 | V11: =(1-Assum!$F$10)^(17-1) -> 0.92293112 | W11: =(1-Assum!$F$10)^(18-1) -> 0.91831647 | X11: =(1-Assum!$F$10)^(19-1) -> 0.91372489 | Y11: =(1-Assum!$F$10)^(20-1) -> 0.90915626
B12: 발전량(송전단) | C12: [MWh] | D12: =SUM(F12:Y12) | F12: =F9*8760*F10*(1-Assum!$F$11)*F11 -> 58989.84 | G12: =G9*8760*G10*(1-Assum!$F$11)*G11 -> 58694.891 | H12: =H9*8760*H10*(1-Assum!$F$11)*H11 -> 58401.416 | I12: =I9*8760*I10*(1-Assum!$F$11)*I11 -> 58109.409 | J12: =J9*8760*J10*(1-Assum!$F$11)*J11 -> 57818.862 | K12: =K9*8760*K10*(1-Assum!$F$11)*K11 -> 57529.768 | L12: =L9*8760*L10*(1-Assum!$F$11)*L11 -> 57242.119 | M12: =M9*8760*M10*(1-Assum!$F$11)*M11 -> 56955.908 | ... Y12: =Y9*8760*Y10*(1-Assum!$F$11)*Y11 -> 53630.982
B14: 판매단가 | C14: [KRW/kWh] | F14: =Assum!$F$44*(1+Assum!$F$45)^(1-1) -> 172 | G14: =Assum!$F$44*(1+Assum!$F$45)^(2-1) -> 174.064 | H14: =Assum!$F$44*(1+Assum!$F$45)^(3-1) -> 176.15277 | I14: =Assum!$F$44*(1+Assum!$F$45)^(4-1) -> 178.2666 | J14: =Assum!$F$44*(1+Assum!$F$45)^(5-1) -> 180.4058 | K14: =Assum!$F$44*(1+Assum!$F$45)^(6-1) -> 182.57067 | L14: =Assum!$F$44*(1+Assum!$F$45)^(7-1) -> 184.76152 | M14: =Assum!$F$44*(1+Assum!$F$45)^(8-1) -> 186.97866 | N14: =Assum!$F$44*(1+Assum!$F$45)^(9-1) -> 189.2224 | O14: =Assum!$F$44*(1+Assum!$F$45)^(10-1) -> 191.49307 | P14: =Assum!$F$44*(1+Assum!$F$45)^(11-1) -> 193.79099 | Q14: =Assum!$F$44*(1+Assum!$F$45)^(12-1) -> 196.11648 | R14: =Assum!$F$44*(1+Assum!$F$45)^(13-1) -> 198.46988 | S14: =Assum!$F$44*(1+Assum!$F$45)^(14-1) -> 200.85151 | T14: =Assum!$F$44*(1+Assum!$F$45)^(15-1) -> 203.26173 | U14: =Assum!$F$44*(1+Assum!$F$45)^(16-1) -> 205.70087 | V14: =Assum!$F$44*(1+Assum!$F$45)^(17-1) -> 208.16928 | W14: =Assum!$F$44*(1+Assum!$F$45)^(18-1) -> 210.66731 | X14: =Assum!$F$44*(1+Assum!$F$45)^(19-1) -> 213.19532 | Y14: =Assum!$F$44*(1+Assum!$F$45)^(20-1) -> 215.75367
B16: 영업수익 | C16: [KRWm] | D16: =SUM(F16:Y16) | F16: =F12*F14/1000 -> 10146.252 | G16: =G12*G14/1000 -> 10216.667 | H16: =H12*H14/1000 -> 10287.571 | I16: =I12*I14/1000 -> 10358.967 | J16: =J12*J14/1000 -> 10430.858 | K16: =K12*K14/1000 -> 10503.248 | L16: =L12*L14/1000 -> 10576.141 | M16: =M12*M14/1000 -> 10649.539 | ... Y16: =Y12*Y14/1000 -> 11571.081

Sheet Opex
A1: E2E검증_방식2
A2: 영업비용 추정
B4: 운영비용
B6: 구 분 | C6: unit | D6: 합 계 | E6: 건설기간 | F6: 1년차 | G6: 2년차 | H6: 3년차 | I6: 4년차 | J6: 5년차 | K6: 6년차 | L6: 7년차 | M6: 8년차 | N6: 9년차 | O6: 10년차 | P6: 11년차 | Q6: 12년차 | R6: 13년차 | S6: 14년차 | T6: 15년차 | U6: 16년차 | V6: 17년차 | W6: 18년차 | X6: 19년차 | Y6: 20년차
E7: 2027 | F7: 2028 | G7: 2029 | H7: 2030 | I7: 2031 | J7: 2032 | K7: 2033 | L7: 2034 | M7: 2035 | N7: 2036 | O7: 2037 | P7: 2038 | Q7: 2039 | R7: 2040 | S7: 2041 | T7: 2042 | U7: 2043 | V7: 2044 | W7: 2045 | X7: 2046 | Y7: 2047
B9: 운영비(1년차 기준) | C9: [KRWm] | F9: =Assum!$F$49 -> 2200 | G9: =Assum!$F$49 -> 2200 | H9: =Assum!$F$49 -> 2200 | I9: =Assum!$F$49 -> 2200 | J9: =Assum!$F$49 -> 2200 | K9: =Assum!$F$49 -> 2200 | L9: =Assum!$F$49 -> 2200 | M9: =Assum!$F$49 -> 2200 | ... Y9: =Assum!$F$49 -> 2200
B10: 물가상승 계수 | C10: [%] | F10: =(1+Assum!$F$50)^(1-1) -> 1 | G10: =(1+Assum!$F$50)^(2-1) -> 1.018 | H10: =(1+Assum!$F$50)^(3-1) -> 1.036324 | I10: =(1+Assum!$F$50)^(4-1) -> 1.0549778 | J10: =(1+Assum!$F$50)^(5-1) -> 1.0739674 | K10: =(1+Assum!$F$50)^(6-1) -> 1.0932988 | L10: =(1+Assum!$F$50)^(7-1) -> 1.1129782 | M10: =(1+Assum!$F$50)^(8-1) -> 1.1330118 | N10: =(1+Assum!$F$50)^(9-1) -> 1.153406 | O10: =(1+Assum!$F$50)^(10-1) -> 1.1741674 | P10: =(1+Assum!$F$50)^(11-1) -> 1.1953024 | Q10: =(1+Assum!$F$50)^(12-1) -> 1.2168178 | R10: =(1+Assum!$F$50)^(13-1) -> 1.2387205 | S10: =(1+Assum!$F$50)^(14-1) -> 1.2610175 | T10: =(1+Assum!$F$50)^(15-1) -> 1.2837158 | U10: =(1+Assum!$F$50)^(16-1) -> 1.3068227 | V10: =(1+Assum!$F$50)^(17-1) -> 1.3303455 | W10: =(1+Assum!$F$50)^(18-1) -> 1.3542917 | X10: =(1+Assum!$F$50)^(19-1) -> 1.378669 | Y10: =(1+Assum!$F$50)^(20-1) -> 1.403485
B12: 영업비용 합계 | C12: [KRWm] | D12: =SUM(F12:Y12) | F12: =F9*F10 -> 2200 | G12: =G9*G10 -> 2239.6 | H12: =H9*H10 -> 2279.9128 | I12: =I9*I10 -> 2320.9512 | J12: =J9*J10 -> 2362.7284 | K12: =K9*K10 -> 2405.2575 | L12: =L9*L10 -> 2448.5521 | M12: =M9*M10 -> 2492.626 | ... Y12: =Y9*Y10 -> 3087.667

Sheet Debt
A1: E2E검증_방식2
A2: 차입금 인출·상환 스케줄
B4: 선순위 차입금
B6: 구 분 | C6: unit | D6: 합 계 | E6: 건설기간 | F6: 1년차 | G6: 2년차 | H6: 3년차 | I6: 4년차 | J6: 5년차 | K6: 6년차 | L6: 7년차 | M6: 8년차 | N6: 9년차 | O6: 10년차 | P6: 11년차 | Q6: 12년차 | R6: 13년차 | S6: 14년차 | T6: 15년차 | U6: 16년차 | V6: 17년차 | W6: 18년차 | X6: 19년차 | Y6: 20년차
E7: 2027 | F7: 2028 | G7: 2029 | H7: 2030 | I7: 2031 | J7: 2032 | K7: 2033 | L7: 2034 | M7: 2035 | N7: 2036 | O7: 2037 | P7: 2038 | Q7: 2039 | R7: 2040 | S7: 2041 | T7: 2042 | U7: 2043 | V7: 2044 | W7: 2045 | X7: 2046 | Y7: 2047
B9: 기초잔액 | C9: [KRWm] | F9: ='TIC_Funding'!$D$16 -> 54290.366 | G9: =F11 -> 54290.366 | H9: =G11 -> 54290.366 | I9: =H11 -> 51931.123 | J9: =I11 -> 49433.864 | K9: =J11 -> 46790.516 | L9: =K11 -> 43992.531 | M9: =L11 -> 41030.865 | N9: =M11 -> 37895.941 | ... Y9: =X11 -> 0
B10: 원금상환 | C10: [KRWm] | D10: =SUM(F10:Y10) | F10: =IF(AND(1>Assum!$F$36,1<=Assum!$F$36+Assum!$F$37),MIN(F9,IF(Assum!$F$38=2,-PPMT(Assum!$F$35,1-Assum!$F$36,Assum!$F$37,'TIC_Funding'!$D$16),'TIC_Funding'!$D$16/Assum!$F$37)),0) -> 0 | G10: =IF(AND(2>Assum!$F$36,2<=Assum!$F$36+Assum!$F$37),MIN(G9,IF(Assum!$F$38=2,-PPMT(Assum!$F$35,2-Assum!$F$36,Assum!$F$37,'TIC_Funding'!$D$16),'TIC_Funding'!$D$16/Assum!$F$37)),0) -> 0 | H10: =IF(AND(3>Assum!$F$36,3<=Assum!$F$36+Assum!$F$37),MIN(H9,IF(Assum!$F$38=2,-PPMT(Assum!$F$35,3-Assum!$F$36,Assum!$F$37,'TIC_Funding'!$D$16),'TIC_Funding'!$D$16/Assum!$F$37)),0) -> 2359.2431 | I10: =IF(AND(4>Assum!$F$36,4<=Assum!$F$36+Assum!$F$37),MIN(I9,IF(Assum!$F$38=2,-PPMT(Assum!$F$35,4-Assum!$F$36,Assum!$F$37,'TIC_Funding'!$D$16),'TIC_Funding'!$D$16/Assum!$F$37)),0) -> 2497.2589 | J10: =IF(AND(5>Assum!$F$36,5<=Assum!$F$36+Assum!$F$37),MIN(J9,IF(Assum!$F$38=2,-PPMT(Assum!$F$35,5-Assum!$F$36,Assum!$F$37,'TIC_Funding'!$D$16),'TIC_Funding'!$D$16/Assum!$F$37)),0) -> 2643.3485 | K10: =IF(AND(6>Assum!$F$36,6<=Assum!$F$36+Assum!$F$37),MIN(K9,IF(Assum!$F$38=2,-PPMT(Assum!$F$35,6-Assum!$F$36,Assum!$F$37,'TIC_Funding'!$D$16),'TIC_Funding'!$D$16/Assum!$F$37)),0) -> 2797.9844 | L10: =IF(AND(7>Assum!$F$36,7<=Assum!$F$36+Assum!$F$37),MIN(L9,IF(Assum!$F$38=2,-PPMT(Assum!$F$35,7-Assum!$F$36,Assum!$F$37,'TIC_Funding'!$D$16),'TIC_Funding'!$D$16/Assum!$F$37)),0) -> 2961.6665 | M10: =IF(AND(8>Assum!$F$36,8<=Assum!$F$36+Assum!$F$37),MIN(M9,IF(Assum!$F$38=2,-PPMT(Assum!$F$35,8-Assum!$F$36,Assum!$F$37,'TIC_Funding'!$D$16),'TIC_Funding'!$D$16/Assum!$F$37)),0) -> 3134.924 | N10: =IF(AND(9>Assum!$F$36,9<=Assum!$F$36+Assum!$F$37),MIN(N9,IF(Assum!$F$38=2,-PPMT(Assum!$F$35,9-Assum!$F$36,Assum!$F$37,'TIC_Funding'!$D$16),'TIC_Funding'!$D$16/Assum!$F$37)),0) -> 3318.317 | O10: =IF(AND(10>Assum!$F$36,10<=Assum!$F$36+Assum!$F$37),MIN(O9,IF(Assum!$F$38=2,-PPMT(Assum!$F$35,10-Assum!$F$36,Assum!$F$37,'TIC_Funding'!$D$16),'TIC_Funding'!$D$16/Assum!$F$37)),0) -> 3512.4386 | P10: =IF(AND(11>Assum!$F$36,11<=Assum!$F$36+Assum!$F$37),MIN(P9,IF(Assum!$F$38=2,-PPMT(Assum!$F$35,11-Assum!$F$36,Assum!$F$37,'TIC_Funding'!$D$16),'TIC_Funding'!$D$16/Assum!$F$37)),0) -> 3717.9162 | Q10: =IF(AND(12>Assum!$F$36,12<=Assum!$F$36+Assum!$F$37),MIN(Q9,IF(Assum!$F$38=2,-PPMT(Assum!$F$35,12-Assum!$F$36,Assum!$F$37,'TIC_Funding'!$D$16),'TIC_Funding'!$D$16/Assum!$F$37)),0) -> 3935.4143 | R10: =IF(AND(13>Assum!$F$36,13<=Assum!$F$36+Assum!$F$37),MIN(R9,IF(Assum!$F$38=2,-PPMT(Assum!$F$35,13-Assum!$F$36,Assum!$F$37,'TIC_Funding'!$D$16),'TIC_Funding'!$D$16/Assum!$F$37)),0) -> 4165.6361 | S10: =IF(AND(14>Assum!$F$36,14<=Assum!$F$36+Assum!$F$37),MIN(S9,IF(Assum!$F$38=2,-PPMT(Assum!$F$35,14-Assum!$F$36,Assum!$F$37,'TIC_Funding'!$D$16),'TIC_Funding'!$D$16/Assum!$F$37)),0) -> 4409.3258 | T10: =IF(AND(15>Assum!$F$36,15<=Assum!$F$36+Assum!$F$37),MIN(T9,IF(Assum!$F$38=2,-PPMT(Assum!$F$35,15-Assum!$F$36,Assum!$F$37,'TIC_Funding'!$D$16),'TIC_Funding'!$D$16/Assum!$F$37)),0) -> 4667.2713 | U10: =IF(AND(16>Assum!$F$36,16<=Assum!$F$36+Assum!$F$37),MIN(U9,IF(Assum!$F$38=2,-PPMT(Assum!$F$35,16-Assum!$F$36,Assum!$F$37,'TIC_Funding'!$D$16),'TIC_Funding'!$D$16/Assum!$F$37)),0) -> 4940.3067 | V10: =IF(AND(17>Assum!$F$36,17<=Assum!$F$36+Assum!$F$37),MIN(V9,IF(Assum!$F$38=2,-PPMT(Assum!$F$35,17-Assum!$F$36,Assum!$F$37,'TIC_Funding'!$D$16),'TIC_Funding'!$D$16/Assum!$F$37)),0) -> 5229.3147 | W10: =IF(AND(18>Assum!$F$36,18<=Assum!$F$36+Assum!$F$37),MIN(W9,IF(Assum!$F$38=2,-PPMT(Assum!$F$35,18-Assum!$F$36,Assum!$F$37,'TIC_Funding'!$D$16),'TIC_Funding'!$D$16/Assum!$F$37)),0) -> 0 | X10: =IF(AND(19>Assum!$F$36,19<=Assum!$F$36+Assum!$F$37),MIN(X9,IF(Assum!$F$38=2,-PPMT(Assum!$F$35,19-Assum!$F$36,Assum!$F$37,'TIC_Funding'!$D$16),'TIC_Funding'!$D$16/Assum!$F$37)),0) -> 0 | Y10: =IF(AND(20>Assum!$F$36,20<=Assum!$F$36+Assum!$F$37),MIN(Y9,IF(Assum!$F$38=2,-PPMT(Assum!$F$35,20-Assum!$F$36,Assum!$F$37,'TIC_Funding'!$D$16),'TIC_Funding'!$D$16/Assum!$F$37)),0) -> 0
B11: 기말잔액 | C11: [KRWm] | F11: =F9-F10 -> 54290.366 | G11: =G9-G10 -> 54290.366 | H11: =H9-H10 -> 51931.123 | I11: =I9-I10 -> 49433.864 | J11: =J9-J10 -> 46790.516 | K11: =K9-K10 -> 43992.531 | L11: =L9-L10 -> 41030.865 | M11: =M9-M10 -> 37895.941 | ... Y11: =Y9-Y10 -> 0
B12: 이자비용 | C12: [KRWm] | D12: =SUM(F12:Y12) | F12: =(F9-F10*(Assum!$F$39-1)/(2*Assum!$F$39))*Assum!$F$35 -> 3175.9864 | G12: =(G9-G10*(Assum!$F$39-1)/(2*Assum!$F$39))*Assum!$F$35 -> 3175.9864 | H12: =(H9-H10*(Assum!$F$39-1)/(2*Assum!$F$39))*Assum!$F$35 -> 3141.4825 | I12: =(I9-I10*(Assum!$F$39-1)/(2*Assum!$F$39))*Assum!$F$35 -> 3001.4483 | J12: =(J9-J10*(Assum!$F$39-1)/(2*Assum!$F$39))*Assum!$F$35 -> 2853.2221 | K12: =(K9-K10*(Assum!$F$39-1)/(2*Assum!$F$39))*Assum!$F$35 -> 2696.3246 | L12: =(L9-L10*(Assum!$F$39-1)/(2*Assum!$F$39))*Assum!$F$35 -> 2530.2487 | M12: =(M9-M10*(Assum!$F$39-1)/(2*Assum!$F$39))*Assum!$F$35 -> 2354.4573 | ... Y12: =(Y9-Y10*(Assum!$F$39-1)/(2*Assum!$F$39))*Assum!$F$35 -> 0
B13: 원리금 합계(DS) | C13: [KRWm] | D13: =SUM(F13:Y13) | F13: =F10+F12 -> 3175.9864 | G13: =G10+G12 -> 3175.9864 | H13: =H10+H12 -> 5500.7256 | I13: =I10+I12 -> 5498.7072 | J13: =J10+J12 -> 5496.5706 | K13: =K10+K12 -> 5494.3091 | L13: =L10+L12 -> 5491.9152 | M13: =M10+M12 -> 5489.3813 | ... Y13: =Y10+Y12 -> 0
B15: DSRA (원리금상환적립금)
B16: DSRA 잔액(기말) | C16: [KRWm] | F16: =IF(1>=Assum!$F$36+Assum!$F$37,0,G13*Assum!$F$64/12) -> 1587.9932 | G16: =IF(2>=Assum!$F$36+Assum!$F$37,0,H13*Assum!$F$64/12) -> 2750.3628 | H16: =IF(3>=Assum!$F$36+Assum!$F$37,0,I13*Assum!$F$64/12) -> 2749.3536 | I16: =IF(4>=Assum!$F$36+Assum!$F$37,0,J13*Assum!$F$64/12) -> 2748.2853 | J16: =IF(5>=Assum!$F$36+Assum!$F$37,0,K13*Assum!$F$64/12) -> 2747.1545 | K16: =IF(6>=Assum!$F$36+Assum!$F$37,0,L13*Assum!$F$64/12) -> 2745.9576 | L16: =IF(7>=Assum!$F$36+Assum!$F$37,0,M13*Assum!$F$64/12) -> 2744.6907 | M16: =IF(8>=Assum!$F$36+Assum!$F$37,0,N13*Assum!$F$64/12) -> 2743.3496 | N16: =IF(9>=Assum!$F$36+Assum!$F$37,0,O13*Assum!$F$64/12) -> 2741.9301 | O16: =IF(10>=Assum!$F$36+Assum!$F$37,0,P13*Assum!$F$64/12) -> 2740.4275 | P16: =IF(11>=Assum!$F$36+Assum!$F$37,0,Q13*Assum!$F$64/12) -> 2738.8371 | Q16: =IF(12>=Assum!$F$36+Assum!$F$37,0,R13*Assum!$F$64/12) -> 2737.1536 | R16: =IF(13>=Assum!$F$36+Assum!$F$37,0,S13*Assum!$F$64/12) -> 2735.3716 | S16: =IF(14>=Assum!$F$36+Assum!$F$37,0,T13*Assum!$F$64/12) -> 2733.4854 | T16: =IF(15>=Assum!$F$36+Assum!$F$37,0,U13*Assum!$F$64/12) -> 2731.4888 | U16: =IF(16>=Assum!$F$36+Assum!$F$37,0,V13*Assum!$F$64/12) -> 2729.3754 | V16: =IF(17>=Assum!$F$36+Assum!$F$37,0,W13*Assum!$F$64/12) -> 0 | W16: =IF(18>=Assum!$F$36+Assum!$F$37,0,X13*Assum!$F$64/12) -> 0 | X16: =IF(19>=Assum!$F$36+Assum!$F$37,0,Y13*Assum!$F$64/12) -> 0 | Y16: =IF(20>=Assum!$F$36+Assum!$F$37,0,0*Assum!$F$64/12) -> 0
B17: DSRA 증감((+)적립/(-)환입) | C17: [KRWm] | D17: =SUM(F17:Y17) | F17: =F16-Assum!$F$23 -> -912.00679 | G17: =G16-F16 -> 1162.3696 | H17: =H16-G16 -> -1.00924 | I17: =I16-H16 -> -1.0682805 | J17: =J16-I16 -> -1.1307749 | K17: =K16-J16 -> -1.1969253 | L17: =L16-K16 -> -1.2669454 | M17: =M16-L16 -> -1.3410617 | N17: =N16-M16 -> -1.4195138 | ... Y17: =Y16-X16 -> 0
B19: 상환 종료 후 미상환 잔액 | C19: [KRWm] | D19: =Y11 -> 0 | F19: =IF(ABS(D19)<1,"완전상환 확인 (OK)","경고: 미상환 잔액 발생 — 원금상환 행 재산출 필요") -> 완전상환 확인 (OK)

Sheet IS(Y)
A1: E2E검증_방식2
A2: 추정 손익계산서 (연간)
B4: 손익계산서
B6: 구 분 | C6: unit | D6: 합 계 | E6: 건설기간 | F6: 1년차 | G6: 2년차 | H6: 3년차 | I6: 4년차 | J6: 5년차 | K6: 6년차 | L6: 7년차 | M6: 8년차 | N6: 9년차 | O6: 10년차 | P6: 11년차 | Q6: 12년차 | R6: 13년차 | S6: 14년차 | T6: 15년차 | U6: 16년차 | V6: 17년차 | W6: 18년차 | X6: 19년차 | Y6: 20년차
E7: 2027 | F7: 2028 | G7: 2029 | H7: 2030 | I7: 2031 | J7: 2032 | K7: 2033 | L7: 2034 | M7: 2035 | N7: 2036 | O7: 2037 | P7: 2038 | Q7: 2039 | R7: 2040 | S7: 2041 | T7: 2042 | U7: 2043 | V7: 2044 | W7: 2045 | X7: 2046 | Y7: 2047
B9: 영업수익 | C9: [KRWm] | D9: =SUM(F9:Y9) | F9: ='Revenue'!F16 -> 10146.252 | G9: ='Revenue'!G16 -> 10216.667 | H9: ='Revenue'!H16 -> 10287.571 | I9: ='Revenue'!I16 -> 10358.967 | J9: ='Revenue'!J16 -> 10430.858 | K9: ='Revenue'!K16 -> 10503.248 | L9: ='Revenue'!L16 -> 10576.141 | M9: ='Revenue'!M16 -> 10649.539 | ... Y9: ='Revenue'!Y16 -> 11571.081
B10: 영업비용 | C10: [KRWm] | D10: =SUM(F10:Y10) | F10: =-'Opex'!F12 -> -2200 | G10: =-'Opex'!G12 -> -2239.6 | H10: =-'Opex'!H12 -> -2279.9128 | I10: =-'Opex'!I12 -> -2320.9512 | J10: =-'Opex'!J12 -> -2362.7284 | K10: =-'Opex'!K12 -> -2405.2575 | L10: =-'Opex'!L12 -> -2448.5521 | M10: =-'Opex'!M12 -> -2492.626 | ... Y10: =-'Opex'!Y12 -> -3087.667
B11: EBITDA | C11: [KRWm] | D11: =SUM(F11:Y11) | F11: =F9+F10 -> 7946.2525 | G11: =G9+G10 -> 7977.0675 | H11: =H9+H10 -> 8007.6583 | I11: =I9+I10 -> 8038.0157 | J11: =J9+J10 -> 8068.1298 | K11: =K9+K10 -> 8097.9908 | L11: =L9+L10 -> 8127.5887 | M11: =M9+M10 -> 8156.9132 | ... Y11: =Y9+Y10 -> 8483.414
B12: 감가상각비 | C12: [KRWm] | D12: =SUM(F12:Y12) | F12: =IF(1<=Assum!$F$57,-'TIC_Funding'!$D$25,0) -> -3346.1304 | G12: =IF(2<=Assum!$F$57,-'TIC_Funding'!$D$25,0) -> -3346.1304 | H12: =IF(3<=Assum!$F$57,-'TIC_Funding'!$D$25,0) -> -3346.1304 | I12: =IF(4<=Assum!$F$57,-'TIC_Funding'!$D$25,0) -> -3346.1304 | J12: =IF(5<=Assum!$F$57,-'TIC_Funding'!$D$25,0) -> -3346.1304 | K12: =IF(6<=Assum!$F$57,-'TIC_Funding'!$D$25,0) -> -3346.1304 | L12: =IF(7<=Assum!$F$57,-'TIC_Funding'!$D$25,0) -> -3346.1304 | M12: =IF(8<=Assum!$F$57,-'TIC_Funding'!$D$25,0) -> -3346.1304 | N12: =IF(9<=Assum!$F$57,-'TIC_Funding'!$D$25,0) -> -3346.1304 | O12: =IF(10<=Assum!$F$57,-'TIC_Funding'!$D$25,0) -> -3346.1304 | P12: =IF(11<=Assum!$F$57,-'TIC_Funding'!$D$25,0) -> -3346.1304 | Q12: =IF(12<=Assum!$F$57,-'TIC_Funding'!$D$25,0) -> -3346.1304 | R12: =IF(13<=Assum!$F$57,-'TIC_Funding'!$D$25,0) -> -3346.1304 | S12: =IF(14<=Assum!$F$57,-'TIC_Funding'!$D$25,0) -> -3346.1304 | T12: =IF(15<=Assum!$F$57,-'TIC_Funding'!$D$25,0) -> -3346.1304 | U12: =IF(16<=Assum!$F$57,-'TIC_Funding'!$D$25,0) -> -3346.1304 | V12: =IF(17<=Assum!$F$57,-'TIC_Funding'!$D$25,0) -> -3346.1304 | W12: =IF(18<=Assum!$F$57,-'TIC_Funding'!$D$25,0) -> -3346.1304 | X12: =IF(19<=Assum!$F$57,-'TIC_Funding'!$D$25,0) -> 0 | Y12: =IF(20<=Assum!$F$57,-'TIC_Funding'!$D$25,0) -> 0
B13: 영업이익(EBIT) | C13: [KRWm] | D13: =SUM(F13:Y13) | F13: =F11+F12 -> 4600.122 | G13: =G11+G12 -> 4630.937 | H13: =H11+H12 -> 4661.5279 | I13: =I11+I12 -> 4691.8852 | J13: =J11+J12 -> 4721.9993 | K13: =K11+K12 -> 4751.8604 | L13: =L11+L12 -> 4781.4583 | M13: =M11+M12 -> 4810.7828 | ... Y13: =Y11+Y12 -> 8483.414
B14: 이자비용 | C14: [KRWm] | D14: =SUM(F14:Y14) | F14: =-'Debt'!F12 -> -3175.9864 | G14: =-'Debt'!G12 -> -3175.9864 | H14: =-'Debt'!H12 -> -3141.4825 | I14: =-'Debt'!I12 -> -3001.4483 | J14: =-'Debt'!J12 -> -2853.2221 | K14: =-'Debt'!K12 -> -2696.3246 | L14: =-'Debt'!L12 -> -2530.2487 | M14: =-'Debt'!M12 -> -2354.4573 | ... Y14: =-'Debt'!Y12 -> 0
B15: 법인세차감전순이익 | C15: [KRWm] | D15: =SUM(F15:Y15) | F15: =F13+F14 -> 1424.1356 | G15: =G13+G14 -> 1454.9506 | H15: =H13+H14 -> 1520.0454 | I15: =I13+I14 -> 1690.4369 | J15: =J13+J14 -> 1868.7772 | K15: =K13+K14 -> 2055.5357 | L15: =L13+L14 -> 2251.2096 | M15: =M13+M14 -> 2456.3254 | ... Y15: =Y13+Y14 -> 8483.414
B16: 이월결손금(기초) | C16: [KRWm] | F16: 0 | G16: =F20 -> 0 | H16: =G20 -> 0 | I16: =H20 -> 0 | J16: =I20 -> 0 | K16: =J20 -> 0 | L16: =K20 -> 0 | M16: =L20 -> 0 | N16: =M20 -> 0 | ... Y16: =X20 -> 0
B17: 결손금 공제액 | C17: [KRWm] | F17: =MIN(MAX(0,F15)*Assum!$F$60,F16) -> 0 | G17: =MIN(MAX(0,G15)*Assum!$F$60,G16) -> 0 | H17: =MIN(MAX(0,H15)*Assum!$F$60,H16) -> 0 | I17: =MIN(MAX(0,I15)*Assum!$F$60,I16) -> 0 | J17: =MIN(MAX(0,J15)*Assum!$F$60,J16) -> 0 | K17: =MIN(MAX(0,K15)*Assum!$F$60,K16) -> 0 | L17: =MIN(MAX(0,L15)*Assum!$F$60,L16) -> 0 | M17: =MIN(MAX(0,M15)*Assum!$F$60,M16) -> 0 | ... Y17: =MIN(MAX(0,Y15)*Assum!$F$60,Y16) -> 0
B18: 과세표준 | C18: [KRWm] | F18: =MAX(0,F15-F17) -> 1424.1356 | G18: =MAX(0,G15-G17) -> 1454.9506 | H18: =MAX(0,H15-H17) -> 1520.0454 | I18: =MAX(0,I15-I17) -> 1690.4369 | J18: =MAX(0,J15-J17) -> 1868.7772 | K18: =MAX(0,K15-K17) -> 2055.5357 | L18: =MAX(0,L15-L17) -> 2251.2096 | M18: =MAX(0,M15-M17) -> 2456.3254 | ... Y18: =MAX(0,Y15-Y17) -> 8483.414
B19: 법인세비용 | C19: [KRWm] | D19: =SUM(F19:Y19) | F19: =IF(Assum!$F$58=1,IF(F18<=200,F18*0.09,IF(F18<=20000,18+(F18-200)*0.19,3780+(F18-20000)*0.21)),F18*Assum!$F$59) -> 250.58577 | G19: =IF(Assum!$F$58=1,IF(G18<=200,G18*0.09,IF(G18<=20000,18+(G18-200)*0.19,3780+(G18-20000)*0.21)),G18*Assum!$F$59) -> 256.44062 | H19: =IF(Assum!$F$58=1,IF(H18<=200,H18*0.09,IF(H18<=20000,18+(H18-200)*0.19,3780+(H18-20000)*0.21)),H18*Assum!$F$59) -> 268.80863 | I19: =IF(Assum!$F$58=1,IF(I18<=200,I18*0.09,IF(I18<=20000,18+(I18-200)*0.19,3780+(I18-20000)*0.21)),I18*Assum!$F$59) -> 301.18302 | J19: =IF(Assum!$F$58=1,IF(J18<=200,J18*0.09,IF(J18<=20000,18+(J18-200)*0.19,3780+(J18-20000)*0.21)),J18*Assum!$F$59) -> 335.06768 | K19: =IF(Assum!$F$58=1,IF(K18<=200,K18*0.09,IF(K18<=20000,18+(K18-200)*0.19,3780+(K18-20000)*0.21)),K18*Assum!$F$59) -> 370.55179 | L19: =IF(Assum!$F$58=1,IF(L18<=200,L18*0.09,IF(L18<=20000,18+(L18-200)*0.19,3780+(L18-20000)*0.21)),L18*Assum!$F$59) -> 407.72982 | M19: =IF(Assum!$F$58=1,IF(M18<=200,M18*0.09,IF(M18<=20000,18+(M18-200)*0.19,3780+(M18-20000)*0.21)),M18*Assum!$F$59) -> 446.70183 | ... Y19: =IF(Assum!$F$58=1,IF(Y18<=200,Y18*0.09,IF(Y18<=20000,18+(Y18-200)*0.19,3780+(Y18-20000)*0.21)),Y18*Assum!$F$59) -> 1591.8487
B20: 이월결손금(기말) | C20: [KRWm] | F20: =F16-F17+MAX(0,-F15) -> 0 | G20: =G16-G17+MAX(0,-G15) -> 0 | H20: =H16-H17+MAX(0,-H15) -> 0 | I20: =I16-I17+MAX(0,-I15) -> 0 | J20: =J16-J17+MAX(0,-J15) -> 0 | K20: =K16-K17+MAX(0,-K15) -> 0 | L20: =L16-L17+MAX(0,-L15) -> 0 | M20: =M16-M17+MAX(0,-M15) -> 0 | ... Y20: =Y16-Y17+MAX(0,-Y15) -> 0
B21: 당기순이익 | C21: [KRWm] | D21: =SUM(F21:Y21) | F21: =F15-F19 -> 1173.5498 | G21: =G15-G19 -> 1198.51 | H21: =H15-H19 -> 1251.2368 | I21: =I15-I19 -> 1389.2539 | J21: =J15-J19 -> 1533.7096 | K21: =K15-K19 -> 1684.9839 | L21: =L15-L19 -> 1843.4798 | M21: =M15-M19 -> 2009.6236 | ... Y21: =Y15-Y19 -> 6891.5654
B23: EBITDA Margin | C23: [%] | F23: =IFERROR(F11/F9,0) -> 0.78317118 | G23: =IFERROR(G11/G9,0) -> 0.78078958 | H23: =IFERROR(H11/H9,0) -> 0.77838182 | I23: =IFERROR(I11/I9,0) -> 0.77594762 | J23: =IFERROR(J11/J9,0) -> 0.77348668 | K23: =IFERROR(K11/K9,0) -> 0.7709987 | L23: =IFERROR(L11/L9,0) -> 0.76848341 | M23: =IFERROR(M11/M9,0) -> 0.76594048 | ... Y23: =IFERROR(Y11/Y9,0) -> 0.73315656

Sheet CF(Y)
A1: E2E검증_방식2
A2: 추정 현금흐름표 (연간)
B4: 영업활동 현금흐름
B6: 구 분 | C6: unit | D6: 합 계 | E6: 건설기간 | F6: 1년차 | G6: 2년차 | H6: 3년차 | I6: 4년차 | J6: 5년차 | K6: 6년차 | L6: 7년차 | M6: 8년차 | N6: 9년차 | O6: 10년차 | P6: 11년차 | Q6: 12년차 | R6: 13년차 | S6: 14년차 | T6: 15년차 | U6: 16년차 | V6: 17년차 | W6: 18년차 | X6: 19년차 | Y6: 20년차
E7: 2027 | F7: 2028 | G7: 2029 | H7: 2030 | I7: 2031 | J7: 2032 | K7: 2033 | L7: 2034 | M7: 2035 | N7: 2036 | O7: 2037 | P7: 2038 | Q7: 2039 | R7: 2040 | S7: 2041 | T7: 2042 | U7: 2043 | V7: 2044 | W7: 2045 | X7: 2046 | Y7: 2047
B9: EBITDA | C9: [KRWm] | D9: =SUM(F9:Y9) | F9: ='IS(Y)'!F11 -> 7946.2525 | G9: ='IS(Y)'!G11 -> 7977.0675 | H9: ='IS(Y)'!H11 -> 8007.6583 | I9: ='IS(Y)'!I11 -> 8038.0157 | J9: ='IS(Y)'!J11 -> 8068.1298 | K9: ='IS(Y)'!K11 -> 8097.9908 | L9: ='IS(Y)'!L11 -> 8127.5887 | M9: ='IS(Y)'!M11 -> 8156.9132 | ... Y9: ='IS(Y)'!Y11 -> 8483.414
B10: 법인세 지급 | C10: [KRWm] | D10: =SUM(F10:Y10) | F10: =-'IS(Y)'!F19 -> -250.58577 | G10: =-'IS(Y)'!G19 -> -256.44062 | H10: =-'IS(Y)'!H19 -> -268.80863 | I10: =-'IS(Y)'!I19 -> -301.18302 | J10: =-'IS(Y)'!J19 -> -335.06768 | K10: =-'IS(Y)'!K19 -> -370.55179 | L10: =-'IS(Y)'!L19 -> -407.72982 | M10: =-'IS(Y)'!M19 -> -446.70183 | ... Y10: =-'IS(Y)'!Y19 -> -1591.8487
B11: CFADS (상환가능현금) | C11: [KRWm] | D11: =SUM(F11:Y11) | F11: =F9+F10 -> 7695.6667 | G11: =G9+G10 -> 7720.6269 | H11: =H9+H10 -> 7738.8497 | I11: =I9+I10 -> 7736.8326 | J11: =J9+J10 -> 7733.0621 | K11: =K9+K10 -> 7727.439 | L11: =L9+L10 -> 7719.8589 | M11: =M9+M10 -> 7710.2114 | ... Y11: =Y9+Y10 -> 6891.5654
B12: 재무활동 현금흐름
B13: 원리금 상환 | C13: [KRWm] | D13: =SUM(F13:Y13) | F13: =-'Debt'!F13 -> -3175.9864 | G13: =-'Debt'!G13 -> -3175.9864 | H13: =-'Debt'!H13 -> -5500.7256 | I13: =-'Debt'!I13 -> -5498.7072 | J13: =-'Debt'!J13 -> -5496.5706 | K13: =-'Debt'!K13 -> -5494.3091 | L13: =-'Debt'!L13 -> -5491.9152 | M13: =-'Debt'!M13 -> -5489.3813 | ... Y13: =-'Debt'!Y13 -> 0
B14: DSRA 증감 | C14: [KRWm] | D14: =SUM(F14:Y14) | F14: =-'Debt'!F17 -> 912.00679 | G14: =-'Debt'!G17 -> -1162.3696 | H14: =-'Debt'!H17 -> 1.00924 | I14: =-'Debt'!I17 -> 1.0682805 | J14: =-'Debt'!J17 -> 1.1307749 | K14: =-'Debt'!K17 -> 1.1969253 | L14: =-'Debt'!L17 -> 1.2669454 | M14: =-'Debt'!M17 -> 1.3410617 | ... Y14: =-'Debt'!Y17 -> 0
B15: 철거·복구비 | C15: [KRWm] | D15: =SUM(F15:Y15) | F15: =IF(1=Assum!$F$18,-Assum!$F$51,0) -> 0 | G15: =IF(2=Assum!$F$18,-Assum!$F$51,0) -> 0 | H15: =IF(3=Assum!$F$18,-Assum!$F$51,0) -> 0 | I15: =IF(4=Assum!$F$18,-Assum!$F$51,0) -> 0 | J15: =IF(5=Assum!$F$18,-Assum!$F$51,0) -> 0 | K15: =IF(6=Assum!$F$18,-Assum!$F$51,0) -> 0 | L15: =IF(7=Assum!$F$18,-Assum!$F$51,0) -> 0 | M15: =IF(8=Assum!$F$18,-Assum!$F$51,0) -> 0 | N15: =IF(9=Assum!$F$18,-Assum!$F$51,0) -> 0 | O15: =IF(10=Assum!$F$18,-Assum!$F$51,0) -> 0 | P15: =IF(11=Assum!$F$18,-Assum!$F$51,0) -> 0 | Q15: =IF(12=Assum!$F$18,-Assum!$F$51,0) -> 0 | R15: =IF(13=Assum!$F$18,-Assum!$F$51,0) -> 0 | S15: =IF(14=Assum!$F$18,-Assum!$F$51,0) -> 0 | T15: =IF(15=Assum!$F$18,-Assum!$F$51,0) -> 0 | U15: =IF(16=Assum!$F$18,-Assum!$F$51,0) -> 0 | V15: =IF(17=Assum!$F$18,-Assum!$F$51,0) -> 0 | W15: =IF(18=Assum!$F$18,-Assum!$F$51,0) -> 0 | X15: =IF(19=Assum!$F$18,-Assum!$F$51,0) -> 0 | Y15: =IF(20=Assum!$F$18,-Assum!$F$51,0) -> -1600
B17: 주주귀속 잉여현금(FCFE) | C17: [KRWm] | D17: =SUM(F17:Y17) | F17: =F11+F13+F14+F15 -> 5431.6871 | G17: =G11+G13+G14+G15 -> 3382.2708 | H17: =H11+H13+H14+H15 -> 2239.1333 | I17: =I11+I13+I14+I15 -> 2239.1938 | J17: =J11+J13+J14+J15 -> 2237.6223 | K17: =K11+K13+K14+K15 -> 2234.3269 | L17: =L11+L13+L14+L15 -> 2229.2106 | M17: =M11+M13+M14+M15 -> 2222.1711 | ... Y17: =Y11+Y13+Y14+Y15 -> 5291.5654
B18: 배당 및 현금계정
B19: 배당금 지급 | C19: [KRWm] | D19: =SUM(F19:Y19) | F19: =IF(AND(1>=Assum!$F$67,IF(ISNUMBER('DSCR'!F11),'DSCR'!F11,99)>=Assum!$F$66),MAX(0,F21+F17-IF(1=Assum!$F$18,0,Assum!$F$65)),0) -> 0 | G19: =IF(AND(2>=Assum!$F$67,IF(ISNUMBER('DSCR'!G11),'DSCR'!G11,99)>=Assum!$F$66),MAX(0,G21+G17-IF(2=Assum!$F$18,0,Assum!$F$65)),0) -> 0 | H19: =IF(AND(3>=Assum!$F$67,IF(ISNUMBER('DSCR'!H11),'DSCR'!H11,99)>=Assum!$F$66),MAX(0,H21+H17-IF(3=Assum!$F$18,0,Assum!$F$65)),0) -> 10053.091 | I19: =IF(AND(4>=Assum!$F$67,IF(ISNUMBER('DSCR'!I11),'DSCR'!I11,99)>=Assum!$F$66),MAX(0,I21+I17-IF(4=Assum!$F$18,0,Assum!$F$65)),0) -> 2239.1938 | J19: =IF(AND(5>=Assum!$F$67,IF(ISNUMBER('DSCR'!J11),'DSCR'!J11,99)>=Assum!$F$66),MAX(0,J21+J17-IF(5=Assum!$F$18,0,Assum!$F$65)),0) -> 2237.6223 | K19: =IF(AND(6>=Assum!$F$67,IF(ISNUMBER('DSCR'!K11),'DSCR'!K11,99)>=Assum!$F$66),MAX(0,K21+K17-IF(6=Assum!$F$18,0,Assum!$F$65)),0) -> 2234.3269 | L19: =IF(AND(7>=Assum!$F$67,IF(ISNUMBER('DSCR'!L11),'DSCR'!L11,99)>=Assum!$F$66),MAX(0,L21+L17-IF(7=Assum!$F$18,0,Assum!$F$65)),0) -> 2229.2106 | M19: =IF(AND(8>=Assum!$F$67,IF(ISNUMBER('DSCR'!M11),'DSCR'!M11,99)>=Assum!$F$66),MAX(0,M21+M17-IF(8=Assum!$F$18,0,Assum!$F$65)),0) -> 2222.1711 | N19: =IF(AND(9>=Assum!$F$67,IF(ISNUMBER('DSCR'!N11),'DSCR'!N11,99)>=Assum!$F$66),MAX(0,N21+N17-IF(9=Assum!$F$18,0,Assum!$F$65)),0) -> 2213.1002 | O19: =IF(AND(10>=Assum!$F$67,IF(ISNUMBER('DSCR'!O11),'DSCR'!O11,99)>=Assum!$F$66),MAX(0,O21+O17-IF(10=Assum!$F$18,0,Assum!$F$65)),0) -> 2201.8839 | P19: =IF(AND(11>=Assum!$F$67,IF(ISNUMBER('DSCR'!P11),'DSCR'!P11,99)>=Assum!$F$66),MAX(0,P21+P17-IF(11=Assum!$F$18,0,Assum!$F$65)),0) -> 2188.4018 | Q19: =IF(AND(12>=Assum!$F$67,IF(ISNUMBER('DSCR'!Q11),'DSCR'!Q11,99)>=Assum!$F$66),MAX(0,Q21+Q17-IF(12=Assum!$F$18,0,Assum!$F$65)),0) -> 2172.5266 | R19: =IF(AND(13>=Assum!$F$67,IF(ISNUMBER('DSCR'!R11),'DSCR'!R11,99)>=Assum!$F$66),MAX(0,R21+R17-IF(13=Assum!$F$18,0,Assum!$F$65)),0) -> 2154.1241 | S19: =IF(AND(14>=Assum!$F$67,IF(ISNUMBER('DSCR'!S11),'DSCR'!S11,99)>=Assum!$F$66),MAX(0,S21+S17-IF(14=Assum!$F$18,0,Assum!$F$65)),0) -> 2133.0526 | T19: =IF(AND(15>=Assum!$F$67,IF(ISNUMBER('DSCR'!T11),'DSCR'!T11,99)>=Assum!$F$66),MAX(0,T21+T17-IF(15=Assum!$F$18,0,Assum!$F$65)),0) -> 2109.1623 | U19: =IF(AND(16>=Assum!$F$67,IF(ISNUMBER('DSCR'!U11),'DSCR'!U11,99)>=Assum!$F$66),MAX(0,U21+U17-IF(16=Assum!$F$18,0,Assum!$F$65)),0) -> 2082.2952 | V19: =IF(AND(17>=Assum!$F$67,IF(ISNUMBER('DSCR'!V11),'DSCR'!V11,99)>=Assum!$F$66),MAX(0,V21+V17-IF(17=Assum!$F$18,0,Assum!$F$65)),0) -> 4779.4227 | W19: =IF(AND(18>=Assum!$F$67,IF(ISNUMBER('DSCR'!W11),'DSCR'!W11,99)>=Assum!$F$66),MAX(0,W21+W17-IF(18=Assum!$F$18,0,Assum!$F$65)),0) -> 7486.2431 | X19: =IF(AND(19>=Assum!$F$67,IF(ISNUMBER('DSCR'!X11),'DSCR'!X11,99)>=Assum!$F$66),MAX(0,X21+X17-IF(19=Assum!$F$18,0,Assum!$F$65)),0) -> 6871.1902 | Y19: =IF(AND(20>=Assum!$F$67,IF(ISNUMBER('DSCR'!Y11),'DSCR'!Y11,99)>=Assum!$F$66),MAX(0,Y21+Y17-IF(20=Assum!$F$18,0,Assum!$F$65)),0) -> 6291.5654
B21: 기초현금 | C21: [KRWm] | F21: 0 | G21: =F22 -> 5431.6871 | H21: =G22 -> 8813.9579 | I21: =H22 -> 1000 | J21: =I22 -> 1000 | K21: =J22 -> 1000 | L21: =K22 -> 1000 | M21: =L22 -> 1000 | N21: =M22 -> 1000 | ... Y21: =X22 -> 1000
B22: 기말현금 | C22: [KRWm] | F22: =F21+F17-F19 -> 5431.6871 | G22: =G21+G17-G19 -> 8813.9579 | H22: =H21+H17-H19 -> 1000 | I22: =I21+I17-I19 -> 1000 | J22: =J21+J17-J19 -> 1000 | K22: =K21+K17-K19 -> 1000 | L22: =L21+L17-L19 -> 1000 | M22: =M21+M17-M19 -> 1000 | ... Y22: =Y21+Y17-Y19 -> 0
B23: DSRA 잔액 | C23: [KRWm] | F23: ='Debt'!F16 -> 1587.9932 | G23: ='Debt'!G16 -> 2750.3628 | H23: ='Debt'!H16 -> 2749.3536 | I23: ='Debt'!I16 -> 2748.2853 | J23: ='Debt'!J16 -> 2747.1545 | K23: ='Debt'!K16 -> 2745.9576 | L23: ='Debt'!L16 -> 2744.6907 | M23: ='Debt'!M16 -> 2743.3496 | ... Y23: ='Debt'!Y16 -> 0

Sheet DSCR
A1: E2E검증_방식2
A2: 원리금 상환능력 분석
B4: DSCR
B6: 구 분 | C6: unit | D6: 합 계 | E6: 건설기간 | F6: 1년차 | G6: 2년차 | H6: 3년차 | I6: 4년차 | J6: 5년차 | K6: 6년차 | L6: 7년차 | M6: 8년차 | N6: 9년차 | O6: 10년차 | P6: 11년차 | Q6: 12년차 | R6: 13년차 | S6: 14년차 | T6: 15년차 | U6: 16년차 | V6: 17년차 | W6: 18년차 | X6: 19년차 | Y6: 20년차
E7: 2027 | F7: 2028 | G7: 2029 | H7: 2030 | I7: 2031 | J7: 2032 | K7: 2033 | L7: 2034 | M7: 2035 | N7: 2036 | O7: 2037 | P7: 2038 | Q7: 2039 | R7: 2040 | S7: 2041 | T7: 2042 | U7: 2043 | V7: 2044 | W7: 2045 | X7: 2046 | Y7: 2047
B9: CFADS | C9: [KRWm] | F9: ='CF(Y)'!F11 -> 7695.6667 | G9: ='CF(Y)'!G11 -> 7720.6269 | H9: ='CF(Y)'!H11 -> 7738.8497 | I9: ='CF(Y)'!I11 -> 7736.8326 | J9: ='CF(Y)'!J11 -> 7733.0621 | K9: ='CF(Y)'!K11 -> 7727.439 | L9: ='CF(Y)'!L11 -> 7719.8589 | M9: ='CF(Y)'!M11 -> 7710.2114 | ... Y9: ='CF(Y)'!Y11 -> 6891.5654
B10: 원리금(DS) | C10: [KRWm] | F10: ='Debt'!F13 -> 3175.9864 | G10: ='Debt'!G13 -> 3175.9864 | H10: ='Debt'!H13 -> 5500.7256 | I10: ='Debt'!I13 -> 5498.7072 | J10: ='Debt'!J13 -> 5496.5706 | K10: ='Debt'!K13 -> 5494.3091 | L10: ='Debt'!L13 -> 5491.9152 | M10: ='Debt'!M13 -> 5489.3813 | ... Y10: ='Debt'!Y13 -> 0
B11: 단순 DSCR | C11: [x] | F11: =IF(F10<=0.001,"-",F9/F10) -> 2.4230792 | G11: =IF(G10<=0.001,"-",G9/G10) -> 2.4309382 | H11: =IF(H10<=0.001,"-",H9/H10) -> 1.406878 | I11: =IF(I10<=0.001,"-",I9/I10) -> 1.4070276 | J11: =IF(J10<=0.001,"-",J9/J10) -> 1.4068885 | K11: =IF(K10<=0.001,"-",K9/K10) -> 1.4064442 | L11: =IF(L10<=0.001,"-",L9/L10) -> 1.405677 | M11: =IF(M10<=0.001,"-",M9/M10) -> 1.4045684 | ... Y11: =IF(Y10<=0.001,"-",Y9/Y10) -> -
B13: 최소 DSCR | C13: [x] | D13: =MIN(F11:Y11) -> 1.3755525
B14: 평균 DSCR | C14: [x] | D14: =IFERROR(AVERAGE(F11:Y11),0) -> 1.518567
B16: ※ 상환이 없는 연도는 "-"로 표시되며 최소/평균 산출에서 제외됩니다.

Sheet IRR
A1: E2E검증_방식2
A2: 수익성 분석 (IRR / NPV)
B4: Project IRR
B6: 구 분 | C6: unit | D6: 합 계 | E6: 건설기간 | F6: 1년차 | G6: 2년차 | H6: 3년차 | I6: 4년차 | J6: 5년차 | K6: 6년차 | L6: 7년차 | M6: 8년차 | N6: 9년차 | O6: 10년차 | P6: 11년차 | Q6: 12년차 | R6: 13년차 | S6: 14년차 | T6: 15년차 | U6: 16년차 | V6: 17년차 | W6: 18년차 | X6: 19년차 | Y6: 20년차
E7: 2027 | F7: 2028 | G7: 2029 | H7: 2030 | I7: 2031 | J7: 2032 | K7: 2033 | L7: 2034 | M7: 2035 | N7: 2036 | O7: 2037 | P7: 2038 | Q7: 2039 | R7: 2040 | S7: 2041 | T7: 2042 | U7: 2043 | V7: 2044 | W7: 2045 | X7: 2046 | Y7: 2047
B9: 총투자비 | C9: [KRWm] | E9: =-'TIC_Funding'!$D$10+Assum!$F$23 -> -63400.366 | F9: 0 | G9: 0 | H9: 0 | I9: 0 | J9: 0 | K9: 0 | L9: 0 | M9: 0 | N9: 0 | O9: 0 | P9: 0 | Q9: 0 | R9: 0 | S9: 0 | T9: 0 | U9: 0 | V9: 0 | W9: 0 | X9: 0 | Y9: 0
B10: EBITDA | C10: [KRWm] | E10: 0 | F10: ='IS(Y)'!F11 -> 7946.2525 | G10: ='IS(Y)'!G11 -> 7977.0675 | H10: ='IS(Y)'!H11 -> 8007.6583 | I10: ='IS(Y)'!I11 -> 8038.0157 | J10: ='IS(Y)'!J11 -> 8068.1298 | K10: ='IS(Y)'!K11 -> 8097.9908 | L10: ='IS(Y)'!L11 -> 8127.5887 | M10: ='IS(Y)'!M11 -> 8156.9132 | ... Y10: ='IS(Y)'!Y11 -> 8483.414
B11: 법인세 | C11: [KRWm] | E11: 0 | F11: =-'IS(Y)'!F19 -> -250.58577 | G11: =-'IS(Y)'!G19 -> -256.44062 | H11: =-'IS(Y)'!H19 -> -268.80863 | I11: =-'IS(Y)'!I19 -> -301.18302 | J11: =-'IS(Y)'!J19 -> -335.06768 | K11: =-'IS(Y)'!K19 -> -370.55179 | L11: =-'IS(Y)'!L19 -> -407.72982 | M11: =-'IS(Y)'!M19 -> -446.70183 | ... Y11: =-'IS(Y)'!Y19 -> -1591.8487
B12: 철거·복구비 | C12: [KRWm] | E12: 0 | F12: ='CF(Y)'!F15 -> 0 | G12: ='CF(Y)'!G15 -> 0 | H12: ='CF(Y)'!H15 -> 0 | I12: ='CF(Y)'!I15 -> 0 | J12: ='CF(Y)'!J15 -> 0 | K12: ='CF(Y)'!K15 -> 0 | L12: ='CF(Y)'!L15 -> 0 | M12: ='CF(Y)'!M15 -> 0 | ... Y12: ='CF(Y)'!Y15 -> -1600
B13: Net Cashflow | C13: [KRWm] | E13: =SUM(E9:E12) -> -63400.366 | F13: =SUM(F9:F12) -> 7695.6667 | G13: =SUM(G9:G12) -> 7720.6269 | H13: =SUM(H9:H12) -> 7738.8497 | I13: =SUM(I9:I12) -> 7736.8326 | J13: =SUM(J9:J12) -> 7733.0621 | K13: =SUM(K9:K12) -> 7727.439 | L13: =SUM(L9:L12) -> 7719.8589 | ... Y13: =SUM(Y9:Y12) -> 5291.5654
B15: Project IRR (세후) | C15: [%] | D15: =IRR(E13:Y13) -> 0.10364197
B16: NPV @ 할인율 | C16: [KRWm] | D16: =NPV(Assum!$F$71,F13:Y13)+E13 -> 23642.556
B18: Equity IRR
B20: 자본금 납입 | C20: [KRWm] | E20: =-'TIC_Funding'!$D$15 -> -11610 | F20: 0 | G20: 0 | H20: 0 | I20: 0 | J20: 0 | K20: 0 | L20: 0 | M20: 0 | N20: 0 | O20: 0 | P20: 0 | Q20: 0 | R20: 0 | S20: 0 | T20: 0 | U20: 0 | V20: 0 | W20: 0 | X20: 0 | Y20: 0
B21: FCFE | C21: [KRWm] | E21: 0 | F21: ='CF(Y)'!F17 -> 5431.6871 | G21: ='CF(Y)'!G17 -> 3382.2708 | H21: ='CF(Y)'!H17 -> 2239.1333 | I21: ='CF(Y)'!I17 -> 2239.1938 | J21: ='CF(Y)'!J17 -> 2237.6223 | K21: ='CF(Y)'!K17 -> 2234.3269 | L21: ='CF(Y)'!L17 -> 2229.2106 | M21: ='CF(Y)'!M17 -> 2222.1711 | ... Y21: ='CF(Y)'!Y17 -> 5291.5654
B22: Net Cashflow (FCFE base) | C22: [KRWm] | E22: =E20+E21 -> -11610 | F22: =F20+F21 -> 5431.6871 | G22: =G20+G21 -> 3382.2708 | H22: =H20+H21 -> 2239.1333 | I22: =I20+I21 -> 2239.1938 | J22: =J20+J21 -> 2237.6223 | K22: =K20+K21 -> 2234.3269 | L22: =L20+L21 -> 2229.2106 | ... Y22: =Y20+Y21 -> 5291.5654
B24: 배당금 | C24: [KRWm] | E24: =-'TIC_Funding'!$D$15 -> -11610 | F24: ='CF(Y)'!F19 -> 0 | G24: ='CF(Y)'!G19 -> 0 | H24: ='CF(Y)'!H19 -> 10053.091 | I24: ='CF(Y)'!I19 -> 2239.1938 | J24: ='CF(Y)'!J19 -> 2237.6223 | K24: ='CF(Y)'!K19 -> 2234.3269 | L24: ='CF(Y)'!L19 -> 2229.2106 | M24: ='CF(Y)'!M19 -> 2222.1711 | ... Y24: ='CF(Y)'!Y19 -> 6291.5654
B26: Equity IRR (FCFE 기준) | C26: [%] | D26: =IRR(E22:Y22) -> 0.2697522
B27: Equity IRR (배당 기준) | C27: [%] | D27: =IRR(E24:Y24) -> 0.21462725

Sheet Sensitivity
A1: E2E검증_방식2
A2: 민감도 분석 (재무모델 생성기 산출값)
B4: 이용률
B6: 변동값 | C6: Equity IRR | D6: Project IRR | E6: 최소 DSCR | F6: NPV [KRWm]
B7: 13.32 % | C7: 0.17999183 | D7: 0.08612758 | E7: 1.20738 | F7: 13699.531
B8: 14.06 % | C8: 0.22513194 | D8: 0.0950093 | E8: 1.2914662 | F8: 18671.044
B9: 14.80 % | C9: 0.2697522 | D9: 0.10364197 | E9: 1.3755525 | F9: 23642.556
B10: 15.54 % | C10: 0.31375902 | D10: 0.11205838 | E10: 1.4596387 | F10: 28614.069
B11: 16.28 % | C11: 0.35713067 | D11: 0.12028573 | E11: 1.5437249 | F11: 33585.582
B14: 차입 금리
B16: 변동값 | C16: Equity IRR | D16: Project IRR | E16: 최소 DSCR | F16: NPV [KRWm]
B17: 4.68 % | C17: 0.31668157 | D17: 0.10182788 | E17: 1.4815662 | F17: 22684.123
B18: 5.27 % | C18: 0.29278753 | D18: 0.10273727 | E18: 1.4265494 | F18: 23164.316
B19: 5.85 % | C19: 0.2697522 | D19: 0.10364197 | E19: 1.3755525 | F19: 23642.556
B20: 6.44 % | C20: 0.24683369 | D20: 0.10457282 | E20: 1.3266014 | F20: 24135.178
B21: 7.02 % | C21: 0.22486512 | D21: 0.10549789 | E21: 1.2811614 | F21: 24625.323
B24: 매출 단가
B26: 변동값 | C26: Equity IRR | D26: Project IRR | E26: 최소 DSCR | F26: NPV [KRWm]
B27: 154.80 원/kWh | C27: 0.17999183 | D27: 0.08612758 | E27: 1.20738 | F27: 13699.531
B28: 163.40 원/kWh | C28: 0.22513194 | D28: 0.0950093 | E28: 1.2914662 | F28: 18671.044
B29: 172.00 원/kWh | C29: 0.2697522 | D29: 0.10364197 | E29: 1.3755525 | F29: 23642.556
B30: 180.60 원/kWh | C30: 0.31375902 | D30: 0.11205838 | E30: 1.4596387 | F30: 28614.069
B31: 189.20 원/kWh | C31: 0.35713067 | D31: 0.12028573 | E31: 1.5437249 | F31: 33585.582
B34: ※ 민감도 표는 각 케이스를 별도 계산한 결과값이며 수식으로 연결되어 있지 않습니다.
