Workbook

Sheet 목차
B2: 샘플 태양광 100MW
B3: 재무모델 v2 (분기·5트랜치) — 재생E AI Agent 자동생성 · 2026-10-02
B6: 시트 | C6: 내용
B7: Report | C7: Executive Summary — 핵심 KPI
B8: 입력값 | C8: 화면에서 입력한 원본 값 — Funding 등이 이 시트를 참조
B9: Funding | C9: 자금조달 — 자본금 + 5트랜치 조건
B10: Debt | C10: 트랜치별 상환 스케줄 (A/B/C/D/후순위) + 합계
B11: Revenue | C11: 발전량 · 매출
B12: Opex | C12: 운영비 (선순위/후순위)
B13: IS(Q) | C13: 분기 손익계산서
B14: CF(Q) | C14: 분기 현금흐름 · DSCR · 배당
B16: ※ 입력값 시트(노란 탭) 외의 모든 값은 수식입니다. 노란 셀을 고치면 세금·DSCR·배당·IRR 까지 전부 다시 계산됩니다. 회색 셀(거치·상환·방식·투입순서, DSRA 적립기준)은 스케줄의 모양을 정하는 값이라 화면에서 다시 생성해야 합니다. 각 계산 시트 맨 아래 "가정" 블록이 입력값 시트를 참조하는 유일한 곳입니다.

Sheet Report
A1: 샘플 태양광 100MW
A2: Executive Summary (v2 · 분기 · 5트랜치)
B4: 사업 개요
B6: 사업명 | D6: ='입력값'!C6 -> 샘플 태양광 100MW
B7: 설비용량 [MW] | D7: ='입력값'!C7 -> 100
B8: 총 기간 수(분기) | D8: 86
B9: 건설 개시 | D9: 2024-06
B11: 재원조달
B13: 총투자비(TIC) [KRWm] | D13: ='Funding'!C15 -> 144794.28
B14: 건설이자(IDC) [KRWm] | D14: ='Funding'!C14 -> 3725.2771
B15: 자기자본 [KRWm] | D15: ='Funding'!C7 -> 15000
B16: 차입금 합계 [KRWm] | D16: ='Funding'!C10 -> 126069
B18: 수익성 지표
B20: Equity IRR (배당) [%] | D20: ='CF(Q)'!D67 -> 0.14800228 | E20: 출자자가 실제로 받는 배당 기준(세후) — 가장 보수적인 대표 수익률
B21: Equity IRR (FCFE) 세전 [%] | D21: ='CF(Q)'!D65 -> 0.19725566 | E21: 원리금 갚고 남은 현금 전부가 출자자 몫이라고 볼 때, 법인세 전
B22: Equity IRR (FCFE) 세후 [%] | D22: ='CF(Q)'!D66 -> 0.16514145 | E22: 위와 같되 법인세 후 — 배당 제한(DSCR·최소현금·배당가능이익)이 없다고 본 값
B23: Project IRR 세전 [%] | D23: ='CF(Q)'!D63 -> 0.084758692 | E23: 차입 없이 사업 전체(총사업비 vs 영업현금흐름)의 수익률, 법인세 전
B24: Project IRR 세후 [%] | D24: ='CF(Q)'!D64 -> 0.076956715 | E24: 위와 같되 법인세 후
B25: Investor IRR [%] | D25: ='CF(Q)'!D68 -> 0.079348567 | E25: 출자자+대주단 합산 — 자본·대출 투입 vs 원리금·이자·배당 회수 (원본 IRR 시트 정의)
B26: 최소 단순DSCR(연 합산) [x] | D26: ='CF(Q)'!D47 -> 1.0703256
B27: 최소 누적DSCR [x] | D27: ='CF(Q)'!D48 -> 1.254816
B28: 총영업수익(전체기간) [KRWm] | D28: ='Revenue'!D14 -> 405788.89
B29: 총영업비용(전체기간) [KRWm] | D29: ='Opex'!D10 -> 106510.05
B30: 총선순위이자 [KRWm] | D30: ='Debt'!D45 -> 64000.879
B31: 총법인세 [KRWm] | D31: =-'IS(Q)'!D28 -> 19544.19
B32: 총배당(연차+청산) [KRWm] | D32: ='CF(Q)'!D16 -> 92664.772

Sheet 입력값
A1: 샘플 태양광 100MW
A2: 입력값 — 화면에서 입력한 값 (다른 시트가 이 시트를 참조)
B4: 사업 기본 가정
B6: 사업명 | C6: 샘플 태양광 100MW
B7: 설비용량[MW] | C7: 100
B8: 총사업비[억원] | C8: 1410.69
B9: 자기자본[억원] | C9: 150
B10: 판매단가[원/kWh] | C10: 154.8
B11: 판매단가 에스컬레이션[%/yr] | C11: 0
B12: 발전량 열화율[%/yr] | C12: 0.5
B13: 소내소비율[%] | C13: 0
B14: 일조시간[h/day] | C14: 3.77
B15: 상각대상 비율(TIC 대비)[%] | C15: 95
B16: 감가상각 내용연수[yr] | C16: 20
B17: 철거비(복구충당부채)[억원] | C17: 20
B18: 운영비 총액[억원/yr] | C18: 49.8
... B28: 배당 개시 운영연차 | C28: 2
B30: 법인세 가정
B32: 이월결손금 공제한도[%] | C32: 80
B33: 최저한세율[%] | C33: 0
B34: 통합투자세액공제율[%] | C34: 0
B35: 지방소득세율(법인세 대비)[%] | C35: 10
B36: 세액공제 농특세율[%] | C36: 0
B38: 트랜치 조건
B40: 트랜치 | C40: 금액[억원] | D40: 건설금리[%] | E40: 운영금리[%] | F40: 거치(yr) | G40: 상환(yr) | H40: 방식 | I40: 투입순서
B41: 선순위A | C41: 800 | D41: 0.056 | E41: 0.056 | F41: 2 | G41: 16 | H41: 1 | I41: 2
B42: 선순위B | C42: 460.69 | D42: 0.055 | E42: 0.055 | F42: 2 | G42: 16 | H42: 1 | I42: 2
B43: 자본금 | C43: =C9 -> 150 | I43: 1
B45: 총사업비 지출 스케줄 (건설 분기별 비중)
B47: 구 분 | C47: unit | D47: 합 계 | E47: 2024-06-30 | F47: 2024-09-30 | G47: 2024-12-31 | H47: 2025-03-31 | I47: 2025-06-30 | J47: 2025-09-30 | K47: 2025-12-31 | L47: 2026-03-31 | M47: 2026-06-30 | N47: 2026-09-30 | O47: 2026-12-31 | P47: 2027-03-31 | Q47: 2027-06-30 | R47: 2027-09-30 | S47: 2027-12-31 | T47: 2028-03-31 | U47: 2028-06-30 | V47: 2028-09-30 | W47: 2028-12-31 | X47: 2029-03-31 | Y47: 2029-06-30 | Z47: 2029-09-30 | AA47: 2029-12-31 | AB47: 2030-03-31 | AC47: 2030-06-30 | AD47: 2030-09-30 | AE47: 2030-12-31 | AF47: 2031-03-31 | AG47: 2031-06-30 | AH47: 2031-09-30 | AI47: 2031-12-31 | AJ47: 2032-03-31 | AK47: 2032-06-30 | AL47: 2032-09-30 | AM47: 2032-12-31 | AN47: 2033-03-31 | AO47: 2033-06-30 | AP47: 2033-09-30 | AQ47: 2033-12-31 | AR47: 2034-03-31 | AS47: 2034-06-30 | AT47: 2034-09-30 | AU47: 2034-12-31 | AV47: 2035-03-31 | AW47: 2035-06-30 | AX47: 2035-09-30 | AY47: 2035-12-31 | AZ47: 2036-03-31 | BA47: 2036-06-30 | BB47: 2036-09-30 | BC47: 2036-12-31 | BD47: 2037-03-31 | BE47: 2037-06-30 | BF47: 2037-09-30 | BG47: 2037-12-31 | BH47: 2038-03-31 | BI47: 2038-06-30 | BJ47: 2038-09-30 | BK47: 2038-12-31 | BL47: 2039-03-31 | BM47: 2039-06-30 | BN47: 2039-09-30 | BO47: 2039-12-31 | BP47: 2040-03-31 | BQ47: 2040-06-30 | BR47: 2040-09-30 | BS47: 2040-12-31 | BT47: 2041-03-31 | BU47: 2041-06-30 | BV47: 2041-09-30 | BW47: 2041-12-31 | BX47: 2042-03-31 | BY47: 2042-06-30 | BZ47: 2042-09-30 | CA47: 2042-12-31 | CB47: 2043-03-31 | CC47: 2043-06-30 | CD47: 2043-09-30 | CE47: 2043-12-31 | CF47: 2044-03-31 | CG47: 2044-06-30 | CH47: 2044-09-30 | CI47: 2044-12-31 | CJ47: 2045-03-31 | CK47: 2045-06-30 | CL47: 2045-09-30
B49: 지출 비중 | C49: [비율] | D49: =SUM(E49:CL49) -> 1 | E49: 0.1 | F49: 0.15 | G49: 0.2 | H49: 0.25 | I49: 0.2 | J49: 0.1
B51: 사업자 구성
B53: 사업자 | C53: 지분율[%]
B54: 출자자1 | C54: 60
B55: 출자자2 | C55: 40
B57: ※ 노란색 셀 = 여기서 고치면 다른 시트가 전부 따라 계산됩니다(재무모델링 관례). 이 시트 외의 모든 값은 이 시트를 참조하는 수식입니다.
B58: ※ 회색 셀(거치·상환·방식·투입순서, DSRA 적립기준) = 스케줄의 "모양"을 정하는 값이라 열 구성을 다시 만들어야 합니다. 엑셀에서 고쳐도 상환 스케줄은 따라오지 않으니, 이 값들을 바꾸려면 화면(HTML)에서 고친 뒤 다시 생성하세요.

Sheet Funding
A1: 샘플 태양광 100MW
A2: 자금조달 — 자본금 + 5개 트랜치
B4: 트랜치 조건
B6: 트랜치 | C6: 금액[KRWm] | D6: 투입순서 | E6: 건설금리 | F6: 운영금리 | G6: 거치(yr) | H6: 상환(yr) | I6: 방식 | J6: 상환개시
B7: 자본금 | C7: ='입력값'!C9*100 -> 15000
B8: 선순위A | C8: ='입력값'!C41*100 -> 80000 | E8: ='입력값'!D41 -> 0.056 | F8: ='입력값'!E41 -> 0.056 | G8: ='입력값'!F41 -> 2 | H8: ='입력값'!G41 -> 16 | I8: ='입력값'!H41 -> 1 | J8: 2026-12-31
B9: 선순위B | C9: ='입력값'!C42*100 -> 46069 | E9: ='입력값'!D42 -> 0.055 | F9: ='입력값'!E42 -> 0.055 | G9: ='입력값'!F42 -> 2 | H9: ='입력값'!G42 -> 16 | I9: ='입력값'!H42 -> 1 | J9: 2026-12-31
B10: 차입금 합계 | C10: =C8+C9 -> 126069
B12: 건설이자(IDC)
B14: IDC 합계[KRWm] | C14: ='Debt'!D12 -> 3725.2771
B15: 총투자비(TIC)[KRWm] | C15: =$D$30*100+'Debt'!D12 -> 144794.28
B16: 총사업비(건설이자 제외)[KRWm] | C16: ='입력값'!C8*100 -> 141069
B17: 총조달 소요액[KRWm] (= 총사업비 + DSRA + 건설이자) | C17: =$D$30*100+$D$32*100+'Debt'!D12 -> 149794.28
B18: 조달 약정 합계[KRWm] (= 자본금 + 트랜치 약정) | C18: =$D$31*100+$D$33*100+$D$34*100 -> 141069
B19: 조달 과부족[KRWm] (조달 − 소요, 0 이상이어야 함) | C19: =C18-C17 -> -8725.2771 | E19: =IF(C18-C17>=-1,"조달 충족 (OK)","경고: 조달 부족 — 못 빌린 돈이 공짜로 조달된 셈이 되어 이자가 과소계상됩니다") -> 경고: 조달 부족 — 못 빌린 돈이 공짜로 조달된 셈이 되어 이자가 과소계상됩니다
B21: 사업자 구성 (지분)
B23: 사업자 | C23: 지분율 | D23: 출자금액[KRWm] | E23: 누적배당[KRWm]
B24: ='입력값'!B54 -> 출자자1 | C24: ='입력값'!C54/100 -> 0.6 | D24: 9000 | E24: 55598.863
B25: ='입력값'!B55 -> 출자자2 | C25: ='입력값'!C55/100 -> 0.4 | D25: 6000 | E25: 37065.909
B28: 가정 (입력값 연결) — 이 시트의 계산이 쓰는 원천값 | D28: 값
B29: ※ 입력값 시트는 여기서만 참조합니다(초록 글자 = 입력값 연결). 위의 분기 계산은 이 셀들만 참조하므로, 값을 바꾸려면 입력값 시트를 고치세요.
B30: 총사업비[억원] | C30: C8 | D30: ='입력값'!C8 -> 1410.69
B31: 자기자본[억원] | C31: C9 | D31: ='입력값'!C9 -> 150
B32: DSRA 최초 적립액[억원] | C32: C23 | D32: ='입력값'!C23 -> 50
B33: 선순위A · 금액[억원] | C33: C41 | D33: ='입력값'!C41 -> 800
B34: 선순위B · 금액[억원] | C34: C42 | D34: ='입력값'!C42 -> 460.69

Sheet Debt
A1: 샘플 태양광 100MW
A2: 차입금 상환 스케줄 — 건설기간 인출 + 트랜치별 상환
B4: 건설기간 자금조달 (인출·건설이자)
B6: 구 분 | C6: unit | D6: 합 계 | E6: 2024-06-30 | F6: 2024-09-30 | G6: 2024-12-31 | H6: 2025-03-31 | I6: 2025-06-30 | J6: 2025-09-30 | K6: 2025-12-31 | L6: 2026-03-31 | M6: 2026-06-30 | N6: 2026-09-30 | O6: 2026-12-31 | P6: 2027-03-31 | Q6: 2027-06-30 | R6: 2027-09-30 | S6: 2027-12-31 | T6: 2028-03-31 | U6: 2028-06-30 | V6: 2028-09-30 | W6: 2028-12-31 | X6: 2029-03-31 | Y6: 2029-06-30 | Z6: 2029-09-30 | AA6: 2029-12-31 | AB6: 2030-03-31 | AC6: 2030-06-30 | AD6: 2030-09-30 | AE6: 2030-12-31 | AF6: 2031-03-31 | AG6: 2031-06-30 | AH6: 2031-09-30 | AI6: 2031-12-31 | AJ6: 2032-03-31 | AK6: 2032-06-30 | AL6: 2032-09-30 | AM6: 2032-12-31 | AN6: 2033-03-31 | AO6: 2033-06-30 | AP6: 2033-09-30 | AQ6: 2033-12-31 | AR6: 2034-03-31 | AS6: 2034-06-30 | AT6: 2034-09-30 | AU6: 2034-12-31 | AV6: 2035-03-31 | AW6: 2035-06-30 | AX6: 2035-09-30 | AY6: 2035-12-31 | AZ6: 2036-03-31 | BA6: 2036-06-30 | BB6: 2036-09-30 | BC6: 2036-12-31 | BD6: 2037-03-31 | BE6: 2037-06-30 | BF6: 2037-09-30 | BG6: 2037-12-31 | BH6: 2038-03-31 | BI6: 2038-06-30 | BJ6: 2038-09-30 | BK6: 2038-12-31 | BL6: 2039-03-31 | BM6: 2039-06-30 | BN6: 2039-09-30 | BO6: 2039-12-31 | BP6: 2040-03-31 | BQ6: 2040-06-30 | BR6: 2040-09-30 | BS6: 2040-12-31 | BT6: 2041-03-31 | BU6: 2041-06-30 | BV6: 2041-09-30 | BW6: 2041-12-31 | BX6: 2042-03-31 | BY6: 2042-06-30 | BZ6: 2042-09-30 | CA6: 2042-12-31 | CB6: 2043-03-31 | CC6: 2043-06-30 | CD6: 2043-09-30 | CE6: 2043-12-31 | CF6: 2044-03-31 | CG6: 2044-06-30 | CH6: 2044-09-30 | CI6: 2044-12-31 | CJ6: 2045-03-31 | CK6: 2045-06-30 | CL6: 2045-09-30
B8: 공사비 지출 | C8: [KRWm] | D8: =SUM(E8:CL8) -> 141069 | E8: =E64*$D$56*100 -> 14106.9 | F8: =F64*$D$56*100 -> 21160.35 | G8: =G64*$D$56*100 -> 28213.8 | H8: =H64*$D$56*100 -> 35267.25 | I8: =I64*$D$56*100 -> 28213.8 | J8: =J64*$D$56*100 -> 14106.9 | K8: 0 | L8: 0 | M8: 0 | N8: 0 | O8: 0 | P8: 0 | Q8: 0 | R8: 0 | S8: 0 | T8: 0 | U8: 0 | V8: 0 | W8: 0 | X8: 0 | Y8: 0 | Z8: 0 | AA8: 0 | AB8: 0 | AC8: 0 | AD8: 0 | AE8: 0 | AF8: 0 | AG8: 0 | AH8: 0 | AI8: 0 | AJ8: 0 | AK8: 0 | AL8: 0 | AM8: 0 | AN8: 0 | AO8: 0 | AP8: 0 | AQ8: 0 | AR8: 0 | AS8: 0 | AT8: 0 | AU8: 0 | AV8: 0 | AW8: 0 | AX8: 0 | AY8: 0 | AZ8: 0 | BA8: 0 | BB8: 0 | BC8: 0 | BD8: 0 | BE8: 0 | BF8: 0 | BG8: 0 | BH8: 0 | BI8: 0 | BJ8: 0 | BK8: 0 | BL8: 0 | BM8: 0 | BN8: 0 | BO8: 0 | BP8: 0 | BQ8: 0 | BR8: 0 | BS8: 0 | BT8: 0 | BU8: 0 | BV8: 0 | BW8: 0 | BX8: 0 | BY8: 0 | BZ8: 0 | CA8: 0 | CB8: 0 | CC8: 0 | CD8: 0 | CE8: 0 | CF8: 0 | CG8: 0 | CH8: 0 | CI8: 0 | CJ8: 0 | CK8: 0 | CL8: 0
B9: DSRA 적립 | C9: [KRWm] | D9: =SUM(E9:CL9) -> 5000 | E9: 0 | F9: 0 | G9: 0 | H9: 0 | I9: 0 | J9: ='입력값'!C23*100 -> 5000 | K9: 0 | L9: 0 | M9: 0 | N9: 0 | O9: 0 | P9: 0 | Q9: 0 | R9: 0 | S9: 0 | T9: 0 | U9: 0 | V9: 0 | W9: 0 | X9: 0 | Y9: 0 | Z9: 0 | AA9: 0 | AB9: 0 | AC9: 0 | AD9: 0 | AE9: 0 | AF9: 0 | AG9: 0 | AH9: 0 | AI9: 0 | AJ9: 0 | AK9: 0 | AL9: 0 | AM9: 0 | AN9: 0 | AO9: 0 | AP9: 0 | AQ9: 0 | AR9: 0 | AS9: 0 | AT9: 0 | AU9: 0 | AV9: 0 | AW9: 0 | AX9: 0 | AY9: 0 | AZ9: 0 | BA9: 0 | BB9: 0 | BC9: 0 | BD9: 0 | BE9: 0 | BF9: 0 | BG9: 0 | BH9: 0 | BI9: 0 | BJ9: 0 | BK9: 0 | BL9: 0 | BM9: 0 | BN9: 0 | BO9: 0 | BP9: 0 | BQ9: 0 | BR9: 0 | BS9: 0 | BT9: 0 | BU9: 0 | BV9: 0 | BW9: 0 | BX9: 0 | BY9: 0 | BZ9: 0 | CA9: 0 | CB9: 0 | CC9: 0 | CD9: 0 | CE9: 0 | CF9: 0 | CG9: 0 | CH9: 0 | CI9: 0 | CJ9: 0 | CK9: 0 | CL9: 0
B10: 선순위A 건설이자 | C10: [KRWm] | D10: =SUM(E10:CL10) -> 2379.4881 | E10: 0 | F10: =E15*$D$59/4 -> 0 | G10: =F15*$D$59/4 -> 180.05473 | H10: =G15*$D$59/4 -> 433.21112 | I10: =H15*$D$59/4 -> 752.55159 | J10: =I15*$D$59/4 -> 1013.6706 | K10: 0 | L10: 0 | M10: 0 | N10: 0 | O10: 0 | P10: 0 | Q10: 0 | R10: 0 | S10: 0 | T10: 0 | U10: 0 | V10: 0 | W10: 0 | X10: 0 | Y10: 0 | Z10: 0 | AA10: 0 | AB10: 0 | AC10: 0 | AD10: 0 | AE10: 0 | AF10: 0 | AG10: 0 | AH10: 0 | AI10: 0 | AJ10: 0 | AK10: 0 | AL10: 0 | AM10: 0 | AN10: 0 | AO10: 0 | AP10: 0 | AQ10: 0 | AR10: 0 | AS10: 0 | AT10: 0 | AU10: 0 | AV10: 0 | AW10: 0 | AX10: 0 | AY10: 0 | AZ10: 0 | BA10: 0 | BB10: 0 | BC10: 0 | BD10: 0 | BE10: 0 | BF10: 0 | BG10: 0 | BH10: 0 | BI10: 0 | BJ10: 0 | BK10: 0 | BL10: 0 | BM10: 0 | BN10: 0 | BO10: 0 | BP10: 0 | BQ10: 0 | BR10: 0 | BS10: 0 | BT10: 0 | BU10: 0 | BV10: 0 | BW10: 0 | BX10: 0 | BY10: 0 | BZ10: 0 | CA10: 0 | CB10: 0 | CC10: 0 | CD10: 0 | CE10: 0 | CF10: 0 | CG10: 0 | CH10: 0 | CI10: 0 | CJ10: 0 | CK10: 0 | CL10: 0
B11: 선순위B 건설이자 | C11: [KRWm] | D11: =SUM(E11:CL11) -> 1345.7891 | E11: 0 | F11: =E16*$D$62/4 -> 0 | G11: =F16*$D$62/4 -> 101.83522 | H11: =G16*$D$62/4 -> 245.01522 | I11: =H16*$D$62/4 -> 425.62756 | J11: =I16*$D$62/4 -> 573.31107 | K11: 0 | L11: 0 | M11: 0 | N11: 0 | O11: 0 | P11: 0 | Q11: 0 | R11: 0 | S11: 0 | T11: 0 | U11: 0 | V11: 0 | W11: 0 | X11: 0 | Y11: 0 | Z11: 0 | AA11: 0 | AB11: 0 | AC11: 0 | AD11: 0 | AE11: 0 | AF11: 0 | AG11: 0 | AH11: 0 | AI11: 0 | AJ11: 0 | AK11: 0 | AL11: 0 | AM11: 0 | AN11: 0 | AO11: 0 | AP11: 0 | AQ11: 0 | AR11: 0 | AS11: 0 | AT11: 0 | AU11: 0 | AV11: 0 | AW11: 0 | AX11: 0 | AY11: 0 | AZ11: 0 | BA11: 0 | BB11: 0 | BC11: 0 | BD11: 0 | BE11: 0 | BF11: 0 | BG11: 0 | BH11: 0 | BI11: 0 | BJ11: 0 | BK11: 0 | BL11: 0 | BM11: 0 | BN11: 0 | BO11: 0 | BP11: 0 | BQ11: 0 | BR11: 0 | BS11: 0 | BT11: 0 | BU11: 0 | BV11: 0 | BW11: 0 | BX11: 0 | BY11: 0 | BZ11: 0 | CA11: 0 | CB11: 0 | CC11: 0 | CD11: 0 | CE11: 0 | CF11: 0 | CG11: 0 | CH11: 0 | CI11: 0 | CJ11: 0 | CK11: 0 | CL11: 0
B12: 건설이자 합계(당기) | C12: [KRWm] | D12: =SUM(E12:CL12) -> 3725.2771 | E12: =E10+E11 -> 0 | F12: =F10+F11 -> 0 | G12: =G10+G11 -> 281.88995 | H12: =H10+H11 -> 678.22634 | I12: =I10+I11 -> 1178.1791 | J12: =J10+J11 -> 1586.9817 | K12: =K10+K11 -> 0 | L12: =L10+L11 -> 0 | ... CL12: =CL10+CL11 -> 0
B13: 누적 소요액 | C13: [KRWm] | E13: =E8+E9+E12 -> 14106.9 | F13: =E13+F8+F9+F12 -> 35267.25 | G13: =F13+G8+G9+G12 -> 63762.94 | H13: =G13+H8+H9+H12 -> 99708.416 | I13: =H13+I8+I9+I12 -> 129100.4 | J13: =I13+J8+J9+J12 -> 149794.28 | K13: =J13+K8+K9+K12 -> 149794.28 | L13: =K13+L8+L9+L12 -> 149794.28 | M13: =L13+M8+M9+M12 -> 149794.28 | ... CL13: =CK13+CL8+CL9+CL12 -> 149794.28
B14: 자본금 누적인출 | C14: [KRWm] | E14: =MIN(MAX(E13-(0),0),$D$57*100)*($D$57*100)/IF(($D$57*100)=0,1,$D$57*100) -> 14106.9 | F14: =MIN(MAX(F13-(0),0),$D$57*100)*($D$57*100)/IF(($D$57*100)=0,1,$D$57*100) -> 15000 | G14: =MIN(MAX(G13-(0),0),$D$57*100)*($D$57*100)/IF(($D$57*100)=0,1,$D$57*100) -> 15000 | H14: =MIN(MAX(H13-(0),0),$D$57*100)*($D$57*100)/IF(($D$57*100)=0,1,$D$57*100) -> 15000 | I14: =MIN(MAX(I13-(0),0),$D$57*100)*($D$57*100)/IF(($D$57*100)=0,1,$D$57*100) -> 15000 | J14: =MIN(MAX(J13-(0),0),$D$57*100)*($D$57*100)/IF(($D$57*100)=0,1,$D$57*100) -> 15000 | K14: =MIN(MAX(K13-(0),0),$D$57*100)*($D$57*100)/IF(($D$57*100)=0,1,$D$57*100) -> 15000 | L14: =MIN(MAX(L13-(0),0),$D$57*100)*($D$57*100)/IF(($D$57*100)=0,1,$D$57*100) -> 15000 | ... CL14: =MIN(MAX(CL13-(0),0),$D$57*100)*($D$57*100)/IF(($D$57*100)=0,1,$D$57*100) -> 15000
B15: 선순위A 누적인출 | C15: [KRWm] | E15: =MIN(MAX(E13-($D$57*100),0),$D$58*100+$D$61*100)*($D$58*100)/IF(($D$58*100+$D$61*100)=0,1,$D$58*100+$D$61*100) -> 0 | F15: =MIN(MAX(F13-($D$57*100),0),$D$58*100+$D$61*100)*($D$58*100)/IF(($D$58*100+$D$61*100)=0,1,$D$58*100+$D$61*100) -> 12861.052 | G15: =MIN(MAX(G13-($D$57*100),0),$D$58*100+$D$61*100)*($D$58*100)/IF(($D$58*100+$D$61*100)=0,1,$D$58*100+$D$61*100) -> 30943.651 | H15: =MIN(MAX(H13-($D$57*100),0),$D$58*100+$D$61*100)*($D$58*100)/IF(($D$58*100+$D$61*100)=0,1,$D$58*100+$D$61*100) -> 53753.685 | I15: =MIN(MAX(I13-($D$57*100),0),$D$58*100+$D$61*100)*($D$58*100)/IF(($D$58*100+$D$61*100)=0,1,$D$58*100+$D$61*100) -> 72405.045 | J15: =MIN(MAX(J13-($D$57*100),0),$D$58*100+$D$61*100)*($D$58*100)/IF(($D$58*100+$D$61*100)=0,1,$D$58*100+$D$61*100) -> 80000 | K15: =MIN(MAX(K13-($D$57*100),0),$D$58*100+$D$61*100)*($D$58*100)/IF(($D$58*100+$D$61*100)=0,1,$D$58*100+$D$61*100) -> 80000 | L15: =MIN(MAX(L13-($D$57*100),0),$D$58*100+$D$61*100)*($D$58*100)/IF(($D$58*100+$D$61*100)=0,1,$D$58*100+$D$61*100) -> 80000 | ... CL15: =MIN(MAX(CL13-($D$57*100),0),$D$58*100+$D$61*100)*($D$58*100)/IF(($D$58*100+$D$61*100)=0,1,$D$58*100+$D$61*100) -> 80000
B16: 선순위B 누적인출 | C16: [KRWm] | E16: =MIN(MAX(E13-($D$57*100),0),$D$58*100+$D$61*100)*($D$61*100)/IF(($D$58*100+$D$61*100)=0,1,$D$58*100+$D$61*100) -> 0 | F16: =MIN(MAX(F13-($D$57*100),0),$D$58*100+$D$61*100)*($D$61*100)/IF(($D$58*100+$D$61*100)=0,1,$D$58*100+$D$61*100) -> 7406.1977 | G16: =MIN(MAX(G13-($D$57*100),0),$D$58*100+$D$61*100)*($D$61*100)/IF(($D$58*100+$D$61*100)=0,1,$D$58*100+$D$61*100) -> 17819.288 | H16: =MIN(MAX(H13-($D$57*100),0),$D$58*100+$D$61*100)*($D$61*100)/IF(($D$58*100+$D$61*100)=0,1,$D$58*100+$D$61*100) -> 30954.731 | I16: =MIN(MAX(I13-($D$57*100),0),$D$58*100+$D$61*100)*($D$61*100)/IF(($D$58*100+$D$61*100)=0,1,$D$58*100+$D$61*100) -> 41695.35 | J16: =MIN(MAX(J13-($D$57*100),0),$D$58*100+$D$61*100)*($D$61*100)/IF(($D$58*100+$D$61*100)=0,1,$D$58*100+$D$61*100) -> 46069 | K16: =MIN(MAX(K13-($D$57*100),0),$D$58*100+$D$61*100)*($D$61*100)/IF(($D$58*100+$D$61*100)=0,1,$D$58*100+$D$61*100) -> 46069 | L16: =MIN(MAX(L13-($D$57*100),0),$D$58*100+$D$61*100)*($D$61*100)/IF(($D$58*100+$D$61*100)=0,1,$D$58*100+$D$61*100) -> 46069 | ... CL16: =MIN(MAX(CL13-($D$57*100),0),$D$58*100+$D$61*100)*($D$61*100)/IF(($D$58*100+$D$61*100)=0,1,$D$58*100+$D$61*100) -> 46069
B19: 트랜치별 인출/상환 + 전체 합계
B21: 구 분 | C21: unit | D21: 합 계 | E21: 2024-06-30 | F21: 2024-09-30 | G21: 2024-12-31 | H21: 2025-03-31 | I21: 2025-06-30 | J21: 2025-09-30 | K21: 2025-12-31 | L21: 2026-03-31 | M21: 2026-06-30 | N21: 2026-09-30 | O21: 2026-12-31 | P21: 2027-03-31 | Q21: 2027-06-30 | R21: 2027-09-30 | S21: 2027-12-31 | T21: 2028-03-31 | U21: 2028-06-30 | V21: 2028-09-30 | W21: 2028-12-31 | X21: 2029-03-31 | Y21: 2029-06-30 | Z21: 2029-09-30 | AA21: 2029-12-31 | AB21: 2030-03-31 | AC21: 2030-06-30 | AD21: 2030-09-30 | AE21: 2030-12-31 | AF21: 2031-03-31 | AG21: 2031-06-30 | AH21: 2031-09-30 | AI21: 2031-12-31 | AJ21: 2032-03-31 | AK21: 2032-06-30 | AL21: 2032-09-30 | AM21: 2032-12-31 | AN21: 2033-03-31 | AO21: 2033-06-30 | AP21: 2033-09-30 | AQ21: 2033-12-31 | AR21: 2034-03-31 | AS21: 2034-06-30 | AT21: 2034-09-30 | AU21: 2034-12-31 | AV21: 2035-03-31 | AW21: 2035-06-30 | AX21: 2035-09-30 | AY21: 2035-12-31 | AZ21: 2036-03-31 | BA21: 2036-06-30 | BB21: 2036-09-30 | BC21: 2036-12-31 | BD21: 2037-03-31 | BE21: 2037-06-30 | BF21: 2037-09-30 | BG21: 2037-12-31 | BH21: 2038-03-31 | BI21: 2038-06-30 | BJ21: 2038-09-30 | BK21: 2038-12-31 | BL21: 2039-03-31 | BM21: 2039-06-30 | BN21: 2039-09-30 | BO21: 2039-12-31 | BP21: 2040-03-31 | BQ21: 2040-06-30 | BR21: 2040-09-30 | BS21: 2040-12-31 | BT21: 2041-03-31 | BU21: 2041-06-30 | BV21: 2041-09-30 | BW21: 2041-12-31 | BX21: 2042-03-31 | BY21: 2042-06-30 | BZ21: 2042-09-30 | CA21: 2042-12-31 | CB21: 2043-03-31 | CC21: 2043-06-30 | CD21: 2043-09-30 | CE21: 2043-12-31 | CF21: 2044-03-31 | CG21: 2044-06-30 | CH21: 2044-09-30 | CI21: 2044-12-31 | CJ21: 2045-03-31 | CK21: 2045-06-30 | CL21: 2045-09-30
B23: 선순위A
B24: 기초잔액 | C24: [KRWm] | E24: 0 | F24: =E29 -> 0 | G24: =F29 -> 12861.052 | H24: =G29 -> 30943.651 | I24: =H29 -> 53753.685 | J24: =I29 -> 72405.045 | K24: =J29 -> 80000 | L24: =K29 -> 80000 | M24: =L29 -> 80000 | ... CL24: =CK29 -> 0
B25: 인출 | C25: [KRWm] | D25: =SUM(E25:CL25) -> 80000 | E25: =E15 -> 0 | F25: =F15-E15 -> 12861.052 | G25: =G15-F15 -> 18082.599 | H25: =H15-G15 -> 22810.033 | I25: =I15-H15 -> 18651.36 | J25: =J15-I15 -> 7594.9549 | K25: =K15-J15 -> 0 | L25: =L15-K15 -> 0 | M25: =M15-L15 -> 0 | ... CL25: =CL15-CK15 -> 0
B26: 건설이자(IDC) | C26: [KRWm] | D26: =SUM(E26:CL26) -> 2379.4881 | E26: =E10 -> 0 | F26: =F10 -> 0 | G26: =G10 -> 180.05473 | H26: =H10 -> 433.21112 | I26: =I10 -> 752.55159 | J26: =J10 -> 1013.6706 | K26: =K10 -> 0 | L26: =L10 -> 0 | ... CL26: =CL10 -> 0
B27: 이자(운영) | C27: [KRWm] | D27: =SUM(E27:CL27) -> 40880 | E27: 0 | F27: 0 | G27: 0 | H27: 0 | I27: 0 | J27: 0 | K27: =K24*$D$60/4 -> 1120 | L27: =L24*$D$60/4 -> 1120 | M27: =M24*$D$60/4 -> 1120 | N27: =N24*$D$60/4 -> 1120 | O27: =O24*$D$60/4 -> 1120 | P27: =P24*$D$60/4 -> 1102.5 | Q27: =Q24*$D$60/4 -> 1085 | R27: =R24*$D$60/4 -> 1067.5 | ... CL27: =CL24*$D$60/4 -> 0
B28: 원금상환 | C28: [KRWm] | D28: =SUM(E28:CL28) -> 80000 | E28: 0 | F28: 0 | G28: 0 | H28: 0 | I28: 0 | J28: 0 | K28: 0 | L28: 0 | M28: 0 | N28: 0 | O28: =D25/64 -> 1250 | P28: =D25/64 -> 1250 | Q28: =D25/64 -> 1250 | R28: =D25/64 -> 1250 | S28: =D25/64 -> 1250 | T28: =D25/64 -> 1250 | U28: =D25/64 -> 1250 | V28: =D25/64 -> 1250 | W28: =D25/64 -> 1250 | X28: =D25/64 -> 1250 | Y28: =D25/64 -> 1250 | Z28: =D25/64 -> 1250 | AA28: =D25/64 -> 1250 | AB28: =D25/64 -> 1250 | AC28: =D25/64 -> 1250 | AD28: =D25/64 -> 1250 | AE28: =D25/64 -> 1250 | AF28: =D25/64 -> 1250 | AG28: =D25/64 -> 1250 | AH28: =D25/64 -> 1250 | AI28: =D25/64 -> 1250 | AJ28: =D25/64 -> 1250 | AK28: =D25/64 -> 1250 | AL28: =D25/64 -> 1250 | AM28: =D25/64 -> 1250 | AN28: =D25/64 -> 1250 | AO28: =D25/64 -> 1250 | AP28: =D25/64 -> 1250 | AQ28: =D25/64 -> 1250 | AR28: =D25/64 -> 1250 | AS28: =D25/64 -> 1250 | AT28: =D25/64 -> 1250 | AU28: =D25/64 -> 1250 | AV28: =D25/64 -> 1250 | AW28: =D25/64 -> 1250 | AX28: =D25/64 -> 1250 | AY28: =D25/64 -> 1250 | AZ28: =D25/64 -> 1250 | BA28: =D25/64 -> 1250 | BB28: =D25/64 -> 1250 | BC28: =D25/64 -> 1250 | BD28: =D25/64 -> 1250 | BE28: =D25/64 -> 1250 | BF28: =D25/64 -> 1250 | BG28: =D25/64 -> 1250 | BH28: =D25/64 -> 1250 | BI28: =D25/64 -> 1250 | BJ28: =D25/64 -> 1250 | BK28: =D25/64 -> 1250 | BL28: =D25/64 -> 1250 | BM28: =D25/64 -> 1250 | BN28: =D25/64 -> 1250 | BO28: =D25/64 -> 1250 | BP28: =D25/64 -> 1250 | BQ28: =D25/64 -> 1250 | BR28: =D25/64 -> 1250 | BS28: =D25/64 -> 1250 | BT28: =D25/64 -> 1250 | BU28: =D25/64 -> 1250 | BV28: =D25/64 -> 1250 | BW28: =D25/64 -> 1250 | BX28: =D25/64 -> 1250 | BY28: =D25/64 -> 1250 | BZ28: =D25/64 -> 1250 | CA28: 0 | CB28: 0 | CC28: 0 | CD28: 0 | CE28: 0 | CF28: 0 | CG28: 0 | CH28: 0 | CI28: 0 | CJ28: 0 | CK28: 0 | CL28: 0
B29: 기말잔액 | C29: [KRWm] | E29: =E24+E25-E28 -> 0 | F29: =F24+F25-F28 -> 12861.052 | G29: =G24+G25-G28 -> 30943.651 | H29: =H24+H25-H28 -> 53753.685 | I29: =I24+I25-I28 -> 72405.045 | J29: =J24+J25-J28 -> 80000 | K29: =K24+K25-K28 -> 80000 | L29: =L24+L25-L28 -> 80000 | ... CL29: =CL24+CL25-CL28 -> 0
B30: 미상환 잔액(검증용) | C30: [KRWm] | D30: =CL29 -> 0 | F30: =IF(ABS(D30)<1,"완전상환 확인 (OK)","경고: 미상환 잔액") -> 완전상환 확인 (OK)
B31: 인출 시작 가정 검증 | F31: =IF(AND(E15<1,F15>1),"인출 시작 분기 일치 (OK)","경고: 첫 인출 분기가 생성 당시(2024-09-30)와 달라졌습니다. 상환 스케줄이 들어간 열은 고정이라 실제와 어긋납니다 — 화면(HTML)에서 다시 생성하세요.") -> 인출 시작 분기 일치 (OK)
B33: 선순위B
B34: 기초잔액 | C34: [KRWm] | E34: 0 | F34: =E39 -> 0 | G34: =F39 -> 7406.1977 | H34: =G39 -> 17819.288 | I34: =H39 -> 30954.731 | J34: =I39 -> 41695.35 | K34: =J39 -> 46069 | L34: =K39 -> 46069 | M34: =L39 -> 46069 | ... CL34: =CK39 -> 0
B35: 인출 | C35: [KRWm] | D35: =SUM(E35:CL35) -> 46069 | E35: =E16 -> 0 | F35: =F16-E16 -> 7406.1977 | G35: =G16-F16 -> 10413.091 | H35: =H16-G16 -> 13135.443 | I35: =I16-H16 -> 10740.619 | J35: =J16-I16 -> 4373.6497 | K35: =K16-J16 -> 0 | L35: =L16-K16 -> 0 | M35: =M16-L16 -> 0 | ... CL35: =CL16-CK16 -> 0
B36: 건설이자(IDC) | C36: [KRWm] | D36: =SUM(E36:CL36) -> 1345.7891 | E36: =E11 -> 0 | F36: =F11 -> 0 | G36: =G11 -> 101.83522 | H36: =H11 -> 245.01522 | I36: =I11 -> 425.62756 | J36: =J11 -> 573.31107 | K36: =K11 -> 0 | L36: =L11 -> 0 | ... CL36: =CL11 -> 0
B37: 이자(운영) | C37: [KRWm] | D37: =SUM(E37:CL37) -> 23120.879 | E37: 0 | F37: 0 | G37: 0 | H37: 0 | I37: 0 | J37: 0 | K37: =K34*$D$63/4 -> 633.44875 | L37: =L34*$D$63/4 -> 633.44875 | M37: =M34*$D$63/4 -> 633.44875 | N37: =N34*$D$63/4 -> 633.44875 | O37: =O34*$D$63/4 -> 633.44875 | P37: =P34*$D$63/4 -> 623.55111 | Q37: =Q34*$D$63/4 -> 613.65348 | R37: =R34*$D$63/4 -> 603.75584 | ... CL37: =CL34*$D$63/4 -> 0
B38: 원금상환 | C38: [KRWm] | D38: =SUM(E38:CL38) -> 46069 | E38: 0 | F38: 0 | G38: 0 | H38: 0 | I38: 0 | J38: 0 | K38: 0 | L38: 0 | M38: 0 | N38: 0 | O38: =D35/64 -> 719.82812 | P38: =D35/64 -> 719.82812 | Q38: =D35/64 -> 719.82812 | R38: =D35/64 -> 719.82812 | S38: =D35/64 -> 719.82812 | T38: =D35/64 -> 719.82812 | U38: =D35/64 -> 719.82812 | V38: =D35/64 -> 719.82812 | W38: =D35/64 -> 719.82812 | X38: =D35/64 -> 719.82812 | Y38: =D35/64 -> 719.82812 | Z38: =D35/64 -> 719.82812 | AA38: =D35/64 -> 719.82812 | AB38: =D35/64 -> 719.82812 | AC38: =D35/64 -> 719.82812 | AD38: =D35/64 -> 719.82812 | AE38: =D35/64 -> 719.82812 | AF38: =D35/64 -> 719.82812 | AG38: =D35/64 -> 719.82812 | AH38: =D35/64 -> 719.82812 | AI38: =D35/64 -> 719.82812 | AJ38: =D35/64 -> 719.82812 | AK38: =D35/64 -> 719.82812 | AL38: =D35/64 -> 719.82812 | AM38: =D35/64 -> 719.82812 | AN38: =D35/64 -> 719.82812 | AO38: =D35/64 -> 719.82812 | AP38: =D35/64 -> 719.82812 | AQ38: =D35/64 -> 719.82812 | AR38: =D35/64 -> 719.82812 | AS38: =D35/64 -> 719.82812 | AT38: =D35/64 -> 719.82812 | AU38: =D35/64 -> 719.82812 | AV38: =D35/64 -> 719.82812 | AW38: =D35/64 -> 719.82812 | AX38: =D35/64 -> 719.82812 | AY38: =D35/64 -> 719.82812 | AZ38: =D35/64 -> 719.82812 | BA38: =D35/64 -> 719.82812 | BB38: =D35/64 -> 719.82812 | BC38: =D35/64 -> 719.82812 | BD38: =D35/64 -> 719.82812 | BE38: =D35/64 -> 719.82812 | BF38: =D35/64 -> 719.82812 | BG38: =D35/64 -> 719.82812 | BH38: =D35/64 -> 719.82812 | BI38: =D35/64 -> 719.82812 | BJ38: =D35/64 -> 719.82812 | BK38: =D35/64 -> 719.82812 | BL38: =D35/64 -> 719.82812 | BM38: =D35/64 -> 719.82812 | BN38: =D35/64 -> 719.82812 | BO38: =D35/64 -> 719.82812 | BP38: =D35/64 -> 719.82812 | BQ38: =D35/64 -> 719.82812 | BR38: =D35/64 -> 719.82812 | BS38: =D35/64 -> 719.82812 | BT38: =D35/64 -> 719.82812 | BU38: =D35/64 -> 719.82812 | BV38: =D35/64 -> 719.82812 | BW38: =D35/64 -> 719.82812 | BX38: =D35/64 -> 719.82812 | BY38: =D35/64 -> 719.82812 | BZ38: =D35/64 -> 719.82812 | CA38: 0 | CB38: 0 | CC38: 0 | CD38: 0 | CE38: 0 | CF38: 0 | CG38: 0 | CH38: 0 | CI38: 0 | CJ38: 0 | CK38: 0 | CL38: 0
B39: 기말잔액 | C39: [KRWm] | E39: =E34+E35-E38 -> 0 | F39: =F34+F35-F38 -> 7406.1977 | G39: =G34+G35-G38 -> 17819.288 | H39: =H34+H35-H38 -> 30954.731 | I39: =I34+I35-I38 -> 41695.35 | J39: =J34+J35-J38 -> 46069 | K39: =K34+K35-K38 -> 46069 | L39: =L34+L35-L38 -> 46069 | ... CL39: =CL34+CL35-CL38 -> 0
B40: 미상환 잔액(검증용) | C40: [KRWm] | D40: =CL39 -> 0 | F40: =IF(ABS(D40)<1,"완전상환 확인 (OK)","경고: 미상환 잔액") -> 완전상환 확인 (OK)
B41: 인출 시작 가정 검증 | F41: =IF(AND(E16<1,F16>1),"인출 시작 분기 일치 (OK)","경고: 첫 인출 분기가 생성 당시(2024-09-30)와 달라졌습니다. 상환 스케줄이 들어간 열은 고정이라 실제와 어긋납니다 — 화면(HTML)에서 다시 생성하세요.") -> 인출 시작 분기 일치 (OK)
B43: 전체 합계
B44: 기초잔액 | C44: [KRWm] | E44: =E24+E34 -> 0 | F44: =F24+F34 -> 0 | G44: =G24+G34 -> 20267.25 | H44: =H24+H34 -> 48762.94 | I44: =I24+I34 -> 84708.416 | J44: =J24+J34 -> 114100.4 | K44: =K24+K34 -> 126069 | L44: =L24+L34 -> 126069 | ... CL44: =CL24+CL34 -> 0
B45: 이자 | C45: [KRWm] | D45: =SUM(E45:CL45) -> 64000.879 | E45: =E27+E37 -> 0 | F45: =F27+F37 -> 0 | G45: =G27+G37 -> 0 | H45: =H27+H37 -> 0 | I45: =I27+I37 -> 0 | J45: =J27+J37 -> 0 | K45: =K27+K37 -> 1753.4487 | L45: =L27+L37 -> 1753.4487 | ... CL45: =CL27+CL37 -> 0
B46: 원금상환 | C46: [KRWm] | D46: =SUM(E46:CL46) -> 126069 | E46: =E28+E38 -> 0 | F46: =F28+F38 -> 0 | G46: =G28+G38 -> 0 | H46: =H28+H38 -> 0 | I46: =I28+I38 -> 0 | J46: =J28+J38 -> 0 | K46: =K28+K38 -> 0 | L46: =L28+L38 -> 0 | ... CL46: =CL28+CL38 -> 0
B47: 원리금(DS) | C47: [KRWm] | D47: =SUM(E47:CL47) -> 190069.88 | E47: =E45+E46 -> 0 | F47: =F45+F46 -> 0 | G47: =G45+G46 -> 0 | H47: =H45+H46 -> 0 | I47: =I45+I46 -> 0 | J47: =J45+J46 -> 0 | K47: =K45+K46 -> 1753.4487 | L47: =L45+L46 -> 1753.4487 | ... CL47: =CL45+CL46 -> 0
B48: 기말잔액 | C48: [KRWm] | E48: =E29+E39 -> 0 | F48: =F29+F39 -> 20267.25 | G48: =G29+G39 -> 48762.94 | H48: =H29+H39 -> 84708.416 | I48: =I29+I39 -> 114100.4 | J48: =J29+J39 -> 126069 | K48: =K29+K39 -> 126069 | L48: =L29+L39 -> 126069 | ... CL48: =CL29+CL39 -> 0
B50: DSRA 기초잔액 | C50: [KRWm] | E50: =0 -> 0 | F50: =E51 -> 0 | G50: =F51 -> 0 | H50: =G51 -> 0 | I50: =H51 -> 0 | J50: ='입력값'!C23*100 -> 5000 | K50: =J51 -> 5000 | L50: =K51 -> 3506.8975 | M50: =L51 -> 3506.8975 | N50: =M51 -> 5476.7256 | O50: =N51 -> 7419.1561 | P50: =O51 -> 7364.3608 | Q50: =P51 -> 7309.5656 | R50: =Q51 -> 7254.7703 | ... CL50: =CK51 -> 0
...

Sheet Revenue
A1: 샘플 태양광 100MW
A2: 영업수익 추정
B4: 발전량 및 매출
B6: 구 분 | C6: unit | D6: 합 계 | E6: 2024-06-30 | F6: 2024-09-30 | G6: 2024-12-31 | H6: 2025-03-31 | I6: 2025-06-30 | J6: 2025-09-30 | K6: 2025-12-31 | L6: 2026-03-31 | M6: 2026-06-30 | N6: 2026-09-30 | O6: 2026-12-31 | P6: 2027-03-31 | Q6: 2027-06-30 | R6: 2027-09-30 | S6: 2027-12-31 | T6: 2028-03-31 | U6: 2028-06-30 | V6: 2028-09-30 | W6: 2028-12-31 | X6: 2029-03-31 | Y6: 2029-06-30 | Z6: 2029-09-30 | AA6: 2029-12-31 | AB6: 2030-03-31 | AC6: 2030-06-30 | AD6: 2030-09-30 | AE6: 2030-12-31 | AF6: 2031-03-31 | AG6: 2031-06-30 | AH6: 2031-09-30 | AI6: 2031-12-31 | AJ6: 2032-03-31 | AK6: 2032-06-30 | AL6: 2032-09-30 | AM6: 2032-12-31 | AN6: 2033-03-31 | AO6: 2033-06-30 | AP6: 2033-09-30 | AQ6: 2033-12-31 | AR6: 2034-03-31 | AS6: 2034-06-30 | AT6: 2034-09-30 | AU6: 2034-12-31 | AV6: 2035-03-31 | AW6: 2035-06-30 | AX6: 2035-09-30 | AY6: 2035-12-31 | AZ6: 2036-03-31 | BA6: 2036-06-30 | BB6: 2036-09-30 | BC6: 2036-12-31 | BD6: 2037-03-31 | BE6: 2037-06-30 | BF6: 2037-09-30 | BG6: 2037-12-31 | BH6: 2038-03-31 | BI6: 2038-06-30 | BJ6: 2038-09-30 | BK6: 2038-12-31 | BL6: 2039-03-31 | BM6: 2039-06-30 | BN6: 2039-09-30 | BO6: 2039-12-31 | BP6: 2040-03-31 | BQ6: 2040-06-30 | BR6: 2040-09-30 | BS6: 2040-12-31 | BT6: 2041-03-31 | BU6: 2041-06-30 | BV6: 2041-09-30 | BW6: 2041-12-31 | BX6: 2042-03-31 | BY6: 2042-06-30 | BZ6: 2042-09-30 | CA6: 2042-12-31 | CB6: 2043-03-31 | CC6: 2043-06-30 | CD6: 2043-09-30 | CE6: 2043-12-31 | CF6: 2044-03-31 | CG6: 2044-06-30 | CH6: 2044-09-30 | CI6: 2044-12-31 | CJ6: 2045-03-31 | CK6: 2045-06-30 | CL6: 2045-09-30
B8: 운영연차 (첫 해 = 0) | C8: [yr] | E8: 0 | F8: 0 | G8: 0 | H8: 0 | I8: 0 | J8: 0 | K8: 0 | L8: 0 | M8: 0 | N8: 0 | O8: 1 | P8: 1 | Q8: 1 | R8: 1 | S8: 2 | T8: 2 | U8: 2 | V8: 2 | W8: 3 | X8: 3 | Y8: 3 | Z8: 3 | AA8: 4 | AB8: 4 | AC8: 4 | AD8: 4 | AE8: 5 | AF8: 5 | AG8: 5 | AH8: 5 | AI8: 6 | AJ8: 6 | AK8: 6 | AL8: 6 | AM8: 7 | AN8: 7 | AO8: 7 | AP8: 7 | AQ8: 8 | AR8: 8 | AS8: 8 | AT8: 8 | AU8: 9 | AV8: 9 | AW8: 9 | AX8: 9 | AY8: 10 | AZ8: 10 | BA8: 10 | BB8: 10 | BC8: 11 | BD8: 11 | BE8: 11 | BF8: 11 | BG8: 12 | BH8: 12 | BI8: 12 | BJ8: 12 | BK8: 13 | BL8: 13 | BM8: 13 | BN8: 13 | BO8: 14 | BP8: 14 | BQ8: 14 | BR8: 14 | BS8: 15 | BT8: 15 | BU8: 15 | BV8: 15 | BW8: 16 | BX8: 16 | BY8: 16 | BZ8: 16 | CA8: 17 | CB8: 17 | CC8: 17 | CD8: 17 | CE8: 18 | CF8: 18 | CG8: 18 | CH8: 18 | CI8: 19 | CJ8: 19 | CK8: 19 | CL8: 19
B9: 발전 기간비중 (연간 = 1) | C9: [배] | E9: 0 | F9: 0 | G9: 0 | H9: 0 | I9: 0 | J9: 0 | K9: 0.25 | L9: 0.25 | M9: 0.25 | N9: 0.25 | O9: 0.25 | P9: 0.25 | Q9: 0.25 | R9: 0.25 | S9: 0.25 | T9: 0.25 | U9: 0.25 | V9: 0.25 | W9: 0.25 | X9: 0.25 | Y9: 0.25 | Z9: 0.25 | AA9: 0.25 | AB9: 0.25 | AC9: 0.25 | AD9: 0.25 | AE9: 0.25 | AF9: 0.25 | AG9: 0.25 | AH9: 0.25 | AI9: 0.25 | AJ9: 0.25 | AK9: 0.25 | AL9: 0.25 | AM9: 0.25 | AN9: 0.25 | AO9: 0.25 | AP9: 0.25 | AQ9: 0.25 | AR9: 0.25 | AS9: 0.25 | AT9: 0.25 | AU9: 0.25 | AV9: 0.25 | AW9: 0.25 | AX9: 0.25 | AY9: 0.25 | AZ9: 0.25 | BA9: 0.25 | BB9: 0.25 | BC9: 0.25 | BD9: 0.25 | BE9: 0.25 | BF9: 0.25 | BG9: 0.25 | BH9: 0.25 | BI9: 0.25 | BJ9: 0.25 | BK9: 0.25 | BL9: 0.25 | BM9: 0.25 | BN9: 0.25 | BO9: 0.25 | BP9: 0.25 | BQ9: 0.25 | BR9: 0.25 | BS9: 0.25 | BT9: 0.25 | BU9: 0.25 | BV9: 0.25 | BW9: 0.25 | BX9: 0.25 | BY9: 0.25 | BZ9: 0.25 | CA9: 0.25 | CB9: 0.25 | CC9: 0.25 | CD9: 0.25 | CE9: 0.25 | CF9: 0.25 | CG9: 0.25 | CH9: 0.25 | CI9: 0.25 | CJ9: 0.25 | CK9: 0.25 | CL9: 0.25
B11: 발전량 | C11: [MWh] | D11: =SUM(E11:CL11) -> 2621375.2 | E11: =($D$25*$D$30*365)*MAX(0,1-$D$28/100*E8)*(1-$D$29/100)*E9 -> 0 | F11: =($D$25*$D$30*365)*MAX(0,1-$D$28/100*F8)*(1-$D$29/100)*F9 -> 0 | G11: =($D$25*$D$30*365)*MAX(0,1-$D$28/100*G8)*(1-$D$29/100)*G9 -> 0 | H11: =($D$25*$D$30*365)*MAX(0,1-$D$28/100*H8)*(1-$D$29/100)*H9 -> 0 | I11: =($D$25*$D$30*365)*MAX(0,1-$D$28/100*I8)*(1-$D$29/100)*I9 -> 0 | J11: =($D$25*$D$30*365)*MAX(0,1-$D$28/100*J8)*(1-$D$29/100)*J9 -> 0 | K11: =($D$25*$D$30*365)*MAX(0,1-$D$28/100*K8)*(1-$D$29/100)*K9 -> 34401.25 | L11: =($D$25*$D$30*365)*MAX(0,1-$D$28/100*L8)*(1-$D$29/100)*L9 -> 34401.25 | ... CL11: =($D$25*$D$30*365)*MAX(0,1-$D$28/100*CL8)*(1-$D$29/100)*CL9 -> 31133.131
B13: 판매단가 | C13: [원/kWh] | K13: =$D$26*(1+$D$27/100)^K8 -> 154.8 | L13: =$D$26*(1+$D$27/100)^L8 -> 154.8 | M13: =$D$26*(1+$D$27/100)^M8 -> 154.8 | N13: =$D$26*(1+$D$27/100)^N8 -> 154.8 | O13: =$D$26*(1+$D$27/100)^O8 -> 154.8 | P13: =$D$26*(1+$D$27/100)^P8 -> 154.8 | Q13: =$D$26*(1+$D$27/100)^Q8 -> 154.8 | R13: =$D$26*(1+$D$27/100)^R8 -> 154.8 | ... CL13: =$D$26*(1+$D$27/100)^CL8 -> 154.8
B14: 영업수익 | C14: [KRWm] | D14: =SUM(E14:CL14) -> 405788.89 | E14: 0 | F14: 0 | G14: 0 | H14: 0 | I14: 0 | J14: 0 | K14: =K11*K13/1000 -> 5325.3135 | L14: =L11*L13/1000 -> 5325.3135 | M14: =M11*M13/1000 -> 5325.3135 | N14: =N11*N13/1000 -> 5325.3135 | O14: =O11*O13/1000 -> 5298.6869 | P14: =P11*P13/1000 -> 5298.6869 | Q14: =Q11*Q13/1000 -> 5298.6869 | R14: =R11*R13/1000 -> 5298.6869 | ... CL14: =CL11*CL13/1000 -> 4819.4087
B16: 매출채권(A/R) 회수 시차
B18: 전체 기말 미수금 | C18: [KRWm] | E18: =MIN(1,3)/3*E14 -> 0 | F18: =MIN(1,3)/3*F14+MAX(0,MIN(1-3,3))/3*E14 -> 0 | G18: =MIN(1,3)/3*G14+MAX(0,MIN(1-3,3))/3*F14+MAX(0,MIN(1-6,3))/3*E14 -> 0 | H18: =MIN(1,3)/3*H14+MAX(0,MIN(1-3,3))/3*G14+MAX(0,MIN(1-6,3))/3*F14+MAX(0,MIN(1-9,3))/3*E14 -> 0 | I18: =MIN(1,3)/3*I14+MAX(0,MIN(1-3,3))/3*H14+MAX(0,MIN(1-6,3))/3*G14+MAX(0,MIN(1-9,3))/3*F14 -> 0 | J18: =MIN(1,3)/3*J14+MAX(0,MIN(1-3,3))/3*I14+MAX(0,MIN(1-6,3))/3*H14+MAX(0,MIN(1-9,3))/3*G14 -> 0 | K18: =MIN(1,3)/3*K14+MAX(0,MIN(1-3,3))/3*J14+MAX(0,MIN(1-6,3))/3*I14+MAX(0,MIN(1-9,3))/3*H14 -> 1775.1045 | L18: =MIN(1,3)/3*L14+MAX(0,MIN(1-3,3))/3*K14+MAX(0,MIN(1-6,3))/3*J14+MAX(0,MIN(1-9,3))/3*I14 -> 1775.1045 | M18: =MIN(1,3)/3*M14+MAX(0,MIN(1-3,3))/3*L14+MAX(0,MIN(1-6,3))/3*K14+MAX(0,MIN(1-9,3))/3*J14 -> 1775.1045 | N18: =MIN(1,3)/3*N14+MAX(0,MIN(1-3,3))/3*M14+MAX(0,MIN(1-6,3))/3*L14+MAX(0,MIN(1-9,3))/3*K14 -> 1775.1045 | O18: =MIN(1,3)/3*O14+MAX(0,MIN(1-3,3))/3*N14+MAX(0,MIN(1-6,3))/3*M14+MAX(0,MIN(1-9,3))/3*L14 -> 1766.229 | ... CK18: =MIN(1,3)/3*CK14+MAX(0,MIN(1-3,3))/3*CJ14+MAX(0,MIN(1-6,3))/3*CI14+MAX(0,MIN(1-9,3))/3*CH14 -> 1606.4696 | CL18: 0
B19: 운전자본 증감(A/R) | C19: [KRWm] | D19: =SUM(E19:CL19) -> 0 | E19: =0-E18 -> 0 | F19: =E18-F18 -> 0 | G19: =F18-G18 -> 0 | H19: =G18-H18 -> 0 | I19: =H18-I18 -> 0 | J19: =I18-J18 -> 0 | K19: =J18-K18 -> -1775.1045 | L19: =K18-L18 -> 0 | M19: =L18-M18 -> 0 | ... CL19: =CK18-CL18 -> 1606.4696
B20: ※ 20년 전체 합계는 0입니다(초기에 묶인 미수금을 마지막에 전액 회수). 다만 분기별로는 크게 움직여서 준공 직후 DSCR과 Equity IRR에 영향을 줍니다.
B23: 가정 (입력값 연결) — 이 시트의 계산이 쓰는 원천값 | D23: 값
B24: ※ 입력값 시트는 여기서만 참조합니다(초록 글자 = 입력값 연결). 위의 분기 계산은 이 셀들만 참조하므로, 값을 바꾸려면 입력값 시트를 고치세요.
B25: 설비용량[MW] | C25: C7 | D25: ='입력값'!C7 -> 100
B26: 판매단가[원/kWh] | C26: C10 | D26: ='입력값'!C10 -> 154.8
B27: 판매단가 에스컬레이션[%/yr] | C27: C11 | D27: ='입력값'!C11 -> 0
B28: 발전량 열화율[%/yr] | C28: C12 | D28: ='입력값'!C12 -> 0.5
B29: 소내소비율[%] | C29: C13 | D29: ='입력값'!C13 -> 0
B30: 일조시간[h/day] | C30: C14 | D30: ='입력값'!C14 -> 3.77

Sheet Opex
A1: 샘플 태양광 100MW
A2: 영업비용 추정
B4: 운영비용 (선순위/후순위 지급순위 반영)
B6: 구 분 | C6: unit | D6: 합 계 | E6: 2024-06-30 | F6: 2024-09-30 | G6: 2024-12-31 | H6: 2025-03-31 | I6: 2025-06-30 | J6: 2025-09-30 | K6: 2025-12-31 | L6: 2026-03-31 | M6: 2026-06-30 | N6: 2026-09-30 | O6: 2026-12-31 | P6: 2027-03-31 | Q6: 2027-06-30 | R6: 2027-09-30 | S6: 2027-12-31 | T6: 2028-03-31 | U6: 2028-06-30 | V6: 2028-09-30 | W6: 2028-12-31 | X6: 2029-03-31 | Y6: 2029-06-30 | Z6: 2029-09-30 | AA6: 2029-12-31 | AB6: 2030-03-31 | AC6: 2030-06-30 | AD6: 2030-09-30 | AE6: 2030-12-31 | AF6: 2031-03-31 | AG6: 2031-06-30 | AH6: 2031-09-30 | AI6: 2031-12-31 | AJ6: 2032-03-31 | AK6: 2032-06-30 | AL6: 2032-09-30 | AM6: 2032-12-31 | AN6: 2033-03-31 | AO6: 2033-06-30 | AP6: 2033-09-30 | AQ6: 2033-12-31 | AR6: 2034-03-31 | AS6: 2034-06-30 | AT6: 2034-09-30 | AU6: 2034-12-31 | AV6: 2035-03-31 | AW6: 2035-06-30 | AX6: 2035-09-30 | AY6: 2035-12-31 | AZ6: 2036-03-31 | BA6: 2036-06-30 | BB6: 2036-09-30 | BC6: 2036-12-31 | BD6: 2037-03-31 | BE6: 2037-06-30 | BF6: 2037-09-30 | BG6: 2037-12-31 | BH6: 2038-03-31 | BI6: 2038-06-30 | BJ6: 2038-09-30 | BK6: 2038-12-31 | BL6: 2039-03-31 | BM6: 2039-06-30 | BN6: 2039-09-30 | BO6: 2039-12-31 | BP6: 2040-03-31 | BQ6: 2040-06-30 | BR6: 2040-09-30 | BS6: 2040-12-31 | BT6: 2041-03-31 | BU6: 2041-06-30 | BV6: 2041-09-30 | BW6: 2041-12-31 | BX6: 2042-03-31 | BY6: 2042-06-30 | BZ6: 2042-09-30 | CA6: 2042-12-31 | CB6: 2043-03-31 | CC6: 2043-06-30 | CD6: 2043-09-30 | CE6: 2043-12-31 | CF6: 2044-03-31 | CG6: 2044-06-30 | CH6: 2044-09-30 | CI6: 2044-12-31 | CJ6: 2045-03-31 | CK6: 2045-06-30 | CL6: 2045-09-30
B8: 선순위운영비 | C8: [KRWm] | D8: =SUM(E8:CL8) -> 106510.05 | E8: 0 | F8: 0 | G8: 0 | H8: 0 | I8: 0 | J8: 0 | K8: =K10-K9 -> 1245 | L8: =L10-L9 -> 1245 | M8: =M10-M9 -> 1245 | N8: =N10-N9 -> 1245 | O8: =O10-O9 -> 1253.715 | P8: =P10-P9 -> 1253.715 | Q8: =Q10-Q9 -> 1253.715 | R8: =R10-R9 -> 1253.715 | ... CL8: =CL10-CL9 -> 1421.4425
B9: 후순위운영비 | C9: [KRWm] | D9: =SUM(E9:CL9) -> 0 | E9: 0 | F9: 0 | G9: 0 | H9: 0 | I9: 0 | J9: 0 | K9: =K10*$D$19/100 -> 0 | L9: =L10*$D$19/100 -> 0 | M9: =M10*$D$19/100 -> 0 | N9: =N10*$D$19/100 -> 0 | O9: =O10*$D$19/100 -> 0 | P9: =P10*$D$19/100 -> 0 | Q9: =Q10*$D$19/100 -> 0 | R9: =R10*$D$19/100 -> 0 | ... CL9: =CL10*$D$19/100 -> 0
B10: 영업비용 합계 | C10: [KRWm] | D10: =SUM(E10:CL10) -> 106510.05 | E10: =E8+E9 -> 0 | F10: =F8+F9 -> 0 | G10: =G8+G9 -> 0 | H10: =H8+H9 -> 0 | I10: =I8+I9 -> 0 | J10: =J8+J9 -> 0 | K10: =$D$17*100*(1+$D$18/100)^0*(3/12) -> 1245 | L10: =$D$17*100*(1+$D$18/100)^0*(3/12) -> 1245 | M10: =$D$17*100*(1+$D$18/100)^0*(3/12) -> 1245 | N10: =$D$17*100*(1+$D$18/100)^0*(3/12) -> 1245 | O10: =$D$17*100*(1+$D$18/100)^1*(3/12) -> 1253.715 | P10: =$D$17*100*(1+$D$18/100)^1*(3/12) -> 1253.715 | Q10: =$D$17*100*(1+$D$18/100)^1*(3/12) -> 1253.715 | R10: =$D$17*100*(1+$D$18/100)^1*(3/12) -> 1253.715 | S10: =$D$17*100*(1+$D$18/100)^2*(3/12) -> 1262.491 | T10: =$D$17*100*(1+$D$18/100)^2*(3/12) -> 1262.491 | U10: =$D$17*100*(1+$D$18/100)^2*(3/12) -> 1262.491 | V10: =$D$17*100*(1+$D$18/100)^2*(3/12) -> 1262.491 | W10: =$D$17*100*(1+$D$18/100)^3*(3/12) -> 1271.3284 | X10: =$D$17*100*(1+$D$18/100)^3*(3/12) -> 1271.3284 | Y10: =$D$17*100*(1+$D$18/100)^3*(3/12) -> 1271.3284 | Z10: =$D$17*100*(1+$D$18/100)^3*(3/12) -> 1271.3284 | AA10: =$D$17*100*(1+$D$18/100)^4*(3/12) -> 1280.2277 | AB10: =$D$17*100*(1+$D$18/100)^4*(3/12) -> 1280.2277 | AC10: =$D$17*100*(1+$D$18/100)^4*(3/12) -> 1280.2277 | AD10: =$D$17*100*(1+$D$18/100)^4*(3/12) -> 1280.2277 | AE10: =$D$17*100*(1+$D$18/100)^5*(3/12) -> 1289.1893 | AF10: =$D$17*100*(1+$D$18/100)^5*(3/12) -> 1289.1893 | AG10: =$D$17*100*(1+$D$18/100)^5*(3/12) -> 1289.1893 | AH10: =$D$17*100*(1+$D$18/100)^5*(3/12) -> 1289.1893 | AI10: =$D$17*100*(1+$D$18/100)^6*(3/12) -> 1298.2137 | AJ10: =$D$17*100*(1+$D$18/100)^6*(3/12) -> 1298.2137 | AK10: =$D$17*100*(1+$D$18/100)^6*(3/12) -> 1298.2137 | AL10: =$D$17*100*(1+$D$18/100)^6*(3/12) -> 1298.2137 | AM10: =$D$17*100*(1+$D$18/100)^7*(3/12) -> 1307.3012 | AN10: =$D$17*100*(1+$D$18/100)^7*(3/12) -> 1307.3012 | AO10: =$D$17*100*(1+$D$18/100)^7*(3/12) -> 1307.3012 | AP10: =$D$17*100*(1+$D$18/100)^7*(3/12) -> 1307.3012 | AQ10: =$D$17*100*(1+$D$18/100)^8*(3/12) -> 1316.4523 | AR10: =$D$17*100*(1+$D$18/100)^8*(3/12) -> 1316.4523 | AS10: =$D$17*100*(1+$D$18/100)^8*(3/12) -> 1316.4523 | AT10: =$D$17*100*(1+$D$18/100)^8*(3/12) -> 1316.4523 | AU10: =$D$17*100*(1+$D$18/100)^9*(3/12) -> 1325.6674 | AV10: =$D$17*100*(1+$D$18/100)^9*(3/12) -> 1325.6674 | AW10: =$D$17*100*(1+$D$18/100)^9*(3/12) -> 1325.6674 | AX10: =$D$17*100*(1+$D$18/100)^9*(3/12) -> 1325.6674 | AY10: =$D$17*100*(1+$D$18/100)^10*(3/12) -> 1334.9471 | AZ10: =$D$17*100*(1+$D$18/100)^10*(3/12) -> 1334.9471 | BA10: =$D$17*100*(1+$D$18/100)^10*(3/12) -> 1334.9471 | BB10: =$D$17*100*(1+$D$18/100)^10*(3/12) -> 1334.9471 | BC10: =$D$17*100*(1+$D$18/100)^11*(3/12) -> 1344.2917 | BD10: =$D$17*100*(1+$D$18/100)^11*(3/12) -> 1344.2917 | BE10: =$D$17*100*(1+$D$18/100)^11*(3/12) -> 1344.2917 | BF10: =$D$17*100*(1+$D$18/100)^11*(3/12) -> 1344.2917 | BG10: =$D$17*100*(1+$D$18/100)^12*(3/12) -> 1353.7018 | BH10: =$D$17*100*(1+$D$18/100)^12*(3/12) -> 1353.7018 | BI10: =$D$17*100*(1+$D$18/100)^12*(3/12) -> 1353.7018 | BJ10: =$D$17*100*(1+$D$18/100)^12*(3/12) -> 1353.7018 | BK10: =$D$17*100*(1+$D$18/100)^13*(3/12) -> 1363.1777 | BL10: =$D$17*100*(1+$D$18/100)^13*(3/12) -> 1363.1777 | BM10: =$D$17*100*(1+$D$18/100)^13*(3/12) -> 1363.1777 | BN10: =$D$17*100*(1+$D$18/100)^13*(3/12) -> 1363.1777 | BO10: =$D$17*100*(1+$D$18/100)^14*(3/12) -> 1372.7199 | BP10: =$D$17*100*(1+$D$18/100)^14*(3/12) -> 1372.7199 | BQ10: =$D$17*100*(1+$D$18/100)^14*(3/12) -> 1372.7199 | BR10: =$D$17*100*(1+$D$18/100)^14*(3/12) -> 1372.7199 | BS10: =$D$17*100*(1+$D$18/100)^15*(3/12) -> 1382.329 | BT10: =$D$17*100*(1+$D$18/100)^15*(3/12) -> 1382.329 | BU10: =$D$17*100*(1+$D$18/100)^15*(3/12) -> 1382.329 | BV10: =$D$17*100*(1+$D$18/100)^15*(3/12) -> 1382.329 | BW10: =$D$17*100*(1+$D$18/100)^16*(3/12) -> 1392.0053 | BX10: =$D$17*100*(1+$D$18/100)^16*(3/12) -> 1392.0053 | BY10: =$D$17*100*(1+$D$18/100)^16*(3/12) -> 1392.0053 | BZ10: =$D$17*100*(1+$D$18/100)^16*(3/12) -> 1392.0053 | CA10: =$D$17*100*(1+$D$18/100)^17*(3/12) -> 1401.7493 | CB10: =$D$17*100*(1+$D$18/100)^17*(3/12) -> 1401.7493 | CC10: =$D$17*100*(1+$D$18/100)^17*(3/12) -> 1401.7493 | CD10: =$D$17*100*(1+$D$18/100)^17*(3/12) -> 1401.7493 | CE10: =$D$17*100*(1+$D$18/100)^18*(3/12) -> 1411.5616 | CF10: =$D$17*100*(1+$D$18/100)^18*(3/12) -> 1411.5616 | CG10: =$D$17*100*(1+$D$18/100)^18*(3/12) -> 1411.5616 | CH10: =$D$17*100*(1+$D$18/100)^18*(3/12) -> 1411.5616 | CI10: =$D$17*100*(1+$D$18/100)^19*(3/12) -> 1421.4425 | CJ10: =$D$17*100*(1+$D$18/100)^19*(3/12) -> 1421.4425 | CK10: =$D$17*100*(1+$D$18/100)^19*(3/12) -> 1421.4425 | CL10: =$D$17*100*(1+$D$18/100)^19*(3/12) -> 1421.4425
B12: ※ 실측 오버라이드가 적용된 분기(예시 불러오기)는 "입력값" 시트의 실측 표를, 그 외 분기는 운영비 총액/에스컬레이션/후순위 비중(또는 운영비 항목)을 참조하는 수식입니다.
B15: 가정 (입력값 연결) — 이 시트의 계산이 쓰는 원천값 | D15: 값
B16: ※ 입력값 시트는 여기서만 참조합니다(초록 글자 = 입력값 연결). 위의 분기 계산은 이 셀들만 참조하므로, 값을 바꾸려면 입력값 시트를 고치세요.
B17: 운영비 총액[억원/yr] | C17: C18 | D17: ='입력값'!C18 -> 49.8
B18: 운영비 에스컬레이션[%/yr] | C18: C19 | D18: ='입력값'!C19 -> 0.7
B19: 운영비 중 후순위 비중[%] | C19: C20 | D19: ='입력값'!C20 -> 0

Sheet IS(Q)
A1: 샘플 태양광 100MW
A2: 추정 손익계산서 (분기)
B4: 손익계산서
B6: 구 분 | C6: unit | D6: 합 계 | E6: 2024-06-30 | F6: 2024-09-30 | G6: 2024-12-31 | H6: 2025-03-31 | I6: 2025-06-30 | J6: 2025-09-30 | K6: 2025-12-31 | L6: 2026-03-31 | M6: 2026-06-30 | N6: 2026-09-30 | O6: 2026-12-31 | P6: 2027-03-31 | Q6: 2027-06-30 | R6: 2027-09-30 | S6: 2027-12-31 | T6: 2028-03-31 | U6: 2028-06-30 | V6: 2028-09-30 | W6: 2028-12-31 | X6: 2029-03-31 | Y6: 2029-06-30 | Z6: 2029-09-30 | AA6: 2029-12-31 | AB6: 2030-03-31 | AC6: 2030-06-30 | AD6: 2030-09-30 | AE6: 2030-12-31 | AF6: 2031-03-31 | AG6: 2031-06-30 | AH6: 2031-09-30 | AI6: 2031-12-31 | AJ6: 2032-03-31 | AK6: 2032-06-30 | AL6: 2032-09-30 | AM6: 2032-12-31 | AN6: 2033-03-31 | AO6: 2033-06-30 | AP6: 2033-09-30 | AQ6: 2033-12-31 | AR6: 2034-03-31 | AS6: 2034-06-30 | AT6: 2034-09-30 | AU6: 2034-12-31 | AV6: 2035-03-31 | AW6: 2035-06-30 | AX6: 2035-09-30 | AY6: 2035-12-31 | AZ6: 2036-03-31 | BA6: 2036-06-30 | BB6: 2036-09-30 | BC6: 2036-12-31 | BD6: 2037-03-31 | BE6: 2037-06-30 | BF6: 2037-09-30 | BG6: 2037-12-31 | BH6: 2038-03-31 | BI6: 2038-06-30 | BJ6: 2038-09-30 | BK6: 2038-12-31 | BL6: 2039-03-31 | BM6: 2039-06-30 | BN6: 2039-09-30 | BO6: 2039-12-31 | BP6: 2040-03-31 | BQ6: 2040-06-30 | BR6: 2040-09-30 | BS6: 2040-12-31 | BT6: 2041-03-31 | BU6: 2041-06-30 | BV6: 2041-09-30 | BW6: 2041-12-31 | BX6: 2042-03-31 | BY6: 2042-06-30 | BZ6: 2042-09-30 | CA6: 2042-12-31 | CB6: 2043-03-31 | CC6: 2043-06-30 | CD6: 2043-09-30 | CE6: 2043-12-31 | CF6: 2044-03-31 | CG6: 2044-06-30 | CH6: 2044-09-30 | CI6: 2044-12-31 | CJ6: 2045-03-31 | CK6: 2045-06-30 | CL6: 2045-09-30
B8: 영업수익 | C8: [KRWm] | D8: =SUM(E8:CL8) -> 405788.89 | E8: ='Revenue'!E14 -> 0 | F8: ='Revenue'!F14 -> 0 | G8: ='Revenue'!G14 -> 0 | H8: ='Revenue'!H14 -> 0 | I8: ='Revenue'!I14 -> 0 | J8: ='Revenue'!J14 -> 0 | K8: ='Revenue'!K14 -> 5325.3135 | L8: ='Revenue'!L14 -> 5325.3135 | ... CL8: ='Revenue'!CL14 -> 4819.4087
B10: 영업비용 합계 | C10: [KRWm] | D10: =SUM(E10:CL10) -> -106510.05 | E10: =-'Opex'!E10 -> 0 | F10: =-'Opex'!F10 -> 0 | G10: =-'Opex'!G10 -> 0 | H10: =-'Opex'!H10 -> 0 | I10: =-'Opex'!I10 -> 0 | J10: =-'Opex'!J10 -> 0 | K10: =-'Opex'!K10 -> -1245 | L10: =-'Opex'!L10 -> -1245 | ... CL10: =-'Opex'!CL10 -> -1421.4425
B12: EBITDA | C12: [KRWm] | D12: =SUM(E12:CL12) -> 299278.84 | E12: =E8+E10 -> 0 | F12: =F8+F10 -> 0 | G12: =G8+G10 -> 0 | H12: =H8+H10 -> 0 | I12: =I8+I10 -> 0 | J12: =J8+J10 -> 0 | K12: =K8+K10 -> 4080.3135 | L12: =L8+L10 -> 4080.3135 | ... CL12: =CL8+CL10 -> 3397.9662
B13: EBITDA 마진 | C13: [%] | E13: =IF(E8<=0,"",E12/E8) | F13: =IF(F8<=0,"",F12/F8) | G13: =IF(G8<=0,"",G12/G8) | H13: =IF(H8<=0,"",H12/H8) | I13: =IF(I8<=0,"",I12/I8) | J13: =IF(J8<=0,"",J12/J8) | K13: =IF(K8<=0,"",K12/K8) -> 0.76621095 | L13: =IF(L8<=0,"",L12/L8) -> 0.76621095 | ... CL13: =IF(CL8<=0,"",CL12/CL8) -> 0.70505874
B15: 감가상각비 | C15: [KRWm] | D15: =SUM(E15:CL15) -> -137554.56 | E15: 0 | F15: 0 | G15: 0 | H15: 0 | I15: 0 | J15: 0 | K15: =-(('Funding'!C15*$D$58/100)/$D$59*(3/12)) -> -1719.432 | L15: =-(('Funding'!C15*$D$58/100)/$D$59*(3/12)) -> -1719.432 | M15: =-(('Funding'!C15*$D$58/100)/$D$59*(3/12)) -> -1719.432 | N15: =-(('Funding'!C15*$D$58/100)/$D$59*(3/12)) -> -1719.432 | O15: =-(('Funding'!C15*$D$58/100)/$D$59*(3/12)) -> -1719.432 | P15: =-(('Funding'!C15*$D$58/100)/$D$59*(3/12)) -> -1719.432 | Q15: =-(('Funding'!C15*$D$58/100)/$D$59*(3/12)) -> -1719.432 | R15: =-(('Funding'!C15*$D$58/100)/$D$59*(3/12)) -> -1719.432 | S15: =-(('Funding'!C15*$D$58/100)/$D$59*(3/12)) -> -1719.432 | T15: =-(('Funding'!C15*$D$58/100)/$D$59*(3/12)) -> -1719.432 | U15: =-(('Funding'!C15*$D$58/100)/$D$59*(3/12)) -> -1719.432 | V15: =-(('Funding'!C15*$D$58/100)/$D$59*(3/12)) -> -1719.432 | W15: =-(('Funding'!C15*$D$58/100)/$D$59*(3/12)) -> -1719.432 | X15: =-(('Funding'!C15*$D$58/100)/$D$59*(3/12)) -> -1719.432 | Y15: =-(('Funding'!C15*$D$58/100)/$D$59*(3/12)) -> -1719.432 | Z15: =-(('Funding'!C15*$D$58/100)/$D$59*(3/12)) -> -1719.432 | AA15: =-(('Funding'!C15*$D$58/100)/$D$59*(3/12)) -> -1719.432 | AB15: =-(('Funding'!C15*$D$58/100)/$D$59*(3/12)) -> -1719.432 | AC15: =-(('Funding'!C15*$D$58/100)/$D$59*(3/12)) -> -1719.432 | AD15: =-(('Funding'!C15*$D$58/100)/$D$59*(3/12)) -> -1719.432 | AE15: =-(('Funding'!C15*$D$58/100)/$D$59*(3/12)) -> -1719.432 | AF15: =-(('Funding'!C15*$D$58/100)/$D$59*(3/12)) -> -1719.432 | AG15: =-(('Funding'!C15*$D$58/100)/$D$59*(3/12)) -> -1719.432 | AH15: =-(('Funding'!C15*$D$58/100)/$D$59*(3/12)) -> -1719.432 | AI15: =-(('Funding'!C15*$D$58/100)/$D$59*(3/12)) -> -1719.432 | AJ15: =-(('Funding'!C15*$D$58/100)/$D$59*(3/12)) -> -1719.432 | AK15: =-(('Funding'!C15*$D$58/100)/$D$59*(3/12)) -> -1719.432 | AL15: =-(('Funding'!C15*$D$58/100)/$D$59*(3/12)) -> -1719.432 | AM15: =-(('Funding'!C15*$D$58/100)/$D$59*(3/12)) -> -1719.432 | AN15: =-(('Funding'!C15*$D$58/100)/$D$59*(3/12)) -> -1719.432 | AO15: =-(('Funding'!C15*$D$58/100)/$D$59*(3/12)) -> -1719.432 | AP15: =-(('Funding'!C15*$D$58/100)/$D$59*(3/12)) -> -1719.432 | AQ15: =-(('Funding'!C15*$D$58/100)/$D$59*(3/12)) -> -1719.432 | AR15: =-(('Funding'!C15*$D$58/100)/$D$59*(3/12)) -> -1719.432 | AS15: =-(('Funding'!C15*$D$58/100)/$D$59*(3/12)) -> -1719.432 | AT15: =-(('Funding'!C15*$D$58/100)/$D$59*(3/12)) -> -1719.432 | AU15: =-(('Funding'!C15*$D$58/100)/$D$59*(3/12)) -> -1719.432 | AV15: =-(('Funding'!C15*$D$58/100)/$D$59*(3/12)) -> -1719.432 | AW15: =-(('Funding'!C15*$D$58/100)/$D$59*(3/12)) -> -1719.432 | AX15: =-(('Funding'!C15*$D$58/100)/$D$59*(3/12)) -> -1719.432 | AY15: =-(('Funding'!C15*$D$58/100)/$D$59*(3/12)) -> -1719.432 | AZ15: =-(('Funding'!C15*$D$58/100)/$D$59*(3/12)) -> -1719.432 | BA15: =-(('Funding'!C15*$D$58/100)/$D$59*(3/12)) -> -1719.432 | BB15: =-(('Funding'!C15*$D$58/100)/$D$59*(3/12)) -> -1719.432 | BC15: =-(('Funding'!C15*$D$58/100)/$D$59*(3/12)) -> -1719.432 | BD15: =-(('Funding'!C15*$D$58/100)/$D$59*(3/12)) -> -1719.432 | BE15: =-(('Funding'!C15*$D$58/100)/$D$59*(3/12)) -> -1719.432 | BF15: =-(('Funding'!C15*$D$58/100)/$D$59*(3/12)) -> -1719.432 | BG15: =-(('Funding'!C15*$D$58/100)/$D$59*(3/12)) -> -1719.432 | BH15: =-(('Funding'!C15*$D$58/100)/$D$59*(3/12)) -> -1719.432 | BI15: =-(('Funding'!C15*$D$58/100)/$D$59*(3/12)) -> -1719.432 | BJ15: =-(('Funding'!C15*$D$58/100)/$D$59*(3/12)) -> -1719.432 | BK15: =-(('Funding'!C15*$D$58/100)/$D$59*(3/12)) -> -1719.432 | BL15: =-(('Funding'!C15*$D$58/100)/$D$59*(3/12)) -> -1719.432 | BM15: =-(('Funding'!C15*$D$58/100)/$D$59*(3/12)) -> -1719.432 | BN15: =-(('Funding'!C15*$D$58/100)/$D$59*(3/12)) -> -1719.432 | BO15: =-(('Funding'!C15*$D$58/100)/$D$59*(3/12)) -> -1719.432 | BP15: =-(('Funding'!C15*$D$58/100)/$D$59*(3/12)) -> -1719.432 | BQ15: =-(('Funding'!C15*$D$58/100)/$D$59*(3/12)) -> -1719.432 | BR15: =-(('Funding'!C15*$D$58/100)/$D$59*(3/12)) -> -1719.432 | BS15: =-(('Funding'!C15*$D$58/100)/$D$59*(3/12)) -> -1719.432 | BT15: =-(('Funding'!C15*$D$58/100)/$D$59*(3/12)) -> -1719.432 | BU15: =-(('Funding'!C15*$D$58/100)/$D$59*(3/12)) -> -1719.432 | BV15: =-(('Funding'!C15*$D$58/100)/$D$59*(3/12)) -> -1719.432 | BW15: =-(('Funding'!C15*$D$58/100)/$D$59*(3/12)) -> -1719.432 | BX15: =-(('Funding'!C15*$D$58/100)/$D$59*(3/12)) -> -1719.432 | BY15: =-(('Funding'!C15*$D$58/100)/$D$59*(3/12)) -> -1719.432 | BZ15: =-(('Funding'!C15*$D$58/100)/$D$59*(3/12)) -> -1719.432 | CA15: =-(('Funding'!C15*$D$58/100)/$D$59*(3/12)) -> -1719.432 | CB15: =-(('Funding'!C15*$D$58/100)/$D$59*(3/12)) -> -1719.432 | CC15: =-(('Funding'!C15*$D$58/100)/$D$59*(3/12)) -> -1719.432 | CD15: =-(('Funding'!C15*$D$58/100)/$D$59*(3/12)) -> -1719.432 | CE15: =-(('Funding'!C15*$D$58/100)/$D$59*(3/12)) -> -1719.432 | CF15: =-(('Funding'!C15*$D$58/100)/$D$59*(3/12)) -> -1719.432 | CG15: =-(('Funding'!C15*$D$58/100)/$D$59*(3/12)) -> -1719.432 | CH15: =-(('Funding'!C15*$D$58/100)/$D$59*(3/12)) -> -1719.432 | CI15: =-(('Funding'!C15*$D$58/100)/$D$59*(3/12)) -> -1719.432 | CJ15: =-(('Funding'!C15*$D$58/100)/$D$59*(3/12)) -> -1719.432 | CK15: =-(('Funding'!C15*$D$58/100)/$D$59*(3/12)) -> -1719.432 | CL15: =-(('Funding'!C15*$D$58/100)/$D$59*(3/12)) -> -1719.432
B16: 복구충당부채 전입액 | C16: [KRWm] | D16: =SUM(E16:CL16) -> -2000 | E16: 0 | F16: 0 | G16: 0 | H16: 0 | I16: 0 | J16: 0 | K16: =-($D$60*100/80) -> -25 | L16: =-($D$60*100/80) -> -25 | M16: =-($D$60*100/80) -> -25 | N16: =-($D$60*100/80) -> -25 | O16: =-($D$60*100/80) -> -25 | P16: =-($D$60*100/80) -> -25 | Q16: =-($D$60*100/80) -> -25 | R16: =-($D$60*100/80) -> -25 | ... CL16: =-($D$60*100/80) -> -25
B17: 기타 비현금 세무손금 | C17: [KRWm] | D17: =SUM(E17:CL17) -> 0 | E17: 0 | F17: 0 | G17: 0 | H17: 0 | I17: 0 | J17: 0 | K17: =-($D$62/80) -> 0 | L17: =-($D$62/80) -> 0 | M17: =-($D$62/80) -> 0 | N17: =-($D$62/80) -> 0 | O17: =-($D$62/80) -> 0 | P17: =-($D$62/80) -> 0 | Q17: =-($D$62/80) -> 0 | R17: =-($D$62/80) -> 0 | ... CL17: =-($D$62/80) -> 0
B18: 대리은행수수료 | C18: [KRWm] | D18: =SUM(E18:CL18) -> 0 | E18: 0 | F18: 0 | G18: 0 | H18: 0 | I18: 0 | J18: 0 | K18: =-($D$61/80) -> 0 | L18: =-($D$61/80) -> 0 | M18: =-($D$61/80) -> 0 | N18: =-($D$61/80) -> 0 | O18: =-($D$61/80) -> 0 | P18: =-($D$61/80) -> 0 | Q18: =-($D$61/80) -> 0 | R18: =-($D$61/80) -> 0 | ... CL18: =-($D$61/80) -> 0
B19: 영업이익(EBIT) | C19: [KRWm] | D19: =SUM(E19:CL19) -> 159724.28 | E19: =E12+E15+E16+E17+E18 -> 0 | F19: =F12+F15+F16+F17+F18 -> 0 | G19: =G12+G15+G16+G17+G18 -> 0 | H19: =H12+H15+H16+H17+H18 -> 0 | I19: =I12+I15+I16+I17+I18 -> 0 | J19: =J12+J15+J16+J17+J18 -> 0 | K19: =K12+K15+K16+K17+K18 -> 2335.8815 | L19: =L12+L15+L16+L17+L18 -> 2335.8815 | ... CL19: =CL12+CL15+CL16+CL17+CL18 -> 1653.5342
B20: 영업이익률 | C20: [%] | E20: =IF(E8<=0,"",E19/E8) | F20: =IF(F8<=0,"",F19/F8) | G20: =IF(G8<=0,"",G19/G8) | H20: =IF(H8<=0,"",H19/H8) | I20: =IF(I8<=0,"",I19/I8) | J20: =IF(J8<=0,"",J19/J8) | K20: =IF(K8<=0,"",K19/K8) -> 0.43863736 | L20: =IF(L8<=0,"",L19/L8) -> 0.43863736 | ... CL20: =IF(CL8<=0,"",CL19/CL8) -> 0.34309897
B22: 이자비용 세부내역
B23: 선순위A 이자 | C23: [KRWm] | D23: =SUM(E23:CL23) -> -40880 | E23: =-'Debt'!E27 -> 0 | F23: =-'Debt'!F27 -> 0 | G23: =-'Debt'!G27 -> 0 | H23: =-'Debt'!H27 -> 0 | I23: =-'Debt'!I27 -> 0 | J23: =-'Debt'!J27 -> 0 | K23: =-'Debt'!K27 -> -1120 | L23: =-'Debt'!L27 -> -1120 | ... CL23: =-'Debt'!CL27 -> 0
B24: 선순위B 이자 | C24: [KRWm] | D24: =SUM(E24:CL24) -> -23120.879 | E24: =-'Debt'!E37 -> 0 | F24: =-'Debt'!F37 -> 0 | G24: =-'Debt'!G37 -> 0 | H24: =-'Debt'!H37 -> 0 | I24: =-'Debt'!I37 -> 0 | J24: =-'Debt'!J37 -> 0 | K24: =-'Debt'!K37 -> -633.44875 | L24: =-'Debt'!L37 -> -633.44875 | ... CL24: =-'Debt'!CL37 -> 0
B25: 이자비용 합계 | C25: [KRWm] | D25: =SUM(E25:CL25) -> -64000.879 | E25: =E23+E24 -> 0 | F25: =F23+F24 -> 0 | G25: =G23+G24 -> 0 | H25: =H23+H24 -> 0 | I25: =I23+I24 -> 0 | J25: =J23+J24 -> 0 | K25: =K23+K24 -> -1753.4487 | L25: =L23+L24 -> -1753.4487 | ... CL25: =CL23+CL24 -> 0
B27: 법인세차감전순이익 | C27: [KRWm] | D27: =SUM(E27:CL27) -> 95723.399 | E27: =E19+E25 -> 0 | F27: =F19+F25 -> 0 | G27: =G19+G25 -> 0 | H27: =H19+H25 -> 0 | I27: =I19+I25 -> 0 | J27: =J19+J25 -> 0 | K27: =K19+K25 -> 582.43271 | L27: =L19+L25 -> 582.43271 | ... CL27: =CL19+CL25 -> 1653.5342
B28: 법인세비용 | C28: [KRWm] | D28: =SUM(E28:CL28) -> -19544.19 | E28: =IF(AND(E27>0,E51>0),-E50*E27/E51,0) -> 0 | F28: =IF(AND(F27>0,E51>0),-E50*F27/E51,0) -> 0 | G28: =IF(AND(G27>0,E51>0),-E50*G27/E51,0) -> 0 | H28: =IF(AND(H27>0,F51>0),-F50*H27/F51,0) -> 0 | I28: =IF(AND(I27>0,F51>0),-F50*I27/F51,0) -> 0 | J28: =IF(AND(J27>0,F51>0),-F50*J27/F51,0) -> 0 | K28: =IF(AND(K27>0,F51>0),-F50*K27/F51,0) -> -104.95344 | L28: =IF(AND(L27>0,G51>0),-G50*L27/G51,0) -> -121.4492 | M28: =IF(AND(M27>0,G51>0),-G50*M27/G51,0) -> -121.4492 | N28: =IF(AND(N27>0,G51>0),-G50*N27/G51,0) -> -121.4492 | O28: =IF(AND(O27>0,G51>0),-G50*O27/G51,0) -> -114.07976 | P28: =IF(AND(P27>0,H51>0),-H50*P27/H51,0) -> -119.80777 | Q28: =IF(AND(Q27>0,H51>0),-H50*Q27/H51,0) -> -125.52146 | R28: =IF(AND(R27>0,H51>0),-H50*R27/H51,0) -> -131.23515 | S28: =IF(AND(S27>0,H51>0),-H50*S27/H51,0) -> -129.56574 | T28: =IF(AND(T27>0,I51>0),-I50*T27/I51,0) -> -135.31146 | U28: =IF(AND(U27>0,I51>0),-I50*U27/I51,0) -> -141.0265 | V28: =IF(AND(V27>0,I51>0),-I50*V27/I51,0) -> -146.74154 | W28: =IF(AND(W27>0,I51>0),-I50*W27/I51,0) -> -145.05893 | X28: =IF(AND(X27>0,J51>0),-J50*X27/J51,0) -> -150.80262 | Y28: =IF(AND(Y27>0,J51>0),-J50*Y27/J51,0) -> -156.51875 | Z28: =IF(AND(Z27>0,J51>0),-J50*Z27/J51,0) -> -162.23488 | AA28: =IF(AND(AA27>0,J51>0),-J50*AA27/J51,0) -> -160.53904 | AB28: =IF(AND(AB27>0,K51>0),-K50*AB27/K51,0) -> -166.28109 | AC28: =IF(AND(AC27>0,K51>0),-K50*AC27/K51,0) -> -171.99811 | AD28: =IF(AND(AD27>0,K51>0),-K50*AD27/K51,0) -> -177.71512 | AE28: =IF(AND(AE27>0,K51>0),-K50*AE27/K51,0) -> -176.00602 | AF28: =IF(AND(AF27>0,L51>0),-L50*AF27/L51,0) -> -181.74671 | AG28: =IF(AND(AG27>0,L51>0),-L50*AG27/L51,0) -> -187.46447 | AH28: =IF(AND(AH27>0,L51>0),-L50*AH27/L51,0) -> -193.18223 | AI28: =IF(AND(AI27>0,L51>0),-L50*AI27/L51,0) -> -191.45981 | AJ28: =IF(AND(AJ27>0,M51>0),-M50*AJ27/M51,0) -> -197.19935 | AK28: =IF(AND(AK27>0,M51>0),-M50*AK27/M51,0) -> -202.91774 | AL28: =IF(AND(AL27>0,M51>0),-M50*AL27/M51,0) -> -208.63614 | AM28: =IF(AND(AM27>0,M51>0),-M50*AM27/M51,0) -> -206.90034 | AN28: =IF(AND(AN27>0,N51>0),-N50*AN27/N51,0) -> -212.63889 | AO28: =IF(AND(AO27>0,N51>0),-N50*AO27/N51,0) -> -218.35783 | AP28: =IF(AND(AP27>0,N51>0),-N50*AP27/N51,0) -> -224.07676 | AQ28: =IF(AND(AQ27>0,N51>0),-N50*AQ27/N51,0) -> -222.32753 | AR28: =IF(AND(AR27>0,O51>0),-O50*AR27/O51,0) -> -228.06523 | AS28: =IF(AND(AS27>0,O51>0),-O50*AS27/O51,0) -> -233.78463 | AT28: =IF(AND(AT27>0,O51>0),-O50*AT27/O51,0) -> -239.50404 | AU28: =IF(AND(AU27>0,O51>0),-O50*AU27/O51,0) -> -237.74129 | AV28: =IF(AND(AV27>0,P51>0),-P50*AV27/P51,0) -> -243.47824 | AW28: =IF(AND(AW27>0,P51>0),-P50*AW27/P51,0) -> -249.19806 | AX28: =IF(AND(AX27>0,P51>0),-P50*AX27/P51,0) -> -254.91788 | AY28: =IF(AND(AY27>0,P51>0),-P50*AY27/P51,0) -> -253.14153 | AZ28: =IF(AND(AZ27>0,Q51>0),-Q50*AZ27/Q51,0) -> -258.87783 | BA28: =IF(AND(BA27>0,Q51>0),-Q50*BA27/Q51,0) -> -264.59801 | BB28: =IF(AND(BB27>0,Q51>0),-Q50*BB27/Q51,0) -> -270.3182 | BC28: =IF(AND(BC27>0,Q51>0),-Q50*BC27/Q51,0) -> -268.52818 | BD28: =IF(AND(BD27>0,R51>0),-R50*BD27/R51,0) -> -274.26389 | BE28: =IF(AND(BE27>0,R51>0),-R50*BE27/R51,0) -> -279.9844 | BF28: =IF(AND(BF27>0,R51>0),-R50*BF27/R51,0) -> -285.70491 | BG28: =IF(AND(BG27>0,R51>0),-R50*BG27/R51,0) -> -283.90113 | BH28: =IF(AND(BH27>0,S51>0),-S50*BH27/S51,0) -> -289.63632 | BI28: =IF(AND(BI27>0,S51>0),-S50*BI27/S51,0) -> -295.35712 | BJ28: =IF(AND(BJ27>0,S51>0),-S50*BJ27/S51,0) -> -301.07792 | BK28: =IF(AND(BK27>0,S51>0),-S50*BK27/S51,0) -> -299.26029 | BL28: =IF(AND(BL27>0,T51>0),-T50*BL27/T51,0) -> -304.99502 | BM28: =IF(AND(BM27>0,T51>0),-T50*BM27/T51,0) -> -310.71608 | BN28: =IF(AND(BN27>0,T51>0),-T50*BN27/T51,0) -> -316.43714 | BO28: =IF(AND(BO27>0,T51>0),-T50*BO27/T51,0) -> -314.60558 | BP28: =IF(AND(BP27>0,U51>0),-U50*BP27/U51,0) -> -320.33988 | BQ28: =IF(AND(BQ27>0,U51>0),-U50*BQ27/U51,0) -> -326.06118 | BR28: =IF(AND(BR27>0,U51>0),-U50*BR27/U51,0) -> -331.78247 | BS28: =IF(AND(BS27>0,U51>0),-U50*BS27/U51,0) -> -329.93689 | BT28: =IF(AND(BT27>0,V51>0),-V50*BT27/V51,0) -> -335.67081 | BU28: =IF(AND(BU27>0,V51>0),-V50*BU27/V51,0) -> -341.39232 | BV28: =IF(AND(BV27>0,V51>0),-V50*BV27/V51,0) -> -347.11383 | BW28: =IF(AND(BW27>0,V51>0),-V50*BW27/V51,0) -> -345.25413 | BX28: =IF(AND(BX27>0,W51>0),-W50*BX27/W51,0) -> -350.9877 | BY28: =IF(AND(BY27>0,W51>0),-W50*BY27/W51,0) -> -356.70941 | BZ28: =IF(AND(BZ27>0,W51>0),-W50*BZ27/W51,0) -> -362.43112 | CA28: =IF(AND(CA27>0,W51>0),-W50*CA27/W51,0) -> -360.55721 | CB28: =IF(AND(CB27>0,X51>0),-X50*CB27/X51,0) -> -360.55797 | CC28: =IF(AND(CC27>0,X51>0),-X50*CC27/X51,0) -> -360.55797 | CD28: =IF(AND(CD27>0,X51>0),-X50*CD27/X51,0) -> -360.55797 | CE28: =IF(AND(CE27>0,X51>0),-X50*CE27/X51,0) -> -352.94809 | CF28: =IF(AND(CF27>0,Y51>0),-Y50*CF27/Y51,0) -> -352.94222 | CG28: =IF(AND(CG27>0,Y51>0),-Y50*CG27/Y51,0) -> -352.94222 | CH28: =IF(AND(CH27>0,Y51>0),-Y50*CH27/Y51,0) -> -352.94222 | CI28: =IF(AND(CI27>0,Y51>0),-Y50*CI27/Y51,0) -> -345.31813 | CJ28: =IF(AND(CJ27>0,Z51>0),-Z50*CJ27/Z51,0) -> -204.14698 | CK28: =IF(AND(CK27>0,Z51>0),-Z50*CK27/Z51,0) -> -204.14698 | CL28: =IF(AND(CL27>0,Z51>0),-Z50*CL27/Z51,0) -> -204.14698
B29: 당기순이익 | C29: [KRWm] | D29: =SUM(E29:CL29) -> 76179.208 | E29: =E27+E28 -> 0 | F29: =F27+F28 -> 0 | G29: =G27+G28 -> 0 | H29: =H27+H28 -> 0 | I29: =I27+I28 -> 0 | J29: =J27+J28 -> 0 | K29: =K27+K28 -> 477.47927 | L29: =L27+L28 -> 460.98351 | ... CL29: =CL27+CL28 -> 1449.3872
B32: 연도별 법인세 산출
B34: 세무상 과세표준(분기, 연간집계용) | C34: [KRWm] | D34: =SUM(E34:CL34) -> 95723.399 | E34: =E27-E16-(0) -> 0 | F34: =F27-F16-(0) -> 0 | G34: =G27-G16-(0) -> 0 | H34: =H27-H16-(0) -> 0 | I34: =I27-I16-(0) -> 0 | J34: =J27-J16-(0) -> 0 | K34: =K27-K16-(0) -> 607.43271 | L34: =L27-L16-(0) -> 607.43271 | ... CK34: =CK27-CK16-(0) -> 1678.5342 | CL34: =CL27-CL16-($D$60*100) -> -321.46581
B36: 연도 | E36: 2024 | F36: 2025 | G36: 2026 | H36: 2027 | I36: 2028 | J36: 2029 | K36: 2030 | L36: 2031 | M36: 2032 | N36: 2033 | O36: 2034 | P36: 2035 | Q36: 2036 | R36: 2037 | S36: 2038 | T36: 2039 | U36: 2040 | V36: 2041 | W36: 2042 | X36: 2043 | Y36: 2044 | Z36: 2045
B37: 과세표준(연간, 손실이월 전) | C37: [KRWm] | E37: =E34+F34+G34 -> 0 | F37: =H34+I34+J34+K34 -> 607.43271 | G37: =L34+M34+N34+O34 -> 2394.3893 | H37: =P34+Q34+R34+S34 -> 2526.9384 | I37: =T34+U34+V34+W34 -> 2823.6288 | J37: =X34+Y34+Z34+AA34 -> 3120.0731 | K37: =AB34+AC34+AD34+AE34 -> 3416.2696 | L37: =AF34+AG34+AH34+AI34 -> 3712.2164 | M37: =AJ34+AK34+AL34+AM34 -> 4007.9118 | N37: =AN34+AO34+AP34+AQ34 -> 4303.3541 | O37: =AR34+AS34+AT34+AU34 -> 4598.5416 | P37: =AV34+AW34+AX34+AY34 -> 4893.4723 | Q37: =AZ34+BA34+BB34+BC34 -> 5188.1446 | R37: =BD34+BE34+BF34+BG34 -> 5482.5566 | S37: =BH34+BI34+BJ34+BK34 -> 5776.7064 | T37: =BL34+BM34+BN34+BO34 -> 6070.5924 | U37: =BP34+BQ34+BR34+BS34 -> 6364.2125 | V37: =BT34+BU34+BV34+BW34 -> 6657.565 | W37: =BX34+BY34+BZ34+CA34 -> 6950.648 | X37: =CB34+CC34+CD34+CE34 -> 6969.4832 | Y37: =CF34+CG34+CH34+CI34 -> 6823.6593 | Z37: =CJ34+CK34+CL34 -> 3035.6026
B38: 직전 이월결손금(기초) | C38: [KRWm] | E38: =0 -> 0 | F38: =E40 -> 0 | G38: =F40 -> 0 | H38: =G40 -> 0 | I38: =H40 -> 0 | J38: =I40 -> 0 | K38: =J40 -> 0 | L38: =K40 -> 0 | M38: =L40 -> 0 | ... Z38: =Y40 -> 0
