Workbook

Sheet 목차
B2: 태양광 발전사업
B3: 재무모델 v2 (분기·5트랜치) — 재생E AI Agent 자동생성 · 2026-09-22
B6: 시트 | C6: 내용
B7: Report | C7: Executive Summary — 핵심 KPI
B8: 입력값 | C8: 화면에서 입력한 원본 값 — Funding 등이 이 시트를 참조
B9: Funding | C9: 자금조달 — 자본금 + 5트랜치 조건
B10: Debt | C10: 트랜치별 상환 스케줄 (A/B/C/D/후순위) + 합계
B11: Revenue | C11: 발전량 · 매출
B12: Opex | C12: 운영비 (선순위/후순위)
B13: IS(Q) | C13: 분기 손익계산서
B14: CF(Q) | C14: 분기 현금흐름 · DSCR · 배당
B16: ※ 입력값 시트(노란 탭) 외의 모든 값은 수식입니다. 노란 셀을 고치면 세금·DSCR·배당·IRR 까지 전부 다시 계산됩니다. 회색 셀(거치·상환·방식·투입순서, DSRA 적립기준)은 스케줄의 모양을 정하는 값이라 화면에서 다시 생성해야 합니다. 각 계산 시트 맨 아래 "가정" 블록이 입력값 시트를 참조하는 유일한 곳입니다.

Sheet Report
A1: 태양광 발전사업
A2: Executive Summary (v2 · 분기 · 5트랜치)
B4: 사업 개요
B6: 사업명 | D6: ='입력값'!C6
B7: 설비용량 [MW] | D7: ='입력값'!C7
B8: 총 기간 수(분기) | D8: 86
B9: 건설 개시 | D9: 2024-06
B11: 재원조달
B13: 총투자비(TIC) [KRWm] | D13: ='Funding'!C18
B14: 건설이자(IDC) [KRWm] | D14: ='Funding'!C17
B15: 자기자본 [KRWm] | D15: ='Funding'!C7
B16: 차입금 합계 [KRWm] | D16: ='Funding'!C13
B18: 수익성 지표
B20: Project IRR 세전 [%] | D20: ='CF(Q)'!D62
B21: Project IRR 세후 [%] | D21: ='CF(Q)'!D63
B22: Equity IRR (FCFE) [%] | D22: ='CF(Q)'!D64
B23: Equity IRR (배당) [%] | D23: ='CF(Q)'!D65
B24: Investor IRR [%] | D24: ='CF(Q)'!D66
B25: 최소 단순DSCR(연 합산) [x] | D25: ='CF(Q)'!D47
B26: 최소 누적DSCR [x] | D26: ='CF(Q)'!D48
B27: 총영업수익(전체기간) [KRWm] | D27: ='Revenue'!D17
B28: 총영업비용(전체기간) [KRWm] | D28: ='Opex'!D24
B29: 총선순위이자 [KRWm] | D29: ='Debt'!D77
B30: 총법인세 [KRWm] | D30: =-'IS(Q)'!D44
B31: 총배당(연차+청산) [KRWm] | D31: ='CF(Q)'!D16

Sheet 입력값
A1: 태양광 발전사업
A2: 입력값 — 화면에서 입력한 값 (다른 시트가 이 시트를 참조)
B4: 사업 기본 가정
B6: 사업명 | C6: 태양광 발전사업
B7: 설비용량[MW] | C7: 99.998
B8: 총사업비[억원] | C8: 1410.69
B9: 자기자본[억원] | C9: 150
B10: 판매단가[원/kWh] | C10: 154.8
B11: 판매단가 에스컬레이션[%/yr] | C11: 0
B12: 발전량 열화율[%/yr] | C12: 0.5
B13: 소내소비율[%] | C13: 0
B14: 일조시간[h/day] | C14: 3.77
B15: 상각대상 비율(TIC 대비)[%] | C15: 95
B16: 감가상각 내용연수[yr] | C16: 20
B17: 철거비(복구충당부채)[억원] | C17: 20
B18: 운영비 총액[억원/yr] | C18: 49.8
... B28: 배당 개시 운영연차 | C28: 2
B30: 법인세 가정
B32: 이월결손금 공제한도[%] | C32: 80
B33: 최저한세율[%] | C33: 0
B34: 통합투자세액공제율[%] | C34: 0
B35: 지방소득세율(법인세 대비)[%] | C35: 10
B36: 세액공제 농특세율[%] | C36: 0
B38: 판매단가 트랙 (PPA/SMP+REC 등)
B40: 트랙 | C40: 비중[%] | D40: 단가[원/kWh] | E40: 에스컬레이션[%/yr] | F40: 대금회수시차[개월]
B41: PPA | C41: 100 | D41: 154.8 | E41: 0 | F41: 1
B43: 트랜치 조건
B45: 트랜치 | C45: 금액[억원] | D45: 건설금리[%] | E45: 운영금리[%] | F45: 거치(yr) | G45: 상환(yr) | H45: 방식 | I45: 투입순서
B46: 선순위A | C46: 500 | D46: 0.056 | E46: 0.056 | F46: 2 | G46: 16 | H46: 1 | I46: 2
B47: 선순위B | C47: 500 | D47: 0.055 | E47: 0.055 | F47: 2 | G47: 16 | H47: 1 | I47: 2
B48: 선순위C | C48: 350 | D48: 0.055 | E48: 0.055 | F48: 1.25 | G48: 16 | H48: 1 | I48: 4
B49: 선순위D | C49: 0 | D49: 0.0225 | E49: 0.0225 | F49: 5 | G49: 10 | H49: 1 | I49: 3
B50: 후순위 | C50: 0 | D50: 0.0565 | E50: 0.0565 | F50: 15 | G50: 2.75 | H50: 1 | I50: 1
B51: 자본금 | C51: =C9 | I51: 1
B53: 총사업비 지출 스케줄 (건설 분기별 비중)
B55: 구 분 | C55: unit | D55: 합 계 | E55: 2024-06-30 | F55: 2024-09-30 | G55: 2024-12-31 | H55: 2025-03-31 | I55: 2025-06-30 | J55: 2025-09-30 | K55: 2025-12-31 | L55: 2026-03-31 | M55: 2026-06-30 | N55: 2026-09-30 | O55: 2026-12-31 | P55: 2027-03-31 | Q55: 2027-06-30 | R55: 2027-09-30 | S55: 2027-12-31 | T55: 2028-03-31 | U55: 2028-06-30 | V55: 2028-09-30 | W55: 2028-12-31 | X55: 2029-03-31 | Y55: 2029-06-30 | Z55: 2029-09-30 | AA55: 2029-12-31 | AB55: 2030-03-31 | AC55: 2030-06-30 | AD55: 2030-09-30 | AE55: 2030-12-31 | AF55: 2031-03-31 | AG55: 2031-06-30 | AH55: 2031-09-30 | AI55: 2031-12-31 | AJ55: 2032-03-31 | AK55: 2032-06-30 | AL55: 2032-09-30 | AM55: 2032-12-31 | AN55: 2033-03-31 | AO55: 2033-06-30 | AP55: 2033-09-30 | AQ55: 2033-12-31 | AR55: 2034-03-31 | AS55: 2034-06-30 | AT55: 2034-09-30 | AU55: 2034-12-31 | AV55: 2035-03-31 | AW55: 2035-06-30 | AX55: 2035-09-30 | AY55: 2035-12-31 | AZ55: 2036-03-31 | BA55: 2036-06-30 | BB55: 2036-09-30 | BC55: 2036-12-31 | BD55: 2037-03-31 | BE55: 2037-06-30 | BF55: 2037-09-30 | BG55: 2037-12-31 | BH55: 2038-03-31 | BI55: 2038-06-30 | BJ55: 2038-09-30 | BK55: 2038-12-31 | BL55: 2039-03-31 | BM55: 2039-06-30 | BN55: 2039-09-30 | BO55: 2039-12-31 | BP55: 2040-03-31 | BQ55: 2040-06-30 | BR55: 2040-09-30 | BS55: 2040-12-31 | BT55: 2041-03-31 | BU55: 2041-06-30 | BV55: 2041-09-30 | BW55: 2041-12-31 | BX55: 2042-03-31 | BY55: 2042-06-30 | BZ55: 2042-09-30 | CA55: 2042-12-31 | CB55: 2043-03-31 | CC55: 2043-06-30 | CD55: 2043-09-30 | CE55: 2043-12-31 | CF55: 2044-03-31 | CG55: 2044-06-30 | CH55: 2044-09-30 | CI55: 2044-12-31 | CJ55: 2045-03-31 | CK55: 2045-06-30 | CL55: 2045-09-30
B57: 지출 비중 | C57: [비율] | D57: =SUM(E57:CL57) | E57: 0.16666667 | F57: 0.16666667 | G57: 0.16666667 | H57: 0.16666667 | I57: 0.16666667 | J57: 0.16666667
B59: 총사업비 항목
B61: 항목 | C61: 금액[억원]
B62: EPC
...

Sheet Funding
A1: 태양광 발전사업
A2: 자금조달 — 자본금 + 5개 트랜치
B4: 트랜치 조건
B6: 트랜치 | C6: 금액[KRWm] | D6: 투입순서 | E6: 건설금리 | F6: 운영금리 | G6: 거치(yr) | H6: 상환(yr) | I6: 방식 | J6: 상환개시
B7: 자본금 | C7: ='입력값'!C9*100
B8: 선순위A | C8: ='입력값'!C46*100 | E8: ='입력값'!D46 | F8: ='입력값'!E46 | G8: ='입력값'!F46 | H8: ='입력값'!G46 | I8: ='입력값'!H46 | J8: 2026-09-30
B9: 선순위B | C9: ='입력값'!C47*100 | E9: ='입력값'!D47 | F9: ='입력값'!E47 | G9: ='입력값'!F47 | H9: ='입력값'!G47 | I9: ='입력값'!H47 | J9: 2026-09-30
B10: 선순위C | C10: ='입력값'!C48*100 | E10: ='입력값'!D48 | F10: ='입력값'!E48 | G10: ='입력값'!F48 | H10: ='입력값'!G48 | I10: ='입력값'!H48 | J10: 2026-09-30
B11: 선순위D | C11: ='입력값'!C49*100 | E11: ='입력값'!D49 | F11: ='입력값'!E49 | G11: ='입력값'!F49 | H11: ='입력값'!G49 | I11: ='입력값'!H49 | J11: -
B12: 후순위 | C12: ='입력값'!C50*100 | E12: ='입력값'!D50 | F12: ='입력값'!E50 | G12: ='입력값'!F50 | H12: ='입력값'!G50 | I12: ='입력값'!H50 | J12: -
B13: 차입금 합계 | C13: =C8+C9+C10+C11+C12
B15: 건설이자(IDC)
B17: IDC 합계[KRWm] | C17: ='Debt'!D15
B18: 총투자비(TIC)[KRWm] | C18: =$D$41*100+'Debt'!D15
B19: 총사업비(건설이자 제외)[KRWm] | C19: ='입력값'!C8*100
B21: 총사업비 세부내역
B23: 항목 | C23: 금액[KRWm]
B24: ='입력값'!B62
B25: ='입력값'!B63
B26: ='입력값'!B64
B27: ='입력값'!B65
B28: ='입력값'!B66
B29: ='입력값'!B67
B30: ='입력값'!B68
B31: ='입력값'!B69
B32: ='입력값'!B70
B33: ='입력값'!B71
B34: ='입력값'!B72
B35: ='입력값'!B73
B36: 총사업비 (항목별 금액 미입력) | C36: ='입력값'!C8*100
B39: 가정 (입력값 연결) — 이 시트의 계산이 쓰는 원천값 | D39: 값
B40: ※ 입력값 시트는 여기서만 참조합니다(초록 글자 = 입력값 연결). 위의 분기 계산은 이 셀들만 참조하므로, 값을 바꾸려면 입력값 시트를 고치세요.
B41: 총사업비[억원] | C41: C8 | D41: ='입력값'!C8

Sheet Debt
A1: 태양광 발전사업
A2: 차입금 상환 스케줄 — 건설기간 인출 + 트랜치별 상환
B4: 건설기간 자금조달 (인출·건설이자)
B6: 구 분 | C6: unit | D6: 합 계 | E6: 2024-06-30 | F6: 2024-09-30 | G6: 2024-12-31 | H6: 2025-03-31 | I6: 2025-06-30 | J6: 2025-09-30 | K6: 2025-12-31 | L6: 2026-03-31 | M6: 2026-06-30 | N6: 2026-09-30 | O6: 2026-12-31 | P6: 2027-03-31 | Q6: 2027-06-30 | R6: 2027-09-30 | S6: 2027-12-31 | T6: 2028-03-31 | U6: 2028-06-30 | V6: 2028-09-30 | W6: 2028-12-31 | X6: 2029-03-31 | Y6: 2029-06-30 | Z6: 2029-09-30 | AA6: 2029-12-31 | AB6: 2030-03-31 | AC6: 2030-06-30 | AD6: 2030-09-30 | AE6: 2030-12-31 | AF6: 2031-03-31 | AG6: 2031-06-30 | AH6: 2031-09-30 | AI6: 2031-12-31 | AJ6: 2032-03-31 | AK6: 2032-06-30 | AL6: 2032-09-30 | AM6: 2032-12-31 | AN6: 2033-03-31 | AO6: 2033-06-30 | AP6: 2033-09-30 | AQ6: 2033-12-31 | AR6: 2034-03-31 | AS6: 2034-06-30 | AT6: 2034-09-30 | AU6: 2034-12-31 | AV6: 2035-03-31 | AW6: 2035-06-30 | AX6: 2035-09-30 | AY6: 2035-12-31 | AZ6: 2036-03-31 | BA6: 2036-06-30 | BB6: 2036-09-30 | BC6: 2036-12-31 | BD6: 2037-03-31 | BE6: 2037-06-30 | BF6: 2037-09-30 | BG6: 2037-12-31 | BH6: 2038-03-31 | BI6: 2038-06-30 | BJ6: 2038-09-30 | BK6: 2038-12-31 | BL6: 2039-03-31 | BM6: 2039-06-30 | BN6: 2039-09-30 | BO6: 2039-12-31 | BP6: 2040-03-31 | BQ6: 2040-06-30 | BR6: 2040-09-30 | BS6: 2040-12-31 | BT6: 2041-03-31 | BU6: 2041-06-30 | BV6: 2041-09-30 | BW6: 2041-12-31 | BX6: 2042-03-31 | BY6: 2042-06-30 | BZ6: 2042-09-30 | CA6: 2042-12-31 | CB6: 2043-03-31 | CC6: 2043-06-30 | CD6: 2043-09-30 | CE6: 2043-12-31 | CF6: 2044-03-31 | CG6: 2044-06-30 | CH6: 2044-09-30 | CI6: 2044-12-31 | CJ6: 2045-03-31 | CK6: 2045-06-30 | CL6: 2045-09-30
B8: 공사비 지출 | C8: [KRWm] | D8: =SUM(E8:CL8) | E8: =E105*$D$88*100 | F8: =F105*$D$88*100 | G8: =G105*$D$88*100 | H8: =H105*$D$88*100 | I8: =I105*$D$88*100 | J8: =J105*$D$88*100 | K8: 0 | L8: 0 | M8: 0 | N8: 0 | O8: 0 | P8: 0 | Q8: 0 | R8: 0 | S8: 0 | T8: 0 | U8: 0 | V8: 0 | W8: 0 | X8: 0 | Y8: 0 | Z8: 0 | AA8: 0 | AB8: 0 | AC8: 0 | AD8: 0 | AE8: 0 | AF8: 0 | AG8: 0 | AH8: 0 | AI8: 0 | AJ8: 0 | AK8: 0 | AL8: 0 | AM8: 0 | AN8: 0 | AO8: 0 | AP8: 0 | AQ8: 0 | AR8: 0 | AS8: 0 | AT8: 0 | AU8: 0 | AV8: 0 | AW8: 0 | AX8: 0 | AY8: 0 | AZ8: 0 | BA8: 0 | BB8: 0 | BC8: 0 | BD8: 0 | BE8: 0 | BF8: 0 | BG8: 0 | BH8: 0 | BI8: 0 | BJ8: 0 | BK8: 0 | BL8: 0 | BM8: 0 | BN8: 0 | BO8: 0 | BP8: 0 | BQ8: 0 | BR8: 0 | BS8: 0 | BT8: 0 | BU8: 0 | BV8: 0 | BW8: 0 | BX8: 0 | BY8: 0 | BZ8: 0 | CA8: 0 | CB8: 0 | CC8: 0 | CD8: 0 | CE8: 0 | CF8: 0 | CG8: 0 | CH8: 0 | CI8: 0 | CJ8: 0 | CK8: 0 | CL8: 0
B9: DSRA 적립 | C9: [KRWm] | D9: =SUM(E9:CL9) | E9: 0 | F9: 0 | G9: 0 | H9: 0 | I9: 0 | J9: ='입력값'!C23*100 | K9: 0 | L9: 0 | M9: 0 | N9: 0 | O9: 0 | P9: 0 | Q9: 0 | R9: 0 | S9: 0 | T9: 0 | U9: 0 | V9: 0 | W9: 0 | X9: 0 | Y9: 0 | Z9: 0 | AA9: 0 | AB9: 0 | AC9: 0 | AD9: 0 | AE9: 0 | AF9: 0 | AG9: 0 | AH9: 0 | AI9: 0 | AJ9: 0 | AK9: 0 | AL9: 0 | AM9: 0 | AN9: 0 | AO9: 0 | AP9: 0 | AQ9: 0 | AR9: 0 | AS9: 0 | AT9: 0 | AU9: 0 | AV9: 0 | AW9: 0 | AX9: 0 | AY9: 0 | AZ9: 0 | BA9: 0 | BB9: 0 | BC9: 0 | BD9: 0 | BE9: 0 | BF9: 0 | BG9: 0 | BH9: 0 | BI9: 0 | BJ9: 0 | BK9: 0 | BL9: 0 | BM9: 0 | BN9: 0 | BO9: 0 | BP9: 0 | BQ9: 0 | BR9: 0 | BS9: 0 | BT9: 0 | BU9: 0 | BV9: 0 | BW9: 0 | BX9: 0 | BY9: 0 | BZ9: 0 | CA9: 0 | CB9: 0 | CC9: 0 | CD9: 0 | CE9: 0 | CF9: 0 | CG9: 0 | CH9: 0 | CI9: 0 | CJ9: 0 | CK9: 0 | CL9: 0
B10: 선순위A 건설이자 | C10: [KRWm] | D10: =SUM(E10:CL10) | E10: 0 | F10: =E18*$D$91/4 | G10: =F18*$D$91/4 | H10: =G18*$D$91/4 | I10: =H18*$D$91/4 | J10: =I18*$D$91/4 | K10: 0 | L10: 0 | M10: 0 | N10: 0 | O10: 0 | P10: 0 | Q10: 0 | R10: 0 | S10: 0 | T10: 0 | U10: 0 | V10: 0 | W10: 0 | X10: 0 | Y10: 0 | Z10: 0 | AA10: 0 | AB10: 0 | AC10: 0 | AD10: 0 | AE10: 0 | AF10: 0 | AG10: 0 | AH10: 0 | AI10: 0 | AJ10: 0 | AK10: 0 | AL10: 0 | AM10: 0 | AN10: 0 | AO10: 0 | AP10: 0 | AQ10: 0 | AR10: 0 | AS10: 0 | AT10: 0 | AU10: 0 | AV10: 0 | AW10: 0 | AX10: 0 | AY10: 0 | AZ10: 0 | BA10: 0 | BB10: 0 | BC10: 0 | BD10: 0 | BE10: 0 | BF10: 0 | BG10: 0 | BH10: 0 | BI10: 0 | BJ10: 0 | BK10: 0 | BL10: 0 | BM10: 0 | BN10: 0 | BO10: 0 | BP10: 0 | BQ10: 0 | BR10: 0 | BS10: 0 | BT10: 0 | BU10: 0 | BV10: 0 | BW10: 0 | BX10: 0 | BY10: 0 | BZ10: 0 | CA10: 0 | CB10: 0 | CC10: 0 | CD10: 0 | CE10: 0 | CF10: 0 | CG10: 0 | CH10: 0 | CI10: 0 | CJ10: 0 | CK10: 0 | CL10: 0
B11: 선순위B 건설이자 | C11: [KRWm] | D11: =SUM(E11:CL11) | E11: 0 | F11: =E19*$D$94/4 | G11: =F19*$D$94/4 | H11: =G19*$D$94/4 | I11: =H19*$D$94/4 | J11: =I19*$D$94/4 | K11: 0 | L11: 0 | M11: 0 | N11: 0 | O11: 0 | P11: 0 | Q11: 0 | R11: 0 | S11: 0 | T11: 0 | U11: 0 | V11: 0 | W11: 0 | X11: 0 | Y11: 0 | Z11: 0 | AA11: 0 | AB11: 0 | AC11: 0 | AD11: 0 | AE11: 0 | AF11: 0 | AG11: 0 | AH11: 0 | AI11: 0 | AJ11: 0 | AK11: 0 | AL11: 0 | AM11: 0 | AN11: 0 | AO11: 0 | AP11: 0 | AQ11: 0 | AR11: 0 | AS11: 0 | AT11: 0 | AU11: 0 | AV11: 0 | AW11: 0 | AX11: 0 | AY11: 0 | AZ11: 0 | BA11: 0 | BB11: 0 | BC11: 0 | BD11: 0 | BE11: 0 | BF11: 0 | BG11: 0 | BH11: 0 | BI11: 0 | BJ11: 0 | BK11: 0 | BL11: 0 | BM11: 0 | BN11: 0 | BO11: 0 | BP11: 0 | BQ11: 0 | BR11: 0 | BS11: 0 | BT11: 0 | BU11: 0 | BV11: 0 | BW11: 0 | BX11: 0 | BY11: 0 | BZ11: 0 | CA11: 0 | CB11: 0 | CC11: 0 | CD11: 0 | CE11: 0 | CF11: 0 | CG11: 0 | CH11: 0 | CI11: 0 | CJ11: 0 | CK11: 0 | CL11: 0
B12: 선순위C 건설이자 | C12: [KRWm] | D12: =SUM(E12:CL12) | E12: 0 | F12: =E20*$D$97/4 | G12: =F20*$D$97/4 | H12: =G20*$D$97/4 | I12: =H20*$D$97/4 | J12: =I20*$D$97/4 | K12: 0 | L12: 0 | M12: 0 | N12: 0 | O12: 0 | P12: 0 | Q12: 0 | R12: 0 | S12: 0 | T12: 0 | U12: 0 | V12: 0 | W12: 0 | X12: 0 | Y12: 0 | Z12: 0 | AA12: 0 | AB12: 0 | AC12: 0 | AD12: 0 | AE12: 0 | AF12: 0 | AG12: 0 | AH12: 0 | AI12: 0 | AJ12: 0 | AK12: 0 | AL12: 0 | AM12: 0 | AN12: 0 | AO12: 0 | AP12: 0 | AQ12: 0 | AR12: 0 | AS12: 0 | AT12: 0 | AU12: 0 | AV12: 0 | AW12: 0 | AX12: 0 | AY12: 0 | AZ12: 0 | BA12: 0 | BB12: 0 | BC12: 0 | BD12: 0 | BE12: 0 | BF12: 0 | BG12: 0 | BH12: 0 | BI12: 0 | BJ12: 0 | BK12: 0 | BL12: 0 | BM12: 0 | BN12: 0 | BO12: 0 | BP12: 0 | BQ12: 0 | BR12: 0 | BS12: 0 | BT12: 0 | BU12: 0 | BV12: 0 | BW12: 0 | BX12: 0 | BY12: 0 | BZ12: 0 | CA12: 0 | CB12: 0 | CC12: 0 | CD12: 0 | CE12: 0 | CF12: 0 | CG12: 0 | CH12: 0 | CI12: 0 | CJ12: 0 | CK12: 0 | CL12: 0
B13: 선순위D 건설이자 | C13: [KRWm] | D13: =SUM(E13:CL13) | E13: 0 | F13: =E21*$D$100/4 | G13: =F21*$D$100/4 | H13: =G21*$D$100/4 | I13: =H21*$D$100/4 | J13: =I21*$D$100/4 | K13: 0 | L13: 0 | M13: 0 | N13: 0 | O13: 0 | P13: 0 | Q13: 0 | R13: 0 | S13: 0 | T13: 0 | U13: 0 | V13: 0 | W13: 0 | X13: 0 | Y13: 0 | Z13: 0 | AA13: 0 | AB13: 0 | AC13: 0 | AD13: 0 | AE13: 0 | AF13: 0 | AG13: 0 | AH13: 0 | AI13: 0 | AJ13: 0 | AK13: 0 | AL13: 0 | AM13: 0 | AN13: 0 | AO13: 0 | AP13: 0 | AQ13: 0 | AR13: 0 | AS13: 0 | AT13: 0 | AU13: 0 | AV13: 0 | AW13: 0 | AX13: 0 | AY13: 0 | AZ13: 0 | BA13: 0 | BB13: 0 | BC13: 0 | BD13: 0 | BE13: 0 | BF13: 0 | BG13: 0 | BH13: 0 | BI13: 0 | BJ13: 0 | BK13: 0 | BL13: 0 | BM13: 0 | BN13: 0 | BO13: 0 | BP13: 0 | BQ13: 0 | BR13: 0 | BS13: 0 | BT13: 0 | BU13: 0 | BV13: 0 | BW13: 0 | BX13: 0 | BY13: 0 | BZ13: 0 | CA13: 0 | CB13: 0 | CC13: 0 | CD13: 0 | CE13: 0 | CF13: 0 | CG13: 0 | CH13: 0 | CI13: 0 | CJ13: 0 | CK13: 0 | CL13: 0
B14: 후순위 건설이자 | C14: [KRWm] | D14: =SUM(E14:CL14) | E14: 0 | F14: =E22*$D$103/4 | G14: =F22*$D$103/4 | H14: =G22*$D$103/4 | I14: =H22*$D$103/4 | J14: =I22*$D$103/4 | K14: 0 | L14: 0 | M14: 0 | N14: 0 | O14: 0 | P14: 0 | Q14: 0 | R14: 0 | S14: 0 | T14: 0 | U14: 0 | V14: 0 | W14: 0 | X14: 0 | Y14: 0 | Z14: 0 | AA14: 0 | AB14: 0 | AC14: 0 | AD14: 0 | AE14: 0 | AF14: 0 | AG14: 0 | AH14: 0 | AI14: 0 | AJ14: 0 | AK14: 0 | AL14: 0 | AM14: 0 | AN14: 0 | AO14: 0 | AP14: 0 | AQ14: 0 | AR14: 0 | AS14: 0 | AT14: 0 | AU14: 0 | AV14: 0 | AW14: 0 | AX14: 0 | AY14: 0 | AZ14: 0 | BA14: 0 | BB14: 0 | BC14: 0 | BD14: 0 | BE14: 0 | BF14: 0 | BG14: 0 | BH14: 0 | BI14: 0 | BJ14: 0 | BK14: 0 | BL14: 0 | BM14: 0 | BN14: 0 | BO14: 0 | BP14: 0 | BQ14: 0 | BR14: 0 | BS14: 0 | BT14: 0 | BU14: 0 | BV14: 0 | BW14: 0 | BX14: 0 | BY14: 0 | BZ14: 0 | CA14: 0 | CB14: 0 | CC14: 0 | CD14: 0 | CE14: 0 | CF14: 0 | CG14: 0 | CH14: 0 | CI14: 0 | CJ14: 0 | CK14: 0 | CL14: 0
B15: 건설이자 합계(당기) | C15: [KRWm] | D15: =SUM(E15:CL15) | E15: =E10+E11+E12+E13+E14 | F15: =F10+F11+F12+F13+F14 | G15: =G10+G11+G12+G13+G14 | H15: =H10+H11+H12+H13+H14 | I15: =I10+I11+I12+I13+I14 | J15: =J10+J11+J12+J13+J14 | K15: =K10+K11+K12+K13+K14 | L15: =L10+L11+L12+L13+L14 | ... CL15: =CL10+CL11+CL12+CL13+CL14
B16: 누적 소요액 | C16: [KRWm] | E16: =E8+E9+E15 | F16: =E16+F8+F9+F15 | G16: =F16+G8+G9+G15 | H16: =G16+H8+H9+H15 | I16: =H16+I8+I9+I15 | J16: =I16+J8+J9+J15 | K16: =J16+K8+K9+K15 | L16: =K16+L8+L9+L15 | M16: =L16+M8+M9+M15 | ... CL16: =CK16+CL8+CL9+CL15
B17: 자본금 누적인출 | C17: [KRWm] | E17: =MIN(MAX(E16-(0),0),$D$89*100+$D$102*100)*($D$89*100)/IF(($D$89*100+$D$102*100)=0,1,$D$89*100+$D$102*100) | F17: =MIN(MAX(F16-(0),0),$D$89*100+$D$102*100)*($D$89*100)/IF(($D$89*100+$D$102*100)=0,1,$D$89*100+$D$102*100) | G17: =MIN(MAX(G16-(0),0),$D$89*100+$D$102*100)*($D$89*100)/IF(($D$89*100+$D$102*100)=0,1,$D$89*100+$D$102*100) | H17: =MIN(MAX(H16-(0),0),$D$89*100+$D$102*100)*($D$89*100)/IF(($D$89*100+$D$102*100)=0,1,$D$89*100+$D$102*100) | I17: =MIN(MAX(I16-(0),0),$D$89*100+$D$102*100)*($D$89*100)/IF(($D$89*100+$D$102*100)=0,1,$D$89*100+$D$102*100) | J17: =MIN(MAX(J16-(0),0),$D$89*100+$D$102*100)*($D$89*100)/IF(($D$89*100+$D$102*100)=0,1,$D$89*100+$D$102*100) | K17: =MIN(MAX(K16-(0),0),$D$89*100+$D$102*100)*($D$89*100)/IF(($D$89*100+$D$102*100)=0,1,$D$89*100+$D$102*100) | L17: =MIN(MAX(L16-(0),0),$D$89*100+$D$102*100)*($D$89*100)/IF(($D$89*100+$D$102*100)=0,1,$D$89*100+$D$102*100) | ... CL17: =MIN(MAX(CL16-(0),0),$D$89*100+$D$102*100)*($D$89*100)/IF(($D$89*100+$D$102*100)=0,1,$D$89*100+$D$102*100)
B18: 선순위A 누적인출 | C18: [KRWm] | E18: =MIN(MAX(E16-($D$89*100+$D$102*100),0),$D$90*100+$D$93*100)*($D$90*100)/IF(($D$90*100+$D$93*100)=0,1,$D$90*100+$D$93*100) | F18: =MIN(MAX(F16-($D$89*100+$D$102*100),0),$D$90*100+$D$93*100)*($D$90*100)/IF(($D$90*100+$D$93*100)=0,1,$D$90*100+$D$93*100) | G18: =MIN(MAX(G16-($D$89*100+$D$102*100),0),$D$90*100+$D$93*100)*($D$90*100)/IF(($D$90*100+$D$93*100)=0,1,$D$90*100+$D$93*100) | H18: =MIN(MAX(H16-($D$89*100+$D$102*100),0),$D$90*100+$D$93*100)*($D$90*100)/IF(($D$90*100+$D$93*100)=0,1,$D$90*100+$D$93*100) | I18: =MIN(MAX(I16-($D$89*100+$D$102*100),0),$D$90*100+$D$93*100)*($D$90*100)/IF(($D$90*100+$D$93*100)=0,1,$D$90*100+$D$93*100) | J18: =MIN(MAX(J16-($D$89*100+$D$102*100),0),$D$90*100+$D$93*100)*($D$90*100)/IF(($D$90*100+$D$93*100)=0,1,$D$90*100+$D$93*100) | K18: =MIN(MAX(K16-($D$89*100+$D$102*100),0),$D$90*100+$D$93*100)*($D$90*100)/IF(($D$90*100+$D$93*100)=0,1,$D$90*100+$D$93*100) | L18: =MIN(MAX(L16-($D$89*100+$D$102*100),0),$D$90*100+$D$93*100)*($D$90*100)/IF(($D$90*100+$D$93*100)=0,1,$D$90*100+$D$93*100) | ... CL18: =MIN(MAX(CL16-($D$89*100+$D$102*100),0),$D$90*100+$D$93*100)*($D$90*100)/IF(($D$90*100+$D$93*100)=0,1,$D$90*100+$D$93*100)
B19: 선순위B 누적인출 | C19: [KRWm] | E19: =MIN(MAX(E16-($D$89*100+$D$102*100),0),$D$90*100+$D$93*100)*($D$93*100)/IF(($D$90*100+$D$93*100)=0,1,$D$90*100+$D$93*100) | F19: =MIN(MAX(F16-($D$89*100+$D$102*100),0),$D$90*100+$D$93*100)*($D$93*100)/IF(($D$90*100+$D$93*100)=0,1,$D$90*100+$D$93*100) | G19: =MIN(MAX(G16-($D$89*100+$D$102*100),0),$D$90*100+$D$93*100)*($D$93*100)/IF(($D$90*100+$D$93*100)=0,1,$D$90*100+$D$93*100) | H19: =MIN(MAX(H16-($D$89*100+$D$102*100),0),$D$90*100+$D$93*100)*($D$93*100)/IF(($D$90*100+$D$93*100)=0,1,$D$90*100+$D$93*100) | I19: =MIN(MAX(I16-($D$89*100+$D$102*100),0),$D$90*100+$D$93*100)*($D$93*100)/IF(($D$90*100+$D$93*100)=0,1,$D$90*100+$D$93*100) | J19: =MIN(MAX(J16-($D$89*100+$D$102*100),0),$D$90*100+$D$93*100)*($D$93*100)/IF(($D$90*100+$D$93*100)=0,1,$D$90*100+$D$93*100) | K19: =MIN(MAX(K16-($D$89*100+$D$102*100),0),$D$90*100+$D$93*100)*($D$93*100)/IF(($D$90*100+$D$93*100)=0,1,$D$90*100+$D$93*100) | L19: =MIN(MAX(L16-($D$89*100+$D$102*100),0),$D$90*100+$D$93*100)*($D$93*100)/IF(($D$90*100+$D$93*100)=0,1,$D$90*100+$D$93*100) | ... CL19: =MIN(MAX(CL16-($D$89*100+$D$102*100),0),$D$90*100+$D$93*100)*($D$93*100)/IF(($D$90*100+$D$93*100)=0,1,$D$90*100+$D$93*100)
B20: 선순위C 누적인출 | C20: [KRWm] | E20: =MIN(MAX(E16-($D$89*100+$D$90*100+$D$93*100+$D$99*100+$D$102*100),0),$D$96*100)*($D$96*100)/IF(($D$96*100)=0,1,$D$96*100) | F20: =MIN(MAX(F16-($D$89*100+$D$90*100+$D$93*100+$D$99*100+$D$102*100),0),$D$96*100)*($D$96*100)/IF(($D$96*100)=0,1,$D$96*100) | G20: =MIN(MAX(G16-($D$89*100+$D$90*100+$D$93*100+$D$99*100+$D$102*100),0),$D$96*100)*($D$96*100)/IF(($D$96*100)=0,1,$D$96*100) | H20: =MIN(MAX(H16-($D$89*100+$D$90*100+$D$93*100+$D$99*100+$D$102*100),0),$D$96*100)*($D$96*100)/IF(($D$96*100)=0,1,$D$96*100) | I20: =MIN(MAX(I16-($D$89*100+$D$90*100+$D$93*100+$D$99*100+$D$102*100),0),$D$96*100)*($D$96*100)/IF(($D$96*100)=0,1,$D$96*100) | J20: =MIN(MAX(J16-($D$89*100+$D$90*100+$D$93*100+$D$99*100+$D$102*100),0),$D$96*100)*($D$96*100)/IF(($D$96*100)=0,1,$D$96*100) | K20: =MIN(MAX(K16-($D$89*100+$D$90*100+$D$93*100+$D$99*100+$D$102*100),0),$D$96*100)*($D$96*100)/IF(($D$96*100)=0,1,$D$96*100) | L20: =MIN(MAX(L16-($D$89*100+$D$90*100+$D$93*100+$D$99*100+$D$102*100),0),$D$96*100)*($D$96*100)/IF(($D$96*100)=0,1,$D$96*100) | ... CL20: =MIN(MAX(CL16-($D$89*100+$D$90*100+$D$93*100+$D$99*100+$D$102*100),0),$D$96*100)*($D$96*100)/IF(($D$96*100)=0,1,$D$96*100)
B21: 선순위D 누적인출 | C21: [KRWm] | E21: =MIN(MAX(E16-($D$89*100+$D$90*100+$D$93*100+$D$102*100),0),$D$99*100)*($D$99*100)/IF(($D$99*100)=0,1,$D$99*100) | F21: =MIN(MAX(F16-($D$89*100+$D$90*100+$D$93*100+$D$102*100),0),$D$99*100)*($D$99*100)/IF(($D$99*100)=0,1,$D$99*100) | G21: =MIN(MAX(G16-($D$89*100+$D$90*100+$D$93*100+$D$102*100),0),$D$99*100)*($D$99*100)/IF(($D$99*100)=0,1,$D$99*100) | H21: =MIN(MAX(H16-($D$89*100+$D$90*100+$D$93*100+$D$102*100),0),$D$99*100)*($D$99*100)/IF(($D$99*100)=0,1,$D$99*100) | I21: =MIN(MAX(I16-($D$89*100+$D$90*100+$D$93*100+$D$102*100),0),$D$99*100)*($D$99*100)/IF(($D$99*100)=0,1,$D$99*100) | J21: =MIN(MAX(J16-($D$89*100+$D$90*100+$D$93*100+$D$102*100),0),$D$99*100)*($D$99*100)/IF(($D$99*100)=0,1,$D$99*100) | K21: =MIN(MAX(K16-($D$89*100+$D$90*100+$D$93*100+$D$102*100),0),$D$99*100)*($D$99*100)/IF(($D$99*100)=0,1,$D$99*100) | L21: =MIN(MAX(L16-($D$89*100+$D$90*100+$D$93*100+$D$102*100),0),$D$99*100)*($D$99*100)/IF(($D$99*100)=0,1,$D$99*100) | ... CL21: =MIN(MAX(CL16-($D$89*100+$D$90*100+$D$93*100+$D$102*100),0),$D$99*100)*($D$99*100)/IF(($D$99*100)=0,1,$D$99*100)
B22: 후순위 누적인출 | C22: [KRWm] | E22: =MIN(MAX(E16-(0),0),$D$89*100+$D$102*100)*($D$102*100)/IF(($D$89*100+$D$102*100)=0,1,$D$89*100+$D$102*100) | F22: =MIN(MAX(F16-(0),0),$D$89*100+$D$102*100)*($D$102*100)/IF(($D$89*100+$D$102*100)=0,1,$D$89*100+$D$102*100) | G22: =MIN(MAX(G16-(0),0),$D$89*100+$D$102*100)*($D$102*100)/IF(($D$89*100+$D$102*100)=0,1,$D$89*100+$D$102*100) | H22: =MIN(MAX(H16-(0),0),$D$89*100+$D$102*100)*($D$102*100)/IF(($D$89*100+$D$102*100)=0,1,$D$89*100+$D$102*100) | I22: =MIN(MAX(I16-(0),0),$D$89*100+$D$102*100)*($D$102*100)/IF(($D$89*100+$D$102*100)=0,1,$D$89*100+$D$102*100) | J22: =MIN(MAX(J16-(0),0),$D$89*100+$D$102*100)*($D$102*100)/IF(($D$89*100+$D$102*100)=0,1,$D$89*100+$D$102*100) | K22: =MIN(MAX(K16-(0),0),$D$89*100+$D$102*100)*($D$102*100)/IF(($D$89*100+$D$102*100)=0,1,$D$89*100+$D$102*100) | L22: =MIN(MAX(L16-(0),0),$D$89*100+$D$102*100)*($D$102*100)/IF(($D$89*100+$D$102*100)=0,1,$D$89*100+$D$102*100) | ... CL22: =MIN(MAX(CL16-(0),0),$D$89*100+$D$102*100)*($D$102*100)/IF(($D$89*100+$D$102*100)=0,1,$D$89*100+$D$102*100)
B25: 트랜치별 인출/상환 + 전체 합계
B27: 구 분 | C27: unit | D27: 합 계 | E27: 2024-06-30 | F27: 2024-09-30 | G27: 2024-12-31 | H27: 2025-03-31 | I27: 2025-06-30 | J27: 2025-09-30 | K27: 2025-12-31 | L27: 2026-03-31 | M27: 2026-06-30 | N27: 2026-09-30 | O27: 2026-12-31 | P27: 2027-03-31 | Q27: 2027-06-30 | R27: 2027-09-30 | S27: 2027-12-31 | T27: 2028-03-31 | U27: 2028-06-30 | V27: 2028-09-30 | W27: 2028-12-31 | X27: 2029-03-31 | Y27: 2029-06-30 | Z27: 2029-09-30 | AA27: 2029-12-31 | AB27: 2030-03-31 | AC27: 2030-06-30 | AD27: 2030-09-30 | AE27: 2030-12-31 | AF27: 2031-03-31 | AG27: 2031-06-30 | AH27: 2031-09-30 | AI27: 2031-12-31 | AJ27: 2032-03-31 | AK27: 2032-06-30 | AL27: 2032-09-30 | AM27: 2032-12-31 | AN27: 2033-03-31 | AO27: 2033-06-30 | AP27: 2033-09-30 | AQ27: 2033-12-31 | AR27: 2034-03-31 | AS27: 2034-06-30 | AT27: 2034-09-30 | AU27: 2034-12-31 | AV27: 2035-03-31 | AW27: 2035-06-30 | AX27: 2035-09-30 | AY27: 2035-12-31 | AZ27: 2036-03-31 | BA27: 2036-06-30 | BB27: 2036-09-30 | BC27: 2036-12-31 | BD27: 2037-03-31 | BE27: 2037-06-30 | BF27: 2037-09-30 | BG27: 2037-12-31 | BH27: 2038-03-31 | BI27: 2038-06-30 | BJ27: 2038-09-30 | BK27: 2038-12-31 | BL27: 2039-03-31 | BM27: 2039-06-30 | BN27: 2039-09-30 | BO27: 2039-12-31 | BP27: 2040-03-31 | BQ27: 2040-06-30 | BR27: 2040-09-30 | BS27: 2040-12-31 | BT27: 2041-03-31 | BU27: 2041-06-30 | BV27: 2041-09-30 | BW27: 2041-12-31 | BX27: 2042-03-31 | BY27: 2042-06-30 | BZ27: 2042-09-30 | CA27: 2042-12-31 | CB27: 2043-03-31 | CC27: 2043-06-30 | CD27: 2043-09-30 | CE27: 2043-12-31 | CF27: 2044-03-31 | CG27: 2044-06-30 | CH27: 2044-09-30 | CI27: 2044-12-31 | CJ27: 2045-03-31 | CK27: 2045-06-30 | CL27: 2045-09-30
B29: 선순위A
B30: 기초잔액 | C30: [KRWm] | E30: 0 | F30: =E35 | G30: =F35 | H30: =G35 | I30: =H35 | J30: =I35 | K30: =J35 | L30: =K35 | M30: =L35 | ... CL30: =CK35
B31: 인출 | C31: [KRWm] | D31: =SUM(E31:CL31) | E31: =E18 | F31: =F18-E18 | G31: =G18-F18 | H31: =H18-G18 | I31: =I18-H18 | J31: =J18-I18 | K31: =K18-J18 | L31: =L18-K18 | M31: =M18-L18 | ... CL31: =CL18-CK18
B32: 건설이자(IDC) | C32: [KRWm] | D32: =SUM(E32:CL32) | E32: =E10 | F32: =F10 | G32: =G10 | H32: =H10 | I32: =I10 | J32: =J10 | K32: =K10 | L32: =L10 | ... CL32: =CL10
B33: 이자(운영) | C33: [KRWm] | D33: =SUM(E33:CL33) | E33: 0 | F33: 0 | G33: 0 | H33: 0 | I33: 0 | J33: 0 | K33: =K30*$D$92/4 | L33: =L30*$D$92/4 | M33: =M30*$D$92/4 | N33: =N30*$D$92/4 | O33: =O30*$D$92/4 | P33: =P30*$D$92/4 | Q33: =Q30*$D$92/4 | R33: =R30*$D$92/4 | ... CL33: =CL30*$D$92/4
B34: 원금상환 | C34: [KRWm] | D34: =SUM(E34:CL34) | E34: 0 | F34: 0 | G34: 0 | H34: 0 | I34: 0 | J34: 0 | K34: 0 | L34: 0 | M34: 0 | N34: =N30/64 | O34: =N30/64 | P34: =N30/64 | Q34: =N30/64 | R34: =N30/64 | S34: =N30/64 | T34: =N30/64 | U34: =N30/64 | V34: =N30/64 | W34: =N30/64 | X34: =N30/64 | Y34: =N30/64 | Z34: =N30/64 | AA34: =N30/64 | AB34: =N30/64 | AC34: =N30/64 | AD34: =N30/64 | AE34: =N30/64 | AF34: =N30/64 | AG34: =N30/64 | AH34: =N30/64 | AI34: =N30/64 | AJ34: =N30/64 | AK34: =N30/64 | AL34: =N30/64 | AM34: =N30/64 | AN34: =N30/64 | AO34: =N30/64 | AP34: =N30/64 | AQ34: =N30/64 | AR34: =N30/64 | AS34: =N30/64 | AT34: =N30/64 | AU34: =N30/64 | AV34: =N30/64 | AW34: =N30/64 | AX34: =N30/64 | AY34: =N30/64 | AZ34: =N30/64 | BA34: =N30/64 | BB34: =N30/64 | BC34: =N30/64 | BD34: =N30/64 | BE34: =N30/64 | BF34: =N30/64 | BG34: =N30/64 | BH34: =N30/64 | BI34: =N30/64 | BJ34: =N30/64 | BK34: =N30/64 | BL34: =N30/64 | BM34: =N30/64 | BN34: =N30/64 | BO34: =N30/64 | BP34: =N30/64 | BQ34: =N30/64 | BR34: =N30/64 | BS34: =N30/64 | BT34: =N30/64 | BU34: =N30/64 | BV34: =N30/64 | BW34: =N30/64 | BX34: =N30/64 | BY34: =N30/64 | BZ34: 0 | CA34: 0 | CB34: 0 | CC34: 0 | CD34: 0 | CE34: 0 | CF34: 0 | CG34: 0 | CH34: 0 | CI34: 0 | CJ34: 0 | CK34: 0 | CL34: 0
B35: 기말잔액 | C35: [KRWm] | E35: =E30+E31-E34 | F35: =F30+F31-F34 | G35: =G30+G31-G34 | H35: =H30+H31-H34 | I35: =I30+I31-I34 | J35: =J30+J31-J34 | K35: =K30+K31-K34 | L35: =L30+L31-L34 | ... CL35: =CL30+CL31-CL34
B36: 미상환 잔액(검증용) | C36: [KRWm] | D36: =CL35 | F36: =IF(ABS(D36)<1,"완전상환 확인 (OK)","경고: 미상환 잔액")
B38: 선순위B
B39: 기초잔액 | C39: [KRWm] | E39: 0 | F39: =E44 | G39: =F44 | H39: =G44 | I39: =H44 | J39: =I44 | K39: =J44 | L39: =K44 | M39: =L44 | ... CL39: =CK44
B40: 인출 | C40: [KRWm] | D40: =SUM(E40:CL40) | E40: =E19 | F40: =F19-E19 | G40: =G19-F19 | H40: =H19-G19 | I40: =I19-H19 | J40: =J19-I19 | K40: =K19-J19 | L40: =L19-K19 | M40: =M19-L19 | ... CL40: =CL19-CK19
B41: 건설이자(IDC) | C41: [KRWm] | D41: =SUM(E41:CL41) | E41: =E11 | F41: =F11 | G41: =G11 | H41: =H11 | I41: =I11 | J41: =J11 | K41: =K11 | L41: =L11 | ... CL41: =CL11
B42: 이자(운영) | C42: [KRWm] | D42: =SUM(E42:CL42) | E42: 0 | F42: 0 | G42: 0 | H42: 0 | I42: 0 | J42: 0 | K42: =K39*$D$95/4 | L42: =L39*$D$95/4 | M42: =M39*$D$95/4 | N42: =N39*$D$95/4 | O42: =O39*$D$95/4 | P42: =P39*$D$95/4 | Q42: =Q39*$D$95/4 | R42: =R39*$D$95/4 | ... CL42: =CL39*$D$95/4
B43: 원금상환 | C43: [KRWm] | D43: =SUM(E43:CL43) | E43: 0 | F43: 0 | G43: 0 | H43: 0 | I43: 0 | J43: 0 | K43: 0 | L43: 0 | M43: 0 | N43: =N39/64 | O43: =N39/64 | P43: =N39/64 | Q43: =N39/64 | R43: =N39/64 | S43: =N39/64 | T43: =N39/64 | U43: =N39/64 | V43: =N39/64 | W43: =N39/64 | X43: =N39/64 | Y43: =N39/64 | Z43: =N39/64 | AA43: =N39/64 | AB43: =N39/64 | AC43: =N39/64 | AD43: =N39/64 | AE43: =N39/64 | AF43: =N39/64 | AG43: =N39/64 | AH43: =N39/64 | AI43: =N39/64 | AJ43: =N39/64 | AK43: =N39/64 | AL43: =N39/64 | AM43: =N39/64 | AN43: =N39/64 | AO43: =N39/64 | AP43: =N39/64 | AQ43: =N39/64 | AR43: =N39/64 | AS43: =N39/64 | AT43: =N39/64 | AU43: =N39/64 | AV43: =N39/64 | AW43: =N39/64 | AX43: =N39/64 | AY43: =N39/64 | AZ43: =N39/64 | BA43: =N39/64 | BB43: =N39/64 | BC43: =N39/64 | BD43: =N39/64 | BE43: =N39/64 | BF43: =N39/64 | BG43: =N39/64 | BH43: =N39/64 | BI43: =N39/64 | BJ43: =N39/64 | BK43: =N39/64 | BL43: =N39/64 | BM43: =N39/64 | BN43: =N39/64 | BO43: =N39/64 | BP43: =N39/64 | BQ43: =N39/64 | BR43: =N39/64 | BS43: =N39/64 | BT43: =N39/64 | BU43: =N39/64 | BV43: =N39/64 | BW43: =N39/64 | BX43: =N39/64 | BY43: =N39/64 | BZ43: 0 | CA43: 0 | CB43: 0 | CC43: 0 | CD43: 0 | CE43: 0 | CF43: 0 | CG43: 0 | CH43: 0 | CI43: 0 | CJ43: 0 | CK43: 0 | CL43: 0
B44: 기말잔액 | C44: [KRWm] | E44: =E39+E40-E43 | F44: =F39+F40-F43 | G44: =G39+G40-G43 | H44: =H39+H40-H43 | I44: =I39+I40-I43 | J44: =J39+J40-J43 | K44: =K39+K40-K43 | L44: =L39+L40-L43 | ... CL44: =CL39+CL40-CL43
B45: 미상환 잔액(검증용) | C45: [KRWm] | D45: =CL44 | F45: =IF(ABS(D45)<1,"완전상환 확인 (OK)","경고: 미상환 잔액")
B47: 선순위C
B48: 기초잔액 | C48: [KRWm] | E48: 0 | F48: =E53 | G48: =F53 | H48: =G53 | I48: =H53 | J48: =I53 | K48: =J53 | L48: =K53 | M48: =L53 | ... CL48: =CK53
B49: 인출 | C49: [KRWm] | D49: =SUM(E49:CL49) | E49: =E20 | F49: =F20-E20 | G49: =G20-F20 | H49: =H20-G20 | I49: =I20-H20 | J49: =J20-I20 | K49: =K20-J20 | L49: =L20-K20 | M49: =M20-L20 | ... CL49: =CL20-CK20
...

Sheet Revenue
A1: 태양광 발전사업
A2: 영업수익 추정
B4: 발전량 및 매출
B6: 구 분 | C6: unit | D6: 합 계 | E6: 2024-06-30 | F6: 2024-09-30 | G6: 2024-12-31 | H6: 2025-03-31 | I6: 2025-06-30 | J6: 2025-09-30 | K6: 2025-12-31 | L6: 2026-03-31 | M6: 2026-06-30 | N6: 2026-09-30 | O6: 2026-12-31 | P6: 2027-03-31 | Q6: 2027-06-30 | R6: 2027-09-30 | S6: 2027-12-31 | T6: 2028-03-31 | U6: 2028-06-30 | V6: 2028-09-30 | W6: 2028-12-31 | X6: 2029-03-31 | Y6: 2029-06-30 | Z6: 2029-09-30 | AA6: 2029-12-31 | AB6: 2030-03-31 | AC6: 2030-06-30 | AD6: 2030-09-30 | AE6: 2030-12-31 | AF6: 2031-03-31 | AG6: 2031-06-30 | AH6: 2031-09-30 | AI6: 2031-12-31 | AJ6: 2032-03-31 | AK6: 2032-06-30 | AL6: 2032-09-30 | AM6: 2032-12-31 | AN6: 2033-03-31 | AO6: 2033-06-30 | AP6: 2033-09-30 | AQ6: 2033-12-31 | AR6: 2034-03-31 | AS6: 2034-06-30 | AT6: 2034-09-30 | AU6: 2034-12-31 | AV6: 2035-03-31 | AW6: 2035-06-30 | AX6: 2035-09-30 | AY6: 2035-12-31 | AZ6: 2036-03-31 | BA6: 2036-06-30 | BB6: 2036-09-30 | BC6: 2036-12-31 | BD6: 2037-03-31 | BE6: 2037-06-30 | BF6: 2037-09-30 | BG6: 2037-12-31 | BH6: 2038-03-31 | BI6: 2038-06-30 | BJ6: 2038-09-30 | BK6: 2038-12-31 | BL6: 2039-03-31 | BM6: 2039-06-30 | BN6: 2039-09-30 | BO6: 2039-12-31 | BP6: 2040-03-31 | BQ6: 2040-06-30 | BR6: 2040-09-30 | BS6: 2040-12-31 | BT6: 2041-03-31 | BU6: 2041-06-30 | BV6: 2041-09-30 | BW6: 2041-12-31 | BX6: 2042-03-31 | BY6: 2042-06-30 | BZ6: 2042-09-30 | CA6: 2042-12-31 | CB6: 2043-03-31 | CC6: 2043-06-30 | CD6: 2043-09-30 | CE6: 2043-12-31 | CF6: 2044-03-31 | CG6: 2044-06-30 | CH6: 2044-09-30 | CI6: 2044-12-31 | CJ6: 2045-03-31 | CK6: 2045-06-30 | CL6: 2045-09-30
B8: 운영연차 (첫 해 = 0) | C8: [yr] | E8: 0 | F8: 0 | G8: 0 | H8: 0 | I8: 0 | J8: 0 | K8: 0 | L8: 0 | M8: 0 | N8: 0 | O8: 1 | P8: 1 | Q8: 1 | R8: 1 | S8: 2 | T8: 2 | U8: 2 | V8: 2 | W8: 3 | X8: 3 | Y8: 3 | Z8: 3 | AA8: 4 | AB8: 4 | AC8: 4 | AD8: 4 | AE8: 5 | AF8: 5 | AG8: 5 | AH8: 5 | AI8: 6 | AJ8: 6 | AK8: 6 | AL8: 6 | AM8: 7 | AN8: 7 | AO8: 7 | AP8: 7 | AQ8: 8 | AR8: 8 | AS8: 8 | AT8: 8 | AU8: 9 | AV8: 9 | AW8: 9 | AX8: 9 | AY8: 10 | AZ8: 10 | BA8: 10 | BB8: 10 | BC8: 11 | BD8: 11 | BE8: 11 | BF8: 11 | BG8: 12 | BH8: 12 | BI8: 12 | BJ8: 12 | BK8: 13 | BL8: 13 | BM8: 13 | BN8: 13 | BO8: 14 | BP8: 14 | BQ8: 14 | BR8: 14 | BS8: 15 | BT8: 15 | BU8: 15 | BV8: 15 | BW8: 16 | BX8: 16 | BY8: 16 | BZ8: 16 | CA8: 17 | CB8: 17 | CC8: 17 | CD8: 17 | CE8: 18 | CF8: 18 | CG8: 18 | CH8: 18 | CI8: 19 | CJ8: 19 | CK8: 19 | CL8: 19
B9: 발전 기간비중 (연간 = 1) | C9: [배] | E9: 0 | F9: 0 | G9: 0 | H9: 0 | I9: 0 | J9: 0 | K9: 0.25 | L9: 0.25 | M9: 0.25 | N9: 0.25 | O9: 0.25 | P9: 0.25 | Q9: 0.25 | R9: 0.25 | S9: 0.25 | T9: 0.25 | U9: 0.25 | V9: 0.25 | W9: 0.25 | X9: 0.25 | Y9: 0.25 | Z9: 0.25 | AA9: 0.25 | AB9: 0.25 | AC9: 0.25 | AD9: 0.25 | AE9: 0.25 | AF9: 0.25 | AG9: 0.25 | AH9: 0.25 | AI9: 0.25 | AJ9: 0.25 | AK9: 0.25 | AL9: 0.25 | AM9: 0.25 | AN9: 0.25 | AO9: 0.25 | AP9: 0.25 | AQ9: 0.25 | AR9: 0.25 | AS9: 0.25 | AT9: 0.25 | AU9: 0.25 | AV9: 0.25 | AW9: 0.25 | AX9: 0.25 | AY9: 0.25 | AZ9: 0.25 | BA9: 0.25 | BB9: 0.25 | BC9: 0.25 | BD9: 0.25 | BE9: 0.25 | BF9: 0.25 | BG9: 0.25 | BH9: 0.25 | BI9: 0.25 | BJ9: 0.25 | BK9: 0.25 | BL9: 0.25 | BM9: 0.25 | BN9: 0.25 | BO9: 0.25 | BP9: 0.25 | BQ9: 0.25 | BR9: 0.25 | BS9: 0.25 | BT9: 0.25 | BU9: 0.25 | BV9: 0.25 | BW9: 0.25 | BX9: 0.25 | BY9: 0.25 | BZ9: 0.25 | CA9: 0.25 | CB9: 0.25 | CC9: 0.25 | CD9: 0.25 | CE9: 0.25 | CF9: 0.25 | CG9: 0.25 | CH9: 0.25 | CI9: 0.25 | CJ9: 0.25 | CK9: 0.25 | CL9: 0.25
B11: 발전량 | C11: [MWh] | D11: =SUM(E11:CL11) | E11: =($D$28*$D$31*365)*MAX(0,1-$D$29/100*E8)*(1-$D$30/100)*E9 | F11: =($D$28*$D$31*365)*MAX(0,1-$D$29/100*F8)*(1-$D$30/100)*F9 | G11: =($D$28*$D$31*365)*MAX(0,1-$D$29/100*G8)*(1-$D$30/100)*G9 | H11: =($D$28*$D$31*365)*MAX(0,1-$D$29/100*H8)*(1-$D$30/100)*H9 | I11: =($D$28*$D$31*365)*MAX(0,1-$D$29/100*I8)*(1-$D$30/100)*I9 | J11: =($D$28*$D$31*365)*MAX(0,1-$D$29/100*J8)*(1-$D$30/100)*J9 | K11: =($D$28*$D$31*365)*MAX(0,1-$D$29/100*K8)*(1-$D$30/100)*K9 | L11: =($D$28*$D$31*365)*MAX(0,1-$D$29/100*L8)*(1-$D$30/100)*L9 | ... CL11: =($D$28*$D$31*365)*MAX(0,1-$D$29/100*CL8)*(1-$D$30/100)*CL9
B13: PPA 판매단가 | C13: [원/kWh] | K13: =$D$33*(1+$D$34/100)^K8 | L13: =$D$33*(1+$D$34/100)^L8 | M13: =$D$33*(1+$D$34/100)^M8 | N13: =$D$33*(1+$D$34/100)^N8 | O13: =$D$33*(1+$D$34/100)^O8 | P13: =$D$33*(1+$D$34/100)^P8 | Q13: =$D$33*(1+$D$34/100)^Q8 | R13: =$D$33*(1+$D$34/100)^R8 | ... CL13: =$D$33*(1+$D$34/100)^CL8
B14: PPA 매출 | C14: [KRWm] | D14: =SUM(E14:CL14) | E14: 0 | F14: 0 | G14: 0 | H14: 0 | I14: 0 | J14: 0 | K14: =K11*$D$32/100*K13/1000 | L14: =L11*$D$32/100*L13/1000 | M14: =M11*$D$32/100*M13/1000 | N14: =N11*$D$32/100*N13/1000 | O14: =O11*$D$32/100*O13/1000 | P14: =P11*$D$32/100*P13/1000 | Q14: =Q11*$D$32/100*Q13/1000 | R14: =R11*$D$32/100*R13/1000 | ... CL14: =CL11*$D$32/100*CL13/1000
B16: 판매단가 (가중평균) | C16: [원/kWh] | K16: =IF(K11=0,0,K17*1000/K11) | L16: =IF(L11=0,0,L17*1000/L11) | M16: =IF(M11=0,0,M17*1000/M11) | N16: =IF(N11=0,0,N17*1000/N11) | O16: =IF(O11=0,0,O17*1000/O11) | P16: =IF(P11=0,0,P17*1000/P11) | Q16: =IF(Q11=0,0,Q17*1000/Q11) | R16: =IF(R11=0,0,R17*1000/R11) | ... CL16: =IF(CL11=0,0,CL17*1000/CL11)
B17: 영업수익 | C17: [KRWm] | D17: =SUM(E17:CL17) | E17: 0 | F17: 0 | G17: 0 | H17: 0 | I17: 0 | J17: 0 | K17: =SUM(K14:K14) | L17: =SUM(L14:L14) | M17: =SUM(M14:M14) | N17: =SUM(N14:N14) | O17: =SUM(O14:O14) | P17: =SUM(P14:P14) | Q17: =SUM(Q14:Q14) | R17: =SUM(R14:R14) | ... CL17: =SUM(CL14:CL14)
B19: 매출채권(A/R) 회수 시차
B21: PPA 기말 미수금 | C21: [KRWm] | E21: =MIN($D$35,3)/3*E14+MAX($D$35-3,0)/3*0 | F21: =MIN($D$35,3)/3*F14+MAX($D$35-3,0)/3*E14 | G21: =MIN($D$35,3)/3*G14+MAX($D$35-3,0)/3*F14 | H21: =MIN($D$35,3)/3*H14+MAX($D$35-3,0)/3*G14 | I21: =MIN($D$35,3)/3*I14+MAX($D$35-3,0)/3*H14 | J21: =MIN($D$35,3)/3*J14+MAX($D$35-3,0)/3*I14 | K21: =MIN($D$35,3)/3*K14+MAX($D$35-3,0)/3*J14 | L21: =MIN($D$35,3)/3*L14+MAX($D$35-3,0)/3*K14 | M21: =MIN($D$35,3)/3*M14+MAX($D$35-3,0)/3*L14 | ... CK21: =MIN($D$35,3)/3*CK14+MAX($D$35-3,0)/3*CJ14 | CL21: 0
B22: 운전자본 증감(A/R) | C22: [KRWm] | D22: =SUM(E22:CL22) | E22: =0-E21 | F22: =E21-F21 | G22: =F21-G21 | H22: =G21-H21 | I22: =H21-I21 | J22: =I21-J21 | K22: =J21-K21 | L22: =K21-L21 | M22: =L21-M21 | ... CL22: =CK21-CL21
B23: ※ 20년 전체 합계는 0입니다(초기에 묶인 미수금을 마지막에 전액 회수). 다만 분기별로는 크게 움직여서 준공 직후 DSCR과 Equity IRR에 영향을 줍니다.
B26: 가정 (입력값 연결) — 이 시트의 계산이 쓰는 원천값 | D26: 값
B27: ※ 입력값 시트는 여기서만 참조합니다(초록 글자 = 입력값 연결). 위의 분기 계산은 이 셀들만 참조하므로, 값을 바꾸려면 입력값 시트를 고치세요.
B28: 설비용량[MW] | C28: C7 | D28: ='입력값'!C7
B29: 발전량 열화율[%/yr] | C29: C12 | D29: ='입력값'!C12
B30: 소내소비율[%] | C30: C13 | D30: ='입력값'!C13
B31: 일조시간[h/day] | C31: C14 | D31: ='입력값'!C14
B32: PPA · 비중[%] | C32: C41 | D32: ='입력값'!C41
B33: PPA · 단가[원/kWh] | C33: D41 | D33: ='입력값'!D41
B34: PPA · 에스컬레이션[%/yr] | C34: E41 | D34: ='입력값'!E41
B35: PPA · 대금회수시차[개월] | C35: F41 | D35: ='입력값'!F41

Sheet Opex
A1: 태양광 발전사업
A2: 영업비용 추정
B4: 운영비용 (선순위/후순위 지급순위 반영)
B6: 구 분 | C6: unit | D6: 합 계 | E6: 2024-06-30 | F6: 2024-09-30 | G6: 2024-12-31 | H6: 2025-03-31 | I6: 2025-06-30 | J6: 2025-09-30 | K6: 2025-12-31 | L6: 2026-03-31 | M6: 2026-06-30 | N6: 2026-09-30 | O6: 2026-12-31 | P6: 2027-03-31 | Q6: 2027-06-30 | R6: 2027-09-30 | S6: 2027-12-31 | T6: 2028-03-31 | U6: 2028-06-30 | V6: 2028-09-30 | W6: 2028-12-31 | X6: 2029-03-31 | Y6: 2029-06-30 | Z6: 2029-09-30 | AA6: 2029-12-31 | AB6: 2030-03-31 | AC6: 2030-06-30 | AD6: 2030-09-30 | AE6: 2030-12-31 | AF6: 2031-03-31 | AG6: 2031-06-30 | AH6: 2031-09-30 | AI6: 2031-12-31 | AJ6: 2032-03-31 | AK6: 2032-06-30 | AL6: 2032-09-30 | AM6: 2032-12-31 | AN6: 2033-03-31 | AO6: 2033-06-30 | AP6: 2033-09-30 | AQ6: 2033-12-31 | AR6: 2034-03-31 | AS6: 2034-06-30 | AT6: 2034-09-30 | AU6: 2034-12-31 | AV6: 2035-03-31 | AW6: 2035-06-30 | AX6: 2035-09-30 | AY6: 2035-12-31 | AZ6: 2036-03-31 | BA6: 2036-06-30 | BB6: 2036-09-30 | BC6: 2036-12-31 | BD6: 2037-03-31 | BE6: 2037-06-30 | BF6: 2037-09-30 | BG6: 2037-12-31 | BH6: 2038-03-31 | BI6: 2038-06-30 | BJ6: 2038-09-30 | BK6: 2038-12-31 | BL6: 2039-03-31 | BM6: 2039-06-30 | BN6: 2039-09-30 | BO6: 2039-12-31 | BP6: 2040-03-31 | BQ6: 2040-06-30 | BR6: 2040-09-30 | BS6: 2040-12-31 | BT6: 2041-03-31 | BU6: 2041-06-30 | BV6: 2041-09-30 | BW6: 2041-12-31 | BX6: 2042-03-31 | BY6: 2042-06-30 | BZ6: 2042-09-30 | CA6: 2042-12-31 | CB6: 2043-03-31 | CC6: 2043-06-30 | CD6: 2043-09-30 | CE6: 2043-12-31 | CF6: 2044-03-31 | CG6: 2044-06-30 | CH6: 2044-09-30 | CI6: 2044-12-31 | CJ6: 2045-03-31 | CK6: 2045-06-30 | CL6: 2045-09-30
B8: 항목별 세부내역
B9: 부지임대료 | C9: [KRWm]
B10: O&M | C10: [KRWm]
B11: 보험료 | C11: [KRWm]
B12: 환경모니터링비용 | C12: [KRWm]
B13: 소내전력비 | C13: [KRWm]
B14: 인건비 | C14: [KRWm]
B15: 법인운영비 | C15: [KRWm]
B16: 주민보상비 | C16: [KRWm]
B17: 도로점용료 | C17: [KRWm]
B18: 예비비 | C18: [KRWm]
B19: 전력거래수수료 | C19: [KRWm]
B20: 관리운영비 성과보수 | C20: [KRWm]
B22: 선순위운영비 | C22: [KRWm] | D22: =SUM(E22:CL22) | E22: 0 | F22: 0 | G22: 0 | H22: 0 | I22: 0 | J22: 0 | K22: =K24-K23 | L22: =L24-L23 | M22: =M24-M23 | N22: =N24-N23 | O22: =O24-O23 | P22: =P24-P23 | Q22: =Q24-Q23 | R22: =R24-R23 | ... CL22: =CL24-CL23
B23: 후순위운영비 | C23: [KRWm] | D23: =SUM(E23:CL23) | E23: 0 | F23: 0 | G23: 0 | H23: 0 | I23: 0 | J23: 0 | K23: =K24*$D$33/100 | L23: =L24*$D$33/100 | M23: =M24*$D$33/100 | N23: =N24*$D$33/100 | O23: =O24*$D$33/100 | P23: =P24*$D$33/100 | Q23: =Q24*$D$33/100 | R23: =R24*$D$33/100 | ... CL23: =CL24*$D$33/100
B24: 영업비용 합계 | C24: [KRWm] | D24: =SUM(E24:CL24) | E24: =E22+E23 | F24: =F22+F23 | G24: =G22+G23 | H24: =H22+H23 | I24: =I22+I23 | J24: =J22+J23 | K24: =$D$31*100*(1+$D$32/100)^0*(3/12) | L24: =$D$31*100*(1+$D$32/100)^0*(3/12) | M24: =$D$31*100*(1+$D$32/100)^0*(3/12) | N24: =$D$31*100*(1+$D$32/100)^0*(3/12) | O24: =$D$31*100*(1+$D$32/100)^1*(3/12) | P24: =$D$31*100*(1+$D$32/100)^1*(3/12) | Q24: =$D$31*100*(1+$D$32/100)^1*(3/12) | R24: =$D$31*100*(1+$D$32/100)^1*(3/12) | S24: =$D$31*100*(1+$D$32/100)^2*(3/12) | T24: =$D$31*100*(1+$D$32/100)^2*(3/12) | U24: =$D$31*100*(1+$D$32/100)^2*(3/12) | V24: =$D$31*100*(1+$D$32/100)^2*(3/12) | W24: =$D$31*100*(1+$D$32/100)^3*(3/12) | X24: =$D$31*100*(1+$D$32/100)^3*(3/12) | Y24: =$D$31*100*(1+$D$32/100)^3*(3/12) | Z24: =$D$31*100*(1+$D$32/100)^3*(3/12) | AA24: =$D$31*100*(1+$D$32/100)^4*(3/12) | AB24: =$D$31*100*(1+$D$32/100)^4*(3/12) | AC24: =$D$31*100*(1+$D$32/100)^4*(3/12) | AD24: =$D$31*100*(1+$D$32/100)^4*(3/12) | AE24: =$D$31*100*(1+$D$32/100)^5*(3/12) | AF24: =$D$31*100*(1+$D$32/100)^5*(3/12) | AG24: =$D$31*100*(1+$D$32/100)^5*(3/12) | AH24: =$D$31*100*(1+$D$32/100)^5*(3/12) | AI24: =$D$31*100*(1+$D$32/100)^6*(3/12) | AJ24: =$D$31*100*(1+$D$32/100)^6*(3/12) | AK24: =$D$31*100*(1+$D$32/100)^6*(3/12) | AL24: =$D$31*100*(1+$D$32/100)^6*(3/12) | AM24: =$D$31*100*(1+$D$32/100)^7*(3/12) | AN24: =$D$31*100*(1+$D$32/100)^7*(3/12) | AO24: =$D$31*100*(1+$D$32/100)^7*(3/12) | AP24: =$D$31*100*(1+$D$32/100)^7*(3/12) | AQ24: =$D$31*100*(1+$D$32/100)^8*(3/12) | AR24: =$D$31*100*(1+$D$32/100)^8*(3/12) | AS24: =$D$31*100*(1+$D$32/100)^8*(3/12) | AT24: =$D$31*100*(1+$D$32/100)^8*(3/12) | AU24: =$D$31*100*(1+$D$32/100)^9*(3/12) | AV24: =$D$31*100*(1+$D$32/100)^9*(3/12) | AW24: =$D$31*100*(1+$D$32/100)^9*(3/12) | AX24: =$D$31*100*(1+$D$32/100)^9*(3/12) | AY24: =$D$31*100*(1+$D$32/100)^10*(3/12) | AZ24: =$D$31*100*(1+$D$32/100)^10*(3/12) | BA24: =$D$31*100*(1+$D$32/100)^10*(3/12) | BB24: =$D$31*100*(1+$D$32/100)^10*(3/12) | BC24: =$D$31*100*(1+$D$32/100)^11*(3/12) | BD24: =$D$31*100*(1+$D$32/100)^11*(3/12) | BE24: =$D$31*100*(1+$D$32/100)^11*(3/12) | BF24: =$D$31*100*(1+$D$32/100)^11*(3/12) | BG24: =$D$31*100*(1+$D$32/100)^12*(3/12) | BH24: =$D$31*100*(1+$D$32/100)^12*(3/12) | BI24: =$D$31*100*(1+$D$32/100)^12*(3/12) | BJ24: =$D$31*100*(1+$D$32/100)^12*(3/12) | BK24: =$D$31*100*(1+$D$32/100)^13*(3/12) | BL24: =$D$31*100*(1+$D$32/100)^13*(3/12) | BM24: =$D$31*100*(1+$D$32/100)^13*(3/12) | BN24: =$D$31*100*(1+$D$32/100)^13*(3/12) | BO24: =$D$31*100*(1+$D$32/100)^14*(3/12) | BP24: =$D$31*100*(1+$D$32/100)^14*(3/12) | BQ24: =$D$31*100*(1+$D$32/100)^14*(3/12) | BR24: =$D$31*100*(1+$D$32/100)^14*(3/12) | BS24: =$D$31*100*(1+$D$32/100)^15*(3/12) | BT24: =$D$31*100*(1+$D$32/100)^15*(3/12) | BU24: =$D$31*100*(1+$D$32/100)^15*(3/12) | BV24: =$D$31*100*(1+$D$32/100)^15*(3/12) | BW24: =$D$31*100*(1+$D$32/100)^16*(3/12) | BX24: =$D$31*100*(1+$D$32/100)^16*(3/12) | BY24: =$D$31*100*(1+$D$32/100)^16*(3/12) | BZ24: =$D$31*100*(1+$D$32/100)^16*(3/12) | CA24: =$D$31*100*(1+$D$32/100)^17*(3/12) | CB24: =$D$31*100*(1+$D$32/100)^17*(3/12) | CC24: =$D$31*100*(1+$D$32/100)^17*(3/12) | CD24: =$D$31*100*(1+$D$32/100)^17*(3/12) | CE24: =$D$31*100*(1+$D$32/100)^18*(3/12) | CF24: =$D$31*100*(1+$D$32/100)^18*(3/12) | CG24: =$D$31*100*(1+$D$32/100)^18*(3/12) | CH24: =$D$31*100*(1+$D$32/100)^18*(3/12) | CI24: =$D$31*100*(1+$D$32/100)^19*(3/12) | CJ24: =$D$31*100*(1+$D$32/100)^19*(3/12) | CK24: =$D$31*100*(1+$D$32/100)^19*(3/12) | CL24: =$D$31*100*(1+$D$32/100)^19*(3/12)
B26: ※ 화면에서 운영비를 합계로만 입력해서 항목별 금액은 비어 있습니다 — 항목별로 입력하면 이 표에 실제 금액이 채워집니다.
B29: 가정 (입력값 연결) — 이 시트의 계산이 쓰는 원천값 | D29: 값
B30: ※ 입력값 시트는 여기서만 참조합니다(초록 글자 = 입력값 연결). 위의 분기 계산은 이 셀들만 참조하므로, 값을 바꾸려면 입력값 시트를 고치세요.
B31: 운영비 총액[억원/yr] | C31: C18 | D31: ='입력값'!C18
B32: 운영비 에스컬레이션[%/yr] | C32: C19 | D32: ='입력값'!C19
B33: 운영비 중 후순위 비중[%] | C33: C20 | D33: ='입력값'!C20

Sheet IS(Q)
A1: 태양광 발전사업
A2: 추정 손익계산서 (분기)
B4: 손익계산서
B6: 구 분 | C6: unit | D6: 합 계 | E6: 2024-06-30 | F6: 2024-09-30 | G6: 2024-12-31 | H6: 2025-03-31 | I6: 2025-06-30 | J6: 2025-09-30 | K6: 2025-12-31 | L6: 2026-03-31 | M6: 2026-06-30 | N6: 2026-09-30 | O6: 2026-12-31 | P6: 2027-03-31 | Q6: 2027-06-30 | R6: 2027-09-30 | S6: 2027-12-31 | T6: 2028-03-31 | U6: 2028-06-30 | V6: 2028-09-30 | W6: 2028-12-31 | X6: 2029-03-31 | Y6: 2029-06-30 | Z6: 2029-09-30 | AA6: 2029-12-31 | AB6: 2030-03-31 | AC6: 2030-06-30 | AD6: 2030-09-30 | AE6: 2030-12-31 | AF6: 2031-03-31 | AG6: 2031-06-30 | AH6: 2031-09-30 | AI6: 2031-12-31 | AJ6: 2032-03-31 | AK6: 2032-06-30 | AL6: 2032-09-30 | AM6: 2032-12-31 | AN6: 2033-03-31 | AO6: 2033-06-30 | AP6: 2033-09-30 | AQ6: 2033-12-31 | AR6: 2034-03-31 | AS6: 2034-06-30 | AT6: 2034-09-30 | AU6: 2034-12-31 | AV6: 2035-03-31 | AW6: 2035-06-30 | AX6: 2035-09-30 | AY6: 2035-12-31 | AZ6: 2036-03-31 | BA6: 2036-06-30 | BB6: 2036-09-30 | BC6: 2036-12-31 | BD6: 2037-03-31 | BE6: 2037-06-30 | BF6: 2037-09-30 | BG6: 2037-12-31 | BH6: 2038-03-31 | BI6: 2038-06-30 | BJ6: 2038-09-30 | BK6: 2038-12-31 | BL6: 2039-03-31 | BM6: 2039-06-30 | BN6: 2039-09-30 | BO6: 2039-12-31 | BP6: 2040-03-31 | BQ6: 2040-06-30 | BR6: 2040-09-30 | BS6: 2040-12-31 | BT6: 2041-03-31 | BU6: 2041-06-30 | BV6: 2041-09-30 | BW6: 2041-12-31 | BX6: 2042-03-31 | BY6: 2042-06-30 | BZ6: 2042-09-30 | CA6: 2042-12-31 | CB6: 2043-03-31 | CC6: 2043-06-30 | CD6: 2043-09-30 | CE6: 2043-12-31 | CF6: 2044-03-31 | CG6: 2044-06-30 | CH6: 2044-09-30 | CI6: 2044-12-31 | CJ6: 2045-03-31 | CK6: 2045-06-30 | CL6: 2045-09-30
B8: 영업수익 | C8: [KRWm] | D8: =SUM(E8:CL8) | E8: ='Revenue'!E17 | F8: ='Revenue'!F17 | G8: ='Revenue'!G17 | H8: ='Revenue'!H17 | I8: ='Revenue'!I17 | J8: ='Revenue'!J17 | K8: ='Revenue'!K17 | L8: ='Revenue'!L17 | ... CL8: ='Revenue'!CL17
B10: 영업비용 세부내역
B11: 부지임대료 | C11: [KRWm]
B12: O&M | C12: [KRWm]
B13: 보험료 | C13: [KRWm]
B14: 환경모니터링비용 | C14: [KRWm]
B15: 소내전력비 | C15: [KRWm]
B16: 인건비 | C16: [KRWm]
B17: 법인운영비 | C17: [KRWm]
B18: 주민보상비 | C18: [KRWm]
B19: 도로점용료 | C19: [KRWm]
B20: 예비비 | C20: [KRWm]
B21: 전력거래수수료 | C21: [KRWm]
B22: 관리운영비 성과보수 | C22: [KRWm]
B23: 영업비용 합계 | C23: [KRWm] | D23: =SUM(E23:CL23) | E23: =-'Opex'!E24 | F23: =-'Opex'!F24 | G23: =-'Opex'!G24 | H23: =-'Opex'!H24 | I23: =-'Opex'!I24 | J23: =-'Opex'!J24 | K23: =-'Opex'!K24 | L23: =-'Opex'!L24 | ... CL23: =-'Opex'!CL24
B25: EBITDA | C25: [KRWm] | D25: =SUM(E25:CL25) | E25: =E8+E23 | F25: =F8+F23 | G25: =G8+G23 | H25: =H8+H23 | I25: =I8+I23 | J25: =J8+J23 | K25: =K8+K23 | L25: =L8+L23 | ... CL25: =CL8+CL23
B26: EBITDA 마진 | C26: [%] | E26: =IF(E8<=0,"",E25/E8) | F26: =IF(F8<=0,"",F25/F8) | G26: =IF(G8<=0,"",G25/G8) | H26: =IF(H8<=0,"",H25/H8) | I26: =IF(I8<=0,"",I25/I8) | J26: =IF(J8<=0,"",J25/J8) | K26: =IF(K8<=0,"",K25/K8) | L26: =IF(L8<=0,"",L25/L8) | ... CL26: =IF(CL8<=0,"",CL25/CL8)
B28: 감가상각비 | C28: [KRWm] | D28: =SUM(E28:CL28) | E28: 0 | F28: 0 | G28: 0 | H28: 0 | I28: 0 | J28: 0 | K28: =-(('Funding'!C18*$D$75/100)/$D$76*(3/12)) | L28: =-(('Funding'!C18*$D$75/100)/$D$76*(3/12)) | M28: =-(('Funding'!C18*$D$75/100)/$D$76*(3/12)) | N28: =-(('Funding'!C18*$D$75/100)/$D$76*(3/12)) | O28: =-(('Funding'!C18*$D$75/100)/$D$76*(3/12)) | P28: =-(('Funding'!C18*$D$75/100)/$D$76*(3/12)) | Q28: =-(('Funding'!C18*$D$75/100)/$D$76*(3/12)) | R28: =-(('Funding'!C18*$D$75/100)/$D$76*(3/12)) | S28: =-(('Funding'!C18*$D$75/100)/$D$76*(3/12)) | T28: =-(('Funding'!C18*$D$75/100)/$D$76*(3/12)) | U28: =-(('Funding'!C18*$D$75/100)/$D$76*(3/12)) | V28: =-(('Funding'!C18*$D$75/100)/$D$76*(3/12)) | W28: =-(('Funding'!C18*$D$75/100)/$D$76*(3/12)) | X28: =-(('Funding'!C18*$D$75/100)/$D$76*(3/12)) | Y28: =-(('Funding'!C18*$D$75/100)/$D$76*(3/12)) | Z28: =-(('Funding'!C18*$D$75/100)/$D$76*(3/12)) | AA28: =-(('Funding'!C18*$D$75/100)/$D$76*(3/12)) | AB28: =-(('Funding'!C18*$D$75/100)/$D$76*(3/12)) | AC28: =-(('Funding'!C18*$D$75/100)/$D$76*(3/12)) | AD28: =-(('Funding'!C18*$D$75/100)/$D$76*(3/12)) | AE28: =-(('Funding'!C18*$D$75/100)/$D$76*(3/12)) | AF28: =-(('Funding'!C18*$D$75/100)/$D$76*(3/12)) | AG28: =-(('Funding'!C18*$D$75/100)/$D$76*(3/12)) | AH28: =-(('Funding'!C18*$D$75/100)/$D$76*(3/12)) | AI28: =-(('Funding'!C18*$D$75/100)/$D$76*(3/12)) | AJ28: =-(('Funding'!C18*$D$75/100)/$D$76*(3/12)) | AK28: =-(('Funding'!C18*$D$75/100)/$D$76*(3/12)) | AL28: =-(('Funding'!C18*$D$75/100)/$D$76*(3/12)) | AM28: =-(('Funding'!C18*$D$75/100)/$D$76*(3/12)) | AN28: =-(('Funding'!C18*$D$75/100)/$D$76*(3/12)) | AO28: =-(('Funding'!C18*$D$75/100)/$D$76*(3/12)) | AP28: =-(('Funding'!C18*$D$75/100)/$D$76*(3/12)) | AQ28: =-(('Funding'!C18*$D$75/100)/$D$76*(3/12)) | AR28: =-(('Funding'!C18*$D$75/100)/$D$76*(3/12)) | AS28: =-(('Funding'!C18*$D$75/100)/$D$76*(3/12)) | AT28: =-(('Funding'!C18*$D$75/100)/$D$76*(3/12)) | AU28: =-(('Funding'!C18*$D$75/100)/$D$76*(3/12)) | AV28: =-(('Funding'!C18*$D$75/100)/$D$76*(3/12)) | AW28: =-(('Funding'!C18*$D$75/100)/$D$76*(3/12)) | AX28: =-(('Funding'!C18*$D$75/100)/$D$76*(3/12)) | AY28: =-(('Funding'!C18*$D$75/100)/$D$76*(3/12)) | AZ28: =-(('Funding'!C18*$D$75/100)/$D$76*(3/12)) | BA28: =-(('Funding'!C18*$D$75/100)/$D$76*(3/12)) | BB28: =-(('Funding'!C18*$D$75/100)/$D$76*(3/12)) | BC28: =-(('Funding'!C18*$D$75/100)/$D$76*(3/12)) | BD28: =-(('Funding'!C18*$D$75/100)/$D$76*(3/12)) | BE28: =-(('Funding'!C18*$D$75/100)/$D$76*(3/12)) | BF28: =-(('Funding'!C18*$D$75/100)/$D$76*(3/12)) | BG28: =-(('Funding'!C18*$D$75/100)/$D$76*(3/12)) | BH28: =-(('Funding'!C18*$D$75/100)/$D$76*(3/12)) | BI28: =-(('Funding'!C18*$D$75/100)/$D$76*(3/12)) | BJ28: =-(('Funding'!C18*$D$75/100)/$D$76*(3/12)) | BK28: =-(('Funding'!C18*$D$75/100)/$D$76*(3/12)) | BL28: =-(('Funding'!C18*$D$75/100)/$D$76*(3/12)) | BM28: =-(('Funding'!C18*$D$75/100)/$D$76*(3/12)) | BN28: =-(('Funding'!C18*$D$75/100)/$D$76*(3/12)) | BO28: =-(('Funding'!C18*$D$75/100)/$D$76*(3/12)) | BP28: =-(('Funding'!C18*$D$75/100)/$D$76*(3/12)) | BQ28: =-(('Funding'!C18*$D$75/100)/$D$76*(3/12)) | BR28: =-(('Funding'!C18*$D$75/100)/$D$76*(3/12)) | BS28: =-(('Funding'!C18*$D$75/100)/$D$76*(3/12)) | BT28: =-(('Funding'!C18*$D$75/100)/$D$76*(3/12)) | BU28: =-(('Funding'!C18*$D$75/100)/$D$76*(3/12)) | BV28: =-(('Funding'!C18*$D$75/100)/$D$76*(3/12)) | BW28: =-(('Funding'!C18*$D$75/100)/$D$76*(3/12)) | BX28: =-(('Funding'!C18*$D$75/100)/$D$76*(3/12)) | BY28: =-(('Funding'!C18*$D$75/100)/$D$76*(3/12)) | BZ28: =-(('Funding'!C18*$D$75/100)/$D$76*(3/12)) | CA28: =-(('Funding'!C18*$D$75/100)/$D$76*(3/12)) | CB28: =-(('Funding'!C18*$D$75/100)/$D$76*(3/12)) | CC28: =-(('Funding'!C18*$D$75/100)/$D$76*(3/12)) | CD28: =-(('Funding'!C18*$D$75/100)/$D$76*(3/12)) | CE28: =-(('Funding'!C18*$D$75/100)/$D$76*(3/12)) | CF28: =-(('Funding'!C18*$D$75/100)/$D$76*(3/12)) | CG28: =-(('Funding'!C18*$D$75/100)/$D$76*(3/12)) | CH28: =-(('Funding'!C18*$D$75/100)/$D$76*(3/12)) | CI28: =-(('Funding'!C18*$D$75/100)/$D$76*(3/12)) | CJ28: =-(('Funding'!C18*$D$75/100)/$D$76*(3/12)) | CK28: =-(('Funding'!C18*$D$75/100)/$D$76*(3/12)) | CL28: =-(('Funding'!C18*$D$75/100)/$D$76*(3/12))
B29: 복구충당부채 전입액 | C29: [KRWm] | D29: =SUM(E29:CL29) | E29: 0 | F29: 0 | G29: 0 | H29: 0 | I29: 0 | J29: 0 | K29: =-($D$77*100/80) | L29: =-($D$77*100/80) | M29: =-($D$77*100/80) | N29: =-($D$77*100/80) | O29: =-($D$77*100/80) | P29: =-($D$77*100/80) | Q29: =-($D$77*100/80) | R29: =-($D$77*100/80) | ... CL29: =-($D$77*100/80)
B30: 기타 비현금 세무손금 | C30: [KRWm] | D30: =SUM(E30:CL30) | E30: 0 | F30: 0 | G30: 0 | H30: 0 | I30: 0 | J30: 0 | K30: =-($D$79/80) | L30: =-($D$79/80) | M30: =-($D$79/80) | N30: =-($D$79/80) | O30: =-($D$79/80) | P30: =-($D$79/80) | Q30: =-($D$79/80) | R30: =-($D$79/80) | ... CL30: =-($D$79/80)
B31: 대리은행수수료 | C31: [KRWm] | D31: =SUM(E31:CL31) | E31: 0 | F31: 0 | G31: 0 | H31: 0 | I31: 0 | J31: 0 | K31: =-($D$78/80) | L31: =-($D$78/80) | M31: =-($D$78/80) | N31: =-($D$78/80) | O31: =-($D$78/80) | P31: =-($D$78/80) | Q31: =-($D$78/80) | R31: =-($D$78/80) | ... CL31: =-($D$78/80)
B32: 영업이익(EBIT) | C32: [KRWm] | D32: =SUM(E32:CL32) | E32: =E25+E28+E29+E30+E31 | F32: =F25+F28+F29+F30+F31 | G32: =G25+G28+G29+G30+G31 | H32: =H25+H28+H29+H30+H31 | I32: =I25+I28+I29+I30+I31 | J32: =J25+J28+J29+J30+J31 | K32: =K25+K28+K29+K30+K31 | L32: =L25+L28+L29+L30+L31 | ... CL32: =CL25+CL28+CL29+CL30+CL31
B33: 영업이익률 | C33: [%] | E33: =IF(E8<=0,"",E32/E8) | F33: =IF(F8<=0,"",F32/F8) | G33: =IF(G8<=0,"",G32/G8) | H33: =IF(H8<=0,"",H32/H8) | I33: =IF(I8<=0,"",I32/I8) | J33: =IF(J8<=0,"",J32/J8) | K33: =IF(K8<=0,"",K32/K8) | L33: =IF(L8<=0,"",L32/L8) | ... CL33: =IF(CL8<=0,"",CL32/CL8)
B35: 이자비용 세부내역
B36: 선순위A 이자 | C36: [KRWm] | D36: =SUM(E36:CL36) | E36: =-'Debt'!E33 | F36: =-'Debt'!F33 | G36: =-'Debt'!G33 | H36: =-'Debt'!H33 | I36: =-'Debt'!I33 | J36: =-'Debt'!J33 | K36: =-'Debt'!K33 | L36: =-'Debt'!L33 | ... CL36: =-'Debt'!CL33
B37: 선순위B 이자 | C37: [KRWm] | D37: =SUM(E37:CL37) | E37: =-'Debt'!E42 | F37: =-'Debt'!F42 | G37: =-'Debt'!G42 | H37: =-'Debt'!H42 | I37: =-'Debt'!I42 | J37: =-'Debt'!J42 | K37: =-'Debt'!K42 | L37: =-'Debt'!L42 | ... CL37: =-'Debt'!CL42
B38: 선순위C 이자 | C38: [KRWm] | D38: =SUM(E38:CL38) | E38: =-'Debt'!E51 | F38: =-'Debt'!F51 | G38: =-'Debt'!G51 | H38: =-'Debt'!H51 | I38: =-'Debt'!I51 | J38: =-'Debt'!J51 | K38: =-'Debt'!K51 | L38: =-'Debt'!L51 | ... CL38: =-'Debt'!CL51
B39: 선순위D 이자 | C39: [KRWm] | D39: =SUM(E39:CL39) | E39: =-'Debt'!E61 | F39: =-'Debt'!F61 | G39: =-'Debt'!G61 | H39: =-'Debt'!H61 | I39: =-'Debt'!I61 | J39: =-'Debt'!J61 | K39: =-'Debt'!K61 | L39: =-'Debt'!L61 | ... CL39: =-'Debt'!CL61
B40: 후순위 이자 | C40: [KRWm] | D40: =SUM(E40:CL40) | E40: =-'Debt'!E70 | F40: =-'Debt'!F70 | G40: =-'Debt'!G70 | H40: =-'Debt'!H70 | I40: =-'Debt'!I70 | J40: =-'Debt'!J70 | K40: =-'Debt'!K70 | L40: =-'Debt'!L70 | ... CL40: =-'Debt'!CL70
B41: 이자비용 합계 | C41: [KRWm] | D41: =SUM(E41:CL41) | E41: =E36+E37+E38+E39+E40 | F41: =F36+F37+F38+F39+F40 | G41: =G36+G37+G38+G39+G40 | H41: =H36+H37+H38+H39+H40 | I41: =I36+I37+I38+I39+I40 | J41: =J36+J37+J38+J39+J40 | K41: =K36+K37+K38+K39+K40 | L41: =L36+L37+L38+L39+L40 | ... CL41: =CL36+CL37+CL38+CL39+CL40
B43: 법인세차감전순이익 | C43: [KRWm] | D43: =SUM(E43:CL43) | E43: =E32+E41 | F43: =F32+F41 | G43: =G32+G41 | H43: =H32+H41 | I43: =I32+I41 | J43: =J32+J41 | K43: =K32+K41 | L43: =L32+L41 | ... CL43: =CL32+CL41
B44: 법인세비용 | C44: [KRWm] | D44: =SUM(E44:CL44) | E44: =IF(AND(E43>0,E67>0),-E66*E43/E67,0) | F44: =IF(AND(F43>0,E67>0),-E66*F43/E67,0) | G44: =IF(AND(G43>0,E67>0),-E66*G43/E67,0) | H44: =IF(AND(H43>0,F67>0),-F66*H43/F67,0) | I44: =IF(AND(I43>0,F67>0),-F66*I43/F67,0) | J44: =IF(AND(J43>0,F67>0),-F66*J43/F67,0) | K44: =IF(AND(K43>0,F67>0),-F66*K43/F67,0) | L44: =IF(AND(L43>0,G67>0),-G66*L43/G67,0) | M44: =IF(AND(M43>0,G67>0),-G66*M43/G67,0) | N44: =IF(AND(N43>0,G67>0),-G66*N43/G67,0) | O44: =IF(AND(O43>0,G67>0),-G66*O43/G67,0) | P44: =IF(AND(P43>0,H67>0),-H66*P43/H67,0) | Q44: =IF(AND(Q43>0,H67>0),-H66*Q43/H67,0) | R44: =IF(AND(R43>0,H67>0),-H66*R43/H67,0) | S44: =IF(AND(S43>0,H67>0),-H66*S43/H67,0) | T44: =IF(AND(T43>0,I67>0),-I66*T43/I67,0) | U44: =IF(AND(U43>0,I67>0),-I66*U43/I67,0) | V44: =IF(AND(V43>0,I67>0),-I66*V43/I67,0) | W44: =IF(AND(W43>0,I67>0),-I66*W43/I67,0) | X44: =IF(AND(X43>0,J67>0),-J66*X43/J67,0) | Y44: =IF(AND(Y43>0,J67>0),-J66*Y43/J67,0) | Z44: =IF(AND(Z43>0,J67>0),-J66*Z43/J67,0) | AA44: =IF(AND(AA43>0,J67>0),-J66*AA43/J67,0) | AB44: =IF(AND(AB43>0,K67>0),-K66*AB43/K67,0) | AC44: =IF(AND(AC43>0,K67>0),-K66*AC43/K67,0) | AD44: =IF(AND(AD43>0,K67>0),-K66*AD43/K67,0) | AE44: =IF(AND(AE43>0,K67>0),-K66*AE43/K67,0) | AF44: =IF(AND(AF43>0,L67>0),-L66*AF43/L67,0) | AG44: =IF(AND(AG43>0,L67>0),-L66*AG43/L67,0) | AH44: =IF(AND(AH43>0,L67>0),-L66*AH43/L67,0) | AI44: =IF(AND(AI43>0,L67>0),-L66*AI43/L67,0) | AJ44: =IF(AND(AJ43>0,M67>0),-M66*AJ43/M67,0) | AK44: =IF(AND(AK43>0,M67>0),-M66*AK43/M67,0) | AL44: =IF(AND(AL43>0,M67>0),-M66*AL43/M67,0) | AM44: =IF(AND(AM43>0,M67>0),-M66*AM43/M67,0) | AN44: =IF(AND(AN43>0,N67>0),-N66*AN43/N67,0) | AO44: =IF(AND(AO43>0,N67>0),-N66*AO43/N67,0) | AP44: =IF(AND(AP43>0,N67>0),-N66*AP43/N67,0) | AQ44: =IF(AND(AQ43>0,N67>0),-N66*AQ43/N67,0) | AR44: =IF(AND(AR43>0,O67>0),-O66*AR43/O67,0) | AS44: =IF(AND(AS43>0,O67>0),-O66*AS43/O67,0) | AT44: =IF(AND(AT43>0,O67>0),-O66*AT43/O67,0) | AU44: =IF(AND(AU43>0,O67>0),-O66*AU43/O67,0) | AV44: =IF(AND(AV43>0,P67>0),-P66*AV43/P67,0) | AW44: =IF(AND(AW43>0,P67>0),-P66*AW43/P67,0) | AX44: =IF(AND(AX43>0,P67>0),-P66*AX43/P67,0) | AY44: =IF(AND(AY43>0,P67>0),-P66*AY43/P67,0) | AZ44: =IF(AND(AZ43>0,Q67>0),-Q66*AZ43/Q67,0) | BA44: =IF(AND(BA43>0,Q67>0),-Q66*BA43/Q67,0) | BB44: =IF(AND(BB43>0,Q67>0),-Q66*BB43/Q67,0) | BC44: =IF(AND(BC43>0,Q67>0),-Q66*BC43/Q67,0) | BD44: =IF(AND(BD43>0,R67>0),-R66*BD43/R67,0) | BE44: =IF(AND(BE43>0,R67>0),-R66*BE43/R67,0) | BF44: =IF(AND(BF43>0,R67>0),-R66*BF43/R67,0) | BG44: =IF(AND(BG43>0,R67>0),-R66*BG43/R67,0) | BH44: =IF(AND(BH43>0,S67>0),-S66*BH43/S67,0) | BI44: =IF(AND(BI43>0,S67>0),-S66*BI43/S67,0) | BJ44: =IF(AND(BJ43>0,S67>0),-S66*BJ43/S67,0) | BK44: =IF(AND(BK43>0,S67>0),-S66*BK43/S67,0) | BL44: =IF(AND(BL43>0,T67>0),-T66*BL43/T67,0) | BM44: =IF(AND(BM43>0,T67>0),-T66*BM43/T67,0) | BN44: =IF(AND(BN43>0,T67>0),-T66*BN43/T67,0) | BO44: =IF(AND(BO43>0,T67>0),-T66*BO43/T67,0) | BP44: =IF(AND(BP43>0,U67>0),-U66*BP43/U67,0) | BQ44: =IF(AND(BQ43>0,U67>0),-U66*BQ43/U67,0) | BR44: =IF(AND(BR43>0,U67>0),-U66*BR43/U67,0) | BS44: =IF(AND(BS43>0,U67>0),-U66*BS43/U67,0) | BT44: =IF(AND(BT43>0,V67>0),-V66*BT43/V67,0) | BU44: =IF(AND(BU43>0,V67>0),-V66*BU43/V67,0) | BV44: =IF(AND(BV43>0,V67>0),-V66*BV43/V67,0) | BW44: =IF(AND(BW43>0,V67>0),-V66*BW43/V67,0) | BX44: =IF(AND(BX43>0,W67>0),-W66*BX43/W67,0) | BY44: =IF(AND(BY43>0,W67>0),-W66*BY43/W67,0) | BZ44: =IF(AND(BZ43>0,W67>0),-W66*BZ43/W67,0) | CA44: =IF(AND(CA43>0,W67>0),-W66*CA43/W67,0) | CB44: =IF(AND(CB43>0,X67>0),-X66*CB43/X67,0) | CC44: =IF(AND(CC43>0,X67>0),-X66*CC43/X67,0) | CD44: =IF(AND(CD43>0,X67>0),-X66*CD43/X67,0) | CE44: =IF(AND(CE43>0,X67>0),-X66*CE43/X67,0) | CF44: =IF(AND(CF43>0,Y67>0),-Y66*CF43/Y67,0) | CG44: =IF(AND(CG43>0,Y67>0),-Y66*CG43/Y67,0) | CH44: =IF(AND(CH43>0,Y67>0),-Y66*CH43/Y67,0) | CI44: =IF(AND(CI43>0,Y67>0),-Y66*CI43/Y67,0) | CJ44: =IF(AND(CJ43>0,Z67>0),-Z66*CJ43/Z67,0) | CK44: =IF(AND(CK43>0,Z67>0),-Z66*CK43/Z67,0) | CL44: =IF(AND(CL43>0,Z67>0),-Z66*CL43/Z67,0)
B45: 당기순이익 | C45: [KRWm] | D45: =SUM(E45:CL45) | E45: =E43+E44 | F45: =F43+F44 | G45: =G43+G44 | H45: =H43+H44 | I45: =I43+I44 | J45: =J43+J44 | K45: =K43+K44 | L45: =L43+L44 | ... CL45: =CL43+CL44
B48: 연도별 법인세 산출
B50: 세무상 과세표준(분기, 연간집계용) | C50: [KRWm] | D50: =SUM(E50:CL50) | E50: =E43-E29-(0) | F50: =F43-F29-(0) | G50: =G43-G29-(0) | H50: =H43-H29-(0) | I50: =I43-I29-(0) | J50: =J43-J29-(0) | K50: =K43-K29-(0) | L50: =L43-L29-(0) | ... CK50: =CK43-CK29-(0) | CL50: =CL43-CL29-($D$77*100)
B52: 연도 | E52: 2024 | F52: 2025 | G52: 2026 | H52: 2027 | I52: 2028 | J52: 2029 | K52: 2030 | L52: 2031 | M52: 2032 | N52: 2033 | O52: 2034 | P52: 2035 | Q52: 2036 | R52: 2037 | S52: 2038 | T52: 2039 | U52: 2040 | V52: 2041 | W52: 2042 | X52: 2043 | Y52: 2044 | Z52: 2045
...

Sheet CF(Q)
A1: 태양광 발전사업
A2: 추정 현금흐름표 (분기) · DSCR · 배당
B4: 영업/재무 현금흐름
B6: 구 분 | C6: unit | D6: 합 계 | E6: 2024-06-30 | F6: 2024-09-30 | G6: 2024-12-31 | H6: 2025-03-31 | I6: 2025-06-30 | J6: 2025-09-30 | K6: 2025-12-31 | L6: 2026-03-31 | M6: 2026-06-30 | N6: 2026-09-30 | O6: 2026-12-31 | P6: 2027-03-31 | Q6: 2027-06-30 | R6: 2027-09-30 | S6: 2027-12-31 | T6: 2028-03-31 | U6: 2028-06-30 | V6: 2028-09-30 | W6: 2028-12-31 | X6: 2029-03-31 | Y6: 2029-06-30 | Z6: 2029-09-30 | AA6: 2029-12-31 | AB6: 2030-03-31 | AC6: 2030-06-30 | AD6: 2030-09-30 | AE6: 2030-12-31 | AF6: 2031-03-31 | AG6: 2031-06-30 | AH6: 2031-09-30 | AI6: 2031-12-31 | AJ6: 2032-03-31 | AK6: 2032-06-30 | AL6: 2032-09-30 | AM6: 2032-12-31 | AN6: 2033-03-31 | AO6: 2033-06-30 | AP6: 2033-09-30 | AQ6: 2033-12-31 | AR6: 2034-03-31 | AS6: 2034-06-30 | AT6: 2034-09-30 | AU6: 2034-12-31 | AV6: 2035-03-31 | AW6: 2035-06-30 | AX6: 2035-09-30 | AY6: 2035-12-31 | AZ6: 2036-03-31 | BA6: 2036-06-30 | BB6: 2036-09-30 | BC6: 2036-12-31 | BD6: 2037-03-31 | BE6: 2037-06-30 | BF6: 2037-09-30 | BG6: 2037-12-31 | BH6: 2038-03-31 | BI6: 2038-06-30 | BJ6: 2038-09-30 | BK6: 2038-12-31 | BL6: 2039-03-31 | BM6: 2039-06-30 | BN6: 2039-09-30 | BO6: 2039-12-31 | BP6: 2040-03-31 | BQ6: 2040-06-30 | BR6: 2040-09-30 | BS6: 2040-12-31 | BT6: 2041-03-31 | BU6: 2041-06-30 | BV6: 2041-09-30 | BW6: 2041-12-31 | BX6: 2042-03-31 | BY6: 2042-06-30 | BZ6: 2042-09-30 | CA6: 2042-12-31 | CB6: 2043-03-31 | CC6: 2043-06-30 | CD6: 2043-09-30 | CE6: 2043-12-31 | CF6: 2044-03-31 | CG6: 2044-06-30 | CH6: 2044-09-30 | CI6: 2044-12-31 | CJ6: 2045-03-31 | CK6: 2045-06-30 | CL6: 2045-09-30
B9: CFADS (원리금상환재원) | C9: [KRWm] | D9: =SUM(E9:CL9) | E9: ='Revenue'!E17-'Opex'!E22+'IS(Q)'!E44+'IS(Q)'!E31+'Revenue'!E22 | F9: ='Revenue'!F17-'Opex'!F22+'IS(Q)'!F44+'IS(Q)'!F31+'Revenue'!F22 | G9: ='Revenue'!G17-'Opex'!G22+'IS(Q)'!G44+'IS(Q)'!G31+'Revenue'!G22 | H9: ='Revenue'!H17-'Opex'!H22+'IS(Q)'!H44+'IS(Q)'!H31+'Revenue'!H22 | I9: ='Revenue'!I17-'Opex'!I22+'IS(Q)'!I44+'IS(Q)'!I31+'Revenue'!I22 | J9: ='Revenue'!J17-'Opex'!J22+'IS(Q)'!J44+'IS(Q)'!J31+'Revenue'!J22 | K9: ='Revenue'!K17-'Opex'!K22+'IS(Q)'!K44+'IS(Q)'!K31+'Revenue'!K22 | L9: ='Revenue'!L17-'Opex'!L22+'IS(Q)'!L44+'IS(Q)'!L31+'Revenue'!L22 | ... CL9: ='Revenue'!CL17-'Opex'!CL22+'IS(Q)'!CL44+'IS(Q)'!CL31+'Revenue'!CL22
B10: 원리금(DS) | C10: [KRWm] | D10: =SUM(E10:CL10) | E10: ='Debt'!E79 | F10: ='Debt'!F79 | G10: ='Debt'!G79 | H10: ='Debt'!H79 | I10: ='Debt'!I79 | J10: ='Debt'!J79 | K10: ='Debt'!K79 | L10: ='Debt'!L79 | ... CL10: ='Debt'!CL79
B11: 단순 DSCR | C11: [x] | K11: =K9/K10 | L11: =L9/L10 | M11: =M9/M10 | N11: =N9/N10 | O11: =O9/O10 | P11: =P9/P10 | Q11: =Q9/Q10 | R11: =R9/R10 | ... BY11: =BY9/BY10
B13: FCFE | C13: [KRWm] | D13: =SUM(E13:CL13) | E13: =E9-E10-E14-'Opex'!E23+E19 | F13: =F9-F10-F14-'Opex'!F23+F19 | G13: =G9-G10-G14-'Opex'!G23+G19 | H13: =H9-H10-H14-'Opex'!H23+H19 | I13: =I9-I10-I14-'Opex'!I23+I19 | J13: =J9-J10-J14-'Opex'!J23+J19 | K13: =K9-K10-K14-'Opex'!K23+K19 | L13: =L9-L10-L14-'Opex'!L23+L19 | ... CK13: =CK9-CK10-CK14-'Opex'!CK23+CK19 | CL13: =CL9-CL10-CL14-'Opex'!CL23-$D$73*100+CL19
B14: DSRA 증감 | C14: [KRWm] | D14: =SUM(E14:CL14) | E14: =E21-E20 | F14: =F21-F20 | G14: =G21-G20 | H14: =H21-H20 | I14: =I21-I20 | J14: =J21-J20 | K14: =K21-K20 | L14: =L21-L20 | ... CL14: =CL21-CL20
