Workbook

Sheet 목차
B2: 당진 태양광발전
B3: 재무모델 v2 (분기·5트랜치) — 재생E AI Agent 자동생성 · 2026-08-27
B6: 시트 | C6: 내용
B7: Report | C7: Executive Summary — 핵심 KPI
B8: 입력값 | C8: 화면에서 입력한 원본 값 — Funding 등이 이 시트를 참조
B9: Funding | C9: 자금조달 — 자본금 + 5트랜치 조건
B10: Debt | C10: 트랜치별 상환 스케줄 (A/B/C/D/후순위) + 합계
B11: Revenue | C11: 발전량 · 매출
B12: Opex | C12: 운영비 (선순위/후순위)
B13: IS(Q) | C13: 분기 손익계산서
B14: CF(Q) | C14: 분기 현금흐름 · DSCR · 배당
B16: ※ Funding 시트의 트랜치 조건·총사업비 항목·사업자 지분은 "입력값" 시트를 참조하는 수식입니다(입력값 시트를 고치면 같이 바뀝니다). 그 외 계산 결과(세금·DSCR·배당 등)는 값(baked) 기준이라 가정을 바꾸려면 생성기에서 다시 뽑아야 합니다.

Sheet Report
A1: 당진 태양광발전
A2: Executive Summary (v2 · 분기 · 5트랜치)
B4: 사업 개요
B6: 사업명 | D6: ='입력값'!C6
B7: 설비용량 [MW] | D7: ='입력값'!C7
B8: 총 기간 수(분기) | D8: 86
B9: 건설 개시 | D9: 2024-06
B11: 재원조달
B13: 총투자비(TIC) [KRWm] | D13: ='Funding'!C18
B14: 건설이자(IDC) [KRWm] | D14: ='Funding'!C17
B15: 자기자본 [KRWm] | D15: ='Funding'!C7
B16: 차입금 합계 [KRWm] | D16: ='Funding'!C13
B18: 수익성 지표
B20: Project IRR 세전 [%] | D20: ='CF(Q)'!D62
B21: Project IRR 세후 [%] | D21: ='CF(Q)'!D63
B22: Equity IRR (FCFE) [%] | D22: ='CF(Q)'!D64
B23: Equity IRR (배당) [%] | D23: ='CF(Q)'!D65
B24: Investor IRR [%] | D24: ='CF(Q)'!D66
B25: 최소 단순DSCR(연 합산) [x] | D25: ='CF(Q)'!D47
B26: 최소 누적DSCR [x] | D26: ='CF(Q)'!D48
B27: 총영업수익(전체기간) [KRWm] | D27: ='Revenue'!D12
B28: 총영업비용(전체기간) [KRWm] | D28: ='Opex'!D24
B29: 총선순위이자 [KRWm] | D29: ='Debt'!D55
B30: 총법인세 [KRWm] | D30: =-'IS(Q)'!D44
B31: 총배당(연차+청산) [KRWm] | D31: ='CF(Q)'!D16

Sheet 입력값
A1: 당진 태양광발전
A2: 입력값 — 화면에서 입력한 값 (다른 시트가 이 시트를 참조)
B4: 사업 기본 가정
B6: 사업명 | C6: 당진 태양광발전
B7: 설비용량[MW] | C7: 99.998
B8: 총사업비[억원] | C8: 1410.6882
B9: 자기자본[억원] | C9: 150
B10: 판매단가[원/kWh]
B11: 판매단가 에스컬레이션[%/yr]
B12: 발전량 열화율[%/yr] | C12: 0.5
B13: 소내소비율[%] | C13: 0
B14: 일조시간[h/day] | C14: 3.77
B15: 상각대상액(직접입력)[KRWm] | C15: 137976.35
B16: 감가상각 내용연수[yr] | C16: 20
B17: 철거비(복구충당부채)[억원] | C17: 20
B18: 대리은행수수료(총액)[KRWm] | C18: 320
B19: 기타 비현금 세무손금(총액)[KRWm] | C19: 6743.65
B20: DSRA 최초 적립액[억원] | C20: 50
B21: DSRA 적립기준(차기 X개월분) | C21: 6
B22: 최소 보유현금[억원] | C22: 10
B23: 배당 게이트 — 단순DSCR 최소치[x] | C23: 1.1
... B26: 최초 배당 가능 연도 | C26: 2028
B28: 법인세 가정
B30: 이월결손금 공제한도[%] | C30: 80
B31: 최저한세율[%] | C31: 10
B32: 통합투자세액공제율[%] | C32: 1
B33: 지방소득세율(법인세 대비)[%] | C33: 10
B34: 세액공제 농특세율[%] | C34: 20
B36: 건설기간 손실(연도별)
B38: 연도 | C38: 금액[KRWm]
B39: 2024 | C39: 140
B40: 2025 | C40: 140
B42: 통합투자세액공제 기준액(연도별)
B44: 연도 | C44: 금액[KRWm]
B45: 2024 | C45: 43600
B46: 2025 | C46: 65400
B48: 판매단가 트랙 (PPA/SMP+REC 등)
B50: 트랙 | C50: 비중[%] | D50: 단가[원/kWh] | E50: 에스컬레이션[%/yr]
B51: 트랙1 | C51: 0 | D51: 0 | E51: 0
B52: 트랙2 | C52: 60.0012 | D52: 160 | E52: 0
...

Sheet Funding
A1: 당진 태양광발전
A2: 자금조달 — 자본금 + 5개 트랜치
B4: 트랜치 조건
B6: 트랜치 | C6: 금액[KRWm] | D6: 투입순서 | E6: 건설금리 | F6: 운영금리 | G6: 거치(yr) | H6: 상환(yr) | I6: 방식 | J6: 상환개시
B7: 자본금 | C7: ='입력값'!C9*100
B8: 선순위A | C8: ='입력값'!C58*100 | E8: ='입력값'!D58 | F8: ='입력값'!E58 | G8: ='입력값'!F58 | H8: ='입력값'!G58 | I8: ='입력값'!H58 | J8: 2026-09-30
B9: 선순위B | C9: ='입력값'!C59*100 | E9: ='입력값'!D59 | F9: ='입력값'!E59 | G9: ='입력값'!F59 | H9: ='입력값'!G59 | I9: ='입력값'!H59 | J9: 2026-09-30
B10: 선순위C | C10: ='입력값'!C60*100 | E10: ='입력값'!D60 | F10: ='입력값'!E60 | G10: ='입력값'!F60 | H10: ='입력값'!G60 | I10: ='입력값'!H60 | J10: 2026-09-30
B11: 선순위D | C11: ='입력값'!C61*100 | E11: ='입력값'!D61 | F11: ='입력값'!E61 | G11: ='입력값'!F61 | H11: ='입력값'!G61 | I11: ='입력값'!H61 | J11: -
B12: 후순위 | C12: ='입력값'!C62*100 | E12: ='입력값'!D62 | F12: ='입력값'!E62 | G12: ='입력값'!F62 | H12: ='입력값'!G62 | I12: ='입력값'!H62 | J12: -
B13: 차입금 합계 | C13: =C8+C9+C10+C11+C12
B15: 건설이자(IDC)
B17: IDC 합계[KRWm] | C17: 3931.1785
B18: 총투자비(TIC)[KRWm] | C18: 145000
B19: 총사업비(건설이자 제외)[KRWm] | C19: ='입력값'!C8*100
B21: 총사업비 세부내역
B23: 항목 | C23: 금액[KRWm]
B24: ='입력값'!B75
B25: ='입력값'!B76
B26: ='입력값'!B77
B27: ='입력값'!B78
B28: ='입력값'!B79
B29: ='입력값'!B80
B30: ='입력값'!B81
B31: ='입력값'!B82
B32: ='입력값'!B83
B33: ='입력값'!B84
B34: ='입력값'!B85
B35: ='입력값'!B86
B36: 합계 | C36: ='입력값'!C8*100

Sheet Debt
A1: 당진 태양광발전
A2: 차입금 상환 스케줄 — 트랜치별 + 합계
B4: 트랜치별 인출/상환 + 전체 합계
B6: 구 분 | C6: unit | D6: 합 계 | E6: 2024-06-30 | F6: 2024-09-30 | G6: 2024-12-31 | H6: 2025-03-31 | I6: 2025-06-30 | J6: 2025-09-30 | K6: 2025-12-31 | L6: 2026-03-31 | M6: 2026-06-30 | N6: 2026-09-30 | O6: 2026-12-31 | P6: 2027-03-31 | Q6: 2027-06-30 | R6: 2027-09-30 | S6: 2027-12-31 | T6: 2028-03-31 | U6: 2028-06-30 | V6: 2028-09-30 | W6: 2028-12-31 | X6: 2029-03-31 | Y6: 2029-06-30 | Z6: 2029-09-30 | AA6: 2029-12-31 | AB6: 2030-03-31 | AC6: 2030-06-30 | AD6: 2030-09-30 | AE6: 2030-12-31 | AF6: 2031-03-31 | AG6: 2031-06-30 | AH6: 2031-09-30 | AI6: 2031-12-31 | AJ6: 2032-03-31 | AK6: 2032-06-30 | AL6: 2032-09-30 | AM6: 2032-12-31 | AN6: 2033-03-31 | AO6: 2033-06-30 | AP6: 2033-09-30 | AQ6: 2033-12-31 | AR6: 2034-03-31 | AS6: 2034-06-30 | AT6: 2034-09-30 | AU6: 2034-12-31 | AV6: 2035-03-31 | AW6: 2035-06-30 | AX6: 2035-09-30 | AY6: 2035-12-31 | AZ6: 2036-03-31 | BA6: 2036-06-30 | BB6: 2036-09-30 | BC6: 2036-12-31 | BD6: 2037-03-31 | BE6: 2037-06-30 | BF6: 2037-09-30 | BG6: 2037-12-31 | BH6: 2038-03-31 | BI6: 2038-06-30 | BJ6: 2038-09-30 | BK6: 2038-12-31 | BL6: 2039-03-31 | BM6: 2039-06-30 | BN6: 2039-09-30 | BO6: 2039-12-31 | BP6: 2040-03-31 | BQ6: 2040-06-30 | BR6: 2040-09-30 | BS6: 2040-12-31 | BT6: 2041-03-31 | BU6: 2041-06-30 | BV6: 2041-09-30 | BW6: 2041-12-31 | BX6: 2042-03-31 | BY6: 2042-06-30 | BZ6: 2042-09-30 | CA6: 2042-12-31 | CB6: 2043-03-31 | CC6: 2043-06-30 | CD6: 2043-09-30 | CE6: 2043-12-31 | CF6: 2044-03-31 | CG6: 2044-06-30 | CH6: 2044-09-30 | CI6: 2044-12-31 | CJ6: 2045-03-31 | CK6: 2045-06-30 | CL6: 2045-09-30
B8: 선순위A
B9: 기초잔액 | C9: [KRWm] | E9: 0 | F9: =E14 | G9: =F14 | H9: =G14 | I9: =H14 | J9: =I14 | K9: =J14 | L9: =K14 | M9: =L14 | ... CL9: =CK14
B10: 인출 | C10: [KRWm] | D10: =SUM(E10:CL10) | E10: 9935.1614 | F10: 5714.3708 | G10: 11330.803 | H10: 11493.863 | I10: 11525.802 | J10: 0 | K10: 0 | L10: 0 | M10: 0 | N10: 0 | O10: 0 | P10: 0 | Q10: 0 | R10: 0 | S10: 0 | T10: 0 | U10: 0 | V10: 0 | W10: 0 | X10: 0 | Y10: 0 | Z10: 0 | AA10: 0 | AB10: 0 | AC10: 0 | AD10: 0 | AE10: 0 | AF10: 0 | AG10: 0 | AH10: 0 | AI10: 0 | AJ10: 0 | AK10: 0 | AL10: 0 | AM10: 0 | AN10: 0 | AO10: 0 | AP10: 0 | AQ10: 0 | AR10: 0 | AS10: 0 | AT10: 0 | AU10: 0 | AV10: 0 | AW10: 0 | AX10: 0 | AY10: 0 | AZ10: 0 | BA10: 0 | BB10: 0 | BC10: 0 | BD10: 0 | BE10: 0 | BF10: 0 | BG10: 0 | BH10: 0 | BI10: 0 | BJ10: 0 | BK10: 0 | BL10: 0 | BM10: 0 | BN10: 0 | BO10: 0 | BP10: 0 | BQ10: 0 | BR10: 0 | BS10: 0 | BT10: 0 | BU10: 0 | BV10: 0 | BW10: 0 | BX10: 0 | BY10: 0 | BZ10: 0 | CA10: 0 | CB10: 0 | CC10: 0 | CD10: 0 | CE10: 0 | CF10: 0 | CG10: 0 | CH10: 0 | CI10: 0 | CJ10: 0 | CK10: 0 | CL10: 0
B11: 건설이자(IDC) | C11: [KRWm] | D11: =SUM(E11:CL11) | E11: 0 | F11: 139.09226 | G11: 219.09345 | H11: 377.72469 | I11: 538.63878 | J11: 700 | K11: 0 | L11: 0 | M11: 0 | N11: 0 | O11: 0 | P11: 0 | Q11: 0 | R11: 0 | S11: 0 | T11: 0 | U11: 0 | V11: 0 | W11: 0 | X11: 0 | Y11: 0 | Z11: 0 | AA11: 0 | AB11: 0 | AC11: 0 | AD11: 0 | AE11: 0 | AF11: 0 | AG11: 0 | AH11: 0 | AI11: 0 | AJ11: 0 | AK11: 0 | AL11: 0 | AM11: 0 | AN11: 0 | AO11: 0 | AP11: 0 | AQ11: 0 | AR11: 0 | AS11: 0 | AT11: 0 | AU11: 0 | AV11: 0 | AW11: 0 | AX11: 0 | AY11: 0 | AZ11: 0 | BA11: 0 | BB11: 0 | BC11: 0 | BD11: 0 | BE11: 0 | BF11: 0 | BG11: 0 | BH11: 0 | BI11: 0 | BJ11: 0 | BK11: 0 | BL11: 0 | BM11: 0 | BN11: 0 | BO11: 0 | BP11: 0 | BQ11: 0 | BR11: 0 | BS11: 0 | BT11: 0 | BU11: 0 | BV11: 0 | BW11: 0 | BX11: 0 | BY11: 0 | BZ11: 0 | CA11: 0 | CB11: 0 | CC11: 0 | CD11: 0 | CE11: 0 | CF11: 0 | CG11: 0 | CH11: 0 | CI11: 0 | CJ11: 0 | CK11: 0 | CL11: 0
B12: 이자(운영) | C12: [KRWm] | D12: =SUM(E12:CL12) | E12: 0 | F12: 0 | G12: 0 | H12: 0 | I12: 0 | J12: 0 | K12: =K9*'입력값'!E58/4 | L12: =L9*'입력값'!E58/4 | M12: =M9*'입력값'!E58/4 | N12: =N9*'입력값'!E58/4 | O12: =O9*'입력값'!E58/4 | P12: =P9*'입력값'!E58/4 | Q12: =Q9*'입력값'!E58/4 | R12: =R9*'입력값'!E58/4 | S12: =S9*'입력값'!E58/4 | T12: =T9*'입력값'!E58/4 | U12: =U9*'입력값'!E58/4 | V12: =V9*'입력값'!E58/4 | W12: =W9*'입력값'!E58/4 | X12: =X9*'입력값'!E58/4 | Y12: =Y9*'입력값'!E58/4 | Z12: =Z9*'입력값'!E58/4 | AA12: =AA9*'입력값'!E58/4 | AB12: =AB9*'입력값'!E58/4 | AC12: =AC9*'입력값'!E58/4 | AD12: =AD9*'입력값'!E58/4 | AE12: =AE9*'입력값'!E58/4 | AF12: =AF9*'입력값'!E58/4 | AG12: =AG9*'입력값'!E58/4 | AH12: =AH9*'입력값'!E58/4 | AI12: =AI9*'입력값'!E58/4 | AJ12: =AJ9*'입력값'!E58/4 | AK12: =AK9*'입력값'!E58/4 | AL12: =AL9*'입력값'!E58/4 | AM12: =AM9*'입력값'!E58/4 | AN12: =AN9*'입력값'!E58/4 | AO12: =AO9*'입력값'!E58/4 | AP12: =AP9*'입력값'!E58/4 | AQ12: =AQ9*'입력값'!E58/4 | AR12: =AR9*'입력값'!E58/4 | AS12: =AS9*'입력값'!E58/4 | AT12: =AT9*'입력값'!E58/4 | AU12: =AU9*'입력값'!E58/4 | AV12: =AV9*'입력값'!E58/4 | AW12: =AW9*'입력값'!E58/4 | AX12: =AX9*'입력값'!E58/4 | AY12: =AY9*'입력값'!E58/4 | AZ12: =AZ9*'입력값'!E58/4 | BA12: =BA9*'입력값'!E58/4 | BB12: =BB9*'입력값'!E58/4 | BC12: =BC9*'입력값'!E58/4 | BD12: =BD9*'입력값'!E58/4 | BE12: =BE9*'입력값'!E58/4 | BF12: =BF9*'입력값'!E58/4 | BG12: =BG9*'입력값'!E58/4 | BH12: =BH9*'입력값'!E58/4 | BI12: =BI9*'입력값'!E58/4 | BJ12: =BJ9*'입력값'!E58/4 | BK12: =BK9*'입력값'!E58/4 | BL12: =BL9*'입력값'!E58/4 | BM12: =BM9*'입력값'!E58/4 | BN12: =BN9*'입력값'!E58/4 | BO12: =BO9*'입력값'!E58/4 | BP12: =BP9*'입력값'!E58/4 | BQ12: =BQ9*'입력값'!E58/4 | BR12: =BR9*'입력값'!E58/4 | BS12: =BS9*'입력값'!E58/4 | BT12: =BT9*'입력값'!E58/4 | BU12: =BU9*'입력값'!E58/4 | BV12: =BV9*'입력값'!E58/4 | BW12: =BW9*'입력값'!E58/4 | BX12: =BX9*'입력값'!E58/4 | BY12: =BY9*'입력값'!E58/4 | BZ12: =BZ9*'입력값'!E58/4 | CA12: =CA9*'입력값'!E58/4 | CB12: =CB9*'입력값'!E58/4 | CC12: =CC9*'입력값'!E58/4 | CD12: =CD9*'입력값'!E58/4 | CE12: =CE9*'입력값'!E58/4 | CF12: =CF9*'입력값'!E58/4 | CG12: =CG9*'입력값'!E58/4 | CH12: =CH9*'입력값'!E58/4 | CI12: =CI9*'입력값'!E58/4 | CJ12: =CJ9*'입력값'!E58/4 | CK12: =CK9*'입력값'!E58/4 | CL12: =CL9*'입력값'!E58/4
B13: 원금상환 | C13: [KRWm] | D13: =SUM(E13:CL13) | E13: 0 | F13: 0 | G13: 0 | H13: 0 | I13: 0 | J13: 0 | K13: 0 | L13: 0 | M13: 0 | N13: ='입력값'!N68*'입력값'!C58*100 | O13: ='입력값'!O68*'입력값'!C58*100 | P13: ='입력값'!P68*'입력값'!C58*100 | Q13: ='입력값'!Q68*'입력값'!C58*100 | R13: ='입력값'!R68*'입력값'!C58*100 | S13: ='입력값'!S68*'입력값'!C58*100 | T13: ='입력값'!T68*'입력값'!C58*100 | U13: ='입력값'!U68*'입력값'!C58*100 | V13: ='입력값'!V68*'입력값'!C58*100 | W13: ='입력값'!W68*'입력값'!C58*100 | X13: ='입력값'!X68*'입력값'!C58*100 | Y13: ='입력값'!Y68*'입력값'!C58*100 | Z13: ='입력값'!Z68*'입력값'!C58*100 | AA13: ='입력값'!AA68*'입력값'!C58*100 | AB13: ='입력값'!AB68*'입력값'!C58*100 | AC13: ='입력값'!AC68*'입력값'!C58*100 | AD13: ='입력값'!AD68*'입력값'!C58*100 | AE13: ='입력값'!AE68*'입력값'!C58*100 | AF13: ='입력값'!AF68*'입력값'!C58*100 | AG13: ='입력값'!AG68*'입력값'!C58*100 | AH13: ='입력값'!AH68*'입력값'!C58*100 | AI13: ='입력값'!AI68*'입력값'!C58*100 | AJ13: ='입력값'!AJ68*'입력값'!C58*100 | AK13: ='입력값'!AK68*'입력값'!C58*100 | AL13: ='입력값'!AL68*'입력값'!C58*100 | AM13: ='입력값'!AM68*'입력값'!C58*100 | AN13: ='입력값'!AN68*'입력값'!C58*100 | AO13: ='입력값'!AO68*'입력값'!C58*100 | AP13: ='입력값'!AP68*'입력값'!C58*100 | AQ13: ='입력값'!AQ68*'입력값'!C58*100 | AR13: ='입력값'!AR68*'입력값'!C58*100 | AS13: ='입력값'!AS68*'입력값'!C58*100 | AT13: ='입력값'!AT68*'입력값'!C58*100 | AU13: ='입력값'!AU68*'입력값'!C58*100 | AV13: ='입력값'!AV68*'입력값'!C58*100 | AW13: ='입력값'!AW68*'입력값'!C58*100 | AX13: ='입력값'!AX68*'입력값'!C58*100 | AY13: ='입력값'!AY68*'입력값'!C58*100 | AZ13: ='입력값'!AZ68*'입력값'!C58*100 | BA13: ='입력값'!BA68*'입력값'!C58*100 | BB13: ='입력값'!BB68*'입력값'!C58*100 | BC13: ='입력값'!BC68*'입력값'!C58*100 | BD13: ='입력값'!BD68*'입력값'!C58*100 | BE13: ='입력값'!BE68*'입력값'!C58*100 | BF13: ='입력값'!BF68*'입력값'!C58*100 | BG13: ='입력값'!BG68*'입력값'!C58*100 | BH13: ='입력값'!BH68*'입력값'!C58*100 | BI13: ='입력값'!BI68*'입력값'!C58*100 | BJ13: ='입력값'!BJ68*'입력값'!C58*100 | BK13: ='입력값'!BK68*'입력값'!C58*100 | BL13: ='입력값'!BL68*'입력값'!C58*100 | BM13: ='입력값'!BM68*'입력값'!C58*100 | BN13: ='입력값'!BN68*'입력값'!C58*100 | BO13: ='입력값'!BO68*'입력값'!C58*100 | BP13: ='입력값'!BP68*'입력값'!C58*100 | BQ13: ='입력값'!BQ68*'입력값'!C58*100 | BR13: ='입력값'!BR68*'입력값'!C58*100 | BS13: ='입력값'!BS68*'입력값'!C58*100 | BT13: ='입력값'!BT68*'입력값'!C58*100 | BU13: ='입력값'!BU68*'입력값'!C58*100 | BV13: ='입력값'!BV68*'입력값'!C58*100 | BW13: ='입력값'!BW68*'입력값'!C58*100 | BX13: ='입력값'!BX68*'입력값'!C58*100 | BY13: ='입력값'!BY68*'입력값'!C58*100 | BZ13: 0 | CA13: 0 | CB13: 0 | CC13: 0 | CD13: 0 | CE13: 0 | CF13: 0 | CG13: 0 | CH13: 0 | CI13: 0 | CJ13: 0 | CK13: 0 | CL13: 0
B14: 기말잔액 | C14: [KRWm] | E14: =E9+E10-E13 | F14: =F9+F10-F13 | G14: =G9+G10-G13 | H14: =H9+H10-H13 | I14: =I9+I10-I13 | J14: =J9+J10-J13 | K14: =K9+K10-K13 | L14: =L9+L10-L13 | ... CL14: =CL9+CL10-CL13
B15: 미상환 잔액(검증용) | C15: [KRWm] | D15: =CL14 | F15: =IF(ABS(D15)<1,"완전상환 확인 (OK)","경고: 미상환 잔액") | H15: ※ 방식 3(직접 키인) — 원금상환은 "입력값" 시트의 상환비율 표를 참조하는 수식
B17: 선순위B
B18: 기초잔액 | C18: [KRWm] | E18: 0 | F18: =E23 | G18: =F23 | H18: =G23 | I18: =H23 | J18: =I23 | K18: =J23 | L18: =K23 | M18: =L23 | ... CL18: =CK23
B19: 인출 | C19: [KRWm] | D19: =SUM(E19:CL19) | E19: 9935.1614 | F19: 5714.3708 | G19: 11330.803 | H19: 11493.863 | I19: 11525.802 | J19: 0 | K19: 0 | L19: 0 | M19: 0 | N19: 0 | O19: 0 | P19: 0 | Q19: 0 | R19: 0 | S19: 0 | T19: 0 | U19: 0 | V19: 0 | W19: 0 | X19: 0 | Y19: 0 | Z19: 0 | AA19: 0 | AB19: 0 | AC19: 0 | AD19: 0 | AE19: 0 | AF19: 0 | AG19: 0 | AH19: 0 | AI19: 0 | AJ19: 0 | AK19: 0 | AL19: 0 | AM19: 0 | AN19: 0 | AO19: 0 | AP19: 0 | AQ19: 0 | AR19: 0 | AS19: 0 | AT19: 0 | AU19: 0 | AV19: 0 | AW19: 0 | AX19: 0 | AY19: 0 | AZ19: 0 | BA19: 0 | BB19: 0 | BC19: 0 | BD19: 0 | BE19: 0 | BF19: 0 | BG19: 0 | BH19: 0 | BI19: 0 | BJ19: 0 | BK19: 0 | BL19: 0 | BM19: 0 | BN19: 0 | BO19: 0 | BP19: 0 | BQ19: 0 | BR19: 0 | BS19: 0 | BT19: 0 | BU19: 0 | BV19: 0 | BW19: 0 | BX19: 0 | BY19: 0 | BZ19: 0 | CA19: 0 | CB19: 0 | CC19: 0 | CD19: 0 | CE19: 0 | CF19: 0 | CG19: 0 | CH19: 0 | CI19: 0 | CJ19: 0 | CK19: 0 | CL19: 0
B20: 건설이자(IDC) | C20: [KRWm] | D20: =SUM(E20:CL20) | E20: 0 | F20: 136.60847 | G20: 215.18107 | H20: 370.97961 | I20: 529.02023 | J20: 687.5 | K20: 0 | L20: 0 | M20: 0 | N20: 0 | O20: 0 | P20: 0 | Q20: 0 | R20: 0 | S20: 0 | T20: 0 | U20: 0 | V20: 0 | W20: 0 | X20: 0 | Y20: 0 | Z20: 0 | AA20: 0 | AB20: 0 | AC20: 0 | AD20: 0 | AE20: 0 | AF20: 0 | AG20: 0 | AH20: 0 | AI20: 0 | AJ20: 0 | AK20: 0 | AL20: 0 | AM20: 0 | AN20: 0 | AO20: 0 | AP20: 0 | AQ20: 0 | AR20: 0 | AS20: 0 | AT20: 0 | AU20: 0 | AV20: 0 | AW20: 0 | AX20: 0 | AY20: 0 | AZ20: 0 | BA20: 0 | BB20: 0 | BC20: 0 | BD20: 0 | BE20: 0 | BF20: 0 | BG20: 0 | BH20: 0 | BI20: 0 | BJ20: 0 | BK20: 0 | BL20: 0 | BM20: 0 | BN20: 0 | BO20: 0 | BP20: 0 | BQ20: 0 | BR20: 0 | BS20: 0 | BT20: 0 | BU20: 0 | BV20: 0 | BW20: 0 | BX20: 0 | BY20: 0 | BZ20: 0 | CA20: 0 | CB20: 0 | CC20: 0 | CD20: 0 | CE20: 0 | CF20: 0 | CG20: 0 | CH20: 0 | CI20: 0 | CJ20: 0 | CK20: 0 | CL20: 0
B21: 이자(운영) | C21: [KRWm] | D21: =SUM(E21:CL21) | E21: 0 | F21: 0 | G21: 0 | H21: 0 | I21: 0 | J21: 0 | K21: =K18*'입력값'!E59/4 | L21: =L18*'입력값'!E59/4 | M21: =M18*'입력값'!E59/4 | N21: =N18*'입력값'!E59/4 | O21: =O18*'입력값'!E59/4 | P21: =P18*'입력값'!E59/4 | Q21: =Q18*'입력값'!E59/4 | R21: =R18*'입력값'!E59/4 | S21: =S18*'입력값'!E59/4 | T21: =T18*'입력값'!E59/4 | U21: =U18*'입력값'!E59/4 | V21: =V18*'입력값'!E59/4 | W21: =W18*'입력값'!E59/4 | X21: =X18*'입력값'!E59/4 | Y21: =Y18*'입력값'!E59/4 | Z21: =Z18*'입력값'!E59/4 | AA21: =AA18*'입력값'!E59/4 | AB21: =AB18*'입력값'!E59/4 | AC21: =AC18*'입력값'!E59/4 | AD21: =AD18*'입력값'!E59/4 | AE21: =AE18*'입력값'!E59/4 | AF21: =AF18*'입력값'!E59/4 | AG21: =AG18*'입력값'!E59/4 | AH21: =AH18*'입력값'!E59/4 | AI21: =AI18*'입력값'!E59/4 | AJ21: =AJ18*'입력값'!E59/4 | AK21: =AK18*'입력값'!E59/4 | AL21: =AL18*'입력값'!E59/4 | AM21: =AM18*'입력값'!E59/4 | AN21: =AN18*'입력값'!E59/4 | AO21: =AO18*'입력값'!E59/4 | AP21: =AP18*'입력값'!E59/4 | AQ21: =AQ18*'입력값'!E59/4 | AR21: =AR18*'입력값'!E59/4 | AS21: =AS18*'입력값'!E59/4 | AT21: =AT18*'입력값'!E59/4 | AU21: =AU18*'입력값'!E59/4 | AV21: =AV18*'입력값'!E59/4 | AW21: =AW18*'입력값'!E59/4 | AX21: =AX18*'입력값'!E59/4 | AY21: =AY18*'입력값'!E59/4 | AZ21: =AZ18*'입력값'!E59/4 | BA21: =BA18*'입력값'!E59/4 | BB21: =BB18*'입력값'!E59/4 | BC21: =BC18*'입력값'!E59/4 | BD21: =BD18*'입력값'!E59/4 | BE21: =BE18*'입력값'!E59/4 | BF21: =BF18*'입력값'!E59/4 | BG21: =BG18*'입력값'!E59/4 | BH21: =BH18*'입력값'!E59/4 | BI21: =BI18*'입력값'!E59/4 | BJ21: =BJ18*'입력값'!E59/4 | BK21: =BK18*'입력값'!E59/4 | BL21: =BL18*'입력값'!E59/4 | BM21: =BM18*'입력값'!E59/4 | BN21: =BN18*'입력값'!E59/4 | BO21: =BO18*'입력값'!E59/4 | BP21: =BP18*'입력값'!E59/4 | BQ21: =BQ18*'입력값'!E59/4 | BR21: =BR18*'입력값'!E59/4 | BS21: =BS18*'입력값'!E59/4 | BT21: =BT18*'입력값'!E59/4 | BU21: =BU18*'입력값'!E59/4 | BV21: =BV18*'입력값'!E59/4 | BW21: =BW18*'입력값'!E59/4 | BX21: =BX18*'입력값'!E59/4 | BY21: =BY18*'입력값'!E59/4 | BZ21: =BZ18*'입력값'!E59/4 | CA21: =CA18*'입력값'!E59/4 | CB21: =CB18*'입력값'!E59/4 | CC21: =CC18*'입력값'!E59/4 | CD21: =CD18*'입력값'!E59/4 | CE21: =CE18*'입력값'!E59/4 | CF21: =CF18*'입력값'!E59/4 | CG21: =CG18*'입력값'!E59/4 | CH21: =CH18*'입력값'!E59/4 | CI21: =CI18*'입력값'!E59/4 | CJ21: =CJ18*'입력값'!E59/4 | CK21: =CK18*'입력값'!E59/4 | CL21: =CL18*'입력값'!E59/4
B22: 원금상환 | C22: [KRWm] | D22: =SUM(E22:CL22) | E22: 0 | F22: 0 | G22: 0 | H22: 0 | I22: 0 | J22: 0 | K22: 0 | L22: 0 | M22: 0 | N22: ='입력값'!N69*'입력값'!C59*100 | O22: ='입력값'!O69*'입력값'!C59*100 | P22: ='입력값'!P69*'입력값'!C59*100 | Q22: ='입력값'!Q69*'입력값'!C59*100 | R22: ='입력값'!R69*'입력값'!C59*100 | S22: ='입력값'!S69*'입력값'!C59*100 | T22: ='입력값'!T69*'입력값'!C59*100 | U22: ='입력값'!U69*'입력값'!C59*100 | V22: ='입력값'!V69*'입력값'!C59*100 | W22: ='입력값'!W69*'입력값'!C59*100 | X22: ='입력값'!X69*'입력값'!C59*100 | Y22: ='입력값'!Y69*'입력값'!C59*100 | Z22: ='입력값'!Z69*'입력값'!C59*100 | AA22: ='입력값'!AA69*'입력값'!C59*100 | AB22: ='입력값'!AB69*'입력값'!C59*100 | AC22: ='입력값'!AC69*'입력값'!C59*100 | AD22: ='입력값'!AD69*'입력값'!C59*100 | AE22: ='입력값'!AE69*'입력값'!C59*100 | AF22: ='입력값'!AF69*'입력값'!C59*100 | AG22: ='입력값'!AG69*'입력값'!C59*100 | AH22: ='입력값'!AH69*'입력값'!C59*100 | AI22: ='입력값'!AI69*'입력값'!C59*100 | AJ22: ='입력값'!AJ69*'입력값'!C59*100 | AK22: ='입력값'!AK69*'입력값'!C59*100 | AL22: ='입력값'!AL69*'입력값'!C59*100 | AM22: ='입력값'!AM69*'입력값'!C59*100 | AN22: ='입력값'!AN69*'입력값'!C59*100 | AO22: ='입력값'!AO69*'입력값'!C59*100 | AP22: ='입력값'!AP69*'입력값'!C59*100 | AQ22: ='입력값'!AQ69*'입력값'!C59*100 | AR22: ='입력값'!AR69*'입력값'!C59*100 | AS22: ='입력값'!AS69*'입력값'!C59*100 | AT22: ='입력값'!AT69*'입력값'!C59*100 | AU22: ='입력값'!AU69*'입력값'!C59*100 | AV22: ='입력값'!AV69*'입력값'!C59*100 | AW22: ='입력값'!AW69*'입력값'!C59*100 | AX22: ='입력값'!AX69*'입력값'!C59*100 | AY22: ='입력값'!AY69*'입력값'!C59*100 | AZ22: ='입력값'!AZ69*'입력값'!C59*100 | BA22: ='입력값'!BA69*'입력값'!C59*100 | BB22: ='입력값'!BB69*'입력값'!C59*100 | BC22: ='입력값'!BC69*'입력값'!C59*100 | BD22: ='입력값'!BD69*'입력값'!C59*100 | BE22: ='입력값'!BE69*'입력값'!C59*100 | BF22: ='입력값'!BF69*'입력값'!C59*100 | BG22: ='입력값'!BG69*'입력값'!C59*100 | BH22: ='입력값'!BH69*'입력값'!C59*100 | BI22: ='입력값'!BI69*'입력값'!C59*100 | BJ22: ='입력값'!BJ69*'입력값'!C59*100 | BK22: ='입력값'!BK69*'입력값'!C59*100 | BL22: ='입력값'!BL69*'입력값'!C59*100 | BM22: ='입력값'!BM69*'입력값'!C59*100 | BN22: ='입력값'!BN69*'입력값'!C59*100 | BO22: ='입력값'!BO69*'입력값'!C59*100 | BP22: ='입력값'!BP69*'입력값'!C59*100 | BQ22: ='입력값'!BQ69*'입력값'!C59*100 | BR22: ='입력값'!BR69*'입력값'!C59*100 | BS22: ='입력값'!BS69*'입력값'!C59*100 | BT22: ='입력값'!BT69*'입력값'!C59*100 | BU22: ='입력값'!BU69*'입력값'!C59*100 | BV22: ='입력값'!BV69*'입력값'!C59*100 | BW22: ='입력값'!BW69*'입력값'!C59*100 | BX22: ='입력값'!BX69*'입력값'!C59*100 | BY22: ='입력값'!BY69*'입력값'!C59*100 | BZ22: 0 | CA22: 0 | CB22: 0 | CC22: 0 | CD22: 0 | CE22: 0 | CF22: 0 | CG22: 0 | CH22: 0 | CI22: 0 | CJ22: 0 | CK22: 0 | CL22: 0
B23: 기말잔액 | C23: [KRWm] | E23: =E18+E19-E22 | F23: =F18+F19-F22 | G23: =G18+G19-G22 | H23: =H18+H19-H22 | I23: =I18+I19-I22 | J23: =J18+J19-J22 | K23: =K18+K19-K22 | L23: =L18+L19-L22 | ... CL23: =CL18+CL19-CL22
B24: 미상환 잔액(검증용) | C24: [KRWm] | D24: =CL23 | F24: =IF(ABS(D24)<1,"완전상환 확인 (OK)","경고: 미상환 잔액") | H24: ※ 방식 3(직접 키인) — 원금상환은 "입력값" 시트의 상환비율 표를 참조하는 수식
B26: 선순위C
B27: 기초잔액 | C27: [KRWm] | E27: 0 | F27: =E32 | G27: =F32 | H27: =G32 | I27: =H32 | J27: =I32 | K27: =J32 | L27: =K32 | M27: =L32 | ... CL27: =CK32
B28: 인출 | C28: [KRWm] | D28: =SUM(E28:CL28) | E28: 0 | F28: 0 | G28: 0 | H28: 0 | I28: 1261.0874 | J28: 33738.912 | K28: 0 | L28: 0 | M28: 0 | N28: 0 | O28: 0 | P28: 0 | Q28: 0 | R28: 0 | S28: 0 | T28: 0 | U28: 0 | V28: 0 | W28: 0 | X28: 0 | Y28: 0 | Z28: 0 | AA28: 0 | AB28: 0 | AC28: 0 | AD28: 0 | AE28: 0 | AF28: 0 | AG28: 0 | AH28: 0 | AI28: 0 | AJ28: 0 | AK28: 0 | AL28: 0 | AM28: 0 | AN28: 0 | AO28: 0 | AP28: 0 | AQ28: 0 | AR28: 0 | AS28: 0 | AT28: 0 | AU28: 0 | AV28: 0 | AW28: 0 | AX28: 0 | AY28: 0 | AZ28: 0 | BA28: 0 | BB28: 0 | BC28: 0 | BD28: 0 | BE28: 0 | BF28: 0 | BG28: 0 | BH28: 0 | BI28: 0 | BJ28: 0 | BK28: 0 | BL28: 0 | BM28: 0 | BN28: 0 | BO28: 0 | BP28: 0 | BQ28: 0 | BR28: 0 | BS28: 0 | BT28: 0 | BU28: 0 | BV28: 0 | BW28: 0 | BX28: 0 | BY28: 0 | BZ28: 0 | CA28: 0 | CB28: 0 | CC28: 0 | CD28: 0 | CE28: 0 | CF28: 0 | CG28: 0 | CH28: 0 | CI28: 0 | CJ28: 0 | CK28: 0 | CL28: 0
B29: 건설이자(IDC) | C29: [KRWm] | D29: =SUM(E29:CL29) | E29: 0 | F29: 0 | G29: 0 | H29: 0 | I29: 0 | J29: 17.339952 | K29: 0 | L29: 0 | M29: 0 | N29: 0 | O29: 0 | P29: 0 | Q29: 0 | R29: 0 | S29: 0 | T29: 0 | U29: 0 | V29: 0 | W29: 0 | X29: 0 | Y29: 0 | Z29: 0 | AA29: 0 | AB29: 0 | AC29: 0 | AD29: 0 | AE29: 0 | AF29: 0 | AG29: 0 | AH29: 0 | AI29: 0 | AJ29: 0 | AK29: 0 | AL29: 0 | AM29: 0 | AN29: 0 | AO29: 0 | AP29: 0 | AQ29: 0 | AR29: 0 | AS29: 0 | AT29: 0 | AU29: 0 | AV29: 0 | AW29: 0 | AX29: 0 | AY29: 0 | AZ29: 0 | BA29: 0 | BB29: 0 | BC29: 0 | BD29: 0 | BE29: 0 | BF29: 0 | BG29: 0 | BH29: 0 | BI29: 0 | BJ29: 0 | BK29: 0 | BL29: 0 | BM29: 0 | BN29: 0 | BO29: 0 | BP29: 0 | BQ29: 0 | BR29: 0 | BS29: 0 | BT29: 0 | BU29: 0 | BV29: 0 | BW29: 0 | BX29: 0 | BY29: 0 | BZ29: 0 | CA29: 0 | CB29: 0 | CC29: 0 | CD29: 0 | CE29: 0 | CF29: 0 | CG29: 0 | CH29: 0 | CI29: 0 | CJ29: 0 | CK29: 0 | CL29: 0
B30: 이자(운영) | C30: [KRWm] | D30: =SUM(E30:CL30) | E30: 0 | F30: 0 | G30: 0 | H30: 0 | I30: 0 | J30: 0 | K30: =K27*'입력값'!E60/4 | L30: =L27*'입력값'!E60/4 | M30: =M27*'입력값'!E60/4 | N30: =N27*'입력값'!E60/4 | O30: =O27*'입력값'!E60/4 | P30: =P27*'입력값'!E60/4 | Q30: =Q27*'입력값'!E60/4 | R30: =R27*'입력값'!E60/4 | S30: =S27*'입력값'!E60/4 | T30: =T27*'입력값'!E60/4 | U30: =U27*'입력값'!E60/4 | V30: =V27*'입력값'!E60/4 | W30: =W27*'입력값'!E60/4 | X30: =X27*'입력값'!E60/4 | Y30: =Y27*'입력값'!E60/4 | Z30: =Z27*'입력값'!E60/4 | AA30: =AA27*'입력값'!E60/4 | AB30: =AB27*'입력값'!E60/4 | AC30: =AC27*'입력값'!E60/4 | AD30: =AD27*'입력값'!E60/4 | AE30: =AE27*'입력값'!E60/4 | AF30: =AF27*'입력값'!E60/4 | AG30: =AG27*'입력값'!E60/4 | AH30: =AH27*'입력값'!E60/4 | AI30: =AI27*'입력값'!E60/4 | AJ30: =AJ27*'입력값'!E60/4 | AK30: =AK27*'입력값'!E60/4 | AL30: =AL27*'입력값'!E60/4 | AM30: =AM27*'입력값'!E60/4 | AN30: =AN27*'입력값'!E60/4 | AO30: =AO27*'입력값'!E60/4 | AP30: =AP27*'입력값'!E60/4 | AQ30: =AQ27*'입력값'!E60/4 | AR30: =AR27*'입력값'!E60/4 | AS30: =AS27*'입력값'!E60/4 | AT30: =AT27*'입력값'!E60/4 | AU30: =AU27*'입력값'!E60/4 | AV30: =AV27*'입력값'!E60/4 | AW30: =AW27*'입력값'!E60/4 | AX30: =AX27*'입력값'!E60/4 | AY30: =AY27*'입력값'!E60/4 | AZ30: =AZ27*'입력값'!E60/4 | BA30: =BA27*'입력값'!E60/4 | BB30: =BB27*'입력값'!E60/4 | BC30: =BC27*'입력값'!E60/4 | BD30: =BD27*'입력값'!E60/4 | BE30: =BE27*'입력값'!E60/4 | BF30: =BF27*'입력값'!E60/4 | BG30: =BG27*'입력값'!E60/4 | BH30: =BH27*'입력값'!E60/4 | BI30: =BI27*'입력값'!E60/4 | BJ30: =BJ27*'입력값'!E60/4 | BK30: =BK27*'입력값'!E60/4 | BL30: =BL27*'입력값'!E60/4 | BM30: =BM27*'입력값'!E60/4 | BN30: =BN27*'입력값'!E60/4 | BO30: =BO27*'입력값'!E60/4 | BP30: =BP27*'입력값'!E60/4 | BQ30: =BQ27*'입력값'!E60/4 | BR30: =BR27*'입력값'!E60/4 | BS30: =BS27*'입력값'!E60/4 | BT30: =BT27*'입력값'!E60/4 | BU30: =BU27*'입력값'!E60/4 | BV30: =BV27*'입력값'!E60/4 | BW30: =BW27*'입력값'!E60/4 | BX30: =BX27*'입력값'!E60/4 | BY30: =BY27*'입력값'!E60/4 | BZ30: =BZ27*'입력값'!E60/4 | CA30: =CA27*'입력값'!E60/4 | CB30: =CB27*'입력값'!E60/4 | CC30: =CC27*'입력값'!E60/4 | CD30: =CD27*'입력값'!E60/4 | CE30: =CE27*'입력값'!E60/4 | CF30: =CF27*'입력값'!E60/4 | CG30: =CG27*'입력값'!E60/4 | CH30: =CH27*'입력값'!E60/4 | CI30: =CI27*'입력값'!E60/4 | CJ30: =CJ27*'입력값'!E60/4 | CK30: =CK27*'입력값'!E60/4 | CL30: =CL27*'입력값'!E60/4
B31: 원금상환 | C31: [KRWm] | D31: =SUM(E31:CL31) | E31: 0 | F31: 0 | G31: 0 | H31: 0 | I31: 0 | J31: 0 | K31: 0 | L31: 0 | M31: 0 | N31: ='입력값'!N70*'입력값'!C60*100 | O31: ='입력값'!O70*'입력값'!C60*100 | P31: ='입력값'!P70*'입력값'!C60*100 | Q31: ='입력값'!Q70*'입력값'!C60*100 | R31: ='입력값'!R70*'입력값'!C60*100 | S31: ='입력값'!S70*'입력값'!C60*100 | T31: ='입력값'!T70*'입력값'!C60*100 | U31: ='입력값'!U70*'입력값'!C60*100 | V31: ='입력값'!V70*'입력값'!C60*100 | W31: ='입력값'!W70*'입력값'!C60*100 | X31: ='입력값'!X70*'입력값'!C60*100 | Y31: ='입력값'!Y70*'입력값'!C60*100 | Z31: ='입력값'!Z70*'입력값'!C60*100 | AA31: ='입력값'!AA70*'입력값'!C60*100 | AB31: ='입력값'!AB70*'입력값'!C60*100 | AC31: ='입력값'!AC70*'입력값'!C60*100 | AD31: ='입력값'!AD70*'입력값'!C60*100 | AE31: ='입력값'!AE70*'입력값'!C60*100 | AF31: ='입력값'!AF70*'입력값'!C60*100 | AG31: ='입력값'!AG70*'입력값'!C60*100 | AH31: ='입력값'!AH70*'입력값'!C60*100 | AI31: ='입력값'!AI70*'입력값'!C60*100 | AJ31: ='입력값'!AJ70*'입력값'!C60*100 | AK31: ='입력값'!AK70*'입력값'!C60*100 | AL31: ='입력값'!AL70*'입력값'!C60*100 | AM31: ='입력값'!AM70*'입력값'!C60*100 | AN31: ='입력값'!AN70*'입력값'!C60*100 | AO31: ='입력값'!AO70*'입력값'!C60*100 | AP31: ='입력값'!AP70*'입력값'!C60*100 | AQ31: ='입력값'!AQ70*'입력값'!C60*100 | AR31: ='입력값'!AR70*'입력값'!C60*100 | AS31: ='입력값'!AS70*'입력값'!C60*100 | AT31: ='입력값'!AT70*'입력값'!C60*100 | AU31: ='입력값'!AU70*'입력값'!C60*100 | AV31: ='입력값'!AV70*'입력값'!C60*100 | AW31: ='입력값'!AW70*'입력값'!C60*100 | AX31: ='입력값'!AX70*'입력값'!C60*100 | AY31: ='입력값'!AY70*'입력값'!C60*100 | AZ31: ='입력값'!AZ70*'입력값'!C60*100 | BA31: ='입력값'!BA70*'입력값'!C60*100 | BB31: ='입력값'!BB70*'입력값'!C60*100 | BC31: ='입력값'!BC70*'입력값'!C60*100 | BD31: ='입력값'!BD70*'입력값'!C60*100 | BE31: ='입력값'!BE70*'입력값'!C60*100 | BF31: ='입력값'!BF70*'입력값'!C60*100 | BG31: ='입력값'!BG70*'입력값'!C60*100 | BH31: ='입력값'!BH70*'입력값'!C60*100 | BI31: ='입력값'!BI70*'입력값'!C60*100 | BJ31: ='입력값'!BJ70*'입력값'!C60*100 | BK31: ='입력값'!BK70*'입력값'!C60*100 | BL31: ='입력값'!BL70*'입력값'!C60*100 | BM31: ='입력값'!BM70*'입력값'!C60*100 | BN31: ='입력값'!BN70*'입력값'!C60*100 | BO31: ='입력값'!BO70*'입력값'!C60*100 | BP31: ='입력값'!BP70*'입력값'!C60*100 | BQ31: ='입력값'!BQ70*'입력값'!C60*100 | BR31: ='입력값'!BR70*'입력값'!C60*100 | BS31: ='입력값'!BS70*'입력값'!C60*100 | BT31: ='입력값'!BT70*'입력값'!C60*100 | BU31: ='입력값'!BU70*'입력값'!C60*100 | BV31: ='입력값'!BV70*'입력값'!C60*100 | BW31: ='입력값'!BW70*'입력값'!C60*100 | BX31: ='입력값'!BX70*'입력값'!C60*100 | BY31: ='입력값'!BY70*'입력값'!C60*100 | BZ31: 0 | CA31: 0 | CB31: 0 | CC31: 0 | CD31: 0 | CE31: 0 | CF31: 0 | CG31: 0 | CH31: 0 | CI31: 0 | CJ31: 0 | CK31: 0 | CL31: 0
B32: 기말잔액 | C32: [KRWm] | E32: =E27+E28-E31 | F32: =F27+F28-F31 | G32: =G27+G28-G31 | H32: =H27+H28-H31 | I32: =I27+I28-I31 | J32: =J27+J28-J31 | K32: =K27+K28-K31 | L32: =L27+L28-L31 | ... CL32: =CL27+CL28-CL31
B33: 미상환 잔액(검증용) | C33: [KRWm] | D33: =CL32 | F33: =IF(ABS(D33)<1,"완전상환 확인 (OK)","경고: 미상환 잔액") | H33: ※ 방식 3(직접 키인) — 원금상환은 "입력값" 시트의 상환비율 표를 참조하는 수식
B35: 선순위D
B36: 기초잔액 | C36: [KRWm] | E36: 0 | F36: =E41 | G36: =F41 | H36: =G41 | I36: =H41 | J36: =I41 | K36: =J41 | L36: =K41 | M36: =L41 | ... CL36: =CK41
B37: 인출 | C37: [KRWm] | D37: =SUM(E37:CL37) | E37: 0 | F37: 0 | G37: 0 | H37: 0 | I37: 0 | J37: 0 | K37: 0 | L37: 0 | M37: 0 | N37: 0 | O37: 0 | P37: 0 | Q37: 0 | R37: 0 | S37: 0 | T37: 0 | U37: 0 | V37: 0 | W37: 0 | X37: 0 | Y37: 0 | Z37: 0 | AA37: 0 | AB37: 0 | AC37: 0 | AD37: 0 | AE37: 0 | AF37: 0 | AG37: 0 | AH37: 0 | AI37: 0 | AJ37: 0 | AK37: 0 | AL37: 0 | AM37: 0 | AN37: 0 | AO37: 0 | AP37: 0 | AQ37: 0 | AR37: 0 | AS37: 0 | AT37: 0 | AU37: 0 | AV37: 0 | AW37: 0 | AX37: 0 | AY37: 0 | AZ37: 0 | BA37: 0 | BB37: 0 | BC37: 0 | BD37: 0 | BE37: 0 | BF37: 0 | BG37: 0 | BH37: 0 | BI37: 0 | BJ37: 0 | BK37: 0 | BL37: 0 | BM37: 0 | BN37: 0 | BO37: 0 | BP37: 0 | BQ37: 0 | BR37: 0 | BS37: 0 | BT37: 0 | BU37: 0 | BV37: 0 | BW37: 0 | BX37: 0 | BY37: 0 | BZ37: 0 | CA37: 0 | CB37: 0 | CC37: 0 | CD37: 0 | CE37: 0 | CF37: 0 | CG37: 0 | CH37: 0 | CI37: 0 | CJ37: 0 | CK37: 0 | CL37: 0
B38: 건설이자(IDC) | C38: [KRWm] | D38: =SUM(E38:CL38) | E38: 0 | F38: 0 | G38: 0 | H38: 0 | I38: 0 | J38: 0 | K38: 0 | L38: 0 | M38: 0 | N38: 0 | O38: 0 | P38: 0 | Q38: 0 | R38: 0 | S38: 0 | T38: 0 | U38: 0 | V38: 0 | W38: 0 | X38: 0 | Y38: 0 | Z38: 0 | AA38: 0 | AB38: 0 | AC38: 0 | AD38: 0 | AE38: 0 | AF38: 0 | AG38: 0 | AH38: 0 | AI38: 0 | AJ38: 0 | AK38: 0 | AL38: 0 | AM38: 0 | AN38: 0 | AO38: 0 | AP38: 0 | AQ38: 0 | AR38: 0 | AS38: 0 | AT38: 0 | AU38: 0 | AV38: 0 | AW38: 0 | AX38: 0 | AY38: 0 | AZ38: 0 | BA38: 0 | BB38: 0 | BC38: 0 | BD38: 0 | BE38: 0 | BF38: 0 | BG38: 0 | BH38: 0 | BI38: 0 | BJ38: 0 | BK38: 0 | BL38: 0 | BM38: 0 | BN38: 0 | BO38: 0 | BP38: 0 | BQ38: 0 | BR38: 0 | BS38: 0 | BT38: 0 | BU38: 0 | BV38: 0 | BW38: 0 | BX38: 0 | BY38: 0 | BZ38: 0 | CA38: 0 | CB38: 0 | CC38: 0 | CD38: 0 | CE38: 0 | CF38: 0 | CG38: 0 | CH38: 0 | CI38: 0 | CJ38: 0 | CK38: 0 | CL38: 0
B39: 이자(운영) | C39: [KRWm] | D39: =SUM(E39:CL39) | E39: 0 | F39: 0 | G39: 0 | H39: 0 | I39: 0 | J39: 0 | K39: =K36*'입력값'!E61/4 | L39: =L36*'입력값'!E61/4 | M39: =M36*'입력값'!E61/4 | N39: =N36*'입력값'!E61/4 | O39: =O36*'입력값'!E61/4 | P39: =P36*'입력값'!E61/4 | Q39: =Q36*'입력값'!E61/4 | R39: =R36*'입력값'!E61/4 | S39: =S36*'입력값'!E61/4 | T39: =T36*'입력값'!E61/4 | U39: =U36*'입력값'!E61/4 | V39: =V36*'입력값'!E61/4 | W39: =W36*'입력값'!E61/4 | X39: =X36*'입력값'!E61/4 | Y39: =Y36*'입력값'!E61/4 | Z39: =Z36*'입력값'!E61/4 | AA39: =AA36*'입력값'!E61/4 | AB39: =AB36*'입력값'!E61/4 | AC39: =AC36*'입력값'!E61/4 | AD39: =AD36*'입력값'!E61/4 | AE39: =AE36*'입력값'!E61/4 | AF39: =AF36*'입력값'!E61/4 | AG39: =AG36*'입력값'!E61/4 | AH39: =AH36*'입력값'!E61/4 | AI39: =AI36*'입력값'!E61/4 | AJ39: =AJ36*'입력값'!E61/4 | AK39: =AK36*'입력값'!E61/4 | AL39: =AL36*'입력값'!E61/4 | AM39: =AM36*'입력값'!E61/4 | AN39: =AN36*'입력값'!E61/4 | AO39: =AO36*'입력값'!E61/4 | AP39: =AP36*'입력값'!E61/4 | AQ39: =AQ36*'입력값'!E61/4 | AR39: =AR36*'입력값'!E61/4 | AS39: =AS36*'입력값'!E61/4 | AT39: =AT36*'입력값'!E61/4 | AU39: =AU36*'입력값'!E61/4 | AV39: =AV36*'입력값'!E61/4 | AW39: =AW36*'입력값'!E61/4 | AX39: =AX36*'입력값'!E61/4 | AY39: =AY36*'입력값'!E61/4 | AZ39: =AZ36*'입력값'!E61/4 | BA39: =BA36*'입력값'!E61/4 | BB39: =BB36*'입력값'!E61/4 | BC39: =BC36*'입력값'!E61/4 | BD39: =BD36*'입력값'!E61/4 | BE39: =BE36*'입력값'!E61/4 | BF39: =BF36*'입력값'!E61/4 | BG39: =BG36*'입력값'!E61/4 | BH39: =BH36*'입력값'!E61/4 | BI39: =BI36*'입력값'!E61/4 | BJ39: =BJ36*'입력값'!E61/4 | BK39: =BK36*'입력값'!E61/4 | BL39: =BL36*'입력값'!E61/4 | BM39: =BM36*'입력값'!E61/4 | BN39: =BN36*'입력값'!E61/4 | BO39: =BO36*'입력값'!E61/4 | BP39: =BP36*'입력값'!E61/4 | BQ39: =BQ36*'입력값'!E61/4 | BR39: =BR36*'입력값'!E61/4 | BS39: =BS36*'입력값'!E61/4 | BT39: =BT36*'입력값'!E61/4 | BU39: =BU36*'입력값'!E61/4 | BV39: =BV36*'입력값'!E61/4 | BW39: =BW36*'입력값'!E61/4 | BX39: =BX36*'입력값'!E61/4 | BY39: =BY36*'입력값'!E61/4 | BZ39: =BZ36*'입력값'!E61/4 | CA39: =CA36*'입력값'!E61/4 | CB39: =CB36*'입력값'!E61/4 | CC39: =CC36*'입력값'!E61/4 | CD39: =CD36*'입력값'!E61/4 | CE39: =CE36*'입력값'!E61/4 | CF39: =CF36*'입력값'!E61/4 | CG39: =CG36*'입력값'!E61/4 | CH39: =CH36*'입력값'!E61/4 | CI39: =CI36*'입력값'!E61/4 | CJ39: =CJ36*'입력값'!E61/4 | CK39: =CK36*'입력값'!E61/4 | CL39: =CL36*'입력값'!E61/4
B40: 원금상환 | C40: [KRWm] | D40: =SUM(E40:CL40) | E40: 0 | F40: 0 | G40: 0 | H40: 0 | I40: 0 | J40: 0 | K40: 0 | L40: 0 | M40: 0 | N40: 0 | O40: 0 | P40: 0 | Q40: 0 | R40: 0 | S40: 0 | T40: 0 | U40: 0 | V40: 0 | W40: 0 | X40: 0 | Y40: 0 | Z40: 0 | AA40: 0 | AB40: 0 | AC40: 0 | AD40: 0 | AE40: 0 | AF40: 0 | AG40: 0 | AH40: 0 | AI40: 0 | AJ40: 0 | AK40: 0 | AL40: 0 | AM40: 0 | AN40: 0 | AO40: 0 | AP40: 0 | AQ40: 0 | AR40: 0 | AS40: 0 | AT40: 0 | AU40: 0 | AV40: 0 | AW40: 0 | AX40: 0 | AY40: 0 | AZ40: 0 | BA40: 0 | BB40: 0 | BC40: 0 | BD40: 0 | BE40: 0 | BF40: 0 | BG40: 0 | BH40: 0 | BI40: 0 | BJ40: 0 | BK40: 0 | BL40: 0 | BM40: 0 | BN40: 0 | BO40: 0 | BP40: 0 | BQ40: 0 | BR40: 0 | BS40: 0 | BT40: 0 | BU40: 0 | BV40: 0 | BW40: 0 | BX40: 0 | BY40: 0 | BZ40: 0 | CA40: 0 | CB40: 0 | CC40: 0 | CD40: 0 | CE40: 0 | CF40: 0 | CG40: 0 | CH40: 0 | CI40: 0 | CJ40: 0 | CK40: 0 | CL40: 0
B41: 기말잔액 | C41: [KRWm] | E41: =E36+E37-E40 | F41: =F36+F37-F40 | G41: =G36+G37-G40 | H41: =H36+H37-H40 | I41: =I36+I37-I40 | J41: =J36+J37-J40 | K41: =K36+K37-K40 | L41: =L36+L37-L40 | ... CL41: =CL36+CL37-CL40
B42: 미상환 잔액(검증용) | C42: [KRWm] | D42: =CL41 | F42: =IF(ABS(D42)<1,"완전상환 확인 (OK)","경고: 미상환 잔액") | H42: ※ 미사용 트랜치 — 값(baked) 기준
B44: 후순위
B45: 기초잔액 | C45: [KRWm] | E45: 0 | F45: =E50 | G45: =F50 | H45: =G50 | I45: =H50 | J45: =I50 | K45: =J50 | L45: =K50 | M45: =L50 | ... CL45: =CK50
B46: 인출 | C46: [KRWm] | D46: =SUM(E46:CL46) | E46: 0 | F46: 0 | G46: 0 | H46: 0 | I46: 0 | J46: 0 | K46: 0 | L46: 0 | M46: 0 | N46: 0 | O46: 0 | P46: 0 | Q46: 0 | R46: 0 | S46: 0 | T46: 0 | U46: 0 | V46: 0 | W46: 0 | X46: 0 | Y46: 0 | Z46: 0 | AA46: 0 | AB46: 0 | AC46: 0 | AD46: 0 | AE46: 0 | AF46: 0 | AG46: 0 | AH46: 0 | AI46: 0 | AJ46: 0 | AK46: 0 | AL46: 0 | AM46: 0 | AN46: 0 | AO46: 0 | AP46: 0 | AQ46: 0 | AR46: 0 | AS46: 0 | AT46: 0 | AU46: 0 | AV46: 0 | AW46: 0 | AX46: 0 | AY46: 0 | AZ46: 0 | BA46: 0 | BB46: 0 | BC46: 0 | BD46: 0 | BE46: 0 | BF46: 0 | BG46: 0 | BH46: 0 | BI46: 0 | BJ46: 0 | BK46: 0 | BL46: 0 | BM46: 0 | BN46: 0 | BO46: 0 | BP46: 0 | BQ46: 0 | BR46: 0 | BS46: 0 | BT46: 0 | BU46: 0 | BV46: 0 | BW46: 0 | BX46: 0 | BY46: 0 | BZ46: 0 | CA46: 0 | CB46: 0 | CC46: 0 | CD46: 0 | CE46: 0 | CF46: 0 | CG46: 0 | CH46: 0 | CI46: 0 | CJ46: 0 | CK46: 0 | CL46: 0
B47: 건설이자(IDC) | C47: [KRWm] | D47: =SUM(E47:CL47) | E47: 0 | F47: 0 | G47: 0 | H47: 0 | I47: 0 | J47: 0 | K47: 0 | L47: 0 | M47: 0 | N47: 0 | O47: 0 | P47: 0 | Q47: 0 | R47: 0 | S47: 0 | T47: 0 | U47: 0 | V47: 0 | W47: 0 | X47: 0 | Y47: 0 | Z47: 0 | AA47: 0 | AB47: 0 | AC47: 0 | AD47: 0 | AE47: 0 | AF47: 0 | AG47: 0 | AH47: 0 | AI47: 0 | AJ47: 0 | AK47: 0 | AL47: 0 | AM47: 0 | AN47: 0 | AO47: 0 | AP47: 0 | AQ47: 0 | AR47: 0 | AS47: 0 | AT47: 0 | AU47: 0 | AV47: 0 | AW47: 0 | AX47: 0 | AY47: 0 | AZ47: 0 | BA47: 0 | BB47: 0 | BC47: 0 | BD47: 0 | BE47: 0 | BF47: 0 | BG47: 0 | BH47: 0 | BI47: 0 | BJ47: 0 | BK47: 0 | BL47: 0 | BM47: 0 | BN47: 0 | BO47: 0 | BP47: 0 | BQ47: 0 | BR47: 0 | BS47: 0 | BT47: 0 | BU47: 0 | BV47: 0 | BW47: 0 | BX47: 0 | BY47: 0 | BZ47: 0 | CA47: 0 | CB47: 0 | CC47: 0 | CD47: 0 | CE47: 0 | CF47: 0 | CG47: 0 | CH47: 0 | CI47: 0 | CJ47: 0 | CK47: 0 | CL47: 0
...

Sheet Revenue
A1: 당진 태양광발전
A2: 영업수익 추정
B4: 발전량 및 매출
B6: 구 분 | C6: unit | D6: 합 계 | E6: 2024-06-30 | F6: 2024-09-30 | G6: 2024-12-31 | H6: 2025-03-31 | I6: 2025-06-30 | J6: 2025-09-30 | K6: 2025-12-31 | L6: 2026-03-31 | M6: 2026-06-30 | N6: 2026-09-30 | O6: 2026-12-31 | P6: 2027-03-31 | Q6: 2027-06-30 | R6: 2027-09-30 | S6: 2027-12-31 | T6: 2028-03-31 | U6: 2028-06-30 | V6: 2028-09-30 | W6: 2028-12-31 | X6: 2029-03-31 | Y6: 2029-06-30 | Z6: 2029-09-30 | AA6: 2029-12-31 | AB6: 2030-03-31 | AC6: 2030-06-30 | AD6: 2030-09-30 | AE6: 2030-12-31 | AF6: 2031-03-31 | AG6: 2031-06-30 | AH6: 2031-09-30 | AI6: 2031-12-31 | AJ6: 2032-03-31 | AK6: 2032-06-30 | AL6: 2032-09-30 | AM6: 2032-12-31 | AN6: 2033-03-31 | AO6: 2033-06-30 | AP6: 2033-09-30 | AQ6: 2033-12-31 | AR6: 2034-03-31 | AS6: 2034-06-30 | AT6: 2034-09-30 | AU6: 2034-12-31 | AV6: 2035-03-31 | AW6: 2035-06-30 | AX6: 2035-09-30 | AY6: 2035-12-31 | AZ6: 2036-03-31 | BA6: 2036-06-30 | BB6: 2036-09-30 | BC6: 2036-12-31 | BD6: 2037-03-31 | BE6: 2037-06-30 | BF6: 2037-09-30 | BG6: 2037-12-31 | BH6: 2038-03-31 | BI6: 2038-06-30 | BJ6: 2038-09-30 | BK6: 2038-12-31 | BL6: 2039-03-31 | BM6: 2039-06-30 | BN6: 2039-09-30 | BO6: 2039-12-31 | BP6: 2040-03-31 | BQ6: 2040-06-30 | BR6: 2040-09-30 | BS6: 2040-12-31 | BT6: 2041-03-31 | BU6: 2041-06-30 | BV6: 2041-09-30 | BW6: 2041-12-31 | BX6: 2042-03-31 | BY6: 2042-06-30 | BZ6: 2042-09-30 | CA6: 2042-12-31 | CB6: 2043-03-31 | CC6: 2043-06-30 | CD6: 2043-09-30 | CE6: 2043-12-31 | CF6: 2044-03-31 | CG6: 2044-06-30 | CH6: 2044-09-30 | CI6: 2044-12-31 | CJ6: 2045-03-31 | CK6: 2045-06-30 | CL6: 2045-09-30
B9: 발전량 | C9: [MWh] | D9: =SUM(E9:CL9) | E9: =('입력값'!C7*'입력값'!C14*365)*MAX(0,1-'입력값'!C12/100*0)*(1-'입력값'!C13/100)*0 | F9: =('입력값'!C7*'입력값'!C14*365)*MAX(0,1-'입력값'!C12/100*0)*(1-'입력값'!C13/100)*0 | G9: =('입력값'!C7*'입력값'!C14*365)*MAX(0,1-'입력값'!C12/100*0)*(1-'입력값'!C13/100)*0 | H9: =('입력값'!C7*'입력값'!C14*365)*MAX(0,1-'입력값'!C12/100*0)*(1-'입력값'!C13/100)*0 | I9: =('입력값'!C7*'입력값'!C14*365)*MAX(0,1-'입력값'!C12/100*0)*(1-'입력값'!C13/100)*0 | J9: =('입력값'!C7*'입력값'!C14*365)*MAX(0,1-'입력값'!C12/100*0)*(1-'입력값'!C13/100)*0 | K9: =('입력값'!C7*'입력값'!C14*365)*MAX(0,1-'입력값'!C12/100*0)*(1-'입력값'!C13/100)*0.2347 | L9: =('입력값'!C7*'입력값'!C14*365)*MAX(0,1-'입력값'!C12/100*0)*(1-'입력값'!C13/100)*0.2397 | M9: =('입력값'!C7*'입력값'!C14*365)*MAX(0,1-'입력값'!C12/100*0)*(1-'입력값'!C13/100)*0.3057 | N9: =('입력값'!C7*'입력값'!C14*365)*MAX(0,1-'입력값'!C12/100*0)*(1-'입력값'!C13/100)*0.2199 | O9: =('입력값'!C7*'입력값'!C14*365)*MAX(0,1-'입력값'!C12/100*1)*(1-'입력값'!C13/100)*0.2347 | P9: =('입력값'!C7*'입력값'!C14*365)*MAX(0,1-'입력값'!C12/100*1)*(1-'입력값'!C13/100)*0.2397 | Q9: =('입력값'!C7*'입력값'!C14*365)*MAX(0,1-'입력값'!C12/100*1)*(1-'입력값'!C13/100)*0.3057 | R9: =('입력값'!C7*'입력값'!C14*365)*MAX(0,1-'입력값'!C12/100*1)*(1-'입력값'!C13/100)*0.2199 | S9: =('입력값'!C7*'입력값'!C14*365)*MAX(0,1-'입력값'!C12/100*2)*(1-'입력값'!C13/100)*0.2347 | T9: =('입력값'!C7*'입력값'!C14*365)*MAX(0,1-'입력값'!C12/100*2)*(1-'입력값'!C13/100)*0.2397 | U9: =('입력값'!C7*'입력값'!C14*365)*MAX(0,1-'입력값'!C12/100*2)*(1-'입력값'!C13/100)*0.3057 | V9: =('입력값'!C7*'입력값'!C14*365)*MAX(0,1-'입력값'!C12/100*2)*(1-'입력값'!C13/100)*0.2199 | W9: =('입력값'!C7*'입력값'!C14*365)*MAX(0,1-'입력값'!C12/100*3)*(1-'입력값'!C13/100)*0.2347 | X9: =('입력값'!C7*'입력값'!C14*365)*MAX(0,1-'입력값'!C12/100*3)*(1-'입력값'!C13/100)*0.2397 | Y9: =('입력값'!C7*'입력값'!C14*365)*MAX(0,1-'입력값'!C12/100*3)*(1-'입력값'!C13/100)*0.3057 | Z9: =('입력값'!C7*'입력값'!C14*365)*MAX(0,1-'입력값'!C12/100*3)*(1-'입력값'!C13/100)*0.2199 | AA9: =('입력값'!C7*'입력값'!C14*365)*MAX(0,1-'입력값'!C12/100*4)*(1-'입력값'!C13/100)*0.2347 | AB9: =('입력값'!C7*'입력값'!C14*365)*MAX(0,1-'입력값'!C12/100*4)*(1-'입력값'!C13/100)*0.2397 | AC9: =('입력값'!C7*'입력값'!C14*365)*MAX(0,1-'입력값'!C12/100*4)*(1-'입력값'!C13/100)*0.3057 | AD9: =('입력값'!C7*'입력값'!C14*365)*MAX(0,1-'입력값'!C12/100*4)*(1-'입력값'!C13/100)*0.2199 | AE9: =('입력값'!C7*'입력값'!C14*365)*MAX(0,1-'입력값'!C12/100*5)*(1-'입력값'!C13/100)*0.2347 | AF9: =('입력값'!C7*'입력값'!C14*365)*MAX(0,1-'입력값'!C12/100*5)*(1-'입력값'!C13/100)*0.2397 | AG9: =('입력값'!C7*'입력값'!C14*365)*MAX(0,1-'입력값'!C12/100*5)*(1-'입력값'!C13/100)*0.3057 | AH9: =('입력값'!C7*'입력값'!C14*365)*MAX(0,1-'입력값'!C12/100*5)*(1-'입력값'!C13/100)*0.2199 | AI9: =('입력값'!C7*'입력값'!C14*365)*MAX(0,1-'입력값'!C12/100*6)*(1-'입력값'!C13/100)*0.2347 | AJ9: =('입력값'!C7*'입력값'!C14*365)*MAX(0,1-'입력값'!C12/100*6)*(1-'입력값'!C13/100)*0.2397 | AK9: =('입력값'!C7*'입력값'!C14*365)*MAX(0,1-'입력값'!C12/100*6)*(1-'입력값'!C13/100)*0.3057 | AL9: =('입력값'!C7*'입력값'!C14*365)*MAX(0,1-'입력값'!C12/100*6)*(1-'입력값'!C13/100)*0.2199 | AM9: =('입력값'!C7*'입력값'!C14*365)*MAX(0,1-'입력값'!C12/100*7)*(1-'입력값'!C13/100)*0.2347 | AN9: =('입력값'!C7*'입력값'!C14*365)*MAX(0,1-'입력값'!C12/100*7)*(1-'입력값'!C13/100)*0.2397 | AO9: =('입력값'!C7*'입력값'!C14*365)*MAX(0,1-'입력값'!C12/100*7)*(1-'입력값'!C13/100)*0.3057 | AP9: =('입력값'!C7*'입력값'!C14*365)*MAX(0,1-'입력값'!C12/100*7)*(1-'입력값'!C13/100)*0.2199 | AQ9: =('입력값'!C7*'입력값'!C14*365)*MAX(0,1-'입력값'!C12/100*8)*(1-'입력값'!C13/100)*0.2347 | AR9: =('입력값'!C7*'입력값'!C14*365)*MAX(0,1-'입력값'!C12/100*8)*(1-'입력값'!C13/100)*0.2397 | AS9: =('입력값'!C7*'입력값'!C14*365)*MAX(0,1-'입력값'!C12/100*8)*(1-'입력값'!C13/100)*0.3057 | AT9: =('입력값'!C7*'입력값'!C14*365)*MAX(0,1-'입력값'!C12/100*8)*(1-'입력값'!C13/100)*0.2199 | AU9: =('입력값'!C7*'입력값'!C14*365)*MAX(0,1-'입력값'!C12/100*9)*(1-'입력값'!C13/100)*0.2347 | AV9: =('입력값'!C7*'입력값'!C14*365)*MAX(0,1-'입력값'!C12/100*9)*(1-'입력값'!C13/100)*0.2397 | AW9: =('입력값'!C7*'입력값'!C14*365)*MAX(0,1-'입력값'!C12/100*9)*(1-'입력값'!C13/100)*0.3057 | AX9: =('입력값'!C7*'입력값'!C14*365)*MAX(0,1-'입력값'!C12/100*9)*(1-'입력값'!C13/100)*0.2199 | AY9: =('입력값'!C7*'입력값'!C14*365)*MAX(0,1-'입력값'!C12/100*10)*(1-'입력값'!C13/100)*0.2347 | AZ9: =('입력값'!C7*'입력값'!C14*365)*MAX(0,1-'입력값'!C12/100*10)*(1-'입력값'!C13/100)*0.2397 | BA9: =('입력값'!C7*'입력값'!C14*365)*MAX(0,1-'입력값'!C12/100*10)*(1-'입력값'!C13/100)*0.3057 | BB9: =('입력값'!C7*'입력값'!C14*365)*MAX(0,1-'입력값'!C12/100*10)*(1-'입력값'!C13/100)*0.2199 | BC9: =('입력값'!C7*'입력값'!C14*365)*MAX(0,1-'입력값'!C12/100*11)*(1-'입력값'!C13/100)*0.2347 | BD9: =('입력값'!C7*'입력값'!C14*365)*MAX(0,1-'입력값'!C12/100*11)*(1-'입력값'!C13/100)*0.2397 | BE9: =('입력값'!C7*'입력값'!C14*365)*MAX(0,1-'입력값'!C12/100*11)*(1-'입력값'!C13/100)*0.3057 | BF9: =('입력값'!C7*'입력값'!C14*365)*MAX(0,1-'입력값'!C12/100*11)*(1-'입력값'!C13/100)*0.2199 | BG9: =('입력값'!C7*'입력값'!C14*365)*MAX(0,1-'입력값'!C12/100*12)*(1-'입력값'!C13/100)*0.2347 | BH9: =('입력값'!C7*'입력값'!C14*365)*MAX(0,1-'입력값'!C12/100*12)*(1-'입력값'!C13/100)*0.2397 | BI9: =('입력값'!C7*'입력값'!C14*365)*MAX(0,1-'입력값'!C12/100*12)*(1-'입력값'!C13/100)*0.3057 | BJ9: =('입력값'!C7*'입력값'!C14*365)*MAX(0,1-'입력값'!C12/100*12)*(1-'입력값'!C13/100)*0.2199 | BK9: =('입력값'!C7*'입력값'!C14*365)*MAX(0,1-'입력값'!C12/100*13)*(1-'입력값'!C13/100)*0.2347 | BL9: =('입력값'!C7*'입력값'!C14*365)*MAX(0,1-'입력값'!C12/100*13)*(1-'입력값'!C13/100)*0.2397 | BM9: =('입력값'!C7*'입력값'!C14*365)*MAX(0,1-'입력값'!C12/100*13)*(1-'입력값'!C13/100)*0.3057 | BN9: =('입력값'!C7*'입력값'!C14*365)*MAX(0,1-'입력값'!C12/100*13)*(1-'입력값'!C13/100)*0.2199 | BO9: =('입력값'!C7*'입력값'!C14*365)*MAX(0,1-'입력값'!C12/100*14)*(1-'입력값'!C13/100)*0.2347 | BP9: =('입력값'!C7*'입력값'!C14*365)*MAX(0,1-'입력값'!C12/100*14)*(1-'입력값'!C13/100)*0.2397 | BQ9: =('입력값'!C7*'입력값'!C14*365)*MAX(0,1-'입력값'!C12/100*14)*(1-'입력값'!C13/100)*0.3057 | BR9: =('입력값'!C7*'입력값'!C14*365)*MAX(0,1-'입력값'!C12/100*14)*(1-'입력값'!C13/100)*0.2199 | BS9: =('입력값'!C7*'입력값'!C14*365)*MAX(0,1-'입력값'!C12/100*15)*(1-'입력값'!C13/100)*0.2347 | BT9: =('입력값'!C7*'입력값'!C14*365)*MAX(0,1-'입력값'!C12/100*15)*(1-'입력값'!C13/100)*0.2397 | BU9: =('입력값'!C7*'입력값'!C14*365)*MAX(0,1-'입력값'!C12/100*15)*(1-'입력값'!C13/100)*0.3057 | BV9: =('입력값'!C7*'입력값'!C14*365)*MAX(0,1-'입력값'!C12/100*15)*(1-'입력값'!C13/100)*0.2199 | BW9: =('입력값'!C7*'입력값'!C14*365)*MAX(0,1-'입력값'!C12/100*16)*(1-'입력값'!C13/100)*0.2347 | BX9: =('입력값'!C7*'입력값'!C14*365)*MAX(0,1-'입력값'!C12/100*16)*(1-'입력값'!C13/100)*0.2397 | BY9: =('입력값'!C7*'입력값'!C14*365)*MAX(0,1-'입력값'!C12/100*16)*(1-'입력값'!C13/100)*0.3057 | BZ9: =('입력값'!C7*'입력값'!C14*365)*MAX(0,1-'입력값'!C12/100*16)*(1-'입력값'!C13/100)*0.2199 | CA9: =('입력값'!C7*'입력값'!C14*365)*MAX(0,1-'입력값'!C12/100*17)*(1-'입력값'!C13/100)*0.2347 | CB9: =('입력값'!C7*'입력값'!C14*365)*MAX(0,1-'입력값'!C12/100*17)*(1-'입력값'!C13/100)*0.2397 | CC9: =('입력값'!C7*'입력값'!C14*365)*MAX(0,1-'입력값'!C12/100*17)*(1-'입력값'!C13/100)*0.3057 | CD9: =('입력값'!C7*'입력값'!C14*365)*MAX(0,1-'입력값'!C12/100*17)*(1-'입력값'!C13/100)*0.2199 | CE9: =('입력값'!C7*'입력값'!C14*365)*MAX(0,1-'입력값'!C12/100*18)*(1-'입력값'!C13/100)*0.2347 | CF9: =('입력값'!C7*'입력값'!C14*365)*MAX(0,1-'입력값'!C12/100*18)*(1-'입력값'!C13/100)*0.2397 | CG9: =('입력값'!C7*'입력값'!C14*365)*MAX(0,1-'입력값'!C12/100*18)*(1-'입력값'!C13/100)*0.3057 | CH9: =('입력값'!C7*'입력값'!C14*365)*MAX(0,1-'입력값'!C12/100*18)*(1-'입력값'!C13/100)*0.2199 | CI9: =('입력값'!C7*'입력값'!C14*365)*MAX(0,1-'입력값'!C12/100*19)*(1-'입력값'!C13/100)*0.2347 | CJ9: =('입력값'!C7*'입력값'!C14*365)*MAX(0,1-'입력값'!C12/100*19)*(1-'입력값'!C13/100)*0.2397 | CK9: =('입력값'!C7*'입력값'!C14*365)*MAX(0,1-'입력값'!C12/100*19)*(1-'입력값'!C13/100)*0.3057 | CL9: =('입력값'!C7*'입력값'!C14*365)*MAX(0,1-'입력값'!C12/100*19)*(1-'입력값'!C13/100)*0.2199
B10: 판매단가 | C10: [원/kWh] | K10: ='입력값'!K109 | L10: ='입력값'!L109 | M10: ='입력값'!M109 | N10: ='입력값'!N109 | O10: ='입력값'!O109 | P10: ='입력값'!P109 | Q10: ='입력값'!Q109 | R10: ='입력값'!R109 | ... CL10: ='입력값'!CL109
B12: 영업수익 | C12: [KRWm] | D12: =SUM(E12:CL12) | E12: 0 | F12: 0 | G12: 0 | H12: 0 | I12: 0 | J12: 0 | K12: =K9*K10/1000 | L12: =L9*L10/1000 | M12: =M9*M10/1000 | N12: =N9*N10/1000 | O12: =O9*O10/1000 | P12: =P9*P10/1000 | Q12: =Q9*Q10/1000 | R12: =R9*R10/1000 | ... CL12: =CL9*CL10/1000
B14: ※ 실측 오버라이드가 적용된 분기는 "판매단가"가 그 분기의 실제 정산단가(실측 사실, baked)이고, "영업수익"은 다른 분기와 동일하게 발전량×판매단가/1000 수식으로 계산됩니다(값은 원본과 그대로 일치).

Sheet Opex
A1: 당진 태양광발전
A2: 영업비용 추정
B4: 운영비용 (선순위/후순위 지급순위 반영)
B6: 구 분 | C6: unit | D6: 합 계 | E6: 2024-06-30 | F6: 2024-09-30 | G6: 2024-12-31 | H6: 2025-03-31 | I6: 2025-06-30 | J6: 2025-09-30 | K6: 2025-12-31 | L6: 2026-03-31 | M6: 2026-06-30 | N6: 2026-09-30 | O6: 2026-12-31 | P6: 2027-03-31 | Q6: 2027-06-30 | R6: 2027-09-30 | S6: 2027-12-31 | T6: 2028-03-31 | U6: 2028-06-30 | V6: 2028-09-30 | W6: 2028-12-31 | X6: 2029-03-31 | Y6: 2029-06-30 | Z6: 2029-09-30 | AA6: 2029-12-31 | AB6: 2030-03-31 | AC6: 2030-06-30 | AD6: 2030-09-30 | AE6: 2030-12-31 | AF6: 2031-03-31 | AG6: 2031-06-30 | AH6: 2031-09-30 | AI6: 2031-12-31 | AJ6: 2032-03-31 | AK6: 2032-06-30 | AL6: 2032-09-30 | AM6: 2032-12-31 | AN6: 2033-03-31 | AO6: 2033-06-30 | AP6: 2033-09-30 | AQ6: 2033-12-31 | AR6: 2034-03-31 | AS6: 2034-06-30 | AT6: 2034-09-30 | AU6: 2034-12-31 | AV6: 2035-03-31 | AW6: 2035-06-30 | AX6: 2035-09-30 | AY6: 2035-12-31 | AZ6: 2036-03-31 | BA6: 2036-06-30 | BB6: 2036-09-30 | BC6: 2036-12-31 | BD6: 2037-03-31 | BE6: 2037-06-30 | BF6: 2037-09-30 | BG6: 2037-12-31 | BH6: 2038-03-31 | BI6: 2038-06-30 | BJ6: 2038-09-30 | BK6: 2038-12-31 | BL6: 2039-03-31 | BM6: 2039-06-30 | BN6: 2039-09-30 | BO6: 2039-12-31 | BP6: 2040-03-31 | BQ6: 2040-06-30 | BR6: 2040-09-30 | BS6: 2040-12-31 | BT6: 2041-03-31 | BU6: 2041-06-30 | BV6: 2041-09-30 | BW6: 2041-12-31 | BX6: 2042-03-31 | BY6: 2042-06-30 | BZ6: 2042-09-30 | CA6: 2042-12-31 | CB6: 2043-03-31 | CC6: 2043-06-30 | CD6: 2043-09-30 | CE6: 2043-12-31 | CF6: 2044-03-31 | CG6: 2044-06-30 | CH6: 2044-09-30 | CI6: 2044-12-31 | CJ6: 2045-03-31 | CK6: 2045-06-30 | CL6: 2045-09-30
B8: 항목별 세부내역
