Workbook

Sheet 목차
B2: 당진 태양광발전
B3: 재무모델 (Financial Model) — 재생E AI Agent 자동생성 · 2026-08-06
B6: No | C6: 시트 | D6: 내용
B7: 1 | C7: Assum | D7: 모든 입력 가정 — 노란 셀(파란 글씨)만 수정하면 전 시트 재계산
B8: 2 | C8: TIC_Funding | D8: 총투자비 · 건설이자 · 재원조달 · 감가상각 기준
B9: 3 | C9: Revenue | D9: 발전량 · 판매단가 · 영업수익 추정
B10: 4 | C10: Opex | D10: 운영비용 추정 (물가상승 반영)
B11: 5 | C11: Debt | D11: 차입금 인출/상환 스케줄 · 이자 · DSRA
B12: 6 | C12: IS(Y) | D12: 추정 손익계산서 (이월결손금·법인세 포함)
B13: 7 | C13: CF(Y) | D13: 추정 현금흐름표 · 배당 · 현금계정
B14: 8 | C14: DSCR | D14: 원리금 상환능력 (단순 DSCR, 최소/평균)
B15: 9 | C15: IRR | D15: Project IRR / Equity IRR / NPV
B16: 10 | C16: Report | D16: Executive Summary + 연도별 요약
B17: 11 | C17: Sensitivity | D17: 민감도 분석 (산출값)
B19: 색상 규칙
C20: 파란 글씨 + 노란 배경 | D20: 직접 입력하는 가정값 (Assum 시트)
C21: 검정 글씨 | D21: 해당 시트 내 수식
C22: 초록 글씨 | D22: 다른 시트를 참조하는 수식
C23: 단위 | D23: 별도 표기가 없는 금액은 모두 백만원(KRWm)

Sheet Report
A1: 당진 태양광발전
A2: Executive Summary
B4: 사업 개요
B6: 사업명 | D6: 당진 태양광발전
B7: 설비용량 [MW] | D7: =Assum!$F$7 -> 99.998
B8: 이용률 [%] | D8: =Assum!$F$8 -> 0.1571
B9: 준공(COD) | D9: 2025-10
B10: 운영기간 [Year] | D10: =Assum!$F$18 -> 20
B12: 재원조달
B14: 총투자비(TIC) [KRWm] | D14: =Assum!$F$27 -> 145728.8
B15: 건설이자(IDC) [KRWm] | D15: =Assum!$F$26 -> 4628.7974
B16: 자기자본 [KRWm] | D16: =TIC_Funding!$D$15 -> 14610
B17: 선순위 차입금 [KRWm] | D17: =TIC_Funding!$D$16 -> 136118.8
B18: 차입비율 [%] | D18: =Assum!$F$24 -> 0.9
B20: 수익성 지표
B22: Project IRR (세후) [%] | D22: =IRR!$D$15 -> 0.077942281
B23: Equity IRR (FCFE) [%] | D23: =IRR!$D$26 -> 0.19310569
B24: Equity IRR (배당) [%] | D24: =IRR!$D$27 -> 0.17303465
B25: NPV [KRWm] | D25: =IRR!$D$16 -> 27240.177
B26: 최소 DSCR [x] | D26: =DSCR!$D$13 -> 1.1347612
B27: 평균 DSCR [x] | D27: =DSCR!$D$14 -> 1.1927383
B28: LCOE [KRW/kWh] | D28: 131.81406
B29: 투자비 회수기간 [Year] | D29: 9.5742512
B30: 연평균 EBITDA [KRWm] | D30: 14995.411
B31: EBITDA Margin [%] | D31: 0.73792997
B33: 연도별 요약
B35: 구 분 | C35: unit | D35: 합 계 | E35: 건설기간 | F35: 1년차 | G35: 2년차 | H35: 3년차 | I35: 4년차 | J35: 5년차 | K35: 6년차 | L35: 7년차 | M35: 8년차 | N35: 9년차 | O35: 10년차 | P35: 11년차 | Q35: 12년차 | R35: 13년차 | S35: 14년차 | T35: 15년차 | U35: 16년차 | V35: 17년차 | W35: 18년차 | X35: 19년차 | Y35: 20년차
E36: 2024 | F36: 2025 | G36: 2026 | H36: 2027 | I36: 2028 | J36: 2029 | K36: 2030 | L36: 2031 | M36: 2032 | N36: 2033 | O36: 2034 | P36: 2035 | Q36: 2036 | R36: 2037 | S36: 2038 | T36: 2039 | U36: 2040 | V36: 2041 | W36: 2042 | X36: 2043 | Y36: 2044
B38: 영업수익 | F38: =Revenue!F16 -> 21303.088 | G38: =Revenue!G16 -> 21196.573 | H38: =Revenue!H16 -> 21090.59 | I38: =Revenue!I16 -> 20985.137 | J38: =Revenue!J16 -> 20880.211 | K38: =Revenue!K16 -> 20775.81 | L38: =Revenue!L16 -> 20671.931 | M38: =Revenue!M16 -> 20568.571 | ... Y38: =Revenue!Y16 -> 19367.836
B39: 영업비용 | F39: =Opex!F12 -> 4980 | G39: =Opex!G12 -> 5014.86 | H39: =Opex!H12 -> 5049.964 | I39: =Opex!I12 -> 5085.3138 | J39: =Opex!J12 -> 5120.911 | K39: =Opex!K12 -> 5156.7573 | L39: =Opex!L12 -> 5192.8546 | M39: =Opex!M12 -> 5229.2046 | ... Y39: =Opex!Y12 -> 5685.7699
B40: EBITDA | F40: ='IS(Y)'!F11 -> 16323.088 | G40: ='IS(Y)'!G11 -> 16181.713 | H40: ='IS(Y)'!H11 -> 16040.626 | I40: ='IS(Y)'!I11 -> 15899.823 | J40: ='IS(Y)'!J11 -> 15759.3 | K40: ='IS(Y)'!K11 -> 15619.053 | L40: ='IS(Y)'!L11 -> 15479.076 | M40: ='IS(Y)'!M11 -> 15339.367 | ... Y40: ='IS(Y)'!Y11 -> 13682.066
B41: 당기순이익 | F41: ='IS(Y)'!F21 -> 1526.5909 | G41: ='IS(Y)'!G21 -> 1522.5073 | H41: ='IS(Y)'!H21 -> 1706.1671 | I41: ='IS(Y)'!I21 -> 1899.4458 | J41: ='IS(Y)'!J21 -> 2102.7899 | K41: ='IS(Y)'!K21 -> 2316.6667 | L41: ='IS(Y)'!L21 -> 2541.5653 | M41: ='IS(Y)'!M21 -> 2777.9982 | ... Y41: ='IS(Y)'!Y21 -> 5495.5579
B42: CFADS | F42: ='CF(Y)'!F11 -> 15989.69 | G42: ='CF(Y)'!G11 -> 15849.273 | H42: ='CF(Y)'!H11 -> 15665.105 | I42: ='CF(Y)'!I11 -> 15478.965 | J42: ='CF(Y)'!J11 -> 15290.744 | K42: ='CF(Y)'!K11 -> 15100.328 | L42: ='CF(Y)'!L11 -> 14907.598 | M42: ='CF(Y)'!M11 -> 14712.429 | ... Y42: ='CF(Y)'!Y11 -> 12417.676
B43: 원리금(DS) | F43: =Debt!F13 -> 7540.9814 | G43: =Debt!G13 -> 13967.055 | H43: =Debt!H13 -> 13804.759 | I43: =Debt!I13 -> 13640.725 | J43: =Debt!J13 -> 13474.857 | K43: =Debt!K13 -> 13307.054 | L43: =Debt!L13 -> 13137.212 | M43: =Debt!M13 -> 12965.22 | ... Y43: =Debt!Y13 -> 5.5399716e-08
B44: DSCR | F44: =DSCR!F11 -> 2.1203726 | G44: =DSCR!G11 -> 1.1347612 | H44: =DSCR!H11 -> 1.1347612 | I44: =DSCR!I11 -> 1.1347612 | J44: =DSCR!J11 -> 1.1347612 | K44: =DSCR!K11 -> 1.1347612 | L44: =DSCR!L11 -> 1.1347612 | M44: =DSCR!M11 -> 1.1347612 | ... Y44: =DSCR!Y11 -> -
B45: 배당금 | F45: ='CF(Y)'!F19 -> 0 | G45: ='CF(Y)'!G19 -> 7428.5464 | H45: ='CF(Y)'!H19 -> 1942.3631 | I45: ='CF(Y)'!I19 -> 1921.1746 | J45: ='CF(Y)'!J19 -> 1899.7893 | K45: ='CF(Y)'!K19 -> 1878.1957 | L45: ='CF(Y)'!L19 -> 1856.3822 | M45: ='CF(Y)'!M19 -> 1834.3363 | ... Y45: ='CF(Y)'!Y19 -> 11417.676
B46: Project FCF | F46: =IRR!F13 -> 15989.69 | G46: =IRR!G13 -> 15849.273 | H46: =IRR!H13 -> 15665.105 | I46: =IRR!I13 -> 15478.965 | J46: =IRR!J13 -> 15290.744 | K46: =IRR!K13 -> 15100.328 | L46: =IRR!L13 -> 14907.598 | M46: =IRR!M13 -> 14712.429 | ... Y46: =IRR!Y13 -> 10417.676

Sheet Assum
A1: 당진 태양광발전
A2: Assumption — 파란색 셀만 수정하면 전 시트가 재계산됩니다
B3: 노랑 배경 + 파란 글씨 = 직접 입력값 / 회색 = 수식
B4: General
B6: 사업명 | D6: [text] | F6: 당진 태양광발전
B7: 설비용량 | D7: [MW] | F7: 99.998
B8: 이용률 | D8: [%] | F8: 0.1571 | G8: 일일발전시간 ÷ 24
B9: 일일 발전시간(환산) | D9: [h/day] | F9: =$F$8*24 -> 3.7704
B10: Degradation | D10: [%/yr] | F10: 0.005
B11: 소내 소비율 | D11: [%] | F11: 0
B13: Timing
B15: 착공시점 | D15: [Date] | F15: 2024-06
B16: 공사기간 | D16: [Month] | F16: 16
B17: 준공(COD) | D17: [Date] | F17: 2025-10
B18: 운영기간 | D18: [Year] | F18: 20
B20: TIC & Funding
B22: 총사업비(건설이자 제외) | D22: [KRWm] | F22: 141100
B23: 최초 DSRA | D23: [KRWm] | F23: 5000
B24: 차입비율(Gearing) | D24: [%] | F24: 0.9 | G24: 기준: 총사업비 + 최초DSRA (건설이자는 전액 차입 조달)
B25: 자기자본 | D25: [KRWm] | F25: =($F$22+$F$23)*(1-$F$24) -> 14610
B26: 건설이자(IDC) | D26: [KRWm] | F26: =Construction!$D$13 -> 4628.7974 | G26: Construction 시트에서 월단위 산출
B27: 총투자비(TIC) | D27: [KRWm] | F27: =$F$22+$F$26 -> 145728.8
B28: 소요자금 합계 | D28: [KRWm] | F28: =$F$27+$F$23 -> 150728.8
B29: 차입금 | D29: [KRWm] | F29: =$F$28-$F$25 -> 136118.8
B30: 실질 차입비율(TIC 기준) | D30: [%] | F30: =$F$29/$F$28 -> 0.90307094
B32: Debt
B34: 이자율(건설기간) | D34: [%] | F34: 0.056
B35: 이자율(운영기간) | D35: [%] | F35: 0.0554
B36: 거치기간 | D36: [Year] | F36: 1
B37: 상환기간 | D37: [Year] | F37: 16
B38: 상환방식 | D38: [1/2/3] | F38: 3 | G38: 1: 원금균등 2: 원리금균등 3: DSCR 스컬프팅(수동 스케줄)
B39: 연간 상환횟수 | D39: [회/년] | F39: 4 | G39: 이자는 연중 평균잔액 기준으로 계산
B40: 스컬프팅 균등 DSCR(산출) | D40: [x] | F40: 1.1347612 | G40: 상환방식 3 선택 시 완전상환되는 균등 DSCR
B42: Revenue
B44: 판매단가 | D44: [KRW/kWh] | F44: 154.8 | G44: PPA 또는 SMP+REC 가중평균
B45: 단가 상승률 | D45: [%/yr] | F45: 0
B47: Cost
B49: 운영비(연간, 1년차) | D49: [KRWm/yr] | F49: 4980
B50: 운영비 상승률 | D50: [%/yr] | F50: 0.007
B51: 철거·복구비(만기) | D51: [KRWm] | F51: 2000
...

Sheet Construction
A1: 당진 태양광발전
A2: 건설기간 자금인출 및 건설이자(IDC)
B4: 월별 인출 스케줄
B6: 구 분 | C6: unit | D6: 합 계 | E6: 1 | F6: 2 | G6: 3 | H6: 4 | I6: 5 | J6: 6 | K6: 7 | L6: 8 | M6: 9 | N6: 10 | O6: 11 | P6: 12 | Q6: 13 | R6: 14 | S6: 15 | T6: 16 | U6: 17 | V6: 18 | W6: 19 | X6: 20 | Y6: 21 | Z6: 22 | AA6: 23 | AB6: 24 | AC6: 25 | AD6: 26 | AE6: 27 | AF6: 28
B8: 사업비 인출 | C8: [KRWm] | D8: =SUM(E8:AF8) -> 141100 | E8: =IF(1<=Assum!$F$16,Assum!$F$22/Assum!$F$16,0) -> 8818.75 | F8: =IF(2<=Assum!$F$16,Assum!$F$22/Assum!$F$16,0) -> 8818.75 | G8: =IF(3<=Assum!$F$16,Assum!$F$22/Assum!$F$16,0) -> 8818.75 | H8: =IF(4<=Assum!$F$16,Assum!$F$22/Assum!$F$16,0) -> 8818.75 | I8: =IF(5<=Assum!$F$16,Assum!$F$22/Assum!$F$16,0) -> 8818.75 | J8: =IF(6<=Assum!$F$16,Assum!$F$22/Assum!$F$16,0) -> 8818.75 | K8: =IF(7<=Assum!$F$16,Assum!$F$22/Assum!$F$16,0) -> 8818.75 | L8: =IF(8<=Assum!$F$16,Assum!$F$22/Assum!$F$16,0) -> 8818.75 | M8: =IF(9<=Assum!$F$16,Assum!$F$22/Assum!$F$16,0) -> 8818.75 | N8: =IF(10<=Assum!$F$16,Assum!$F$22/Assum!$F$16,0) -> 8818.75 | O8: =IF(11<=Assum!$F$16,Assum!$F$22/Assum!$F$16,0) -> 8818.75 | P8: =IF(12<=Assum!$F$16,Assum!$F$22/Assum!$F$16,0) -> 8818.75 | Q8: =IF(13<=Assum!$F$16,Assum!$F$22/Assum!$F$16,0) -> 8818.75 | R8: =IF(14<=Assum!$F$16,Assum!$F$22/Assum!$F$16,0) -> 8818.75 | S8: =IF(15<=Assum!$F$16,Assum!$F$22/Assum!$F$16,0) -> 8818.75 | T8: =IF(16<=Assum!$F$16,Assum!$F$22/Assum!$F$16,0) -> 8818.75 | U8: =IF(17<=Assum!$F$16,Assum!$F$22/Assum!$F$16,0) -> 0 | V8: =IF(18<=Assum!$F$16,Assum!$F$22/Assum!$F$16,0) -> 0 | W8: =IF(19<=Assum!$F$16,Assum!$F$22/Assum!$F$16,0) -> 0 | X8: =IF(20<=Assum!$F$16,Assum!$F$22/Assum!$F$16,0) -> 0 | Y8: =IF(21<=Assum!$F$16,Assum!$F$22/Assum!$F$16,0) -> 0 | Z8: =IF(22<=Assum!$F$16,Assum!$F$22/Assum!$F$16,0) -> 0 | AA8: =IF(23<=Assum!$F$16,Assum!$F$22/Assum!$F$16,0) -> 0 | AB8: =IF(24<=Assum!$F$16,Assum!$F$22/Assum!$F$16,0) -> 0 | AC8: =IF(25<=Assum!$F$16,Assum!$F$22/Assum!$F$16,0) -> 0 | AD8: =IF(26<=Assum!$F$16,Assum!$F$22/Assum!$F$16,0) -> 0 | AE8: =IF(27<=Assum!$F$16,Assum!$F$22/Assum!$F$16,0) -> 0 | AF8: =IF(28<=Assum!$F$16,Assum!$F$22/Assum!$F$16,0) -> 0
B9: 자기자본 인출 | C9: [KRWm] | D9: =SUM(E9:AF9) -> 14610 | E9: =MIN(MAX(0,Assum!$F$25-0),E8) -> 8818.75 | F9: =MIN(MAX(0,Assum!$F$25-SUM($E$9:E9)),F8) -> 5791.25 | G9: =MIN(MAX(0,Assum!$F$25-SUM($E$9:F9)),G8) -> 0 | H9: =MIN(MAX(0,Assum!$F$25-SUM($E$9:G9)),H8) -> 0 | I9: =MIN(MAX(0,Assum!$F$25-SUM($E$9:H9)),I8) -> 0 | J9: =MIN(MAX(0,Assum!$F$25-SUM($E$9:I9)),J8) -> 0 | K9: =MIN(MAX(0,Assum!$F$25-SUM($E$9:J9)),K8) -> 0 | L9: =MIN(MAX(0,Assum!$F$25-SUM($E$9:K9)),L8) -> 0 | M9: =MIN(MAX(0,Assum!$F$25-SUM($E$9:L9)),M8) -> 0 | ... AF9: =MIN(MAX(0,Assum!$F$25-SUM($E$9:AE9)),AF8) -> 0
B10: 차입금 인출 | C10: [KRWm] | D10: =SUM(E10:AF10) -> 126490 | E10: =E8-E9 -> 0 | F10: =F8-F9 -> 3027.5 | G10: =G8-G9 -> 8818.75 | H10: =H8-H9 -> 8818.75 | I10: =I8-I9 -> 8818.75 | J10: =J8-J9 -> 8818.75 | K10: =K8-K9 -> 8818.75 | L10: =L8-L9 -> 8818.75 | ... AF10: =AF8-AF9 -> 0
B11: 기초 차입잔액 | C11: [KRWm] | E11: 0 | F11: =E13 -> 0 | G11: =F13 -> 3041.6283 | H11: =G13 -> 11915.727 | I11: =H13 -> 20831.238 | J11: =I13 -> 29788.354 | K11: =J13 -> 38787.271 | L11: =K13 -> 47828.182 | M11: =L13 -> 56911.285 | ... AF11: =AE13 -> 131118.8
B12: 건설이자(월) | C12: [KRWm] | D12: =SUM(E12:AF12) -> 4628.7974 | E12: =IF(1<=Assum!$F$16,(E11+E10)*Assum!$F$34/12,0) -> 0 | F12: =IF(2<=Assum!$F$16,(F11+F10)*Assum!$F$34/12,0) -> 14.128333 | G12: =IF(3<=Assum!$F$16,(G11+G10)*Assum!$F$34/12,0) -> 55.348432 | H12: =IF(4<=Assum!$F$16,(H11+H10)*Assum!$F$34/12,0) -> 96.760892 | I12: =IF(5<=Assum!$F$16,(I11+I10)*Assum!$F$34/12,0) -> 138.36661 | J12: =IF(6<=Assum!$F$16,(J11+J10)*Assum!$F$34/12,0) -> 180.16649 | K12: =IF(7<=Assum!$F$16,(K11+K10)*Assum!$F$34/12,0) -> 222.16143 | L12: =IF(8<=Assum!$F$16,(L11+L10)*Assum!$F$34/12,0) -> 264.35235 | M12: =IF(9<=Assum!$F$16,(M11+M10)*Assum!$F$34/12,0) -> 306.74016 | N12: =IF(10<=Assum!$F$16,(N11+N10)*Assum!$F$34/12,0) -> 349.32578 | O12: =IF(11<=Assum!$F$16,(O11+O10)*Assum!$F$34/12,0) -> 392.11014 | P12: =IF(12<=Assum!$F$16,(P11+P10)*Assum!$F$34/12,0) -> 435.09415 | Q12: =IF(13<=Assum!$F$16,(Q11+Q10)*Assum!$F$34/12,0) -> 478.27876 | R12: =IF(14<=Assum!$F$16,(R11+R10)*Assum!$F$34/12,0) -> 521.66489 | S12: =IF(15<=Assum!$F$16,(S11+S10)*Assum!$F$34/12,0) -> 565.25349 | T12: =IF(16<=Assum!$F$16,(T11+T10)*Assum!$F$34/12,0) -> 609.04551 | U12: =IF(17<=Assum!$F$16,(U11+U10)*Assum!$F$34/12,0) -> 0 | V12: =IF(18<=Assum!$F$16,(V11+V10)*Assum!$F$34/12,0) -> 0 | W12: =IF(19<=Assum!$F$16,(W11+W10)*Assum!$F$34/12,0) -> 0 | X12: =IF(20<=Assum!$F$16,(X11+X10)*Assum!$F$34/12,0) -> 0 | Y12: =IF(21<=Assum!$F$16,(Y11+Y10)*Assum!$F$34/12,0) -> 0 | Z12: =IF(22<=Assum!$F$16,(Z11+Z10)*Assum!$F$34/12,0) -> 0 | AA12: =IF(23<=Assum!$F$16,(AA11+AA10)*Assum!$F$34/12,0) -> 0 | AB12: =IF(24<=Assum!$F$16,(AB11+AB10)*Assum!$F$34/12,0) -> 0 | AC12: =IF(25<=Assum!$F$16,(AC11+AC10)*Assum!$F$34/12,0) -> 0 | AD12: =IF(26<=Assum!$F$16,(AD11+AD10)*Assum!$F$34/12,0) -> 0 | AE12: =IF(27<=Assum!$F$16,(AE11+AE10)*Assum!$F$34/12,0) -> 0 | AF12: =IF(28<=Assum!$F$16,(AF11+AF10)*Assum!$F$34/12,0) -> 0
B13: 기말 차입잔액 | C13: [IDC 합계] | D13: =SUM(E12:AF12) -> 4628.7974 | E13: =E11+E10+E12 -> 0 | F13: =F11+F10+F12 -> 3041.6283 | G13: =G11+G10+G12 -> 11915.727 | H13: =H11+H10+H12 -> 20831.238 | I13: =I11+I10+I12 -> 29788.354 | J13: =J11+J10+J12 -> 38787.271 | K13: =K11+K10+K12 -> 47828.182 | L13: =L11+L10+L12 -> 56911.285 | ... AF13: =AF11+AF10+AF12 -> 131118.8
B15: 준공시점 정산
B17: 기말 차입잔액(사업비) | C17: [KRWm] | D17: =AF13 -> 131118.8
B18: DSRA — 자기자본 조달 | C18: [KRWm] | D18: =MIN(MAX(0,Assum!$F$25-SUM(E9:AF9)),Assum!$F$23) -> 0
B19: DSRA — 차입 조달 | C19: [KRWm] | D19: =Assum!$F$23-D18 -> 5000
B20: 차입금 합계(운영개시) | C20: [KRWm] | D20: =D17+D19 -> 136118.8
B21: Check (Assum 차입금과 일치) | C21: [KRWm] | D21: =D20-Assum!$F$29 -> 0
B23: ※ 자기자본을 먼저 인출하고 잔여 소요액을 차입하는 구조이며, 건설이자는 매월 자본화(원금가산)됩니다.
B24: ※ 공사기간을 28개월 이상으로 늘리려면 열을 추가하거나 생성기에서 다시 만들어 주세요.

Sheet TIC_Funding
A1: 당진 태양광발전
A2: 총투자비 및 재원조달
B4: 총투자비
B6: 구 분 | D6: 금액 | E6: 비중
B7: 총사업비(건설이자 제외) | C7: [KRWm] | D7: =Assum!$F$22 -> 141100 | E7: =D7/$D$10 -> 0.9361184
B8: 건설이자(IDC) | C8: [KRWm] | D8: =Assum!$F$26 -> 4628.7974 | E8: =D8/$D$10 -> 0.030709443
B9: 최초 DSRA | C9: [KRWm] | D9: =Assum!$F$23 -> 5000 | E9: =D9/$D$10 -> 0.033172161
B10: 소요자금 합계 | C10: [KRWm] | D10: =SUM(D7:D9) -> 150728.8 | E10: =D10/$D$10 -> 1
B13: 재원조달
B15: 자기자본 | C15: [KRWm] | D15: =Assum!$F$25 -> 14610 | E15: =D15/$D$17 -> 0.096929056
B16: 선순위 차입금 | C16: [KRWm] | D16: =Assum!$F$29 -> 136118.8 | E16: =D16/$D$17 -> 0.90307094
B17: 합계 | C17: [KRWm] | D17: =SUM(D15:D16) -> 150728.8 | E17: =D17/$D$17 -> 1
B18: Check (소요 - 조달) | C18: [KRWm] | D18: =D10-D17 -> 0
B21: 감가상각
B23: 감가상각 대상자산 | C23: [KRWm] | D23: =Assum!$F$56 -> 138442.36
B24: 내용연수 | C24: [Year] | D24: =Assum!$F$57 -> 20
B25: 연간 상각비 | C25: [KRWm/yr] | D25: =D23/D24 -> 6922.1179
B27: ※ 건설이자는 자기자본 우선인출 가정 하에 월단위로 자본화하여 산출한 값입니다.

Sheet Revenue
A1: 당진 태양광발전
A2: 영업수익 추정
B4: 발전량 및 매출
B6: 구 분 | C6: unit | D6: 합 계 | E6: 건설기간 | F6: 1년차 | G6: 2년차 | H6: 3년차 | I6: 4년차 | J6: 5년차 | K6: 6년차 | L6: 7년차 | M6: 8년차 | N6: 9년차 | O6: 10년차 | P6: 11년차 | Q6: 12년차 | R6: 13년차 | S6: 14년차 | T6: 15년차 | U6: 16년차 | V6: 17년차 | W6: 18년차 | X6: 19년차 | Y6: 20년차
E7: 2024 | F7: 2025 | G7: 2026 | H7: 2027 | I7: 2028 | J7: 2029 | K7: 2030 | L7: 2031 | M7: 2032 | N7: 2033 | O7: 2034 | P7: 2035 | Q7: 2036 | R7: 2037 | S7: 2038 | T7: 2039 | U7: 2040 | V7: 2041 | W7: 2042 | X7: 2043 | Y7: 2044
B9: 설비용량 | C9: [MW] | F9: =Assum!$F$7 -> 99.998 | G9: =Assum!$F$7 -> 99.998 | H9: =Assum!$F$7 -> 99.998 | I9: =Assum!$F$7 -> 99.998 | J9: =Assum!$F$7 -> 99.998 | K9: =Assum!$F$7 -> 99.998 | L9: =Assum!$F$7 -> 99.998 | M9: =Assum!$F$7 -> 99.998 | ... Y9: =Assum!$F$7 -> 99.998
B10: 이용률 | C10: [%] | F10: =Assum!$F$8 -> 0.1571 | G10: =Assum!$F$8 -> 0.1571 | H10: =Assum!$F$8 -> 0.1571 | I10: =Assum!$F$8 -> 0.1571 | J10: =Assum!$F$8 -> 0.1571 | K10: =Assum!$F$8 -> 0.1571 | L10: =Assum!$F$8 -> 0.1571 | M10: =Assum!$F$8 -> 0.1571 | ... Y10: =Assum!$F$8 -> 0.1571
B11: Degradation 계수 | C11: [%] | F11: =(1-Assum!$F$10)^(1-1) -> 1 | G11: =(1-Assum!$F$10)^(2-1) -> 0.995 | H11: =(1-Assum!$F$10)^(3-1) -> 0.990025 | I11: =(1-Assum!$F$10)^(4-1) -> 0.98507488 | J11: =(1-Assum!$F$10)^(5-1) -> 0.9801495 | K11: =(1-Assum!$F$10)^(6-1) -> 0.97524875 | L11: =(1-Assum!$F$10)^(7-1) -> 0.97037251 | M11: =(1-Assum!$F$10)^(8-1) -> 0.96552065 | N11: =(1-Assum!$F$10)^(9-1) -> 0.96069304 | O11: =(1-Assum!$F$10)^(10-1) -> 0.95588958 | P11: =(1-Assum!$F$10)^(11-1) -> 0.95111013 | Q11: =(1-Assum!$F$10)^(12-1) -> 0.94635458 | R11: =(1-Assum!$F$10)^(13-1) -> 0.94162281 | S11: =(1-Assum!$F$10)^(14-1) -> 0.93691469 | T11: =(1-Assum!$F$10)^(15-1) -> 0.93223012 | U11: =(1-Assum!$F$10)^(16-1) -> 0.92756897 | V11: =(1-Assum!$F$10)^(17-1) -> 0.92293112 | W11: =(1-Assum!$F$10)^(18-1) -> 0.91831647 | X11: =(1-Assum!$F$10)^(19-1) -> 0.91372489 | Y11: =(1-Assum!$F$10)^(20-1) -> 0.90915626
B12: 발전량(송전단) | C12: [MWh] | D12: =SUM(F12:Y12) -> 2625441 | F12: =F9*8760*F10*(1-Assum!$F$11)*F11 -> 137616.85 | G12: =G9*8760*G10*(1-Assum!$F$11)*G11 -> 136928.76 | H12: =H9*8760*H10*(1-Assum!$F$11)*H11 -> 136244.12 | I12: =I9*8760*I10*(1-Assum!$F$11)*I11 -> 135562.9 | J12: =J9*8760*J10*(1-Assum!$F$11)*J11 -> 134885.08 | K12: =K9*8760*K10*(1-Assum!$F$11)*K11 -> 134210.66 | L12: =L9*8760*L10*(1-Assum!$F$11)*L11 -> 133539.61 | M12: =M9*8760*M10*(1-Assum!$F$11)*M11 -> 132871.91 | ... Y12: =Y9*8760*Y10*(1-Assum!$F$11)*Y11 -> 125115.22
B14: 판매단가 | C14: [KRW/kWh] | F14: =Assum!$F$44*(1+Assum!$F$45)^(1-1) -> 154.8 | G14: =Assum!$F$44*(1+Assum!$F$45)^(2-1) -> 154.8 | H14: =Assum!$F$44*(1+Assum!$F$45)^(3-1) -> 154.8 | I14: =Assum!$F$44*(1+Assum!$F$45)^(4-1) -> 154.8 | J14: =Assum!$F$44*(1+Assum!$F$45)^(5-1) -> 154.8 | K14: =Assum!$F$44*(1+Assum!$F$45)^(6-1) -> 154.8 | L14: =Assum!$F$44*(1+Assum!$F$45)^(7-1) -> 154.8 | M14: =Assum!$F$44*(1+Assum!$F$45)^(8-1) -> 154.8 | N14: =Assum!$F$44*(1+Assum!$F$45)^(9-1) -> 154.8 | O14: =Assum!$F$44*(1+Assum!$F$45)^(10-1) -> 154.8 | P14: =Assum!$F$44*(1+Assum!$F$45)^(11-1) -> 154.8 | Q14: =Assum!$F$44*(1+Assum!$F$45)^(12-1) -> 154.8 | R14: =Assum!$F$44*(1+Assum!$F$45)^(13-1) -> 154.8 | S14: =Assum!$F$44*(1+Assum!$F$45)^(14-1) -> 154.8 | T14: =Assum!$F$44*(1+Assum!$F$45)^(15-1) -> 154.8 | U14: =Assum!$F$44*(1+Assum!$F$45)^(16-1) -> 154.8 | V14: =Assum!$F$44*(1+Assum!$F$45)^(17-1) -> 154.8 | W14: =Assum!$F$44*(1+Assum!$F$45)^(18-1) -> 154.8 | X14: =Assum!$F$44*(1+Assum!$F$45)^(19-1) -> 154.8 | Y14: =Assum!$F$44*(1+Assum!$F$45)^(20-1) -> 154.8
B16: 영업수익 | C16: [KRWm] | D16: =SUM(F16:Y16) -> 406418.27 | F16: =F12*F14/1000 -> 21303.088 | G16: =G12*G14/1000 -> 21196.573 | H16: =H12*H14/1000 -> 21090.59 | I16: =I12*I14/1000 -> 20985.137 | J16: =J12*J14/1000 -> 20880.211 | K16: =K12*K14/1000 -> 20775.81 | L16: =L12*L14/1000 -> 20671.931 | M16: =M12*M14/1000 -> 20568.571 | ... Y16: =Y12*Y14/1000 -> 19367.836

Sheet Opex
A1: 당진 태양광발전
A2: 영업비용 추정
B4: 운영비용
B6: 구 분 | C6: unit | D6: 합 계 | E6: 건설기간 | F6: 1년차 | G6: 2년차 | H6: 3년차 | I6: 4년차 | J6: 5년차 | K6: 6년차 | L6: 7년차 | M6: 8년차 | N6: 9년차 | O6: 10년차 | P6: 11년차 | Q6: 12년차 | R6: 13년차 | S6: 14년차 | T6: 15년차 | U6: 16년차 | V6: 17년차 | W6: 18년차 | X6: 19년차 | Y6: 20년차
E7: 2024 | F7: 2025 | G7: 2026 | H7: 2027 | I7: 2028 | J7: 2029 | K7: 2030 | L7: 2031 | M7: 2032 | N7: 2033 | O7: 2034 | P7: 2035 | Q7: 2036 | R7: 2037 | S7: 2038 | T7: 2039 | U7: 2040 | V7: 2041 | W7: 2042 | X7: 2043 | Y7: 2044
B9: 운영비(1년차 기준) | C9: [KRWm] | F9: =Assum!$F$49 -> 4980 | G9: =Assum!$F$49 -> 4980 | H9: =Assum!$F$49 -> 4980 | I9: =Assum!$F$49 -> 4980 | J9: =Assum!$F$49 -> 4980 | K9: =Assum!$F$49 -> 4980 | L9: =Assum!$F$49 -> 4980 | M9: =Assum!$F$49 -> 4980 | ... Y9: =Assum!$F$49 -> 4980
B10: 물가상승 계수 | C10: [%] | F10: =(1+Assum!$F$50)^(1-1) -> 1 | G10: =(1+Assum!$F$50)^(2-1) -> 1.007 | H10: =(1+Assum!$F$50)^(3-1) -> 1.014049 | I10: =(1+Assum!$F$50)^(4-1) -> 1.0211473 | J10: =(1+Assum!$F$50)^(5-1) -> 1.0282954 | K10: =(1+Assum!$F$50)^(6-1) -> 1.0354934 | L10: =(1+Assum!$F$50)^(7-1) -> 1.0427419 | M10: =(1+Assum!$F$50)^(8-1) -> 1.0500411 | N10: =(1+Assum!$F$50)^(9-1) -> 1.0573914 | O10: =(1+Assum!$F$50)^(10-1) -> 1.0647931 | P10: =(1+Assum!$F$50)^(11-1) -> 1.0722467 | Q10: =(1+Assum!$F$50)^(12-1) -> 1.0797524 | R10: =(1+Assum!$F$50)^(13-1) -> 1.0873107 | S10: =(1+Assum!$F$50)^(14-1) -> 1.0949218 | T10: =(1+Assum!$F$50)^(15-1) -> 1.1025863 | U10: =(1+Assum!$F$50)^(16-1) -> 1.1103044 | V10: =(1+Assum!$F$50)^(17-1) -> 1.1180765 | W10: =(1+Assum!$F$50)^(18-1) -> 1.1259031 | X10: =(1+Assum!$F$50)^(19-1) -> 1.1337844 | Y10: =(1+Assum!$F$50)^(20-1) -> 1.1417209
B12: 영업비용 합계 | C12: [KRWm] | D12: =SUM(F12:Y12) -> 106510.05 | F12: =F9*F10 -> 4980 | G12: =G9*G10 -> 5014.86 | H12: =H9*H10 -> 5049.964 | I12: =I9*I10 -> 5085.3138 | J12: =J9*J10 -> 5120.911 | K12: =K9*K10 -> 5156.7573 | L12: =L9*L10 -> 5192.8546 | M12: =M9*M10 -> 5229.2046 | ... Y12: =Y9*Y10 -> 5685.7699

Sheet Debt
A1: 당진 태양광발전
A2: 차입금 인출·상환 스케줄
B4: 선순위 차입금
B6: 구 분 | C6: unit | D6: 합 계 | E6: 건설기간 | F6: 1년차 | G6: 2년차 | H6: 3년차 | I6: 4년차 | J6: 5년차 | K6: 6년차 | L6: 7년차 | M6: 8년차 | N6: 9년차 | O6: 10년차 | P6: 11년차 | Q6: 12년차 | R6: 13년차 | S6: 14년차 | T6: 15년차 | U6: 16년차 | V6: 17년차 | W6: 18년차 | X6: 19년차 | Y6: 20년차
E7: 2024 | F7: 2025 | G7: 2026 | H7: 2027 | I7: 2028 | J7: 2029 | K7: 2030 | L7: 2031 | M7: 2032 | N7: 2033 | O7: 2034 | P7: 2035 | Q7: 2036 | R7: 2037 | S7: 2038 | T7: 2039 | U7: 2040 | V7: 2041 | W7: 2042 | X7: 2043 | Y7: 2044
B9: 기초잔액 | C9: [KRWm] | F9: =TIC_Funding!$D$16 -> 136118.8 | G9: =F11 -> 136118.8 | H9: =G11 -> 129556.39 | I9: =H11 -> 122788.45 | J9: =I11 -> 115805.13 | K9: =J11 -> 108596.11 | L9: =K11 -> 101150.6 | M9: =L11 -> 93457.3 | N9: =M11 -> 85504.393 | ... Y9: =X11 -> 9.9999488e-07
B10: 원금상환 | C10: [KRWm] | D10: =SUM(F10:Y10) -> 136118.8 | F10: 0 | G10: 6562.408 | H10: 6767.939 | I10: 6983.3232 | J10: 7209.0199 | K10: 7445.5099 | L10: 7693.2968 | M10: 7952.9074 | N10: 8224.8936 | O10: 8509.8332 | P10: 8808.3308 | Q10: 9121.0197 | R10: 9448.5629 | S10: 9791.6543 | T10: 10151.02 | U10: 10527.422 | V10: 10921.656 | W10: 0 | X10: 0 | Y10: 0
B11: 기말잔액 | C11: [KRWm] | F11: =F9-F10 -> 136118.8 | G11: =G9-G10 -> 129556.39 | H11: =H9-H10 -> 122788.45 | I11: =I9-I10 -> 115805.13 | J11: =J9-J10 -> 108596.11 | K11: =K9-K10 -> 101150.6 | L11: =L9-L10 -> 93457.3 | M11: =M9-M10 -> 85504.393 | ... Y11: =Y9-Y10 -> 9.9999488e-07
B12: 이자비용 | C12: [KRWm] | D12: =SUM(F12:Y12) -> 74250.671 | F12: =(F9-F10*(Assum!$F$39-1)/(2*Assum!$F$39))*Assum!$F$35 -> 7540.9814 | G12: =(G9-G10*(Assum!$F$39-1)/(2*Assum!$F$39))*Assum!$F$35 -> 7404.6473 | H12: =(H9-H10*(Assum!$F$39-1)/(2*Assum!$F$39))*Assum!$F$35 -> 7036.82 | I12: =(I9-I10*(Assum!$F$39-1)/(2*Assum!$F$39))*Assum!$F$35 -> 6657.4016 | J12: =(J9-J10*(Assum!$F$39-1)/(2*Assum!$F$39))*Assum!$F$35 -> 6265.8367 | K12: =(K9-K10*(Assum!$F$39-1)/(2*Assum!$F$39))*Assum!$F$35 -> 5861.5439 | L12: =(L9-L10*(Assum!$F$39-1)/(2*Assum!$F$39))*Assum!$F$35 -> 5443.9148 | M12: =(M9-M10*(Assum!$F$39-1)/(2*Assum!$F$39))*Assum!$F$35 -> 5012.3128 | ... Y12: =(Y9-Y10*(Assum!$F$39-1)/(2*Assum!$F$39))*Assum!$F$35 -> 5.5399716e-08
B13: 원리금 합계(DS) | C13: [KRWm] | D13: =SUM(F13:Y13) -> 210369.47 | F13: =F10+F12 -> 7540.9814 | G13: =G10+G12 -> 13967.055 | H13: =H10+H12 -> 13804.759 | I13: =I10+I12 -> 13640.725 | J13: =J10+J12 -> 13474.857 | K13: =K10+K12 -> 13307.054 | L13: =L10+L12 -> 13137.212 | M13: =M10+M12 -> 12965.22 | ... Y13: =Y10+Y12 -> 5.5399716e-08
B15: DSRA (원리금상환적립금)
B16: DSRA 잔액(기말) | C16: [KRWm] | F16: =IF(1>=Assum!$F$36+Assum!$F$37,0,G13*Assum!$F$64/12) -> 6983.5277 | G16: =IF(2>=Assum!$F$36+Assum!$F$37,0,H13*Assum!$F$64/12) -> 6902.3795 | H16: =IF(3>=Assum!$F$36+Assum!$F$37,0,I13*Assum!$F$64/12) -> 6820.3624 | I16: =IF(4>=Assum!$F$36+Assum!$F$37,0,J13*Assum!$F$64/12) -> 6737.4283 | J16: =IF(5>=Assum!$F$36+Assum!$F$37,0,K13*Assum!$F$64/12) -> 6653.5269 | K16: =IF(6>=Assum!$F$36+Assum!$F$37,0,L13*Assum!$F$64/12) -> 6568.6058 | L16: =IF(7>=Assum!$F$36+Assum!$F$37,0,M13*Assum!$F$64/12) -> 6482.6101 | M16: =IF(8>=Assum!$F$36+Assum!$F$37,0,N13*Assum!$F$64/12) -> 6395.4824 | N16: =IF(9>=Assum!$F$36+Assum!$F$37,0,O13*Assum!$F$64/12) -> 6307.1628 | O16: =IF(10>=Assum!$F$36+Assum!$F$37,0,P13*Assum!$F$64/12) -> 6217.5886 | P16: =IF(11>=Assum!$F$36+Assum!$F$37,0,Q13*Assum!$F$64/12) -> 6126.6943 | Q16: =IF(12>=Assum!$F$36+Assum!$F$37,0,R13*Assum!$F$64/12) -> 6034.4112 | R16: =IF(13>=Assum!$F$36+Assum!$F$37,0,S13*Assum!$F$64/12) -> 5940.6679 | S16: =IF(14>=Assum!$F$36+Assum!$F$37,0,T13*Assum!$F$64/12) -> 5845.3892 | T16: =IF(15>=Assum!$F$36+Assum!$F$37,0,U13*Assum!$F$64/12) -> 5748.497 | U16: =IF(16>=Assum!$F$36+Assum!$F$37,0,V13*Assum!$F$64/12) -> 5649.9091 | V16: =IF(17>=Assum!$F$36+Assum!$F$37,0,W13*Assum!$F$64/12) -> 0 | W16: =IF(18>=Assum!$F$36+Assum!$F$37,0,X13*Assum!$F$64/12) -> 0 | X16: =IF(19>=Assum!$F$36+Assum!$F$37,0,Y13*Assum!$F$64/12) -> 0 | Y16: =IF(20>=Assum!$F$36+Assum!$F$37,0,0*Assum!$F$64/12) -> 0
B17: DSRA 증감((+)적립/(-)환입) | C17: [KRWm] | D17: =SUM(F17:Y17) -> -5000 | F17: =F16-Assum!$F$23 -> 1983.5277 | G17: =G16-F16 -> -81.148159 | H17: =H16-G16 -> -82.017117 | I17: =I16-H16 -> -82.934134 | J17: =J16-I16 -> -83.901374 | K17: =K16-J16 -> -84.921109 | L17: =L16-K16 -> -85.995712 | M17: =M16-L16 -> -87.127672 | N17: =N16-M16 -> -88.319593 | ... Y17: =Y16-X16 -> 0
B19: 상환 종료 후 미상환 잔액 | C19: [KRWm] | D19: =Y11 -> 9.9999488e-07 | F19: =IF(ABS(D19)<1,"완전상환 확인 (OK)","경고: 미상환 잔액 발생 — 원금상환 행 재산출 필요") -> 완전상환 확인 (OK)
B21: ※ 상환방식 3(DSCR 스컬프팅): 위 원금상환 행(파란 셀)은 균등 DSCR 1.135x 로 완전상환되도록 산출해 넣은 스케줄입니다.
B22: 스컬프팅은 반복계산이 필요해 수식으로 자동 재산출되지 않습니다. Assum의 이용률·금리·단가·상환기간 등을 엑셀에서 바꾸면 이 행은 그대로 남아 D19에 미상환 잔액이 뜹니다.
B23: → 가정을 바꾼 뒤에는 생성기에서 다시 추출하거나, 상환방식 1(원금균등)·2(원리금균등)를 쓰면 엑셀에서 완전히 자동 재계산됩니다.

Sheet IS(Y)
A1: 당진 태양광발전
A2: 추정 손익계산서 (연간)
B4: 손익계산서
B6: 구 분 | C6: unit | D6: 합 계 | E6: 건설기간 | F6: 1년차 | G6: 2년차 | H6: 3년차 | I6: 4년차 | J6: 5년차 | K6: 6년차 | L6: 7년차 | M6: 8년차 | N6: 9년차 | O6: 10년차 | P6: 11년차 | Q6: 12년차 | R6: 13년차 | S6: 14년차 | T6: 15년차 | U6: 16년차 | V6: 17년차 | W6: 18년차 | X6: 19년차 | Y6: 20년차
E7: 2024 | F7: 2025 | G7: 2026 | H7: 2027 | I7: 2028 | J7: 2029 | K7: 2030 | L7: 2031 | M7: 2032 | N7: 2033 | O7: 2034 | P7: 2035 | Q7: 2036 | R7: 2037 | S7: 2038 | T7: 2039 | U7: 2040 | V7: 2041 | W7: 2042 | X7: 2043 | Y7: 2044
B9: 영업수익 | C9: [KRWm] | D9: =SUM(F9:Y9) -> 406418.27 | F9: =Revenue!F16 -> 21303.088 | G9: =Revenue!G16 -> 21196.573 | H9: =Revenue!H16 -> 21090.59 | I9: =Revenue!I16 -> 20985.137 | J9: =Revenue!J16 -> 20880.211 | K9: =Revenue!K16 -> 20775.81 | L9: =Revenue!L16 -> 20671.931 | M9: =Revenue!M16 -> 20568.571 | ... Y9: =Revenue!Y16 -> 19367.836
B10: 영업비용 | C10: [KRWm] | D10: =SUM(F10:Y10) -> -106510.05 | F10: =-Opex!F12 -> -4980 | G10: =-Opex!G12 -> -5014.86 | H10: =-Opex!H12 -> -5049.964 | I10: =-Opex!I12 -> -5085.3138 | J10: =-Opex!J12 -> -5120.911 | K10: =-Opex!K12 -> -5156.7573 | L10: =-Opex!L12 -> -5192.8546 | M10: =-Opex!M12 -> -5229.2046 | ... Y10: =-Opex!Y12 -> -5685.7699
B11: EBITDA | C11: [KRWm] | D11: =SUM(F11:Y11) -> 299908.22 | F11: =F9+F10 -> 16323.088 | G11: =G9+G10 -> 16181.713 | H11: =H9+H10 -> 16040.626 | I11: =I9+I10 -> 15899.823 | J11: =J9+J10 -> 15759.3 | K11: =K9+K10 -> 15619.053 | L11: =L9+L10 -> 15479.076 | M11: =M9+M10 -> 15339.367 | ... Y11: =Y9+Y10 -> 13682.066
B12: 감가상각비 | C12: [KRWm] | D12: =SUM(F12:Y12) -> -138442.36 | F12: =IF(1<=Assum!$F$57,-TIC_Funding!$D$25,0) -> -6922.1179 | G12: =IF(2<=Assum!$F$57,-TIC_Funding!$D$25,0) -> -6922.1179 | H12: =IF(3<=Assum!$F$57,-TIC_Funding!$D$25,0) -> -6922.1179 | I12: =IF(4<=Assum!$F$57,-TIC_Funding!$D$25,0) -> -6922.1179 | J12: =IF(5<=Assum!$F$57,-TIC_Funding!$D$25,0) -> -6922.1179 | K12: =IF(6<=Assum!$F$57,-TIC_Funding!$D$25,0) -> -6922.1179 | L12: =IF(7<=Assum!$F$57,-TIC_Funding!$D$25,0) -> -6922.1179 | M12: =IF(8<=Assum!$F$57,-TIC_Funding!$D$25,0) -> -6922.1179 | N12: =IF(9<=Assum!$F$57,-TIC_Funding!$D$25,0) -> -6922.1179 | O12: =IF(10<=Assum!$F$57,-TIC_Funding!$D$25,0) -> -6922.1179 | P12: =IF(11<=Assum!$F$57,-TIC_Funding!$D$25,0) -> -6922.1179 | Q12: =IF(12<=Assum!$F$57,-TIC_Funding!$D$25,0) -> -6922.1179 | R12: =IF(13<=Assum!$F$57,-TIC_Funding!$D$25,0) -> -6922.1179 | S12: =IF(14<=Assum!$F$57,-TIC_Funding!$D$25,0) -> -6922.1179 | T12: =IF(15<=Assum!$F$57,-TIC_Funding!$D$25,0) -> -6922.1179 | U12: =IF(16<=Assum!$F$57,-TIC_Funding!$D$25,0) -> -6922.1179 | V12: =IF(17<=Assum!$F$57,-TIC_Funding!$D$25,0) -> -6922.1179 | W12: =IF(18<=Assum!$F$57,-TIC_Funding!$D$25,0) -> -6922.1179 | X12: =IF(19<=Assum!$F$57,-TIC_Funding!$D$25,0) -> -6922.1179 | Y12: =IF(20<=Assum!$F$57,-TIC_Funding!$D$25,0) -> -6922.1179
B13: 영업이익(EBIT) | C13: [KRWm] | D13: =SUM(F13:Y13) -> 161465.86 | F13: =F11+F12 -> 9400.9701 | G13: =G11+G12 -> 9259.5947 | H13: =H11+H12 -> 9118.5078 | I13: =I11+I12 -> 8977.7051 | J13: =J11+J12 -> 8837.1822 | K13: =K11+K12 -> 8696.9348 | L13: =L11+L12 -> 8556.9584 | M13: =M11+M12 -> 8417.2488 | ... Y13: =Y11+Y12 -> 6759.948
B14: 이자비용 | C14: [KRWm] | D14: =SUM(F14:Y14) -> -74250.671 | F14: =-Debt!F12 -> -7540.9814 | G14: =-Debt!G12 -> -7404.6473 | H14: =-Debt!H12 -> -7036.82 | I14: =-Debt!I12 -> -6657.4016 | J14: =-Debt!J12 -> -6265.8367 | K14: =-Debt!K12 -> -5861.5439 | L14: =-Debt!L12 -> -5443.9148 | M14: =-Debt!M12 -> -5012.3128 | ... Y14: =-Debt!Y12 -> -5.5399716e-08
B15: 법인세차감전순이익 | C15: [KRWm] | D15: =SUM(F15:Y15) -> 87215.191 | F15: =F13+F14 -> 1859.9888 | G15: =G13+G14 -> 1854.9473 | H15: =H13+H14 -> 2081.6878 | I15: =I13+I14 -> 2320.3035 | J15: =J13+J14 -> 2571.3456 | K15: =K13+K14 -> 2835.3909 | L15: =L13+L14 -> 3113.0436 | M15: =M13+M14 -> 3404.936 | ... Y15: =Y13+Y14 -> 6759.948
B16: 이월결손금(기초) | C16: [KRWm] | F16: 0 | G16: =F20 -> 0 | H16: =G20 -> 0 | I16: =H20 -> 0 | J16: =I20 -> 0 | K16: =J20 -> 0 | L16: =K20 -> 0 | M16: =L20 -> 0 | N16: =M20 -> 0 | ... Y16: =X20 -> 0
B17: 결손금 공제액 | C17: [KRWm] | F17: =MIN(MAX(0,F15)*Assum!$F$60,F16) -> 0 | G17: =MIN(MAX(0,G15)*Assum!$F$60,G16) -> 0 | H17: =MIN(MAX(0,H15)*Assum!$F$60,H16) -> 0 | I17: =MIN(MAX(0,I15)*Assum!$F$60,I16) -> 0 | J17: =MIN(MAX(0,J15)*Assum!$F$60,J16) -> 0 | K17: =MIN(MAX(0,K15)*Assum!$F$60,K16) -> 0 | L17: =MIN(MAX(0,L15)*Assum!$F$60,L16) -> 0 | M17: =MIN(MAX(0,M15)*Assum!$F$60,M16) -> 0 | ... Y17: =MIN(MAX(0,Y15)*Assum!$F$60,Y16) -> 0
B18: 과세표준 | C18: [KRWm] | F18: =MAX(0,F15-F17) -> 1859.9888 | G18: =MAX(0,G15-G17) -> 1854.9473 | H18: =MAX(0,H15-H17) -> 2081.6878 | I18: =MAX(0,I15-I17) -> 2320.3035 | J18: =MAX(0,J15-J17) -> 2571.3456 | K18: =MAX(0,K15-K17) -> 2835.3909 | L18: =MAX(0,L15-L17) -> 3113.0436 | M18: =MAX(0,M15-M17) -> 3404.936 | ... Y18: =MAX(0,Y15-Y17) -> 6759.948
B19: 법인세비용 | C19: [KRWm] | D19: =SUM(F19:Y19) -> 16170.886 | F19: =IF(Assum!$F$58=1,IF(F18<=200,F18*0.09,IF(F18<=20000,18+(F18-200)*0.19,3780+(F18-20000)*0.21)),F18*Assum!$F$59) -> 333.39786 | G19: =IF(Assum!$F$58=1,IF(G18<=200,G18*0.09,IF(G18<=20000,18+(G18-200)*0.19,3780+(G18-20000)*0.21)),G18*Assum!$F$59) -> 332.44 | H19: =IF(Assum!$F$58=1,IF(H18<=200,H18*0.09,IF(H18<=20000,18+(H18-200)*0.19,3780+(H18-20000)*0.21)),H18*Assum!$F$59) -> 375.52068 | I19: =IF(Assum!$F$58=1,IF(I18<=200,I18*0.09,IF(I18<=20000,18+(I18-200)*0.19,3780+(I18-20000)*0.21)),I18*Assum!$F$59) -> 420.85767 | J19: =IF(Assum!$F$58=1,IF(J18<=200,J18*0.09,IF(J18<=20000,18+(J18-200)*0.19,3780+(J18-20000)*0.21)),J18*Assum!$F$59) -> 468.55566 | K19: =IF(Assum!$F$58=1,IF(K18<=200,K18*0.09,IF(K18<=20000,18+(K18-200)*0.19,3780+(K18-20000)*0.21)),K18*Assum!$F$59) -> 518.72428 | L19: =IF(Assum!$F$58=1,IF(L18<=200,L18*0.09,IF(L18<=20000,18+(L18-200)*0.19,3780+(L18-20000)*0.21)),L18*Assum!$F$59) -> 571.47828 | M19: =IF(Assum!$F$58=1,IF(M18<=200,M18*0.09,IF(M18<=20000,18+(M18-200)*0.19,3780+(M18-20000)*0.21)),M18*Assum!$F$59) -> 626.93784 | ... Y19: =IF(Assum!$F$58=1,IF(Y18<=200,Y18*0.09,IF(Y18<=20000,18+(Y18-200)*0.19,3780+(Y18-20000)*0.21)),Y18*Assum!$F$59) -> 1264.3901
B20: 이월결손금(기말) | C20: [KRWm] | F20: =F16-F17+MAX(0,-F15) -> 0 | G20: =G16-G17+MAX(0,-G15) -> 0 | H20: =H16-H17+MAX(0,-H15) -> 0 | I20: =I16-I17+MAX(0,-I15) -> 0 | J20: =J16-J17+MAX(0,-J15) -> 0 | K20: =K16-K17+MAX(0,-K15) -> 0 | L20: =L16-L17+MAX(0,-L15) -> 0 | M20: =M16-M17+MAX(0,-M15) -> 0 | ... Y20: =Y16-Y17+MAX(0,-Y15) -> 0
B21: 당기순이익 | C21: [KRWm] | D21: =SUM(F21:Y21) -> 71044.305 | F21: =F15-F19 -> 1526.5909 | G21: =G15-G19 -> 1522.5073 | H21: =H15-H19 -> 1706.1671 | I21: =I15-I19 -> 1899.4458 | J21: =J15-J19 -> 2102.7899 | K21: =K15-K19 -> 2316.6667 | L21: =L15-L19 -> 2541.5653 | M21: =M15-M19 -> 2777.9982 | ... Y21: =Y15-Y19 -> 5495.5579
B23: EBITDA Margin | C23: [%] | F23: =IFERROR(F11/F9,0) -> 0.76623107 | G23: =IFERROR(G11/G9,0) -> 0.76341175 | H23: =IFERROR(H11/H9,0) -> 0.76055842 | I23: =IFERROR(I11/I9,0) -> 0.75767069 | J23: =IFERROR(J11/J9,0) -> 0.75474812 | K23: =IFERROR(K11/K9,0) -> 0.75179031 | L23: =IFERROR(L11/L9,0) -> 0.74879683 | M23: =IFERROR(M11/M9,0) -> 0.74576724 | ... Y23: =IFERROR(Y11/Y9,0) -> 0.70643236

Sheet CF(Y)
A1: 당진 태양광발전
A2: 추정 현금흐름표 (연간)
B4: 영업활동 현금흐름
B6: 구 분 | C6: unit | D6: 합 계 | E6: 건설기간 | F6: 1년차 | G6: 2년차 | H6: 3년차 | I6: 4년차 | J6: 5년차 | K6: 6년차 | L6: 7년차 | M6: 8년차 | N6: 9년차 | O6: 10년차 | P6: 11년차 | Q6: 12년차 | R6: 13년차 | S6: 14년차 | T6: 15년차 | U6: 16년차 | V6: 17년차 | W6: 18년차 | X6: 19년차 | Y6: 20년차
E7: 2024 | F7: 2025 | G7: 2026 | H7: 2027 | I7: 2028 | J7: 2029 | K7: 2030 | L7: 2031 | M7: 2032 | N7: 2033 | O7: 2034 | P7: 2035 | Q7: 2036 | R7: 2037 | S7: 2038 | T7: 2039 | U7: 2040 | V7: 2041 | W7: 2042 | X7: 2043 | Y7: 2044
B9: EBITDA | C9: [KRWm] | D9: =SUM(F9:Y9) -> 299908.22 | F9: ='IS(Y)'!F11 -> 16323.088 | G9: ='IS(Y)'!G11 -> 16181.713 | H9: ='IS(Y)'!H11 -> 16040.626 | I9: ='IS(Y)'!I11 -> 15899.823 | J9: ='IS(Y)'!J11 -> 15759.3 | K9: ='IS(Y)'!K11 -> 15619.053 | L9: ='IS(Y)'!L11 -> 15479.076 | M9: ='IS(Y)'!M11 -> 15339.367 | ... Y9: ='IS(Y)'!Y11 -> 13682.066
B10: 법인세 지급 | C10: [KRWm] | D10: =SUM(F10:Y10) -> -16170.886 | F10: =-'IS(Y)'!F19 -> -333.39786 | G10: =-'IS(Y)'!G19 -> -332.44 | H10: =-'IS(Y)'!H19 -> -375.52068 | I10: =-'IS(Y)'!I19 -> -420.85767 | J10: =-'IS(Y)'!J19 -> -468.55566 | K10: =-'IS(Y)'!K19 -> -518.72428 | L10: =-'IS(Y)'!L19 -> -571.47828 | M10: =-'IS(Y)'!M19 -> -626.93784 | ... Y10: =-'IS(Y)'!Y19 -> -1264.3901
B11: CFADS (상환가능현금) | C11: [KRWm] | D11: =SUM(F11:Y11) -> 283737.33 | F11: =F9+F10 -> 15989.69 | G11: =G9+G10 -> 15849.273 | H11: =H9+H10 -> 15665.105 | I11: =I9+I10 -> 15478.965 | J11: =J9+J10 -> 15290.744 | K11: =K9+K10 -> 15100.328 | L11: =L9+L10 -> 14907.598 | M11: =M9+M10 -> 14712.429 | ... Y11: =Y9+Y10 -> 12417.676
B12: 재무활동 현금흐름
B13: 원리금 상환 | C13: [KRWm] | D13: =SUM(F13:Y13) -> -210369.47 | F13: =-Debt!F13 -> -7540.9814 | G13: =-Debt!G13 -> -13967.055 | H13: =-Debt!H13 -> -13804.759 | I13: =-Debt!I13 -> -13640.725 | J13: =-Debt!J13 -> -13474.857 | K13: =-Debt!K13 -> -13307.054 | L13: =-Debt!L13 -> -13137.212 | M13: =-Debt!M13 -> -12965.22 | ... Y13: =-Debt!Y13 -> -5.5399716e-08
B14: DSRA 증감 | C14: [KRWm] | D14: =SUM(F14:Y14) -> 5000 | F14: =-Debt!F17 -> -1983.5277 | G14: =-Debt!G17 -> 81.148159 | H14: =-Debt!H17 -> 82.017117 | I14: =-Debt!I17 -> 82.934134 | J14: =-Debt!J17 -> 83.901374 | K14: =-Debt!K17 -> 84.921109 | L14: =-Debt!L17 -> 85.995712 | M14: =-Debt!M17 -> 87.127672 | ... Y14: =-Debt!Y17 -> 0
B15: 철거·복구비 | C15: [KRWm] | D15: =SUM(F15:Y15) -> -2000 | F15: =IF(1=Assum!$F$18,-Assum!$F$51,0) -> 0 | G15: =IF(2=Assum!$F$18,-Assum!$F$51,0) -> 0 | H15: =IF(3=Assum!$F$18,-Assum!$F$51,0) -> 0 | I15: =IF(4=Assum!$F$18,-Assum!$F$51,0) -> 0 | J15: =IF(5=Assum!$F$18,-Assum!$F$51,0) -> 0 | K15: =IF(6=Assum!$F$18,-Assum!$F$51,0) -> 0 | L15: =IF(7=Assum!$F$18,-Assum!$F$51,0) -> 0 | M15: =IF(8=Assum!$F$18,-Assum!$F$51,0) -> 0 | N15: =IF(9=Assum!$F$18,-Assum!$F$51,0) -> 0 | O15: =IF(10=Assum!$F$18,-Assum!$F$51,0) -> 0 | P15: =IF(11=Assum!$F$18,-Assum!$F$51,0) -> 0 | Q15: =IF(12=Assum!$F$18,-Assum!$F$51,0) -> 0 | R15: =IF(13=Assum!$F$18,-Assum!$F$51,0) -> 0 | S15: =IF(14=Assum!$F$18,-Assum!$F$51,0) -> 0 | T15: =IF(15=Assum!$F$18,-Assum!$F$51,0) -> 0 | U15: =IF(16=Assum!$F$18,-Assum!$F$51,0) -> 0 | V15: =IF(17=Assum!$F$18,-Assum!$F$51,0) -> 0 | W15: =IF(18=Assum!$F$18,-Assum!$F$51,0) -> 0 | X15: =IF(19=Assum!$F$18,-Assum!$F$51,0) -> 0 | Y15: =IF(20=Assum!$F$18,-Assum!$F$51,0) -> -2000
B17: 주주귀속 잉여현금(FCFE) | C17: [KRWm] | D17: =SUM(F17:Y17) -> 76367.865 | F17: =F11+F13+F14+F15 -> 6465.1811 | G17: =G11+G13+G14+G15 -> 1963.3653 | H17: =H11+H13+H14+H15 -> 1942.3631 | I17: =I11+I13+I14+I15 -> 1921.1746 | J17: =J11+J13+J14+J15 -> 1899.7893 | K17: =K11+K13+K14+K15 -> 1878.1957 | L17: =L11+L13+L14+L15 -> 1856.3822 | M17: =M11+M13+M14+M15 -> 1834.3363 | ... Y17: =Y11+Y13+Y14+Y15 -> 10417.676
B18: 배당 및 현금계정
B19: 배당금 지급 | C19: [KRWm] | D19: =SUM(F19:Y19) -> 76367.865 | F19: =IF(AND(1>=Assum!$F$67,IF(ISNUMBER(DSCR!F11),DSCR!F11,99)>=Assum!$F$66),MAX(0,F21+F17-IF(1=Assum!$F$18,0,Assum!$F$65)),0) -> 0 | G19: =IF(AND(2>=Assum!$F$67,IF(ISNUMBER(DSCR!G11),DSCR!G11,99)>=Assum!$F$66),MAX(0,G21+G17-IF(2=Assum!$F$18,0,Assum!$F$65)),0) -> 7428.5464 | H19: =IF(AND(3>=Assum!$F$67,IF(ISNUMBER(DSCR!H11),DSCR!H11,99)>=Assum!$F$66),MAX(0,H21+H17-IF(3=Assum!$F$18,0,Assum!$F$65)),0) -> 1942.3631 | I19: =IF(AND(4>=Assum!$F$67,IF(ISNUMBER(DSCR!I11),DSCR!I11,99)>=Assum!$F$66),MAX(0,I21+I17-IF(4=Assum!$F$18,0,Assum!$F$65)),0) -> 1921.1746 | J19: =IF(AND(5>=Assum!$F$67,IF(ISNUMBER(DSCR!J11),DSCR!J11,99)>=Assum!$F$66),MAX(0,J21+J17-IF(5=Assum!$F$18,0,Assum!$F$65)),0) -> 1899.7893 | K19: =IF(AND(6>=Assum!$F$67,IF(ISNUMBER(DSCR!K11),DSCR!K11,99)>=Assum!$F$66),MAX(0,K21+K17-IF(6=Assum!$F$18,0,Assum!$F$65)),0) -> 1878.1957 | L19: =IF(AND(7>=Assum!$F$67,IF(ISNUMBER(DSCR!L11),DSCR!L11,99)>=Assum!$F$66),MAX(0,L21+L17-IF(7=Assum!$F$18,0,Assum!$F$65)),0) -> 1856.3822 | M19: =IF(AND(8>=Assum!$F$67,IF(ISNUMBER(DSCR!M11),DSCR!M11,99)>=Assum!$F$66),MAX(0,M21+M17-IF(8=Assum!$F$18,0,Assum!$F$65)),0) -> 1834.3363 | N19: =IF(AND(9>=Assum!$F$67,IF(ISNUMBER(DSCR!N11),DSCR!N11,99)>=Assum!$F$66),MAX(0,N21+N17-IF(9=Assum!$F$18,0,Assum!$F$65)),0) -> 1812.0454 | O19: =IF(AND(10>=Assum!$F$67,IF(ISNUMBER(DSCR!O11),DSCR!O11,99)>=Assum!$F$66),MAX(0,O21+O17-IF(10=Assum!$F$18,0,Assum!$F$65)),0) -> 1789.4959 | P19: =IF(AND(11>=Assum!$F$67,IF(ISNUMBER(DSCR!P11),DSCR!P11,99)>=Assum!$F$66),MAX(0,P21+P17-IF(11=Assum!$F$18,0,Assum!$F$65)),0) -> 1766.6738 | Q19: =IF(AND(12>=Assum!$F$67,IF(ISNUMBER(DSCR!Q11),DSCR!Q11,99)>=Assum!$F$66),MAX(0,Q21+Q17-IF(12=Assum!$F$18,0,Assum!$F$65)),0) -> 1743.5644 | R19: =IF(AND(13>=Assum!$F$67,IF(ISNUMBER(DSCR!R11),DSCR!R11,99)>=Assum!$F$66),MAX(0,R21+R17-IF(13=Assum!$F$18,0,Assum!$F$65)),0) -> 1720.1524 | S19: =IF(AND(14>=Assum!$F$67,IF(ISNUMBER(DSCR!S11),DSCR!S11,99)>=Assum!$F$66),MAX(0,S21+S17-IF(14=Assum!$F$18,0,Assum!$F$65)),0) -> 1696.4217 | T19: =IF(AND(15>=Assum!$F$67,IF(ISNUMBER(DSCR!T11),DSCR!T11,99)>=Assum!$F$66),MAX(0,T21+T17-IF(15=Assum!$F$18,0,Assum!$F$65)),0) -> 1672.3556 | U19: =IF(AND(16>=Assum!$F$67,IF(ISNUMBER(DSCR!U11),DSCR!U11,99)>=Assum!$F$66),MAX(0,U21+U17-IF(16=Assum!$F$18,0,Assum!$F$65)),0) -> 1647.9366 | V19: =IF(AND(17>=Assum!$F$67,IF(ISNUMBER(DSCR!V11),DSCR!V11,99)>=Assum!$F$66),MAX(0,V21+V17-IF(17=Assum!$F$18,0,Assum!$F$65)),0) -> 7172.6862 | W19: =IF(AND(18>=Assum!$F$67,IF(ISNUMBER(DSCR!W11),DSCR!W11,99)>=Assum!$F$66),MAX(0,W21+W17-IF(18=Assum!$F$18,0,Assum!$F$65)),0) -> 12639.546 | X19: =IF(AND(19>=Assum!$F$67,IF(ISNUMBER(DSCR!X11),DSCR!X11,99)>=Assum!$F$66),MAX(0,X21+X17-IF(19=Assum!$F$18,0,Assum!$F$65)),0) -> 12528.524 | Y19: =IF(AND(20>=Assum!$F$67,IF(ISNUMBER(DSCR!Y11),DSCR!Y11,99)>=Assum!$F$66),MAX(0,Y21+Y17-IF(20=Assum!$F$18,0,Assum!$F$65)),0) -> 11417.676
B21: 기초현금 | C21: [KRWm] | F21: 0 | G21: =F22 -> 6465.1811 | H21: =G22 -> 1000 | I21: =H22 -> 1000 | J21: =I22 -> 1000 | K21: =J22 -> 1000 | L21: =K22 -> 1000 | M21: =L22 -> 1000 | N21: =M22 -> 1000 | ... Y21: =X22 -> 1000
B22: 기말현금 | C22: [KRWm] | F22: =F21+F17-F19 -> 6465.1811 | G22: =G21+G17-G19 -> 1000 | H22: =H21+H17-H19 -> 1000 | I22: =I21+I17-I19 -> 1000 | J22: =J21+J17-J19 -> 1000 | K22: =K21+K17-K19 -> 1000 | L22: =L21+L17-L19 -> 1000 | M22: =M21+M17-M19 -> 1000 | ... Y22: =Y21+Y17-Y19 -> 0
B23: DSRA 잔액 | C23: [KRWm] | F23: =Debt!F16 -> 6983.5277 | G23: =Debt!G16 -> 6902.3795 | H23: =Debt!H16 -> 6820.3624 | I23: =Debt!I16 -> 6737.4283 | J23: =Debt!J16 -> 6653.5269 | K23: =Debt!K16 -> 6568.6058 | L23: =Debt!L16 -> 6482.6101 | M23: =Debt!M16 -> 6395.4824 | ... Y23: =Debt!Y16 -> 0

Sheet DSCR
A1: 당진 태양광발전
A2: 원리금 상환능력 분석
B4: DSCR
B6: 구 분 | C6: unit | D6: 합 계 | E6: 건설기간 | F6: 1년차 | G6: 2년차 | H6: 3년차 | I6: 4년차 | J6: 5년차 | K6: 6년차 | L6: 7년차 | M6: 8년차 | N6: 9년차 | O6: 10년차 | P6: 11년차 | Q6: 12년차 | R6: 13년차 | S6: 14년차 | T6: 15년차 | U6: 16년차 | V6: 17년차 | W6: 18년차 | X6: 19년차 | Y6: 20년차
E7: 2024 | F7: 2025 | G7: 2026 | H7: 2027 | I7: 2028 | J7: 2029 | K7: 2030 | L7: 2031 | M7: 2032 | N7: 2033 | O7: 2034 | P7: 2035 | Q7: 2036 | R7: 2037 | S7: 2038 | T7: 2039 | U7: 2040 | V7: 2041 | W7: 2042 | X7: 2043 | Y7: 2044
B9: CFADS | C9: [KRWm] | F9: ='CF(Y)'!F11 -> 15989.69 | G9: ='CF(Y)'!G11 -> 15849.273 | H9: ='CF(Y)'!H11 -> 15665.105 | I9: ='CF(Y)'!I11 -> 15478.965 | J9: ='CF(Y)'!J11 -> 15290.744 | K9: ='CF(Y)'!K11 -> 15100.328 | L9: ='CF(Y)'!L11 -> 14907.598 | M9: ='CF(Y)'!M11 -> 14712.429 | ... Y9: ='CF(Y)'!Y11 -> 12417.676
B10: 원리금(DS) | C10: [KRWm] | F10: =Debt!F13 -> 7540.9814 | G10: =Debt!G13 -> 13967.055 | H10: =Debt!H13 -> 13804.759 | I10: =Debt!I13 -> 13640.725 | J10: =Debt!J13 -> 13474.857 | K10: =Debt!K13 -> 13307.054 | L10: =Debt!L13 -> 13137.212 | M10: =Debt!M13 -> 12965.22 | ... Y10: =Debt!Y13 -> 5.5399716e-08
B11: 단순 DSCR | C11: [x] | F11: =IF(F10<=0.001,"-",F9/F10) -> 2.1203726 | G11: =IF(G10<=0.001,"-",G9/G10) -> 1.1347612 | H11: =IF(H10<=0.001,"-",H9/H10) -> 1.1347612 | I11: =IF(I10<=0.001,"-",I9/I10) -> 1.1347612 | J11: =IF(J10<=0.001,"-",J9/J10) -> 1.1347612 | K11: =IF(K10<=0.001,"-",K9/K10) -> 1.1347612 | L11: =IF(L10<=0.001,"-",L9/L10) -> 1.1347612 | M11: =IF(M10<=0.001,"-",M9/M10) -> 1.1347612 | ... Y11: =IF(Y10<=0.001,"-",Y9/Y10) -> -
B13: 최소 DSCR | C13: [x] | D13: =MIN(F11:Y11) -> 1.1347612
B14: 평균 DSCR | C14: [x] | D14: =IFERROR(AVERAGE(F11:Y11),0) -> 1.1927383
B16: ※ 상환이 없는 연도는 "-"로 표시되며 최소/평균 산출에서 제외됩니다.

Sheet IRR
A1: 당진 태양광발전
A2: 수익성 분석 (IRR / NPV)
B4: Project IRR
B6: 구 분 | C6: unit | D6: 합 계 | E6: 건설기간 | F6: 1년차 | G6: 2년차 | H6: 3년차 | I6: 4년차 | J6: 5년차 | K6: 6년차 | L6: 7년차 | M6: 8년차 | N6: 9년차 | O6: 10년차 | P6: 11년차 | Q6: 12년차 | R6: 13년차 | S6: 14년차 | T6: 15년차 | U6: 16년차 | V6: 17년차 | W6: 18년차 | X6: 19년차 | Y6: 20년차
E7: 2024 | F7: 2025 | G7: 2026 | H7: 2027 | I7: 2028 | J7: 2029 | K7: 2030 | L7: 2031 | M7: 2032 | N7: 2033 | O7: 2034 | P7: 2035 | Q7: 2036 | R7: 2037 | S7: 2038 | T7: 2039 | U7: 2040 | V7: 2041 | W7: 2042 | X7: 2043 | Y7: 2044
B9: 총투자비 | C9: [KRWm] | E9: =-TIC_Funding!$D$10+Assum!$F$23 -> -145728.8 | F9: 0 | G9: 0 | H9: 0 | I9: 0 | J9: 0 | K9: 0 | L9: 0 | M9: 0 | N9: 0 | O9: 0 | P9: 0 | Q9: 0 | R9: 0 | S9: 0 | T9: 0 | U9: 0 | V9: 0 | W9: 0 | X9: 0 | Y9: 0
B10: EBITDA | C10: [KRWm] | E10: 0 | F10: ='IS(Y)'!F11 -> 16323.088 | G10: ='IS(Y)'!G11 -> 16181.713 | H10: ='IS(Y)'!H11 -> 16040.626 | I10: ='IS(Y)'!I11 -> 15899.823 | J10: ='IS(Y)'!J11 -> 15759.3 | K10: ='IS(Y)'!K11 -> 15619.053 | L10: ='IS(Y)'!L11 -> 15479.076 | M10: ='IS(Y)'!M11 -> 15339.367 | ... Y10: ='IS(Y)'!Y11 -> 13682.066
B11: 법인세 | C11: [KRWm] | E11: 0 | F11: =-'IS(Y)'!F19 -> -333.39786 | G11: =-'IS(Y)'!G19 -> -332.44 | H11: =-'IS(Y)'!H19 -> -375.52068 | I11: =-'IS(Y)'!I19 -> -420.85767 | J11: =-'IS(Y)'!J19 -> -468.55566 | K11: =-'IS(Y)'!K19 -> -518.72428 | L11: =-'IS(Y)'!L19 -> -571.47828 | M11: =-'IS(Y)'!M19 -> -626.93784 | ... Y11: =-'IS(Y)'!Y19 -> -1264.3901
B12: 철거·복구비 | C12: [KRWm] | E12: 0 | F12: ='CF(Y)'!F15 -> 0 | G12: ='CF(Y)'!G15 -> 0 | H12: ='CF(Y)'!H15 -> 0 | I12: ='CF(Y)'!I15 -> 0 | J12: ='CF(Y)'!J15 -> 0 | K12: ='CF(Y)'!K15 -> 0 | L12: ='CF(Y)'!L15 -> 0 | M12: ='CF(Y)'!M15 -> 0 | ... Y12: ='CF(Y)'!Y15 -> -2000
B13: Net Cashflow | C13: [KRWm] | E13: =SUM(E9:E12) -> -145728.8 | F13: =SUM(F9:F12) -> 15989.69 | G13: =SUM(G9:G12) -> 15849.273 | H13: =SUM(H9:H12) -> 15665.105 | I13: =SUM(I9:I12) -> 15478.965 | J13: =SUM(J9:J12) -> 15290.744 | K13: =SUM(K9:K12) -> 15100.328 | L13: =SUM(L9:L12) -> 14907.598 | ... Y13: =SUM(Y9:Y12) -> 10417.676
B15: Project IRR (세후) | C15: [%] | D15: =IRR(E13:Y13) -> 0.077942281
B16: NPV @ 할인율 | C16: [KRWm] | D16: =NPV(Assum!$F$71,F13:Y13)+E13 -> 27240.177
B18: Equity IRR
B20: 자본금 납입 | C20: [KRWm] | E20: =-TIC_Funding!$D$15 -> -14610 | F20: 0 | G20: 0 | H20: 0 | I20: 0 | J20: 0 | K20: 0 | L20: 0 | M20: 0 | N20: 0 | O20: 0 | P20: 0 | Q20: 0 | R20: 0 | S20: 0 | T20: 0 | U20: 0 | V20: 0 | W20: 0 | X20: 0 | Y20: 0
B21: FCFE | C21: [KRWm] | E21: 0 | F21: ='CF(Y)'!F17 -> 6465.1811 | G21: ='CF(Y)'!G17 -> 1963.3653 | H21: ='CF(Y)'!H17 -> 1942.3631 | I21: ='CF(Y)'!I17 -> 1921.1746 | J21: ='CF(Y)'!J17 -> 1899.7893 | K21: ='CF(Y)'!K17 -> 1878.1957 | L21: ='CF(Y)'!L17 -> 1856.3822 | M21: ='CF(Y)'!M17 -> 1834.3363 | ... Y21: ='CF(Y)'!Y17 -> 10417.676
B22: Net Cashflow (FCFE base) | C22: [KRWm] | E22: =E20+E21 -> -14610 | F22: =F20+F21 -> 6465.1811 | G22: =G20+G21 -> 1963.3653 | H22: =H20+H21 -> 1942.3631 | I22: =I20+I21 -> 1921.1746 | J22: =J20+J21 -> 1899.7893 | K22: =K20+K21 -> 1878.1957 | L22: =L20+L21 -> 1856.3822 | ... Y22: =Y20+Y21 -> 10417.676
B24: 배당금 | C24: [KRWm] | E24: =-TIC_Funding!$D$15 -> -14610 | F24: ='CF(Y)'!F19 -> 0 | G24: ='CF(Y)'!G19 -> 7428.5464 | H24: ='CF(Y)'!H19 -> 1942.3631 | I24: ='CF(Y)'!I19 -> 1921.1746 | J24: ='CF(Y)'!J19 -> 1899.7893 | K24: ='CF(Y)'!K19 -> 1878.1957 | L24: ='CF(Y)'!L19 -> 1856.3822 | M24: ='CF(Y)'!M19 -> 1834.3363 | ... Y24: ='CF(Y)'!Y19 -> 11417.676
B26: Equity IRR (FCFE 기준) | C26: [%] | D26: =IRR(E22:Y22) -> 0.19310569
B27: Equity IRR (배당 기준) | C27: [%] | D27: =IRR(E24:Y24) -> 0.17303465

Sheet Sensitivity
A1: 당진 태양광발전
A2: 민감도 분석 (재무모델 생성기 산출값)
B4: 이용률
B6: 변동값 | C6: Equity IRR | D6: Project IRR | E6: 최소 DSCR | F6: NPV [KRWm]
B7: 14.14 % | C7: 0.078177651 | D7: 0.061336975 | E7: 1.0053165 | F7: 7295.0366
B8: 14.92 % | C8: 0.13175597 | D8: 0.069748585 | E8: 1.0697021 | F8: 17247.446
B9: 15.71 % | C9: 0.19310569 | D9: 0.077942281 | E9: 1.1347612 | F9: 27240.177
B10: 16.50 % | C10: 0.26032914 | D10: 0.085918297 | E10: 1.1998079 | F10: 37231.321
B11: 17.28 % | C11: 0.32965597 | D11: 0.093606071 | E11: 1.2640208 | F11: 47094.679
B14: 차입 금리
B16: 변동값 | C16: Equity IRR | D16: Project IRR | E16: 최소 DSCR | F16: NPV [KRWm]
B17: 4.43 % | C17: 0.26717618 | D17: 0.076100165 | E17: 1.2068284 | F17: 25083.004
B18: 4.99 % | C18: 0.22837399 | D18: 0.07702387 | E18: 1.1694354 | F18: 26164.818
B19: 5.54 % | C19: 0.19310569 | D19: 0.077942281 | E19: 1.1347612 | F19: 27240.177
B20: 6.09 % | C20: 0.16100885 | D20: 0.078871348 | E20: 1.1019826 | F20: 28327.826
B21: 6.65 % | C21: 0.13169884 | D21: 0.079827802 | E21: 1.0704254 | F21: 29447.411
B24: 매출 단가
B26: 변동값 | C26: Equity IRR | D26: Project IRR | E26: 최소 DSCR | F26: NPV [KRWm]
B27: 139.32 원/kWh | C27: 0.078111376 | D27: 0.061325578 | E27: 1.0052312 | F27: 7281.7783
B28: 147.06 원/kWh | C28: 0.13208447 | D28: 0.069795932 | E28: 1.0700728 | F28: 17304.372
B29: 154.80 원/kWh | C29: 0.19310569 | D29: 0.077942281 | E29: 1.1347612 | F29: 27240.177
B30: 162.54 원/kWh | C30: 0.25993506 | D30: 0.085873428 | E30: 1.1994374 | F30: 37174.413
B31: 170.28 원/kWh | C31: 0.32974568 | D31: 0.093615817 | E31: 1.2641032 | F31: 47107.323
B34: ※ 민감도 표는 각 케이스를 별도 계산한 결과값이며 수식으로 연결되어 있지 않습니다.
