Workbook

Sheet 목차
B2: 당진 태양광발전
B3: 재무모델 v2 (분기·5트랜치) — 재생E AI Agent 자동생성 · 2026-08-27
B6: 시트 | C6: 내용
B7: Report | C7: Executive Summary — 핵심 KPI
B8: 입력값 | C8: 화면에서 입력한 원본 값 — Funding 등이 이 시트를 참조
B9: Funding | C9: 자금조달 — 자본금 + 5트랜치 조건
B10: Debt | C10: 트랜치별 상환 스케줄 (A/B/C/D/후순위) + 합계
B11: Revenue | C11: 발전량 · 매출
B12: Opex | C12: 운영비 (선순위/후순위)
B13: IS(Q) | C13: 분기 손익계산서
B14: CF(Q) | C14: 분기 현금흐름 · DSCR · 배당
B16: ※ Funding 시트의 트랜치 조건·총사업비 항목·사업자 지분은 "입력값" 시트를 참조하는 수식입니다(입력값 시트를 고치면 같이 바뀝니다). 그 외 계산 결과(세금·DSCR·배당 등)는 값(baked) 기준이라 가정을 바꾸려면 생성기에서 다시 뽑아야 합니다.

Sheet Report
A1: 당진 태양광발전
A2: Executive Summary (v2 · 분기 · 5트랜치)
B4: 사업 개요
B6: 사업명 | D6: ='입력값'!C6
B7: 설비용량 [MW] | D7: ='입력값'!C7
B8: 총 기간 수(분기) | D8: 86
B9: 건설 개시 | D9: 2024-06
B11: 재원조달
B13: 총투자비(TIC) [KRWm] | D13: ='Funding'!C18
B14: 건설이자(IDC) [KRWm] | D14: ='Funding'!C17
B15: 자기자본 [KRWm] | D15: ='Funding'!C7
B16: 차입금 합계 [KRWm] | D16: ='Funding'!C13
B18: 수익성 지표
B20: Project IRR 세전 [%] | D20: ='CF(Q)'!D62
B21: Project IRR 세후 [%] | D21: ='CF(Q)'!D63
B22: Equity IRR (FCFE) [%] | D22: ='CF(Q)'!D64
B23: Equity IRR (배당) [%] | D23: ='CF(Q)'!D65
B24: Investor IRR [%] | D24: ='CF(Q)'!D66
B25: 최소 단순DSCR(연 합산) [x] | D25: ='CF(Q)'!D47
B26: 최소 누적DSCR [x] | D26: ='CF(Q)'!D48
B27: 총영업수익(전체기간) [KRWm] | D27: ='Revenue'!D12
B28: 총영업비용(전체기간) [KRWm] | D28: ='Opex'!D24
B29: 총선순위이자 [KRWm] | D29: ='Debt'!D76
B30: 총법인세 [KRWm] | D30: =-'IS(Q)'!D44
B31: 총배당(연차+청산) [KRWm] | D31: ='CF(Q)'!D16

Sheet 입력값
A1: 당진 태양광발전
A2: 입력값 — 화면에서 입력한 값 (다른 시트가 이 시트를 참조)
B4: 사업 기본 가정
B6: 사업명 | C6: 당진 태양광발전
B7: 설비용량[MW] | C7: 99.998
B8: 총사업비[억원] | C8: 1410.6882
B9: 자기자본[억원] | C9: 150
B10: 판매단가[원/kWh]
B11: 판매단가 에스컬레이션[%/yr]
B12: 발전량 열화율[%/yr] | C12: 0.5
B13: 소내소비율[%] | C13: 0
B14: 일조시간[h/day] | C14: 3.77
B15: 상각대상액(직접입력)[KRWm] | C15: 137976.35
B16: 감가상각 내용연수[yr] | C16: 20
B17: 철거비(복구충당부채)[억원] | C17: 20
B18: 대리은행수수료(총액)[KRWm] | C18: 320
B19: 기타 비현금 세무손금(총액)[KRWm] | C19: 6743.65
B20: DSRA 최초 적립액[억원] | C20: 50
B21: DSRA 적립기준(차기 X개월분) | C21: 6
B22: 최소 보유현금[억원] | C22: 10
B23: 배당 게이트 — 단순DSCR 최소치[x] | C23: 1.1
... B26: 최초 배당 가능 연도 | C26: 2028
B28: 법인세 가정
B30: 이월결손금 공제한도[%] | C30: 80
B31: 최저한세율[%] | C31: 10
B32: 통합투자세액공제율[%] | C32: 1
B33: 지방소득세율(법인세 대비)[%] | C33: 10
B34: 세액공제 농특세율[%] | C34: 20
B36: 건설기간 손실(연도별)
B38: 연도 | C38: 금액[KRWm]
B39: 2024 | C39: 140
B40: 2025 | C40: 140
B42: 통합투자세액공제 기준액(연도별)
B44: 연도 | C44: 금액[KRWm]
B45: 2024 | C45: 43600
B46: 2025 | C46: 65400
B48: 판매단가 트랙 (PPA/SMP+REC 등)
B50: 트랙 | C50: 비중[%] | D50: 단가[원/kWh] | E50: 에스컬레이션[%/yr]
B51: 트랙1 | C51: 0 | D51: 0 | E51: 0
B52: 트랙2 | C52: 60.0012 | D52: 160 | E52: 0
...

Sheet Funding
A1: 당진 태양광발전
A2: 자금조달 — 자본금 + 5개 트랜치
B4: 트랜치 조건
B6: 트랜치 | C6: 금액[KRWm] | D6: 투입순서 | E6: 건설금리 | F6: 운영금리 | G6: 거치(yr) | H6: 상환(yr) | I6: 방식 | J6: 상환개시
B7: 자본금 | C7: ='입력값'!C9*100
B8: 선순위A | C8: ='입력값'!C58*100 | E8: ='입력값'!D58 | F8: ='입력값'!E58 | G8: ='입력값'!F58 | H8: ='입력값'!G58 | I8: ='입력값'!H58 | J8: 2026-09-30
B9: 선순위B | C9: ='입력값'!C59*100 | E9: ='입력값'!D59 | F9: ='입력값'!E59 | G9: ='입력값'!F59 | H9: ='입력값'!G59 | I9: ='입력값'!H59 | J9: 2026-09-30
B10: 선순위C | C10: ='입력값'!C60*100 | E10: ='입력값'!D60 | F10: ='입력값'!E60 | G10: ='입력값'!F60 | H10: ='입력값'!G60 | I10: ='입력값'!H60 | J10: 2026-09-30
B11: 선순위D | C11: ='입력값'!C61*100 | E11: ='입력값'!D61 | F11: ='입력값'!E61 | G11: ='입력값'!F61 | H11: ='입력값'!G61 | I11: ='입력값'!H61 | J11: -
B12: 후순위 | C12: ='입력값'!C62*100 | E12: ='입력값'!D62 | F12: ='입력값'!E62 | G12: ='입력값'!F62 | H12: ='입력값'!G62 | I12: ='입력값'!H62 | J12: -
B13: 차입금 합계 | C13: =C8+C9+C10+C11+C12
B15: 건설이자(IDC)
B17: IDC 합계[KRWm] | C17: ='Debt'!D15
B18: 총투자비(TIC)[KRWm] | C18: ='입력값'!C8*100+'Debt'!D15
B19: 총사업비(건설이자 제외)[KRWm] | C19: ='입력값'!C8*100
B21: 총사업비 세부내역
B23: 항목 | C23: 금액[KRWm]
B24: ='입력값'!B82
B25: ='입력값'!B83
B26: ='입력값'!B84
B27: ='입력값'!B85
B28: ='입력값'!B86
B29: ='입력값'!B87
B30: ='입력값'!B88
B31: ='입력값'!B89
B32: ='입력값'!B90
B33: ='입력값'!B91
B34: ='입력값'!B92
B35: ='입력값'!B93
B36: 합계 | C36: ='입력값'!C8*100

Sheet Debt
A1: 당진 태양광발전
A2: 차입금 상환 스케줄 — 건설기간 인출 + 트랜치별 상환
B4: 건설기간 자금조달 (인출·건설이자)
B6: 구 분 | C6: unit | D6: 합 계 | E6: 2024-06-30 | F6: 2024-09-30 | G6: 2024-12-31 | H6: 2025-03-31 | I6: 2025-06-30 | J6: 2025-09-30 | K6: 2025-12-31 | L6: 2026-03-31 | M6: 2026-06-30 | N6: 2026-09-30 | O6: 2026-12-31 | P6: 2027-03-31 | Q6: 2027-06-30 | R6: 2027-09-30 | S6: 2027-12-31 | T6: 2028-03-31 | U6: 2028-06-30 | V6: 2028-09-30 | W6: 2028-12-31 | X6: 2029-03-31 | Y6: 2029-06-30 | Z6: 2029-09-30 | AA6: 2029-12-31 | AB6: 2030-03-31 | AC6: 2030-06-30 | AD6: 2030-09-30 | AE6: 2030-12-31 | AF6: 2031-03-31 | AG6: 2031-06-30 | AH6: 2031-09-30 | AI6: 2031-12-31 | AJ6: 2032-03-31 | AK6: 2032-06-30 | AL6: 2032-09-30 | AM6: 2032-12-31 | AN6: 2033-03-31 | AO6: 2033-06-30 | AP6: 2033-09-30 | AQ6: 2033-12-31 | AR6: 2034-03-31 | AS6: 2034-06-30 | AT6: 2034-09-30 | AU6: 2034-12-31 | AV6: 2035-03-31 | AW6: 2035-06-30 | AX6: 2035-09-30 | AY6: 2035-12-31 | AZ6: 2036-03-31 | BA6: 2036-06-30 | BB6: 2036-09-30 | BC6: 2036-12-31 | BD6: 2037-03-31 | BE6: 2037-06-30 | BF6: 2037-09-30 | BG6: 2037-12-31 | BH6: 2038-03-31 | BI6: 2038-06-30 | BJ6: 2038-09-30 | BK6: 2038-12-31 | BL6: 2039-03-31 | BM6: 2039-06-30 | BN6: 2039-09-30 | BO6: 2039-12-31 | BP6: 2040-03-31 | BQ6: 2040-06-30 | BR6: 2040-09-30 | BS6: 2040-12-31 | BT6: 2041-03-31 | BU6: 2041-06-30 | BV6: 2041-09-30 | BW6: 2041-12-31 | BX6: 2042-03-31 | BY6: 2042-06-30 | BZ6: 2042-09-30 | CA6: 2042-12-31 | CB6: 2043-03-31 | CC6: 2043-06-30 | CD6: 2043-09-30 | CE6: 2043-12-31 | CF6: 2044-03-31 | CG6: 2044-06-30 | CH6: 2044-09-30 | CI6: 2044-12-31 | CJ6: 2045-03-31 | CK6: 2045-06-30 | CL6: 2045-09-30
B8: 공사비 지출 | C8: [KRWm] | D8: =SUM(E8:CL8) | E8: ='입력값'!E69*'입력값'!C8*100 | F8: ='입력값'!F69*'입력값'!C8*100 | G8: ='입력값'!G69*'입력값'!C8*100 | H8: ='입력값'!H69*'입력값'!C8*100 | I8: ='입력값'!I69*'입력값'!C8*100 | J8: ='입력값'!J69*'입력값'!C8*100 | K8: ='입력값'!K69*'입력값'!C8*100 | L8: ='입력값'!L69*'입력값'!C8*100 | M8: ='입력값'!M69*'입력값'!C8*100 | N8: ='입력값'!N69*'입력값'!C8*100 | O8: ='입력값'!O69*'입력값'!C8*100 | P8: ='입력값'!P69*'입력값'!C8*100 | Q8: ='입력값'!Q69*'입력값'!C8*100 | R8: ='입력값'!R69*'입력값'!C8*100 | S8: ='입력값'!S69*'입력값'!C8*100 | T8: ='입력값'!T69*'입력값'!C8*100 | U8: ='입력값'!U69*'입력값'!C8*100 | V8: ='입력값'!V69*'입력값'!C8*100 | W8: ='입력값'!W69*'입력값'!C8*100 | X8: ='입력값'!X69*'입력값'!C8*100 | Y8: ='입력값'!Y69*'입력값'!C8*100 | Z8: ='입력값'!Z69*'입력값'!C8*100 | AA8: ='입력값'!AA69*'입력값'!C8*100 | AB8: ='입력값'!AB69*'입력값'!C8*100 | AC8: ='입력값'!AC69*'입력값'!C8*100 | AD8: ='입력값'!AD69*'입력값'!C8*100 | AE8: ='입력값'!AE69*'입력값'!C8*100 | AF8: ='입력값'!AF69*'입력값'!C8*100 | AG8: ='입력값'!AG69*'입력값'!C8*100 | AH8: ='입력값'!AH69*'입력값'!C8*100 | AI8: ='입력값'!AI69*'입력값'!C8*100 | AJ8: ='입력값'!AJ69*'입력값'!C8*100 | AK8: ='입력값'!AK69*'입력값'!C8*100 | AL8: ='입력값'!AL69*'입력값'!C8*100 | AM8: ='입력값'!AM69*'입력값'!C8*100 | AN8: ='입력값'!AN69*'입력값'!C8*100 | AO8: ='입력값'!AO69*'입력값'!C8*100 | AP8: ='입력값'!AP69*'입력값'!C8*100 | AQ8: ='입력값'!AQ69*'입력값'!C8*100 | AR8: ='입력값'!AR69*'입력값'!C8*100 | AS8: ='입력값'!AS69*'입력값'!C8*100 | AT8: ='입력값'!AT69*'입력값'!C8*100 | AU8: ='입력값'!AU69*'입력값'!C8*100 | AV8: ='입력값'!AV69*'입력값'!C8*100 | AW8: ='입력값'!AW69*'입력값'!C8*100 | AX8: ='입력값'!AX69*'입력값'!C8*100 | AY8: ='입력값'!AY69*'입력값'!C8*100 | AZ8: ='입력값'!AZ69*'입력값'!C8*100 | BA8: ='입력값'!BA69*'입력값'!C8*100 | BB8: ='입력값'!BB69*'입력값'!C8*100 | BC8: ='입력값'!BC69*'입력값'!C8*100 | BD8: ='입력값'!BD69*'입력값'!C8*100 | BE8: ='입력값'!BE69*'입력값'!C8*100 | BF8: ='입력값'!BF69*'입력값'!C8*100 | BG8: ='입력값'!BG69*'입력값'!C8*100 | BH8: ='입력값'!BH69*'입력값'!C8*100 | BI8: ='입력값'!BI69*'입력값'!C8*100 | BJ8: ='입력값'!BJ69*'입력값'!C8*100 | BK8: ='입력값'!BK69*'입력값'!C8*100 | BL8: ='입력값'!BL69*'입력값'!C8*100 | BM8: ='입력값'!BM69*'입력값'!C8*100 | BN8: ='입력값'!BN69*'입력값'!C8*100 | BO8: ='입력값'!BO69*'입력값'!C8*100 | BP8: ='입력값'!BP69*'입력값'!C8*100 | BQ8: ='입력값'!BQ69*'입력값'!C8*100 | BR8: ='입력값'!BR69*'입력값'!C8*100 | BS8: ='입력값'!BS69*'입력값'!C8*100 | BT8: ='입력값'!BT69*'입력값'!C8*100 | BU8: ='입력값'!BU69*'입력값'!C8*100 | BV8: ='입력값'!BV69*'입력값'!C8*100 | BW8: ='입력값'!BW69*'입력값'!C8*100 | BX8: ='입력값'!BX69*'입력값'!C8*100 | BY8: ='입력값'!BY69*'입력값'!C8*100 | BZ8: ='입력값'!BZ69*'입력값'!C8*100 | CA8: ='입력값'!CA69*'입력값'!C8*100 | CB8: ='입력값'!CB69*'입력값'!C8*100 | CC8: ='입력값'!CC69*'입력값'!C8*100 | CD8: ='입력값'!CD69*'입력값'!C8*100 | CE8: ='입력값'!CE69*'입력값'!C8*100 | CF8: ='입력값'!CF69*'입력값'!C8*100 | CG8: ='입력값'!CG69*'입력값'!C8*100 | CH8: ='입력값'!CH69*'입력값'!C8*100 | CI8: ='입력값'!CI69*'입력값'!C8*100 | CJ8: ='입력값'!CJ69*'입력값'!C8*100 | CK8: ='입력값'!CK69*'입력값'!C8*100 | CL8: ='입력값'!CL69*'입력값'!C8*100
B9: DSRA 적립 | C9: [KRWm] | D9: =SUM(E9:CL9) | E9: 0 | F9: 0 | G9: 0 | H9: 0 | I9: 0 | J9: ='입력값'!C20*100 | K9: 0 | L9: 0 | M9: 0 | N9: 0 | O9: 0 | P9: 0 | Q9: 0 | R9: 0 | S9: 0 | T9: 0 | U9: 0 | V9: 0 | W9: 0 | X9: 0 | Y9: 0 | Z9: 0 | AA9: 0 | AB9: 0 | AC9: 0 | AD9: 0 | AE9: 0 | AF9: 0 | AG9: 0 | AH9: 0 | AI9: 0 | AJ9: 0 | AK9: 0 | AL9: 0 | AM9: 0 | AN9: 0 | AO9: 0 | AP9: 0 | AQ9: 0 | AR9: 0 | AS9: 0 | AT9: 0 | AU9: 0 | AV9: 0 | AW9: 0 | AX9: 0 | AY9: 0 | AZ9: 0 | BA9: 0 | BB9: 0 | BC9: 0 | BD9: 0 | BE9: 0 | BF9: 0 | BG9: 0 | BH9: 0 | BI9: 0 | BJ9: 0 | BK9: 0 | BL9: 0 | BM9: 0 | BN9: 0 | BO9: 0 | BP9: 0 | BQ9: 0 | BR9: 0 | BS9: 0 | BT9: 0 | BU9: 0 | BV9: 0 | BW9: 0 | BX9: 0 | BY9: 0 | BZ9: 0 | CA9: 0 | CB9: 0 | CC9: 0 | CD9: 0 | CE9: 0 | CF9: 0 | CG9: 0 | CH9: 0 | CI9: 0 | CJ9: 0 | CK9: 0 | CL9: 0
B10: 선순위A 건설이자 | C10: [KRWm] | D10: =SUM(E10:CL10) | E10: 0 | F10: =E18*'입력값'!D58/4 | G10: =F18*'입력값'!D58/4 | H10: =G18*'입력값'!D58/4 | I10: =H18*'입력값'!D58/4 | J10: =I18*'입력값'!D58/4 | K10: 0 | L10: 0 | M10: 0 | N10: 0 | O10: 0 | P10: 0 | Q10: 0 | R10: 0 | S10: 0 | T10: 0 | U10: 0 | V10: 0 | W10: 0 | X10: 0 | Y10: 0 | Z10: 0 | AA10: 0 | AB10: 0 | AC10: 0 | AD10: 0 | AE10: 0 | AF10: 0 | AG10: 0 | AH10: 0 | AI10: 0 | AJ10: 0 | AK10: 0 | AL10: 0 | AM10: 0 | AN10: 0 | AO10: 0 | AP10: 0 | AQ10: 0 | AR10: 0 | AS10: 0 | AT10: 0 | AU10: 0 | AV10: 0 | AW10: 0 | AX10: 0 | AY10: 0 | AZ10: 0 | BA10: 0 | BB10: 0 | BC10: 0 | BD10: 0 | BE10: 0 | BF10: 0 | BG10: 0 | BH10: 0 | BI10: 0 | BJ10: 0 | BK10: 0 | BL10: 0 | BM10: 0 | BN10: 0 | BO10: 0 | BP10: 0 | BQ10: 0 | BR10: 0 | BS10: 0 | BT10: 0 | BU10: 0 | BV10: 0 | BW10: 0 | BX10: 0 | BY10: 0 | BZ10: 0 | CA10: 0 | CB10: 0 | CC10: 0 | CD10: 0 | CE10: 0 | CF10: 0 | CG10: 0 | CH10: 0 | CI10: 0 | CJ10: 0 | CK10: 0 | CL10: 0
B11: 선순위B 건설이자 | C11: [KRWm] | D11: =SUM(E11:CL11) | E11: 0 | F11: =E19*'입력값'!D59/4 | G11: =F19*'입력값'!D59/4 | H11: =G19*'입력값'!D59/4 | I11: =H19*'입력값'!D59/4 | J11: =I19*'입력값'!D59/4 | K11: 0 | L11: 0 | M11: 0 | N11: 0 | O11: 0 | P11: 0 | Q11: 0 | R11: 0 | S11: 0 | T11: 0 | U11: 0 | V11: 0 | W11: 0 | X11: 0 | Y11: 0 | Z11: 0 | AA11: 0 | AB11: 0 | AC11: 0 | AD11: 0 | AE11: 0 | AF11: 0 | AG11: 0 | AH11: 0 | AI11: 0 | AJ11: 0 | AK11: 0 | AL11: 0 | AM11: 0 | AN11: 0 | AO11: 0 | AP11: 0 | AQ11: 0 | AR11: 0 | AS11: 0 | AT11: 0 | AU11: 0 | AV11: 0 | AW11: 0 | AX11: 0 | AY11: 0 | AZ11: 0 | BA11: 0 | BB11: 0 | BC11: 0 | BD11: 0 | BE11: 0 | BF11: 0 | BG11: 0 | BH11: 0 | BI11: 0 | BJ11: 0 | BK11: 0 | BL11: 0 | BM11: 0 | BN11: 0 | BO11: 0 | BP11: 0 | BQ11: 0 | BR11: 0 | BS11: 0 | BT11: 0 | BU11: 0 | BV11: 0 | BW11: 0 | BX11: 0 | BY11: 0 | BZ11: 0 | CA11: 0 | CB11: 0 | CC11: 0 | CD11: 0 | CE11: 0 | CF11: 0 | CG11: 0 | CH11: 0 | CI11: 0 | CJ11: 0 | CK11: 0 | CL11: 0
B12: 선순위C 건설이자 | C12: [KRWm] | D12: =SUM(E12:CL12) | E12: 0 | F12: =E20*'입력값'!D60/4 | G12: =F20*'입력값'!D60/4 | H12: =G20*'입력값'!D60/4 | I12: =H20*'입력값'!D60/4 | J12: =I20*'입력값'!D60/4 | K12: 0 | L12: 0 | M12: 0 | N12: 0 | O12: 0 | P12: 0 | Q12: 0 | R12: 0 | S12: 0 | T12: 0 | U12: 0 | V12: 0 | W12: 0 | X12: 0 | Y12: 0 | Z12: 0 | AA12: 0 | AB12: 0 | AC12: 0 | AD12: 0 | AE12: 0 | AF12: 0 | AG12: 0 | AH12: 0 | AI12: 0 | AJ12: 0 | AK12: 0 | AL12: 0 | AM12: 0 | AN12: 0 | AO12: 0 | AP12: 0 | AQ12: 0 | AR12: 0 | AS12: 0 | AT12: 0 | AU12: 0 | AV12: 0 | AW12: 0 | AX12: 0 | AY12: 0 | AZ12: 0 | BA12: 0 | BB12: 0 | BC12: 0 | BD12: 0 | BE12: 0 | BF12: 0 | BG12: 0 | BH12: 0 | BI12: 0 | BJ12: 0 | BK12: 0 | BL12: 0 | BM12: 0 | BN12: 0 | BO12: 0 | BP12: 0 | BQ12: 0 | BR12: 0 | BS12: 0 | BT12: 0 | BU12: 0 | BV12: 0 | BW12: 0 | BX12: 0 | BY12: 0 | BZ12: 0 | CA12: 0 | CB12: 0 | CC12: 0 | CD12: 0 | CE12: 0 | CF12: 0 | CG12: 0 | CH12: 0 | CI12: 0 | CJ12: 0 | CK12: 0 | CL12: 0
B13: 선순위D 건설이자 | C13: [KRWm] | D13: =SUM(E13:CL13) | E13: 0 | F13: =E21*'입력값'!D61/4 | G13: =F21*'입력값'!D61/4 | H13: =G21*'입력값'!D61/4 | I13: =H21*'입력값'!D61/4 | J13: =I21*'입력값'!D61/4 | K13: 0 | L13: 0 | M13: 0 | N13: 0 | O13: 0 | P13: 0 | Q13: 0 | R13: 0 | S13: 0 | T13: 0 | U13: 0 | V13: 0 | W13: 0 | X13: 0 | Y13: 0 | Z13: 0 | AA13: 0 | AB13: 0 | AC13: 0 | AD13: 0 | AE13: 0 | AF13: 0 | AG13: 0 | AH13: 0 | AI13: 0 | AJ13: 0 | AK13: 0 | AL13: 0 | AM13: 0 | AN13: 0 | AO13: 0 | AP13: 0 | AQ13: 0 | AR13: 0 | AS13: 0 | AT13: 0 | AU13: 0 | AV13: 0 | AW13: 0 | AX13: 0 | AY13: 0 | AZ13: 0 | BA13: 0 | BB13: 0 | BC13: 0 | BD13: 0 | BE13: 0 | BF13: 0 | BG13: 0 | BH13: 0 | BI13: 0 | BJ13: 0 | BK13: 0 | BL13: 0 | BM13: 0 | BN13: 0 | BO13: 0 | BP13: 0 | BQ13: 0 | BR13: 0 | BS13: 0 | BT13: 0 | BU13: 0 | BV13: 0 | BW13: 0 | BX13: 0 | BY13: 0 | BZ13: 0 | CA13: 0 | CB13: 0 | CC13: 0 | CD13: 0 | CE13: 0 | CF13: 0 | CG13: 0 | CH13: 0 | CI13: 0 | CJ13: 0 | CK13: 0 | CL13: 0
B14: 후순위 건설이자 | C14: [KRWm] | D14: =SUM(E14:CL14) | E14: 0 | F14: =E22*'입력값'!D62/4 | G14: =F22*'입력값'!D62/4 | H14: =G22*'입력값'!D62/4 | I14: =H22*'입력값'!D62/4 | J14: =I22*'입력값'!D62/4 | K14: 0 | L14: 0 | M14: 0 | N14: 0 | O14: 0 | P14: 0 | Q14: 0 | R14: 0 | S14: 0 | T14: 0 | U14: 0 | V14: 0 | W14: 0 | X14: 0 | Y14: 0 | Z14: 0 | AA14: 0 | AB14: 0 | AC14: 0 | AD14: 0 | AE14: 0 | AF14: 0 | AG14: 0 | AH14: 0 | AI14: 0 | AJ14: 0 | AK14: 0 | AL14: 0 | AM14: 0 | AN14: 0 | AO14: 0 | AP14: 0 | AQ14: 0 | AR14: 0 | AS14: 0 | AT14: 0 | AU14: 0 | AV14: 0 | AW14: 0 | AX14: 0 | AY14: 0 | AZ14: 0 | BA14: 0 | BB14: 0 | BC14: 0 | BD14: 0 | BE14: 0 | BF14: 0 | BG14: 0 | BH14: 0 | BI14: 0 | BJ14: 0 | BK14: 0 | BL14: 0 | BM14: 0 | BN14: 0 | BO14: 0 | BP14: 0 | BQ14: 0 | BR14: 0 | BS14: 0 | BT14: 0 | BU14: 0 | BV14: 0 | BW14: 0 | BX14: 0 | BY14: 0 | BZ14: 0 | CA14: 0 | CB14: 0 | CC14: 0 | CD14: 0 | CE14: 0 | CF14: 0 | CG14: 0 | CH14: 0 | CI14: 0 | CJ14: 0 | CK14: 0 | CL14: 0
B15: 건설이자 합계(당기) | C15: [KRWm] | D15: =SUM(E15:CL15) | E15: =E10+E11+E12+E13+E14 | F15: =F10+F11+F12+F13+F14 | G15: =G10+G11+G12+G13+G14 | H15: =H10+H11+H12+H13+H14 | I15: =I10+I11+I12+I13+I14 | J15: =J10+J11+J12+J13+J14 | K15: =K10+K11+K12+K13+K14 | L15: =L10+L11+L12+L13+L14 | ... CL15: =CL10+CL11+CL12+CL13+CL14
B16: 누적 소요액 | C16: [KRWm] | E16: =E8+E9+E15 | F16: =E16+F8+F9+F15 | G16: =F16+G8+G9+G15 | H16: =G16+H8+H9+H15 | I16: =H16+I8+I9+I15 | J16: =I16+J8+J9+J15 | K16: =J16+K8+K9+K15 | L16: =K16+L8+L9+L15 | M16: =L16+M8+M9+M15 | ... CL16: =CK16+CL8+CL9+CL15
B17: 자본금 누적인출 | C17: [KRWm] | E17: =MIN(MAX(E16-(0),0),'입력값'!C9*100+'입력값'!C62*100)*('입력값'!C9*100)/IF(('입력값'!C9*100+'입력값'!C62*100)=0,1,'입력값'!C9*100+'입력값'!C62*100) | F17: =MIN(MAX(F16-(0),0),'입력값'!C9*100+'입력값'!C62*100)*('입력값'!C9*100)/IF(('입력값'!C9*100+'입력값'!C62*100)=0,1,'입력값'!C9*100+'입력값'!C62*100) | G17: =MIN(MAX(G16-(0),0),'입력값'!C9*100+'입력값'!C62*100)*('입력값'!C9*100)/IF(('입력값'!C9*100+'입력값'!C62*100)=0,1,'입력값'!C9*100+'입력값'!C62*100) | H17: =MIN(MAX(H16-(0),0),'입력값'!C9*100+'입력값'!C62*100)*('입력값'!C9*100)/IF(('입력값'!C9*100+'입력값'!C62*100)=0,1,'입력값'!C9*100+'입력값'!C62*100) | I17: =MIN(MAX(I16-(0),0),'입력값'!C9*100+'입력값'!C62*100)*('입력값'!C9*100)/IF(('입력값'!C9*100+'입력값'!C62*100)=0,1,'입력값'!C9*100+'입력값'!C62*100) | J17: =MIN(MAX(J16-(0),0),'입력값'!C9*100+'입력값'!C62*100)*('입력값'!C9*100)/IF(('입력값'!C9*100+'입력값'!C62*100)=0,1,'입력값'!C9*100+'입력값'!C62*100) | K17: =MIN(MAX(K16-(0),0),'입력값'!C9*100+'입력값'!C62*100)*('입력값'!C9*100)/IF(('입력값'!C9*100+'입력값'!C62*100)=0,1,'입력값'!C9*100+'입력값'!C62*100) | L17: =MIN(MAX(L16-(0),0),'입력값'!C9*100+'입력값'!C62*100)*('입력값'!C9*100)/IF(('입력값'!C9*100+'입력값'!C62*100)=0,1,'입력값'!C9*100+'입력값'!C62*100) | M17: =MIN(MAX(M16-(0),0),'입력값'!C9*100+'입력값'!C62*100)*('입력값'!C9*100)/IF(('입력값'!C9*100+'입력값'!C62*100)=0,1,'입력값'!C9*100+'입력값'!C62*100) | N17: =MIN(MAX(N16-(0),0),'입력값'!C9*100+'입력값'!C62*100)*('입력값'!C9*100)/IF(('입력값'!C9*100+'입력값'!C62*100)=0,1,'입력값'!C9*100+'입력값'!C62*100) | O17: =MIN(MAX(O16-(0),0),'입력값'!C9*100+'입력값'!C62*100)*('입력값'!C9*100)/IF(('입력값'!C9*100+'입력값'!C62*100)=0,1,'입력값'!C9*100+'입력값'!C62*100) | P17: =MIN(MAX(P16-(0),0),'입력값'!C9*100+'입력값'!C62*100)*('입력값'!C9*100)/IF(('입력값'!C9*100+'입력값'!C62*100)=0,1,'입력값'!C9*100+'입력값'!C62*100) | Q17: =MIN(MAX(Q16-(0),0),'입력값'!C9*100+'입력값'!C62*100)*('입력값'!C9*100)/IF(('입력값'!C9*100+'입력값'!C62*100)=0,1,'입력값'!C9*100+'입력값'!C62*100) | R17: =MIN(MAX(R16-(0),0),'입력값'!C9*100+'입력값'!C62*100)*('입력값'!C9*100)/IF(('입력값'!C9*100+'입력값'!C62*100)=0,1,'입력값'!C9*100+'입력값'!C62*100) | S17: =MIN(MAX(S16-(0),0),'입력값'!C9*100+'입력값'!C62*100)*('입력값'!C9*100)/IF(('입력값'!C9*100+'입력값'!C62*100)=0,1,'입력값'!C9*100+'입력값'!C62*100) | T17: =MIN(MAX(T16-(0),0),'입력값'!C9*100+'입력값'!C62*100)*('입력값'!C9*100)/IF(('입력값'!C9*100+'입력값'!C62*100)=0,1,'입력값'!C9*100+'입력값'!C62*100) | U17: =MIN(MAX(U16-(0),0),'입력값'!C9*100+'입력값'!C62*100)*('입력값'!C9*100)/IF(('입력값'!C9*100+'입력값'!C62*100)=0,1,'입력값'!C9*100+'입력값'!C62*100) | V17: =MIN(MAX(V16-(0),0),'입력값'!C9*100+'입력값'!C62*100)*('입력값'!C9*100)/IF(('입력값'!C9*100+'입력값'!C62*100)=0,1,'입력값'!C9*100+'입력값'!C62*100) | W17: =MIN(MAX(W16-(0),0),'입력값'!C9*100+'입력값'!C62*100)*('입력값'!C9*100)/IF(('입력값'!C9*100+'입력값'!C62*100)=0,1,'입력값'!C9*100+'입력값'!C62*100) | X17: =MIN(MAX(X16-(0),0),'입력값'!C9*100+'입력값'!C62*100)*('입력값'!C9*100)/IF(('입력값'!C9*100+'입력값'!C62*100)=0,1,'입력값'!C9*100+'입력값'!C62*100) | Y17: =MIN(MAX(Y16-(0),0),'입력값'!C9*100+'입력값'!C62*100)*('입력값'!C9*100)/IF(('입력값'!C9*100+'입력값'!C62*100)=0,1,'입력값'!C9*100+'입력값'!C62*100) | Z17: =MIN(MAX(Z16-(0),0),'입력값'!C9*100+'입력값'!C62*100)*('입력값'!C9*100)/IF(('입력값'!C9*100+'입력값'!C62*100)=0,1,'입력값'!C9*100+'입력값'!C62*100) | AA17: =MIN(MAX(AA16-(0),0),'입력값'!C9*100+'입력값'!C62*100)*('입력값'!C9*100)/IF(('입력값'!C9*100+'입력값'!C62*100)=0,1,'입력값'!C9*100+'입력값'!C62*100) | AB17: =MIN(MAX(AB16-(0),0),'입력값'!C9*100+'입력값'!C62*100)*('입력값'!C9*100)/IF(('입력값'!C9*100+'입력값'!C62*100)=0,1,'입력값'!C9*100+'입력값'!C62*100) | AC17: =MIN(MAX(AC16-(0),0),'입력값'!C9*100+'입력값'!C62*100)*('입력값'!C9*100)/IF(('입력값'!C9*100+'입력값'!C62*100)=0,1,'입력값'!C9*100+'입력값'!C62*100) | AD17: =MIN(MAX(AD16-(0),0),'입력값'!C9*100+'입력값'!C62*100)*('입력값'!C9*100)/IF(('입력값'!C9*100+'입력값'!C62*100)=0,1,'입력값'!C9*100+'입력값'!C62*100) | AE17: =MIN(MAX(AE16-(0),0),'입력값'!C9*100+'입력값'!C62*100)*('입력값'!C9*100)/IF(('입력값'!C9*100+'입력값'!C62*100)=0,1,'입력값'!C9*100+'입력값'!C62*100) | AF17: =MIN(MAX(AF16-(0),0),'입력값'!C9*100+'입력값'!C62*100)*('입력값'!C9*100)/IF(('입력값'!C9*100+'입력값'!C62*100)=0,1,'입력값'!C9*100+'입력값'!C62*100) | AG17: =MIN(MAX(AG16-(0),0),'입력값'!C9*100+'입력값'!C62*100)*('입력값'!C9*100)/IF(('입력값'!C9*100+'입력값'!C62*100)=0,1,'입력값'!C9*100+'입력값'!C62*100) | AH17: =MIN(MAX(AH16-(0),0),'입력값'!C9*100+'입력값'!C62*100)*('입력값'!C9*100)/IF(('입력값'!C9*100+'입력값'!C62*100)=0,1,'입력값'!C9*100+'입력값'!C62*100) | AI17: =MIN(MAX(AI16-(0),0),'입력값'!C9*100+'입력값'!C62*100)*('입력값'!C9*100)/IF(('입력값'!C9*100+'입력값'!C62*100)=0,1,'입력값'!C9*100+'입력값'!C62*100) | AJ17: =MIN(MAX(AJ16-(0),0),'입력값'!C9*100+'입력값'!C62*100)*('입력값'!C9*100)/IF(('입력값'!C9*100+'입력값'!C62*100)=0,1,'입력값'!C9*100+'입력값'!C62*100) | AK17: =MIN(MAX(AK16-(0),0),'입력값'!C9*100+'입력값'!C62*100)*('입력값'!C9*100)/IF(('입력값'!C9*100+'입력값'!C62*100)=0,1,'입력값'!C9*100+'입력값'!C62*100) | AL17: =MIN(MAX(AL16-(0),0),'입력값'!C9*100+'입력값'!C62*100)*('입력값'!C9*100)/IF(('입력값'!C9*100+'입력값'!C62*100)=0,1,'입력값'!C9*100+'입력값'!C62*100) | AM17: =MIN(MAX(AM16-(0),0),'입력값'!C9*100+'입력값'!C62*100)*('입력값'!C9*100)/IF(('입력값'!C9*100+'입력값'!C62*100)=0,1,'입력값'!C9*100+'입력값'!C62*100) | AN17: =MIN(MAX(AN16-(0),0),'입력값'!C9*100+'입력값'!C62*100)*('입력값'!C9*100)/IF(('입력값'!C9*100+'입력값'!C62*100)=0,1,'입력값'!C9*100+'입력값'!C62*100) | AO17: =MIN(MAX(AO16-(0),0),'입력값'!C9*100+'입력값'!C62*100)*('입력값'!C9*100)/IF(('입력값'!C9*100+'입력값'!C62*100)=0,1,'입력값'!C9*100+'입력값'!C62*100) | AP17: =MIN(MAX(AP16-(0),0),'입력값'!C9*100+'입력값'!C62*100)*('입력값'!C9*100)/IF(('입력값'!C9*100+'입력값'!C62*100)=0,1,'입력값'!C9*100+'입력값'!C62*100) | AQ17: =MIN(MAX(AQ16-(0),0),'입력값'!C9*100+'입력값'!C62*100)*('입력값'!C9*100)/IF(('입력값'!C9*100+'입력값'!C62*100)=0,1,'입력값'!C9*100+'입력값'!C62*100) | AR17: =MIN(MAX(AR16-(0),0),'입력값'!C9*100+'입력값'!C62*100)*('입력값'!C9*100)/IF(('입력값'!C9*100+'입력값'!C62*100)=0,1,'입력값'!C9*100+'입력값'!C62*100) | AS17: =MIN(MAX(AS16-(0),0),'입력값'!C9*100+'입력값'!C62*100)*('입력값'!C9*100)/IF(('입력값'!C9*100+'입력값'!C62*100)=0,1,'입력값'!C9*100+'입력값'!C62*100) | AT17: =MIN(MAX(AT16-(0),0),'입력값'!C9*100+'입력값'!C62*100)*('입력값'!C9*100)/IF(('입력값'!C9*100+'입력값'!C62*100)=0,1,'입력값'!C9*100+'입력값'!C62*100) | AU17: =MIN(MAX(AU16-(0),0),'입력값'!C9*100+'입력값'!C62*100)*('입력값'!C9*100)/IF(('입력값'!C9*100+'입력값'!C62*100)=0,1,'입력값'!C9*100+'입력값'!C62*100) | AV17: =MIN(MAX(AV16-(0),0),'입력값'!C9*100+'입력값'!C62*100)*('입력값'!C9*100)/IF(('입력값'!C9*100+'입력값'!C62*100)=0,1,'입력값'!C9*100+'입력값'!C62*100) | AW17: =MIN(MAX(AW16-(0),0),'입력값'!C9*100+'입력값'!C62*100)*('입력값'!C9*100)/IF(('입력값'!C9*100+'입력값'!C62*100)=0,1,'입력값'!C9*100+'입력값'!C62*100) | AX17: =MIN(MAX(AX16-(0),0),'입력값'!C9*100+'입력값'!C62*100)*('입력값'!C9*100)/IF(('입력값'!C9*100+'입력값'!C62*100)=0,1,'입력값'!C9*100+'입력값'!C62*100) | AY17: =MIN(MAX(AY16-(0),0),'입력값'!C9*100+'입력값'!C62*100)*('입력값'!C9*100)/IF(('입력값'!C9*100+'입력값'!C62*100)=0,1,'입력값'!C9*100+'입력값'!C62*100) | AZ17: =MIN(MAX(AZ16-(0),0),'입력값'!C9*100+'입력값'!C62*100)*('입력값'!C9*100)/IF(('입력값'!C9*100+'입력값'!C62*100)=0,1,'입력값'!C9*100+'입력값'!C62*100) | BA17: =MIN(MAX(BA16-(0),0),'입력값'!C9*100+'입력값'!C62*100)*('입력값'!C9*100)/IF(('입력값'!C9*100+'입력값'!C62*100)=0,1,'입력값'!C9*100+'입력값'!C62*100) | BB17: =MIN(MAX(BB16-(0),0),'입력값'!C9*100+'입력값'!C62*100)*('입력값'!C9*100)/IF(('입력값'!C9*100+'입력값'!C62*100)=0,1,'입력값'!C9*100+'입력값'!C62*100) | BC17: =MIN(MAX(BC16-(0),0),'입력값'!C9*100+'입력값'!C62*100)*('입력값'!C9*100)/IF(('입력값'!C9*100+'입력값'!C62*100)=0,1,'입력값'!C9*100+'입력값'!C62*100) | BD17: =MIN(MAX(BD16-(0),0),'입력값'!C9*100+'입력값'!C62*100)*('입력값'!C9*100)/IF(('입력값'!C9*100+'입력값'!C62*100)=0,1,'입력값'!C9*100+'입력값'!C62*100) | BE17: =MIN(MAX(BE16-(0),0),'입력값'!C9*100+'입력값'!C62*100)*('입력값'!C9*100)/IF(('입력값'!C9*100+'입력값'!C62*100)=0,1,'입력값'!C9*100+'입력값'!C62*100) | BF17: =MIN(MAX(BF16-(0),0),'입력값'!C9*100+'입력값'!C62*100)*('입력값'!C9*100)/IF(('입력값'!C9*100+'입력값'!C62*100)=0,1,'입력값'!C9*100+'입력값'!C62*100) | BG17: =MIN(MAX(BG16-(0),0),'입력값'!C9*100+'입력값'!C62*100)*('입력값'!C9*100)/IF(('입력값'!C9*100+'입력값'!C62*100)=0,1,'입력값'!C9*100+'입력값'!C62*100) | BH17: =MIN(MAX(BH16-(0),0),'입력값'!C9*100+'입력값'!C62*100)*('입력값'!C9*100)/IF(('입력값'!C9*100+'입력값'!C62*100)=0,1,'입력값'!C9*100+'입력값'!C62*100) | BI17: =MIN(MAX(BI16-(0),0),'입력값'!C9*100+'입력값'!C62*100)*('입력값'!C9*100)/IF(('입력값'!C9*100+'입력값'!C62*100)=0,1,'입력값'!C9*100+'입력값'!C62*100) | BJ17: =MIN(MAX(BJ16-(0),0),'입력값'!C9*100+'입력값'!C62*100)*('입력값'!C9*100)/IF(('입력값'!C9*100+'입력값'!C62*100)=0,1,'입력값'!C9*100+'입력값'!C62*100) | BK17: =MIN(MAX(BK16-(0),0),'입력값'!C9*100+'입력값'!C62*100)*('입력값'!C9*100)/IF(('입력값'!C9*100+'입력값'!C62*100)=0,1,'입력값'!C9*100+'입력값'!C62*100) | BL17: =MIN(MAX(BL16-(0),0),'입력값'!C9*100+'입력값'!C62*100)*('입력값'!C9*100)/IF(('입력값'!C9*100+'입력값'!C62*100)=0,1,'입력값'!C9*100+'입력값'!C62*100) | BM17: =MIN(MAX(BM16-(0),0),'입력값'!C9*100+'입력값'!C62*100)*('입력값'!C9*100)/IF(('입력값'!C9*100+'입력값'!C62*100)=0,1,'입력값'!C9*100+'입력값'!C62*100) | BN17: =MIN(MAX(BN16-(0),0),'입력값'!C9*100+'입력값'!C62*100)*('입력값'!C9*100)/IF(('입력값'!C9*100+'입력값'!C62*100)=0,1,'입력값'!C9*100+'입력값'!C62*100) | BO17: =MIN(MAX(BO16-(0),0),'입력값'!C9*100+'입력값'!C62*100)*('입력값'!C9*100)/IF(('입력값'!C9*100+'입력값'!C62*100)=0,1,'입력값'!C9*100+'입력값'!C62*100) | BP17: =MIN(MAX(BP16-(0),0),'입력값'!C9*100+'입력값'!C62*100)*('입력값'!C9*100)/IF(('입력값'!C9*100+'입력값'!C62*100)=0,1,'입력값'!C9*100+'입력값'!C62*100) | BQ17: =MIN(MAX(BQ16-(0),0),'입력값'!C9*100+'입력값'!C62*100)*('입력값'!C9*100)/IF(('입력값'!C9*100+'입력값'!C62*100)=0,1,'입력값'!C9*100+'입력값'!C62*100) | BR17: =MIN(MAX(BR16-(0),0),'입력값'!C9*100+'입력값'!C62*100)*('입력값'!C9*100)/IF(('입력값'!C9*100+'입력값'!C62*100)=0,1,'입력값'!C9*100+'입력값'!C62*100) | BS17: =MIN(MAX(BS16-(0),0),'입력값'!C9*100+'입력값'!C62*100)*('입력값'!C9*100)/IF(('입력값'!C9*100+'입력값'!C62*100)=0,1,'입력값'!C9*100+'입력값'!C62*100) | BT17: =MIN(MAX(BT16-(0),0),'입력값'!C9*100+'입력값'!C62*100)*('입력값'!C9*100)/IF(('입력값'!C9*100+'입력값'!C62*100)=0,1,'입력값'!C9*100+'입력값'!C62*100) | BU17: =MIN(MAX(BU16-(0),0),'입력값'!C9*100+'입력값'!C62*100)*('입력값'!C9*100)/IF(('입력값'!C9*100+'입력값'!C62*100)=0,1,'입력값'!C9*100+'입력값'!C62*100) | BV17: =MIN(MAX(BV16-(0),0),'입력값'!C9*100+'입력값'!C62*100)*('입력값'!C9*100)/IF(('입력값'!C9*100+'입력값'!C62*100)=0,1,'입력값'!C9*100+'입력값'!C62*100) | BW17: =MIN(MAX(BW16-(0),0),'입력값'!C9*100+'입력값'!C62*100)*('입력값'!C9*100)/IF(('입력값'!C9*100+'입력값'!C62*100)=0,1,'입력값'!C9*100+'입력값'!C62*100) | BX17: =MIN(MAX(BX16-(0),0),'입력값'!C9*100+'입력값'!C62*100)*('입력값'!C9*100)/IF(('입력값'!C9*100+'입력값'!C62*100)=0,1,'입력값'!C9*100+'입력값'!C62*100) | BY17: =MIN(MAX(BY16-(0),0),'입력값'!C9*100+'입력값'!C62*100)*('입력값'!C9*100)/IF(('입력값'!C9*100+'입력값'!C62*100)=0,1,'입력값'!C9*100+'입력값'!C62*100) | BZ17: =MIN(MAX(BZ16-(0),0),'입력값'!C9*100+'입력값'!C62*100)*('입력값'!C9*100)/IF(('입력값'!C9*100+'입력값'!C62*100)=0,1,'입력값'!C9*100+'입력값'!C62*100) | CA17: =MIN(MAX(CA16-(0),0),'입력값'!C9*100+'입력값'!C62*100)*('입력값'!C9*100)/IF(('입력값'!C9*100+'입력값'!C62*100)=0,1,'입력값'!C9*100+'입력값'!C62*100) | CB17: =MIN(MAX(CB16-(0),0),'입력값'!C9*100+'입력값'!C62*100)*('입력값'!C9*100)/IF(('입력값'!C9*100+'입력값'!C62*100)=0,1,'입력값'!C9*100+'입력값'!C62*100) | CC17: =MIN(MAX(CC16-(0),0),'입력값'!C9*100+'입력값'!C62*100)*('입력값'!C9*100)/IF(('입력값'!C9*100+'입력값'!C62*100)=0,1,'입력값'!C9*100+'입력값'!C62*100) | CD17: =MIN(MAX(CD16-(0),0),'입력값'!C9*100+'입력값'!C62*100)*('입력값'!C9*100)/IF(('입력값'!C9*100+'입력값'!C62*100)=0,1,'입력값'!C9*100+'입력값'!C62*100) | CE17: =MIN(MAX(CE16-(0),0),'입력값'!C9*100+'입력값'!C62*100)*('입력값'!C9*100)/IF(('입력값'!C9*100+'입력값'!C62*100)=0,1,'입력값'!C9*100+'입력값'!C62*100) | CF17: =MIN(MAX(CF16-(0),0),'입력값'!C9*100+'입력값'!C62*100)*('입력값'!C9*100)/IF(('입력값'!C9*100+'입력값'!C62*100)=0,1,'입력값'!C9*100+'입력값'!C62*100) | CG17: =MIN(MAX(CG16-(0),0),'입력값'!C9*100+'입력값'!C62*100)*('입력값'!C9*100)/IF(('입력값'!C9*100+'입력값'!C62*100)=0,1,'입력값'!C9*100+'입력값'!C62*100) | CH17: =MIN(MAX(CH16-(0),0),'입력값'!C9*100+'입력값'!C62*100)*('입력값'!C9*100)/IF(('입력값'!C9*100+'입력값'!C62*100)=0,1,'입력값'!C9*100+'입력값'!C62*100) | CI17: =MIN(MAX(CI16-(0),0),'입력값'!C9*100+'입력값'!C62*100)*('입력값'!C9*100)/IF(('입력값'!C9*100+'입력값'!C62*100)=0,1,'입력값'!C9*100+'입력값'!C62*100) | CJ17: =MIN(MAX(CJ16-(0),0),'입력값'!C9*100+'입력값'!C62*100)*('입력값'!C9*100)/IF(('입력값'!C9*100+'입력값'!C62*100)=0,1,'입력값'!C9*100+'입력값'!C62*100) | CK17: =MIN(MAX(CK16-(0),0),'입력값'!C9*100+'입력값'!C62*100)*('입력값'!C9*100)/IF(('입력값'!C9*100+'입력값'!C62*100)=0,1,'입력값'!C9*100+'입력값'!C62*100) | CL17: =MIN(MAX(CL16-(0),0),'입력값'!C9*100+'입력값'!C62*100)*('입력값'!C9*100)/IF(('입력값'!C9*100+'입력값'!C62*100)=0,1,'입력값'!C9*100+'입력값'!C62*100)
B18: 선순위A 누적인출 | C18: [KRWm] | E18: =MIN(MAX(E16-('입력값'!C9*100+'입력값'!C62*100),0),'입력값'!C58*100+'입력값'!C59*100)*('입력값'!C58*100)/IF(('입력값'!C58*100+'입력값'!C59*100)=0,1,'입력값'!C58*100+'입력값'!C59*100) | F18: =MIN(MAX(F16-('입력값'!C9*100+'입력값'!C62*100),0),'입력값'!C58*100+'입력값'!C59*100)*('입력값'!C58*100)/IF(('입력값'!C58*100+'입력값'!C59*100)=0,1,'입력값'!C58*100+'입력값'!C59*100) | G18: =MIN(MAX(G16-('입력값'!C9*100+'입력값'!C62*100),0),'입력값'!C58*100+'입력값'!C59*100)*('입력값'!C58*100)/IF(('입력값'!C58*100+'입력값'!C59*100)=0,1,'입력값'!C58*100+'입력값'!C59*100) | H18: =MIN(MAX(H16-('입력값'!C9*100+'입력값'!C62*100),0),'입력값'!C58*100+'입력값'!C59*100)*('입력값'!C58*100)/IF(('입력값'!C58*100+'입력값'!C59*100)=0,1,'입력값'!C58*100+'입력값'!C59*100) | I18: =MIN(MAX(I16-('입력값'!C9*100+'입력값'!C62*100),0),'입력값'!C58*100+'입력값'!C59*100)*('입력값'!C58*100)/IF(('입력값'!C58*100+'입력값'!C59*100)=0,1,'입력값'!C58*100+'입력값'!C59*100) | J18: =MIN(MAX(J16-('입력값'!C9*100+'입력값'!C62*100),0),'입력값'!C58*100+'입력값'!C59*100)*('입력값'!C58*100)/IF(('입력값'!C58*100+'입력값'!C59*100)=0,1,'입력값'!C58*100+'입력값'!C59*100) | K18: =MIN(MAX(K16-('입력값'!C9*100+'입력값'!C62*100),0),'입력값'!C58*100+'입력값'!C59*100)*('입력값'!C58*100)/IF(('입력값'!C58*100+'입력값'!C59*100)=0,1,'입력값'!C58*100+'입력값'!C59*100) | L18: =MIN(MAX(L16-('입력값'!C9*100+'입력값'!C62*100),0),'입력값'!C58*100+'입력값'!C59*100)*('입력값'!C58*100)/IF(('입력값'!C58*100+'입력값'!C59*100)=0,1,'입력값'!C58*100+'입력값'!C59*100) | M18: =MIN(MAX(M16-('입력값'!C9*100+'입력값'!C62*100),0),'입력값'!C58*100+'입력값'!C59*100)*('입력값'!C58*100)/IF(('입력값'!C58*100+'입력값'!C59*100)=0,1,'입력값'!C58*100+'입력값'!C59*100) | N18: =MIN(MAX(N16-('입력값'!C9*100+'입력값'!C62*100),0),'입력값'!C58*100+'입력값'!C59*100)*('입력값'!C58*100)/IF(('입력값'!C58*100+'입력값'!C59*100)=0,1,'입력값'!C58*100+'입력값'!C59*100) | O18: =MIN(MAX(O16-('입력값'!C9*100+'입력값'!C62*100),0),'입력값'!C58*100+'입력값'!C59*100)*('입력값'!C58*100)/IF(('입력값'!C58*100+'입력값'!C59*100)=0,1,'입력값'!C58*100+'입력값'!C59*100) | P18: =MIN(MAX(P16-('입력값'!C9*100+'입력값'!C62*100),0),'입력값'!C58*100+'입력값'!C59*100)*('입력값'!C58*100)/IF(('입력값'!C58*100+'입력값'!C59*100)=0,1,'입력값'!C58*100+'입력값'!C59*100) | Q18: =MIN(MAX(Q16-('입력값'!C9*100+'입력값'!C62*100),0),'입력값'!C58*100+'입력값'!C59*100)*('입력값'!C58*100)/IF(('입력값'!C58*100+'입력값'!C59*100)=0,1,'입력값'!C58*100+'입력값'!C59*100) | R18: =MIN(MAX(R16-('입력값'!C9*100+'입력값'!C62*100),0),'입력값'!C58*100+'입력값'!C59*100)*('입력값'!C58*100)/IF(('입력값'!C58*100+'입력값'!C59*100)=0,1,'입력값'!C58*100+'입력값'!C59*100) | S18: =MIN(MAX(S16-('입력값'!C9*100+'입력값'!C62*100),0),'입력값'!C58*100+'입력값'!C59*100)*('입력값'!C58*100)/IF(('입력값'!C58*100+'입력값'!C59*100)=0,1,'입력값'!C58*100+'입력값'!C59*100) | T18: =MIN(MAX(T16-('입력값'!C9*100+'입력값'!C62*100),0),'입력값'!C58*100+'입력값'!C59*100)*('입력값'!C58*100)/IF(('입력값'!C58*100+'입력값'!C59*100)=0,1,'입력값'!C58*100+'입력값'!C59*100) | U18: =MIN(MAX(U16-('입력값'!C9*100+'입력값'!C62*100),0),'입력값'!C58*100+'입력값'!C59*100)*('입력값'!C58*100)/IF(('입력값'!C58*100+'입력값'!C59*100)=0,1,'입력값'!C58*100+'입력값'!C59*100) | V18: =MIN(MAX(V16-('입력값'!C9*100+'입력값'!C62*100),0),'입력값'!C58*100+'입력값'!C59*100)*('입력값'!C58*100)/IF(('입력값'!C58*100+'입력값'!C59*100)=0,1,'입력값'!C58*100+'입력값'!C59*100) | W18: =MIN(MAX(W16-('입력값'!C9*100+'입력값'!C62*100),0),'입력값'!C58*100+'입력값'!C59*100)*('입력값'!C58*100)/IF(('입력값'!C58*100+'입력값'!C59*100)=0,1,'입력값'!C58*100+'입력값'!C59*100) | X18: =MIN(MAX(X16-('입력값'!C9*100+'입력값'!C62*100),0),'입력값'!C58*100+'입력값'!C59*100)*('입력값'!C58*100)/IF(('입력값'!C58*100+'입력값'!C59*100)=0,1,'입력값'!C58*100+'입력값'!C59*100) | Y18: =MIN(MAX(Y16-('입력값'!C9*100+'입력값'!C62*100),0),'입력값'!C58*100+'입력값'!C59*100)*('입력값'!C58*100)/IF(('입력값'!C58*100+'입력값'!C59*100)=0,1,'입력값'!C58*100+'입력값'!C59*100) | Z18: =MIN(MAX(Z16-('입력값'!C9*100+'입력값'!C62*100),0),'입력값'!C58*100+'입력값'!C59*100)*('입력값'!C58*100)/IF(('입력값'!C58*100+'입력값'!C59*100)=0,1,'입력값'!C58*100+'입력값'!C59*100) | AA18: =MIN(MAX(AA16-('입력값'!C9*100+'입력값'!C62*100),0),'입력값'!C58*100+'입력값'!C59*100)*('입력값'!C58*100)/IF(('입력값'!C58*100+'입력값'!C59*100)=0,1,'입력값'!C58*100+'입력값'!C59*100) | AB18: =MIN(MAX(AB16-('입력값'!C9*100+'입력값'!C62*100),0),'입력값'!C58*100+'입력값'!C59*100)*('입력값'!C58*100)/IF(('입력값'!C58*100+'입력값'!C59*100)=0,1,'입력값'!C58*100+'입력값'!C59*100) | AC18: =MIN(MAX(AC16-('입력값'!C9*100+'입력값'!C62*100),0),'입력값'!C58*100+'입력값'!C59*100)*('입력값'!C58*100)/IF(('입력값'!C58*100+'입력값'!C59*100)=0,1,'입력값'!C58*100+'입력값'!C59*100) | AD18: =MIN(MAX(AD16-('입력값'!C9*100+'입력값'!C62*100),0),'입력값'!C58*100+'입력값'!C59*100)*('입력값'!C58*100)/IF(('입력값'!C58*100+'입력값'!C59*100)=0,1,'입력값'!C58*100+'입력값'!C59*100) | AE18: =MIN(MAX(AE16-('입력값'!C9*100+'입력값'!C62*100),0),'입력값'!C58*100+'입력값'!C59*100)*('입력값'!C58*100)/IF(('입력값'!C58*100+'입력값'!C59*100)=0,1,'입력값'!C58*100+'입력값'!C59*100) | AF18: =MIN(MAX(AF16-('입력값'!C9*100+'입력값'!C62*100),0),'입력값'!C58*100+'입력값'!C59*100)*('입력값'!C58*100)/IF(('입력값'!C58*100+'입력값'!C59*100)=0,1,'입력값'!C58*100+'입력값'!C59*100) | AG18: =MIN(MAX(AG16-('입력값'!C9*100+'입력값'!C62*100),0),'입력값'!C58*100+'입력값'!C59*100)*('입력값'!C58*100)/IF(('입력값'!C58*100+'입력값'!C59*100)=0,1,'입력값'!C58*100+'입력값'!C59*100) | AH18: =MIN(MAX(AH16-('입력값'!C9*100+'입력값'!C62*100),0),'입력값'!C58*100+'입력값'!C59*100)*('입력값'!C58*100)/IF(('입력값'!C58*100+'입력값'!C59*100)=0,1,'입력값'!C58*100+'입력값'!C59*100) | AI18: =MIN(MAX(AI16-('입력값'!C9*100+'입력값'!C62*100),0),'입력값'!C58*100+'입력값'!C59*100)*('입력값'!C58*100)/IF(('입력값'!C58*100+'입력값'!C59*100)=0,1,'입력값'!C58*100+'입력값'!C59*100) | AJ18: =MIN(MAX(AJ16-('입력값'!C9*100+'입력값'!C62*100),0),'입력값'!C58*100+'입력값'!C59*100)*('입력값'!C58*100)/IF(('입력값'!C58*100+'입력값'!C59*100)=0,1,'입력값'!C58*100+'입력값'!C59*100) | AK18: =MIN(MAX(AK16-('입력값'!C9*100+'입력값'!C62*100),0),'입력값'!C58*100+'입력값'!C59*100)*('입력값'!C58*100)/IF(('입력값'!C58*100+'입력값'!C59*100)=0,1,'입력값'!C58*100+'입력값'!C59*100) | AL18: =MIN(MAX(AL16-('입력값'!C9*100+'입력값'!C62*100),0),'입력값'!C58*100+'입력값'!C59*100)*('입력값'!C58*100)/IF(('입력값'!C58*100+'입력값'!C59*100)=0,1,'입력값'!C58*100+'입력값'!C59*100) | AM18: =MIN(MAX(AM16-('입력값'!C9*100+'입력값'!C62*100),0),'입력값'!C58*100+'입력값'!C59*100)*('입력값'!C58*100)/IF(('입력값'!C58*100+'입력값'!C59*100)=0,1,'입력값'!C58*100+'입력값'!C59*100) | AN18: =MIN(MAX(AN16-('입력값'!C9*100+'입력값'!C62*100),0),'입력값'!C58*100+'입력값'!C59*100)*('입력값'!C58*100)/IF(('입력값'!C58*100+'입력값'!C59*100)=0,1,'입력값'!C58*100+'입력값'!C59*100) | AO18: =MIN(MAX(AO16-('입력값'!C9*100+'입력값'!C62*100),0),'입력값'!C58*100+'입력값'!C59*100)*('입력값'!C58*100)/IF(('입력값'!C58*100+'입력값'!C59*100)=0,1,'입력값'!C58*100+'입력값'!C59*100) | AP18: =MIN(MAX(AP16-('입력값'!C9*100+'입력값'!C62*100),0),'입력값'!C58*100+'입력값'!C59*100)*('입력값'!C58*100)/IF(('입력값'!C58*100+'입력값'!C59*100)=0,1,'입력값'!C58*100+'입력값'!C59*100) | AQ18: =MIN(MAX(AQ16-('입력값'!C9*100+'입력값'!C62*100),0),'입력값'!C58*100+'입력값'!C59*100)*('입력값'!C58*100)/IF(('입력값'!C58*100+'입력값'!C59*100)=0,1,'입력값'!C58*100+'입력값'!C59*100) | AR18: =MIN(MAX(AR16-('입력값'!C9*100+'입력값'!C62*100),0),'입력값'!C58*100+'입력값'!C59*100)*('입력값'!C58*100)/IF(('입력값'!C58*100+'입력값'!C59*100)=0,1,'입력값'!C58*100+'입력값'!C59*100) | AS18: =MIN(MAX(AS16-('입력값'!C9*100+'입력값'!C62*100),0),'입력값'!C58*100+'입력값'!C59*100)*('입력값'!C58*100)/IF(('입력값'!C58*100+'입력값'!C59*100)=0,1,'입력값'!C58*100+'입력값'!C59*100) | AT18: =MIN(MAX(AT16-('입력값'!C9*100+'입력값'!C62*100),0),'입력값'!C58*100+'입력값'!C59*100)*('입력값'!C58*100)/IF(('입력값'!C58*100+'입력값'!C59*100)=0,1,'입력값'!C58*100+'입력값'!C59*100) | AU18: =MIN(MAX(AU16-('입력값'!C9*100+'입력값'!C62*100),0),'입력값'!C58*100+'입력값'!C59*100)*('입력값'!C58*100)/IF(('입력값'!C58*100+'입력값'!C59*100)=0,1,'입력값'!C58*100+'입력값'!C59*100) | AV18: =MIN(MAX(AV16-('입력값'!C9*100+'입력값'!C62*100),0),'입력값'!C58*100+'입력값'!C59*100)*('입력값'!C58*100)/IF(('입력값'!C58*100+'입력값'!C59*100)=0,1,'입력값'!C58*100+'입력값'!C59*100) | AW18: =MIN(MAX(AW16-('입력값'!C9*100+'입력값'!C62*100),0),'입력값'!C58*100+'입력값'!C59*100)*('입력값'!C58*100)/IF(('입력값'!C58*100+'입력값'!C59*100)=0,1,'입력값'!C58*100+'입력값'!C59*100) | AX18: =MIN(MAX(AX16-('입력값'!C9*100+'입력값'!C62*100),0),'입력값'!C58*100+'입력값'!C59*100)*('입력값'!C58*100)/IF(('입력값'!C58*100+'입력값'!C59*100)=0,1,'입력값'!C58*100+'입력값'!C59*100) | AY18: =MIN(MAX(AY16-('입력값'!C9*100+'입력값'!C62*100),0),'입력값'!C58*100+'입력값'!C59*100)*('입력값'!C58*100)/IF(('입력값'!C58*100+'입력값'!C59*100)=0,1,'입력값'!C58*100+'입력값'!C59*100) | AZ18: =MIN(MAX(AZ16-('입력값'!C9*100+'입력값'!C62*100),0),'입력값'!C58*100+'입력값'!C59*100)*('입력값'!C58*100)/IF(('입력값'!C58*100+'입력값'!C59*100)=0,1,'입력값'!C58*100+'입력값'!C59*100) | BA18: =MIN(MAX(BA16-('입력값'!C9*100+'입력값'!C62*100),0),'입력값'!C58*100+'입력값'!C59*100)*('입력값'!C58*100)/IF(('입력값'!C58*100+'입력값'!C59*100)=0,1,'입력값'!C58*100+'입력값'!C59*100) | BB18: =MIN(MAX(BB16-('입력값'!C9*100+'입력값'!C62*100),0),'입력값'!C58*100+'입력값'!C59*100)*('입력값'!C58*100)/IF(('입력값'!C58*100+'입력값'!C59*100)=0,1,'입력값'!C58*100+'입력값'!C59*100) | BC18: =MIN(MAX(BC16-('입력값'!C9*100+'입력값'!C62*100),0),'입력값'!C58*100+'입력값'!C59*100)*('입력값'!C58*100)/IF(('입력값'!C58*100+'입력값'!C59*100)=0,1,'입력값'!C58*100+'입력값'!C59*100) | BD18: =MIN(MAX(BD16-('입력값'!C9*100+'입력값'!C62*100),0),'입력값'!C58*100+'입력값'!C59*100)*('입력값'!C58*100)/IF(('입력값'!C58*100+'입력값'!C59*100)=0,1,'입력값'!C58*100+'입력값'!C59*100) | BE18: =MIN(MAX(BE16-('입력값'!C9*100+'입력값'!C62*100),0),'입력값'!C58*100+'입력값'!C59*100)*('입력값'!C58*100)/IF(('입력값'!C58*100+'입력값'!C59*100)=0,1,'입력값'!C58*100+'입력값'!C59*100) | BF18: =MIN(MAX(BF16-('입력값'!C9*100+'입력값'!C62*100),0),'입력값'!C58*100+'입력값'!C59*100)*('입력값'!C58*100)/IF(('입력값'!C58*100+'입력값'!C59*100)=0,1,'입력값'!C58*100+'입력값'!C59*100) | BG18: =MIN(MAX(BG16-('입력값'!C9*100+'입력값'!C62*100),0),'입력값'!C58*100+'입력값'!C59*100)*('입력값'!C58*100)/IF(('입력값'!C58*100+'입력값'!C59*100)=0,1,'입력값'!C58*100+'입력값'!C59*100) | BH18: =MIN(MAX(BH16-('입력값'!C9*100+'입력값'!C62*100),0),'입력값'!C58*100+'입력값'!C59*100)*('입력값'!C58*100)/IF(('입력값'!C58*100+'입력값'!C59*100)=0,1,'입력값'!C58*100+'입력값'!C59*100) | BI18: =MIN(MAX(BI16-('입력값'!C9*100+'입력값'!C62*100),0),'입력값'!C58*100+'입력값'!C59*100)*('입력값'!C58*100)/IF(('입력값'!C58*100+'입력값'!C59*100)=0,1,'입력값'!C58*100+'입력값'!C59*100) | BJ18: =MIN(MAX(BJ16-('입력값'!C9*100+'입력값'!C62*100),0),'입력값'!C58*100+'입력값'!C59*100)*('입력값'!C58*100)/IF(('입력값'!C58*100+'입력값'!C59*100)=0,1,'입력값'!C58*100+'입력값'!C59*100) | BK18: =MIN(MAX(BK16-('입력값'!C9*100+'입력값'!C62*100),0),'입력값'!C58*100+'입력값'!C59*100)*('입력값'!C58*100)/IF(('입력값'!C58*100+'입력값'!C59*100)=0,1,'입력값'!C58*100+'입력값'!C59*100) | BL18: =MIN(MAX(BL16-('입력값'!C9*100+'입력값'!C62*100),0),'입력값'!C58*100+'입력값'!C59*100)*('입력값'!C58*100)/IF(('입력값'!C58*100+'입력값'!C59*100)=0,1,'입력값'!C58*100+'입력값'!C59*100) | BM18: =MIN(MAX(BM16-('입력값'!C9*100+'입력값'!C62*100),0),'입력값'!C58*100+'입력값'!C59*100)*('입력값'!C58*100)/IF(('입력값'!C58*100+'입력값'!C59*100)=0,1,'입력값'!C58*100+'입력값'!C59*100) | BN18: =MIN(MAX(BN16-('입력값'!C9*100+'입력값'!C62*100),0),'입력값'!C58*100+'입력값'!C59*100)*('입력값'!C58*100)/IF(('입력값'!C58*100+'입력값'!C59*100)=0,1,'입력값'!C58*100+'입력값'!C59*100) | BO18: =MIN(MAX(BO16-('입력값'!C9*100+'입력값'!C62*100),0),'입력값'!C58*100+'입력값'!C59*100)*('입력값'!C58*100)/IF(('입력값'!C58*100+'입력값'!C59*100)=0,1,'입력값'!C58*100+'입력값'!C59*100) | BP18: =MIN(MAX(BP16-('입력값'!C9*100+'입력값'!C62*100),0),'입력값'!C58*100+'입력값'!C59*100)*('입력값'!C58*100)/IF(('입력값'!C58*100+'입력값'!C59*100)=0,1,'입력값'!C58*100+'입력값'!C59*100) | BQ18: =MIN(MAX(BQ16-('입력값'!C9*100+'입력값'!C62*100),0),'입력값'!C58*100+'입력값'!C59*100)*('입력값'!C58*100)/IF(('입력값'!C58*100+'입력값'!C59*100)=0,1,'입력값'!C58*100+'입력값'!C59*100) | BR18: =MIN(MAX(BR16-('입력값'!C9*100+'입력값'!C62*100),0),'입력값'!C58*100+'입력값'!C59*100)*('입력값'!C58*100)/IF(('입력값'!C58*100+'입력값'!C59*100)=0,1,'입력값'!C58*100+'입력값'!C59*100) | BS18: =MIN(MAX(BS16-('입력값'!C9*100+'입력값'!C62*100),0),'입력값'!C58*100+'입력값'!C59*100)*('입력값'!C58*100)/IF(('입력값'!C58*100+'입력값'!C59*100)=0,1,'입력값'!C58*100+'입력값'!C59*100) | BT18: =MIN(MAX(BT16-('입력값'!C9*100+'입력값'!C62*100),0),'입력값'!C58*100+'입력값'!C59*100)*('입력값'!C58*100)/IF(('입력값'!C58*100+'입력값'!C59*100)=0,1,'입력값'!C58*100+'입력값'!C59*100) | BU18: =MIN(MAX(BU16-('입력값'!C9*100+'입력값'!C62*100),0),'입력값'!C58*100+'입력값'!C59*100)*('입력값'!C58*100)/IF(('입력값'!C58*100+'입력값'!C59*100)=0,1,'입력값'!C58*100+'입력값'!C59*100) | BV18: =MIN(MAX(BV16-('입력값'!C9*100+'입력값'!C62*100),0),'입력값'!C58*100+'입력값'!C59*100)*('입력값'!C58*100)/IF(('입력값'!C58*100+'입력값'!C59*100)=0,1,'입력값'!C58*100+'입력값'!C59*100) | BW18: =MIN(MAX(BW16-('입력값'!C9*100+'입력값'!C62*100),0),'입력값'!C58*100+'입력값'!C59*100)*('입력값'!C58*100)/IF(('입력값'!C58*100+'입력값'!C59*100)=0,1,'입력값'!C58*100+'입력값'!C59*100) | BX18: =MIN(MAX(BX16-('입력값'!C9*100+'입력값'!C62*100),0),'입력값'!C58*100+'입력값'!C59*100)*('입력값'!C58*100)/IF(('입력값'!C58*100+'입력값'!C59*100)=0,1,'입력값'!C58*100+'입력값'!C59*100) | BY18: =MIN(MAX(BY16-('입력값'!C9*100+'입력값'!C62*100),0),'입력값'!C58*100+'입력값'!C59*100)*('입력값'!C58*100)/IF(('입력값'!C58*100+'입력값'!C59*100)=0,1,'입력값'!C58*100+'입력값'!C59*100) | BZ18: =MIN(MAX(BZ16-('입력값'!C9*100+'입력값'!C62*100),0),'입력값'!C58*100+'입력값'!C59*100)*('입력값'!C58*100)/IF(('입력값'!C58*100+'입력값'!C59*100)=0,1,'입력값'!C58*100+'입력값'!C59*100) | CA18: =MIN(MAX(CA16-('입력값'!C9*100+'입력값'!C62*100),0),'입력값'!C58*100+'입력값'!C59*100)*('입력값'!C58*100)/IF(('입력값'!C58*100+'입력값'!C59*100)=0,1,'입력값'!C58*100+'입력값'!C59*100) | CB18: =MIN(MAX(CB16-('입력값'!C9*100+'입력값'!C62*100),0),'입력값'!C58*100+'입력값'!C59*100)*('입력값'!C58*100)/IF(('입력값'!C58*100+'입력값'!C59*100)=0,1,'입력값'!C58*100+'입력값'!C59*100) | CC18: =MIN(MAX(CC16-('입력값'!C9*100+'입력값'!C62*100),0),'입력값'!C58*100+'입력값'!C59*100)*('입력값'!C58*100)/IF(('입력값'!C58*100+'입력값'!C59*100)=0,1,'입력값'!C58*100+'입력값'!C59*100) | CD18: =MIN(MAX(CD16-('입력값'!C9*100+'입력값'!C62*100),0),'입력값'!C58*100+'입력값'!C59*100)*('입력값'!C58*100)/IF(('입력값'!C58*100+'입력값'!C59*100)=0,1,'입력값'!C58*100+'입력값'!C59*100) | CE18: =MIN(MAX(CE16-('입력값'!C9*100+'입력값'!C62*100),0),'입력값'!C58*100+'입력값'!C59*100)*('입력값'!C58*100)/IF(('입력값'!C58*100+'입력값'!C59*100)=0,1,'입력값'!C58*100+'입력값'!C59*100) | CF18: =MIN(MAX(CF16-('입력값'!C9*100+'입력값'!C62*100),0),'입력값'!C58*100+'입력값'!C59*100)*('입력값'!C58*100)/IF(('입력값'!C58*100+'입력값'!C59*100)=0,1,'입력값'!C58*100+'입력값'!C59*100) | CG18: =MIN(MAX(CG16-('입력값'!C9*100+'입력값'!C62*100),0),'입력값'!C58*100+'입력값'!C59*100)*('입력값'!C58*100)/IF(('입력값'!C58*100+'입력값'!C59*100)=0,1,'입력값'!C58*100+'입력값'!C59*100) | CH18: =MIN(MAX(CH16-('입력값'!C9*100+'입력값'!C62*100),0),'입력값'!C58*100+'입력값'!C59*100)*('입력값'!C58*100)/IF(('입력값'!C58*100+'입력값'!C59*100)=0,1,'입력값'!C58*100+'입력값'!C59*100) | CI18: =MIN(MAX(CI16-('입력값'!C9*100+'입력값'!C62*100),0),'입력값'!C58*100+'입력값'!C59*100)*('입력값'!C58*100)/IF(('입력값'!C58*100+'입력값'!C59*100)=0,1,'입력값'!C58*100+'입력값'!C59*100) | CJ18: =MIN(MAX(CJ16-('입력값'!C9*100+'입력값'!C62*100),0),'입력값'!C58*100+'입력값'!C59*100)*('입력값'!C58*100)/IF(('입력값'!C58*100+'입력값'!C59*100)=0,1,'입력값'!C58*100+'입력값'!C59*100) | CK18: =MIN(MAX(CK16-('입력값'!C9*100+'입력값'!C62*100),0),'입력값'!C58*100+'입력값'!C59*100)*('입력값'!C58*100)/IF(('입력값'!C58*100+'입력값'!C59*100)=0,1,'입력값'!C58*100+'입력값'!C59*100) | CL18: =MIN(MAX(CL16-('입력값'!C9*100+'입력값'!C62*100),0),'입력값'!C58*100+'입력값'!C59*100)*('입력값'!C58*100)/IF(('입력값'!C58*100+'입력값'!C59*100)=0,1,'입력값'!C58*100+'입력값'!C59*100)
B19: 선순위B 누적인출 | C19: [KRWm] | E19: =MIN(MAX(E16-('입력값'!C9*100+'입력값'!C62*100),0),'입력값'!C58*100+'입력값'!C59*100)*('입력값'!C59*100)/IF(('입력값'!C58*100+'입력값'!C59*100)=0,1,'입력값'!C58*100+'입력값'!C59*100) | F19: =MIN(MAX(F16-('입력값'!C9*100+'입력값'!C62*100),0),'입력값'!C58*100+'입력값'!C59*100)*('입력값'!C59*100)/IF(('입력값'!C58*100+'입력값'!C59*100)=0,1,'입력값'!C58*100+'입력값'!C59*100) | G19: =MIN(MAX(G16-('입력값'!C9*100+'입력값'!C62*100),0),'입력값'!C58*100+'입력값'!C59*100)*('입력값'!C59*100)/IF(('입력값'!C58*100+'입력값'!C59*100)=0,1,'입력값'!C58*100+'입력값'!C59*100) | H19: =MIN(MAX(H16-('입력값'!C9*100+'입력값'!C62*100),0),'입력값'!C58*100+'입력값'!C59*100)*('입력값'!C59*100)/IF(('입력값'!C58*100+'입력값'!C59*100)=0,1,'입력값'!C58*100+'입력값'!C59*100) | I19: =MIN(MAX(I16-('입력값'!C9*100+'입력값'!C62*100),0),'입력값'!C58*100+'입력값'!C59*100)*('입력값'!C59*100)/IF(('입력값'!C58*100+'입력값'!C59*100)=0,1,'입력값'!C58*100+'입력값'!C59*100) | J19: =MIN(MAX(J16-('입력값'!C9*100+'입력값'!C62*100),0),'입력값'!C58*100+'입력값'!C59*100)*('입력값'!C59*100)/IF(('입력값'!C58*100+'입력값'!C59*100)=0,1,'입력값'!C58*100+'입력값'!C59*100) | K19: =MIN(MAX(K16-('입력값'!C9*100+'입력값'!C62*100),0),'입력값'!C58*100+'입력값'!C59*100)*('입력값'!C59*100)/IF(('입력값'!C58*100+'입력값'!C59*100)=0,1,'입력값'!C58*100+'입력값'!C59*100) | L19: =MIN(MAX(L16-('입력값'!C9*100+'입력값'!C62*100),0),'입력값'!C58*100+'입력값'!C59*100)*('입력값'!C59*100)/IF(('입력값'!C58*100+'입력값'!C59*100)=0,1,'입력값'!C58*100+'입력값'!C59*100) | M19: =MIN(MAX(M16-('입력값'!C9*100+'입력값'!C62*100),0),'입력값'!C58*100+'입력값'!C59*100)*('입력값'!C59*100)/IF(('입력값'!C58*100+'입력값'!C59*100)=0,1,'입력값'!C58*100+'입력값'!C59*100) | N19: =MIN(MAX(N16-('입력값'!C9*100+'입력값'!C62*100),0),'입력값'!C58*100+'입력값'!C59*100)*('입력값'!C59*100)/IF(('입력값'!C58*100+'입력값'!C59*100)=0,1,'입력값'!C58*100+'입력값'!C59*100) | O19: =MIN(MAX(O16-('입력값'!C9*100+'입력값'!C62*100),0),'입력값'!C58*100+'입력값'!C59*100)*('입력값'!C59*100)/IF(('입력값'!C58*100+'입력값'!C59*100)=0,1,'입력값'!C58*100+'입력값'!C59*100) | P19: =MIN(MAX(P16-('입력값'!C9*100+'입력값'!C62*100),0),'입력값'!C58*100+'입력값'!C59*100)*('입력값'!C59*100)/IF(('입력값'!C58*100+'입력값'!C59*100)=0,1,'입력값'!C58*100+'입력값'!C59*100) | Q19: =MIN(MAX(Q16-('입력값'!C9*100+'입력값'!C62*100),0),'입력값'!C58*100+'입력값'!C59*100)*('입력값'!C59*100)/IF(('입력값'!C58*100+'입력값'!C59*100)=0,1,'입력값'!C58*100+'입력값'!C59*100) | R19: =MIN(MAX(R16-('입력값'!C9*100+'입력값'!C62*100),0),'입력값'!C58*100+'입력값'!C59*100)*('입력값'!C59*100)/IF(('입력값'!C58*100+'입력값'!C59*100)=0,1,'입력값'!C58*100+'입력값'!C59*100) | S19: =MIN(MAX(S16-('입력값'!C9*100+'입력값'!C62*100),0),'입력값'!C58*100+'입력값'!C59*100)*('입력값'!C59*100)/IF(('입력값'!C58*100+'입력값'!C59*100)=0,1,'입력값'!C58*100+'입력값'!C59*100) | T19: =MIN(MAX(T16-('입력값'!C9*100+'입력값'!C62*100),0),'입력값'!C58*100+'입력값'!C59*100)*('입력값'!C59*100)/IF(('입력값'!C58*100+'입력값'!C59*100)=0,1,'입력값'!C58*100+'입력값'!C59*100) | U19: =MIN(MAX(U16-('입력값'!C9*100+'입력값'!C62*100),0),'입력값'!C58*100+'입력값'!C59*100)*('입력값'!C59*100)/IF(('입력값'!C58*100+'입력값'!C59*100)=0,1,'입력값'!C58*100+'입력값'!C59*100) | V19: =MIN(MAX(V16-('입력값'!C9*100+'입력값'!C62*100),0),'입력값'!C58*100+'입력값'!C59*100)*('입력값'!C59*100)/IF(('입력값'!C58*100+'입력값'!C59*100)=0,1,'입력값'!C58*100+'입력값'!C59*100) | W19: =MIN(MAX(W16-('입력값'!C9*100+'입력값'!C62*100),0),'입력값'!C58*100+'입력값'!C59*100)*('입력값'!C59*100)/IF(('입력값'!C58*100+'입력값'!C59*100)=0,1,'입력값'!C58*100+'입력값'!C59*100) | X19: =MIN(MAX(X16-('입력값'!C9*100+'입력값'!C62*100),0),'입력값'!C58*100+'입력값'!C59*100)*('입력값'!C59*100)/IF(('입력값'!C58*100+'입력값'!C59*100)=0,1,'입력값'!C58*100+'입력값'!C59*100) | Y19: =MIN(MAX(Y16-('입력값'!C9*100+'입력값'!C62*100),0),'입력값'!C58*100+'입력값'!C59*100)*('입력값'!C59*100)/IF(('입력값'!C58*100+'입력값'!C59*100)=0,1,'입력값'!C58*100+'입력값'!C59*100) | Z19: =MIN(MAX(Z16-('입력값'!C9*100+'입력값'!C62*100),0),'입력값'!C58*100+'입력값'!C59*100)*('입력값'!C59*100)/IF(('입력값'!C58*100+'입력값'!C59*100)=0,1,'입력값'!C58*100+'입력값'!C59*100) | AA19: =MIN(MAX(AA16-('입력값'!C9*100+'입력값'!C62*100),0),'입력값'!C58*100+'입력값'!C59*100)*('입력값'!C59*100)/IF(('입력값'!C58*100+'입력값'!C59*100)=0,1,'입력값'!C58*100+'입력값'!C59*100) | AB19: =MIN(MAX(AB16-('입력값'!C9*100+'입력값'!C62*100),0),'입력값'!C58*100+'입력값'!C59*100)*('입력값'!C59*100)/IF(('입력값'!C58*100+'입력값'!C59*100)=0,1,'입력값'!C58*100+'입력값'!C59*100) | AC19: =MIN(MAX(AC16-('입력값'!C9*100+'입력값'!C62*100),0),'입력값'!C58*100+'입력값'!C59*100)*('입력값'!C59*100)/IF(('입력값'!C58*100+'입력값'!C59*100)=0,1,'입력값'!C58*100+'입력값'!C59*100) | AD19: =MIN(MAX(AD16-('입력값'!C9*100+'입력값'!C62*100),0),'입력값'!C58*100+'입력값'!C59*100)*('입력값'!C59*100)/IF(('입력값'!C58*100+'입력값'!C59*100)=0,1,'입력값'!C58*100+'입력값'!C59*100) | AE19: =MIN(MAX(AE16-('입력값'!C9*100+'입력값'!C62*100),0),'입력값'!C58*100+'입력값'!C59*100)*('입력값'!C59*100)/IF(('입력값'!C58*100+'입력값'!C59*100)=0,1,'입력값'!C58*100+'입력값'!C59*100) | AF19: =MIN(MAX(AF16-('입력값'!C9*100+'입력값'!C62*100),0),'입력값'!C58*100+'입력값'!C59*100)*('입력값'!C59*100)/IF(('입력값'!C58*100+'입력값'!C59*100)=0,1,'입력값'!C58*100+'입력값'!C59*100) | AG19: =MIN(MAX(AG16-('입력값'!C9*100+'입력값'!C62*100),0),'입력값'!C58*100+'입력값'!C59*100)*('입력값'!C59*100)/IF(('입력값'!C58*100+'입력값'!C59*100)=0,1,'입력값'!C58*100+'입력값'!C59*100) | AH19: =MIN(MAX(AH16-('입력값'!C9*100+'입력값'!C62*100),0),'입력값'!C58*100+'입력값'!C59*100)*('입력값'!C59*100)/IF(('입력값'!C58*100+'입력값'!C59*100)=0,1,'입력값'!C58*100+'입력값'!C59*100) | AI19: =MIN(MAX(AI16-('입력값'!C9*100+'입력값'!C62*100),0),'입력값'!C58*100+'입력값'!C59*100)*('입력값'!C59*100)/IF(('입력값'!C58*100+'입력값'!C59*100)=0,1,'입력값'!C58*100+'입력값'!C59*100) | AJ19: =MIN(MAX(AJ16-('입력값'!C9*100+'입력값'!C62*100),0),'입력값'!C58*100+'입력값'!C59*100)*('입력값'!C59*100)/IF(('입력값'!C58*100+'입력값'!C59*100)=0,1,'입력값'!C58*100+'입력값'!C59*100) | AK19: =MIN(MAX(AK16-('입력값'!C9*100+'입력값'!C62*100),0),'입력값'!C58*100+'입력값'!C59*100)*('입력값'!C59*100)/IF(('입력값'!C58*100+'입력값'!C59*100)=0,1,'입력값'!C58*100+'입력값'!C59*100) | AL19: =MIN(MAX(AL16-('입력값'!C9*100+'입력값'!C62*100),0),'입력값'!C58*100+'입력값'!C59*100)*('입력값'!C59*100)/IF(('입력값'!C58*100+'입력값'!C59*100)=0,1,'입력값'!C58*100+'입력값'!C59*100) | AM19: =MIN(MAX(AM16-('입력값'!C9*100+'입력값'!C62*100),0),'입력값'!C58*100+'입력값'!C59*100)*('입력값'!C59*100)/IF(('입력값'!C58*100+'입력값'!C59*100)=0,1,'입력값'!C58*100+'입력값'!C59*100) | AN19: =MIN(MAX(AN16-('입력값'!C9*100+'입력값'!C62*100),0),'입력값'!C58*100+'입력값'!C59*100)*('입력값'!C59*100)/IF(('입력값'!C58*100+'입력값'!C59*100)=0,1,'입력값'!C58*100+'입력값'!C59*100) | AO19: =MIN(MAX(AO16-('입력값'!C9*100+'입력값'!C62*100),0),'입력값'!C58*100+'입력값'!C59*100)*('입력값'!C59*100)/IF(('입력값'!C58*100+'입력값'!C59*100)=0,1,'입력값'!C58*100+'입력값'!C59*100) | AP19: =MIN(MAX(AP16-('입력값'!C9*100+'입력값'!C62*100),0),'입력값'!C58*100+'입력값'!C59*100)*('입력값'!C59*100)/IF(('입력값'!C58*100+'입력값'!C59*100)=0,1,'입력값'!C58*100+'입력값'!C59*100) | AQ19: =MIN(MAX(AQ16-('입력값'!C9*100+'입력값'!C62*100),0),'입력값'!C58*100+'입력값'!C59*100)*('입력값'!C59*100)/IF(('입력값'!C58*100+'입력값'!C59*100)=0,1,'입력값'!C58*100+'입력값'!C59*100) | AR19: =MIN(MAX(AR16-('입력값'!C9*100+'입력값'!C62*100),0),'입력값'!C58*100+'입력값'!C59*100)*('입력값'!C59*100)/IF(('입력값'!C58*100+'입력값'!C59*100)=0,1,'입력값'!C58*100+'입력값'!C59*100) | AS19: =MIN(MAX(AS16-('입력값'!C9*100+'입력값'!C62*100),0),'입력값'!C58*100+'입력값'!C59*100)*('입력값'!C59*100)/IF(('입력값'!C58*100+'입력값'!C59*100)=0,1,'입력값'!C58*100+'입력값'!C59*100) | AT19: =MIN(MAX(AT16-('입력값'!C9*100+'입력값'!C62*100),0),'입력값'!C58*100+'입력값'!C59*100)*('입력값'!C59*100)/IF(('입력값'!C58*100+'입력값'!C59*100)=0,1,'입력값'!C58*100+'입력값'!C59*100) | AU19: =MIN(MAX(AU16-('입력값'!C9*100+'입력값'!C62*100),0),'입력값'!C58*100+'입력값'!C59*100)*('입력값'!C59*100)/IF(('입력값'!C58*100+'입력값'!C59*100)=0,1,'입력값'!C58*100+'입력값'!C59*100) | AV19: =MIN(MAX(AV16-('입력값'!C9*100+'입력값'!C62*100),0),'입력값'!C58*100+'입력값'!C59*100)*('입력값'!C59*100)/IF(('입력값'!C58*100+'입력값'!C59*100)=0,1,'입력값'!C58*100+'입력값'!C59*100) | AW19: =MIN(MAX(AW16-('입력값'!C9*100+'입력값'!C62*100),0),'입력값'!C58*100+'입력값'!C59*100)*('입력값'!C59*100)/IF(('입력값'!C58*100+'입력값'!C59*100)=0,1,'입력값'!C58*100+'입력값'!C59*100) | AX19: =MIN(MAX(AX16-('입력값'!C9*100+'입력값'!C62*100),0),'입력값'!C58*100+'입력값'!C59*100)*('입력값'!C59*100)/IF(('입력값'!C58*100+'입력값'!C59*100)=0,1,'입력값'!C58*100+'입력값'!C59*100) | AY19: =MIN(MAX(AY16-('입력값'!C9*100+'입력값'!C62*100),0),'입력값'!C58*100+'입력값'!C59*100)*('입력값'!C59*100)/IF(('입력값'!C58*100+'입력값'!C59*100)=0,1,'입력값'!C58*100+'입력값'!C59*100) | AZ19: =MIN(MAX(AZ16-('입력값'!C9*100+'입력값'!C62*100),0),'입력값'!C58*100+'입력값'!C59*100)*('입력값'!C59*100)/IF(('입력값'!C58*100+'입력값'!C59*100)=0,1,'입력값'!C58*100+'입력값'!C59*100) | BA19: =MIN(MAX(BA16-('입력값'!C9*100+'입력값'!C62*100),0),'입력값'!C58*100+'입력값'!C59*100)*('입력값'!C59*100)/IF(('입력값'!C58*100+'입력값'!C59*100)=0,1,'입력값'!C58*100+'입력값'!C59*100) | BB19: =MIN(MAX(BB16-('입력값'!C9*100+'입력값'!C62*100),0),'입력값'!C58*100+'입력값'!C59*100)*('입력값'!C59*100)/IF(('입력값'!C58*100+'입력값'!C59*100)=0,1,'입력값'!C58*100+'입력값'!C59*100) | BC19: =MIN(MAX(BC16-('입력값'!C9*100+'입력값'!C62*100),0),'입력값'!C58*100+'입력값'!C59*100)*('입력값'!C59*100)/IF(('입력값'!C58*100+'입력값'!C59*100)=0,1,'입력값'!C58*100+'입력값'!C59*100) | BD19: =MIN(MAX(BD16-('입력값'!C9*100+'입력값'!C62*100),0),'입력값'!C58*100+'입력값'!C59*100)*('입력값'!C59*100)/IF(('입력값'!C58*100+'입력값'!C59*100)=0,1,'입력값'!C58*100+'입력값'!C59*100) | BE19: =MIN(MAX(BE16-('입력값'!C9*100+'입력값'!C62*100),0),'입력값'!C58*100+'입력값'!C59*100)*('입력값'!C59*100)/IF(('입력값'!C58*100+'입력값'!C59*100)=0,1,'입력값'!C58*100+'입력값'!C59*100) | BF19: =MIN(MAX(BF16-('입력값'!C9*100+'입력값'!C62*100),0),'입력값'!C58*100+'입력값'!C59*100)*('입력값'!C59*100)/IF(('입력값'!C58*100+'입력값'!C59*100)=0,1,'입력값'!C58*100+'입력값'!C59*100) | BG19: =MIN(MAX(BG16-('입력값'!C9*100+'입력값'!C62*100),0),'입력값'!C58*100+'입력값'!C59*100)*('입력값'!C59*100)/IF(('입력값'!C58*100+'입력값'!C59*100)=0,1,'입력값'!C58*100+'입력값'!C59*100) | BH19: =MIN(MAX(BH16-('입력값'!C9*100+'입력값'!C62*100),0),'입력값'!C58*100+'입력값'!C59*100)*('입력값'!C59*100)/IF(('입력값'!C58*100+'입력값'!C59*100)=0,1,'입력값'!C58*100+'입력값'!C59*100) | BI19: =MIN(MAX(BI16-('입력값'!C9*100+'입력값'!C62*100),0),'입력값'!C58*100+'입력값'!C59*100)*('입력값'!C59*100)/IF(('입력값'!C58*100+'입력값'!C59*100)=0,1,'입력값'!C58*100+'입력값'!C59*100) | BJ19: =MIN(MAX(BJ16-('입력값'!C9*100+'입력값'!C62*100),0),'입력값'!C58*100+'입력값'!C59*100)*('입력값'!C59*100)/IF(('입력값'!C58*100+'입력값'!C59*100)=0,1,'입력값'!C58*100+'입력값'!C59*100) | BK19: =MIN(MAX(BK16-('입력값'!C9*100+'입력값'!C62*100),0),'입력값'!C58*100+'입력값'!C59*100)*('입력값'!C59*100)/IF(('입력값'!C58*100+'입력값'!C59*100)=0,1,'입력값'!C58*100+'입력값'!C59*100) | BL19: =MIN(MAX(BL16-('입력값'!C9*100+'입력값'!C62*100),0),'입력값'!C58*100+'입력값'!C59*100)*('입력값'!C59*100)/IF(('입력값'!C58*100+'입력값'!C59*100)=0,1,'입력값'!C58*100+'입력값'!C59*100) | BM19: =MIN(MAX(BM16-('입력값'!C9*100+'입력값'!C62*100),0),'입력값'!C58*100+'입력값'!C59*100)*('입력값'!C59*100)/IF(('입력값'!C58*100+'입력값'!C59*100)=0,1,'입력값'!C58*100+'입력값'!C59*100) | BN19: =MIN(MAX(BN16-('입력값'!C9*100+'입력값'!C62*100),0),'입력값'!C58*100+'입력값'!C59*100)*('입력값'!C59*100)/IF(('입력값'!C58*100+'입력값'!C59*100)=0,1,'입력값'!C58*100+'입력값'!C59*100) | BO19: =MIN(MAX(BO16-('입력값'!C9*100+'입력값'!C62*100),0),'입력값'!C58*100+'입력값'!C59*100)*('입력값'!C59*100)/IF(('입력값'!C58*100+'입력값'!C59*100)=0,1,'입력값'!C58*100+'입력값'!C59*100) | BP19: =MIN(MAX(BP16-('입력값'!C9*100+'입력값'!C62*100),0),'입력값'!C58*100+'입력값'!C59*100)*('입력값'!C59*100)/IF(('입력값'!C58*100+'입력값'!C59*100)=0,1,'입력값'!C58*100+'입력값'!C59*100) | BQ19: =MIN(MAX(BQ16-('입력값'!C9*100+'입력값'!C62*100),0),'입력값'!C58*100+'입력값'!C59*100)*('입력값'!C59*100)/IF(('입력값'!C58*100+'입력값'!C59*100)=0,1,'입력값'!C58*100+'입력값'!C59*100) | BR19: =MIN(MAX(BR16-('입력값'!C9*100+'입력값'!C62*100),0),'입력값'!C58*100+'입력값'!C59*100)*('입력값'!C59*100)/IF(('입력값'!C58*100+'입력값'!C59*100)=0,1,'입력값'!C58*100+'입력값'!C59*100) | BS19: =MIN(MAX(BS16-('입력값'!C9*100+'입력값'!C62*100),0),'입력값'!C58*100+'입력값'!C59*100)*('입력값'!C59*100)/IF(('입력값'!C58*100+'입력값'!C59*100)=0,1,'입력값'!C58*100+'입력값'!C59*100) | BT19: =MIN(MAX(BT16-('입력값'!C9*100+'입력값'!C62*100),0),'입력값'!C58*100+'입력값'!C59*100)*('입력값'!C59*100)/IF(('입력값'!C58*100+'입력값'!C59*100)=0,1,'입력값'!C58*100+'입력값'!C59*100) | BU19: =MIN(MAX(BU16-('입력값'!C9*100+'입력값'!C62*100),0),'입력값'!C58*100+'입력값'!C59*100)*('입력값'!C59*100)/IF(('입력값'!C58*100+'입력값'!C59*100)=0,1,'입력값'!C58*100+'입력값'!C59*100) | BV19: =MIN(MAX(BV16-('입력값'!C9*100+'입력값'!C62*100),0),'입력값'!C58*100+'입력값'!C59*100)*('입력값'!C59*100)/IF(('입력값'!C58*100+'입력값'!C59*100)=0,1,'입력값'!C58*100+'입력값'!C59*100) | BW19: =MIN(MAX(BW16-('입력값'!C9*100+'입력값'!C62*100),0),'입력값'!C58*100+'입력값'!C59*100)*('입력값'!C59*100)/IF(('입력값'!C58*100+'입력값'!C59*100)=0,1,'입력값'!C58*100+'입력값'!C59*100) | BX19: =MIN(MAX(BX16-('입력값'!C9*100+'입력값'!C62*100),0),'입력값'!C58*100+'입력값'!C59*100)*('입력값'!C59*100)/IF(('입력값'!C58*100+'입력값'!C59*100)=0,1,'입력값'!C58*100+'입력값'!C59*100) | BY19: =MIN(MAX(BY16-('입력값'!C9*100+'입력값'!C62*100),0),'입력값'!C58*100+'입력값'!C59*100)*('입력값'!C59*100)/IF(('입력값'!C58*100+'입력값'!C59*100)=0,1,'입력값'!C58*100+'입력값'!C59*100) | BZ19: =MIN(MAX(BZ16-('입력값'!C9*100+'입력값'!C62*100),0),'입력값'!C58*100+'입력값'!C59*100)*('입력값'!C59*100)/IF(('입력값'!C58*100+'입력값'!C59*100)=0,1,'입력값'!C58*100+'입력값'!C59*100) | CA19: =MIN(MAX(CA16-('입력값'!C9*100+'입력값'!C62*100),0),'입력값'!C58*100+'입력값'!C59*100)*('입력값'!C59*100)/IF(('입력값'!C58*100+'입력값'!C59*100)=0,1,'입력값'!C58*100+'입력값'!C59*100) | CB19: =MIN(MAX(CB16-('입력값'!C9*100+'입력값'!C62*100),0),'입력값'!C58*100+'입력값'!C59*100)*('입력값'!C59*100)/IF(('입력값'!C58*100+'입력값'!C59*100)=0,1,'입력값'!C58*100+'입력값'!C59*100) | CC19: =MIN(MAX(CC16-('입력값'!C9*100+'입력값'!C62*100),0),'입력값'!C58*100+'입력값'!C59*100)*('입력값'!C59*100)/IF(('입력값'!C58*100+'입력값'!C59*100)=0,1,'입력값'!C58*100+'입력값'!C59*100) | CD19: =MIN(MAX(CD16-('입력값'!C9*100+'입력값'!C62*100),0),'입력값'!C58*100+'입력값'!C59*100)*('입력값'!C59*100)/IF(('입력값'!C58*100+'입력값'!C59*100)=0,1,'입력값'!C58*100+'입력값'!C59*100) | CE19: =MIN(MAX(CE16-('입력값'!C9*100+'입력값'!C62*100),0),'입력값'!C58*100+'입력값'!C59*100)*('입력값'!C59*100)/IF(('입력값'!C58*100+'입력값'!C59*100)=0,1,'입력값'!C58*100+'입력값'!C59*100) | CF19: =MIN(MAX(CF16-('입력값'!C9*100+'입력값'!C62*100),0),'입력값'!C58*100+'입력값'!C59*100)*('입력값'!C59*100)/IF(('입력값'!C58*100+'입력값'!C59*100)=0,1,'입력값'!C58*100+'입력값'!C59*100) | CG19: =MIN(MAX(CG16-('입력값'!C9*100+'입력값'!C62*100),0),'입력값'!C58*100+'입력값'!C59*100)*('입력값'!C59*100)/IF(('입력값'!C58*100+'입력값'!C59*100)=0,1,'입력값'!C58*100+'입력값'!C59*100) | CH19: =MIN(MAX(CH16-('입력값'!C9*100+'입력값'!C62*100),0),'입력값'!C58*100+'입력값'!C59*100)*('입력값'!C59*100)/IF(('입력값'!C58*100+'입력값'!C59*100)=0,1,'입력값'!C58*100+'입력값'!C59*100) | CI19: =MIN(MAX(CI16-('입력값'!C9*100+'입력값'!C62*100),0),'입력값'!C58*100+'입력값'!C59*100)*('입력값'!C59*100)/IF(('입력값'!C58*100+'입력값'!C59*100)=0,1,'입력값'!C58*100+'입력값'!C59*100) | CJ19: =MIN(MAX(CJ16-('입력값'!C9*100+'입력값'!C62*100),0),'입력값'!C58*100+'입력값'!C59*100)*('입력값'!C59*100)/IF(('입력값'!C58*100+'입력값'!C59*100)=0,1,'입력값'!C58*100+'입력값'!C59*100) | CK19: =MIN(MAX(CK16-('입력값'!C9*100+'입력값'!C62*100),0),'입력값'!C58*100+'입력값'!C59*100)*('입력값'!C59*100)/IF(('입력값'!C58*100+'입력값'!C59*100)=0,1,'입력값'!C58*100+'입력값'!C59*100) | CL19: =MIN(MAX(CL16-('입력값'!C9*100+'입력값'!C62*100),0),'입력값'!C58*100+'입력값'!C59*100)*('입력값'!C59*100)/IF(('입력값'!C58*100+'입력값'!C59*100)=0,1,'입력값'!C58*100+'입력값'!C59*100)
