Workbook

Sheet 목차
B2: 태양광 발전사업
B3: 재무모델 v2 (분기·5트랜치) — 재생E AI Agent 자동생성 · 2026-08-26
B6: 시트 | C6: 내용
B7: Report | C7: Executive Summary — 핵심 KPI
B8: 입력값 | C8: 화면에서 입력한 원본 값 — Funding 등이 이 시트를 참조
B9: Funding | C9: 자금조달 — 자본금 + 5트랜치 조건
B10: Debt | C10: 트랜치별 상환 스케줄 (A/B/C/D/후순위) + 합계
B11: Revenue | C11: 발전량 · 매출
B12: Opex | C12: 운영비 (선순위/후순위)
B13: IS(Q) | C13: 분기 손익계산서
B14: CF(Q) | C14: 분기 현금흐름 · DSCR · 배당
B16: ※ Funding 시트의 트랜치 조건·총사업비 항목·사업자 지분은 "입력값" 시트를 참조하는 수식입니다(입력값 시트를 고치면 같이 바뀝니다). 그 외 계산 결과(세금·DSCR·배당 등)는 값(baked) 기준이라 가정을 바꾸려면 생성기에서 다시 뽑아야 합니다.

Sheet Report
A1: 태양광 발전사업
A2: Executive Summary (v2 · 분기 · 5트랜치)
B4: 사업 개요
B6: 사업명 | D6: 태양광 발전사업
B7: 설비용량 [MW] | D7: 99.998
B8: 총 기간 수(분기) | D8: 86
B9: 건설 개시 | D9: 2024-06
B11: 재원조달
B13: 총투자비(TIC) [KRWm] | D13: 145474.28
B14: 건설이자(IDC) [KRWm] | D14: 4405.2812
B15: 자기자본 [KRWm] | D15: 15000
B16: 차입금 합계 [KRWm] | D16: 126069
B18: 수익성 지표
B20: Project IRR 세전 [%] | D20: 0.11848488
B21: Project IRR 세후 [%] | D21: 0.10465735
B22: Equity IRR (FCFE) [%] | D22: 0.32982826
B23: Equity IRR (배당) [%] | D23: 0.29986257
B24: Investor IRR [%] | D24: 0.10770215
B25: 최소 단순DSCR(연 합산) [x] | D25: 1.2410853
B26: 최소 누적DSCR [x] | D26: 1.8119161
B27: 총영업수익(전체기간) [KRWm] | D27: 405780.77
B28: 총영업비용(전체기간) [KRWm] | D28: 28498.934
B29: 총선순위이자 [KRWm] | D29: 58070.533
B30: 총법인세 [KRWm] | D30: 36951.244
B31: 총배당(연차+청산) [KRWm] | D31: 159191.06

Sheet 입력값
A1: 태양광 발전사업
A2: 입력값 — 화면에서 입력한 값 (다른 시트가 이 시트를 참조)
B4: 사업 기본 가정
B6: 사업명 | C6: 태양광 발전사업
B7: 설비용량[MW] | C7: 99.998
B8: 총사업비[억원] | C8: 1410.69
B9: 자기자본[억원] | C9: 150
B10: 판매단가[원/kWh] | C10: 154.8
B11: 판매단가 에스컬레이션[%/yr] | C11: 0
B12: 발전량 열화율[%/yr] | C12: 0.5
B13: 소내소비율[%] | C13: 0
B14: 일조시간[h/day] | C14: 3.77
B16: 트랜치 조건
B18: 트랜치 | C18: 금액[억원] | D18: 건설금리[%] | E18: 운영금리[%] | F18: 거치(yr) | G18: 상환(yr) | H18: 방식
B19: 선순위A | C19: 1260.69 | D19: 0.055 | E19: 0.055 | F19: 2 | G19: 15 | H19: 1
B20: 선순위B | C20: 0 | D20: 0.055 | E20: 0.055 | F20: 2 | G20: 15 | H20: 1
B21: 선순위C | C21: 0 | D21: 0.055 | E21: 0.055 | F21: 2 | G21: 15 | H21: 1
B22: 선순위D | C22: 0 | D22: 0.055 | E22: 0.055 | F22: 2 | G22: 15 | H22: 1
B23: 후순위 | C23: 0 | D23: 0.055 | E23: 0.055 | F23: 2 | G23: 15 | H23: 1
B25: 총사업비 항목
B27: 항목 | C27: 금액[억원]
B28: EPC
B29: 감리비
B30: 공사보험료
B31: 토지임대료(선납)
B32: 토지임대료(분납)
B33: 사업개발비
B34: 민원처리비
B35: 사업성자문비
B36: 법인운영비
B37: 기타예비비
B38: 신주발행비용
B39: 금융부대비용
B41: 운영비 항목
B43: 항목 | C43: 연간금액[억원/yr] | D43: 에스컬레이션[%/yr]
B44: 부지임대료 | C44: 5 | D44: 0
B45: O&M | C45: 8 | D45: 1.5
B46: 보험료 | C46: 0 | D46: 0
B47: 환경모니터링비용 | C47: 0 | D47: 0
B48: 소내전력비 | C48: 0 | D48: 2
...

Sheet Funding
A1: 태양광 발전사업
A2: 자금조달 — 자본금 + 5개 트랜치
B4: 트랜치 조건
B6: 트랜치 | C6: 금액[KRWm] | D6: 투입순서 | E6: 건설금리 | F6: 운영금리 | G6: 거치(yr) | H6: 상환(yr) | I6: 방식 | J6: 상환개시
B7: 자본금 | C7: ='입력값'!C9*100
B8: 선순위A | C8: ='입력값'!C19*100 | E8: ='입력값'!D19 | F8: ='입력값'!E19 | G8: ='입력값'!F19 | H8: ='입력값'!G19 | I8: ='입력값'!H19 | J8: 2026-09-30
B9: 선순위B | C9: ='입력값'!C20*100 | E9: ='입력값'!D20 | F9: ='입력값'!E20 | G9: ='입력값'!F20 | H9: ='입력값'!G20 | I9: ='입력값'!H20 | J9: -
B10: 선순위C | C10: ='입력값'!C21*100 | E10: ='입력값'!D21 | F10: ='입력값'!E21 | G10: ='입력값'!F21 | H10: ='입력값'!G21 | I10: ='입력값'!H21 | J10: -
B11: 선순위D | C11: ='입력값'!C22*100 | E11: ='입력값'!D22 | F11: ='입력값'!E22 | G11: ='입력값'!F22 | H11: ='입력값'!G22 | I11: ='입력값'!H22 | J11: -
B12: 후순위 | C12: ='입력값'!C23*100 | E12: ='입력값'!D23 | F12: ='입력값'!E23 | G12: ='입력값'!F23 | H12: ='입력값'!G23 | I12: ='입력값'!H23 | J12: -
B14: 건설이자(IDC)
B16: IDC 합계[KRWm] | C16: 4405.2812
B17: 총투자비(TIC)[KRWm] | C17: 145474.28
B18: 총사업비(건설이자 제외)[KRWm] | C18: ='입력값'!C8*100
B20: 총사업비 세부내역
B22: 항목 | C22: 금액[KRWm]
B23: ='입력값'!B28
B24: ='입력값'!B29
B25: ='입력값'!B30
B26: ='입력값'!B31
B27: ='입력값'!B32
B28: ='입력값'!B33
B29: ='입력값'!B34
B30: ='입력값'!B35
B31: ='입력값'!B36
B32: ='입력값'!B37
B33: ='입력값'!B38
B34: ='입력값'!B39
B35: 합계 | C35: ='입력값'!C8*100

Sheet Debt
A1: 태양광 발전사업
A2: 차입금 상환 스케줄 — 트랜치별 + 합계
B4: 트랜치별 인출/상환 + 전체 합계
B6: 구 분 | C6: unit | D6: 합 계 | E6: 2024-06-30 | F6: 2024-09-30 | G6: 2024-12-31 | H6: 2025-03-31 | I6: 2025-06-30 | J6: 2025-09-30 | K6: 2025-12-31 | L6: 2026-03-31 | M6: 2026-06-30 | N6: 2026-09-30 | O6: 2026-12-31 | P6: 2027-03-31 | Q6: 2027-06-30 | R6: 2027-09-30 | S6: 2027-12-31 | T6: 2028-03-31 | U6: 2028-06-30 | V6: 2028-09-30 | W6: 2028-12-31 | X6: 2029-03-31 | Y6: 2029-06-30 | Z6: 2029-09-30 | AA6: 2029-12-31 | AB6: 2030-03-31 | AC6: 2030-06-30 | AD6: 2030-09-30 | AE6: 2030-12-31 | AF6: 2031-03-31 | AG6: 2031-06-30 | AH6: 2031-09-30 | AI6: 2031-12-31 | AJ6: 2032-03-31 | AK6: 2032-06-30 | AL6: 2032-09-30 | AM6: 2032-12-31 | AN6: 2033-03-31 | AO6: 2033-06-30 | AP6: 2033-09-30 | AQ6: 2033-12-31 | AR6: 2034-03-31 | AS6: 2034-06-30 | AT6: 2034-09-30 | AU6: 2034-12-31 | AV6: 2035-03-31 | AW6: 2035-06-30 | AX6: 2035-09-30 | AY6: 2035-12-31 | AZ6: 2036-03-31 | BA6: 2036-06-30 | BB6: 2036-09-30 | BC6: 2036-12-31 | BD6: 2037-03-31 | BE6: 2037-06-30 | BF6: 2037-09-30 | BG6: 2037-12-31 | BH6: 2038-03-31 | BI6: 2038-06-30 | BJ6: 2038-09-30 | BK6: 2038-12-31 | BL6: 2039-03-31 | BM6: 2039-06-30 | BN6: 2039-09-30 | BO6: 2039-12-31 | BP6: 2040-03-31 | BQ6: 2040-06-30 | BR6: 2040-09-30 | BS6: 2040-12-31 | BT6: 2041-03-31 | BU6: 2041-06-30 | BV6: 2041-09-30 | BW6: 2041-12-31 | BX6: 2042-03-31 | BY6: 2042-06-30 | BZ6: 2042-09-30 | CA6: 2042-12-31 | CB6: 2043-03-31 | CC6: 2043-06-30 | CD6: 2043-09-30 | CE6: 2043-12-31 | CF6: 2044-03-31 | CG6: 2044-06-30 | CH6: 2044-09-30 | CI6: 2044-12-31 | CJ6: 2045-03-31 | CK6: 2045-06-30 | CL6: 2045-09-30
B8: 선순위A
B9: 기초잔액 | C9: [KRWm] | E9: 0 | F9: =E14 | G9: =F14 | H9: =G14 | I9: =H14 | J9: =I14 | K9: =J14 | L9: =K14 | M9: =L14 | ... CL9: =CK14
B10: 인출 | C10: [KRWm] | D10: 126069 | E10: 21011.5 | F10: 21269.688 | G10: 21531.049 | H10: 21795.622 | I10: 22063.445 | J10: 18397.696 | K10: 0 | L10: 0 | M10: 0 | N10: 0 | O10: 0 | P10: 0 | Q10: 0 | R10: 0 | S10: 0 | T10: 0 | U10: 0 | V10: 0 | W10: 0 | X10: 0 | Y10: 0 | Z10: 0 | AA10: 0 | AB10: 0 | AC10: 0 | AD10: 0 | AE10: 0 | AF10: 0 | AG10: 0 | AH10: 0 | AI10: 0 | AJ10: 0 | AK10: 0 | AL10: 0 | AM10: 0 | AN10: 0 | AO10: 0 | AP10: 0 | AQ10: 0 | AR10: 0 | AS10: 0 | AT10: 0 | AU10: 0 | AV10: 0 | AW10: 0 | AX10: 0 | AY10: 0 | AZ10: 0 | BA10: 0 | BB10: 0 | BC10: 0 | BD10: 0 | BE10: 0 | BF10: 0 | BG10: 0 | BH10: 0 | BI10: 0 | BJ10: 0 | BK10: 0 | BL10: 0 | BM10: 0 | BN10: 0 | BO10: 0 | BP10: 0 | BQ10: 0 | BR10: 0 | BS10: 0 | BT10: 0 | BU10: 0 | BV10: 0 | BW10: 0 | BX10: 0 | BY10: 0 | BZ10: 0 | CA10: 0 | CB10: 0 | CC10: 0 | CD10: 0 | CE10: 0 | CF10: 0 | CG10: 0 | CH10: 0 | CI10: 0 | CJ10: 0 | CK10: 0 | CL10: 0
B11: 건설이자(IDC) | C11: [KRWm] | D11: 4405.2812 | E11: 0 | F11: 288.90813 | G11: 581.36634 | H11: 877.41826 | I11: 1177.1081 | J11: 1480.4804 | K11: 0 | L11: 0 | M11: 0 | N11: 0 | O11: 0 | P11: 0 | Q11: 0 | R11: 0 | S11: 0 | T11: 0 | U11: 0 | V11: 0 | W11: 0 | X11: 0 | Y11: 0 | Z11: 0 | AA11: 0 | AB11: 0 | AC11: 0 | AD11: 0 | AE11: 0 | AF11: 0 | AG11: 0 | AH11: 0 | AI11: 0 | AJ11: 0 | AK11: 0 | AL11: 0 | AM11: 0 | AN11: 0 | AO11: 0 | AP11: 0 | AQ11: 0 | AR11: 0 | AS11: 0 | AT11: 0 | AU11: 0 | AV11: 0 | AW11: 0 | AX11: 0 | AY11: 0 | AZ11: 0 | BA11: 0 | BB11: 0 | BC11: 0 | BD11: 0 | BE11: 0 | BF11: 0 | BG11: 0 | BH11: 0 | BI11: 0 | BJ11: 0 | BK11: 0 | BL11: 0 | BM11: 0 | BN11: 0 | BO11: 0 | BP11: 0 | BQ11: 0 | BR11: 0 | BS11: 0 | BT11: 0 | BU11: 0 | BV11: 0 | BW11: 0 | BX11: 0 | BY11: 0 | BZ11: 0 | CA11: 0 | CB11: 0 | CC11: 0 | CD11: 0 | CE11: 0 | CF11: 0 | CG11: 0 | CH11: 0 | CI11: 0 | CJ11: 0 | CK11: 0 | CL11: 0
B12: 이자(운영) | C12: [KRWm] | D12: 58070.533 | E12: 0 | F12: 0 | G12: 0 | H12: 0 | I12: 0 | J12: 0 | K12: =K9*'입력값'!E19/4 | L12: =L9*'입력값'!E19/4 | M12: =M9*'입력값'!E19/4 | N12: =N9*'입력값'!E19/4 | O12: =O9*'입력값'!E19/4 | P12: =P9*'입력값'!E19/4 | Q12: =Q9*'입력값'!E19/4 | R12: =R9*'입력값'!E19/4 | S12: =S9*'입력값'!E19/4 | T12: =T9*'입력값'!E19/4 | U12: =U9*'입력값'!E19/4 | V12: =V9*'입력값'!E19/4 | W12: =W9*'입력값'!E19/4 | X12: =X9*'입력값'!E19/4 | Y12: =Y9*'입력값'!E19/4 | Z12: =Z9*'입력값'!E19/4 | AA12: =AA9*'입력값'!E19/4 | AB12: =AB9*'입력값'!E19/4 | AC12: =AC9*'입력값'!E19/4 | AD12: =AD9*'입력값'!E19/4 | AE12: =AE9*'입력값'!E19/4 | AF12: =AF9*'입력값'!E19/4 | AG12: =AG9*'입력값'!E19/4 | AH12: =AH9*'입력값'!E19/4 | AI12: =AI9*'입력값'!E19/4 | AJ12: =AJ9*'입력값'!E19/4 | AK12: =AK9*'입력값'!E19/4 | AL12: =AL9*'입력값'!E19/4 | AM12: =AM9*'입력값'!E19/4 | AN12: =AN9*'입력값'!E19/4 | AO12: =AO9*'입력값'!E19/4 | AP12: =AP9*'입력값'!E19/4 | AQ12: =AQ9*'입력값'!E19/4 | AR12: =AR9*'입력값'!E19/4 | AS12: =AS9*'입력값'!E19/4 | AT12: =AT9*'입력값'!E19/4 | AU12: =AU9*'입력값'!E19/4 | AV12: =AV9*'입력값'!E19/4 | AW12: =AW9*'입력값'!E19/4 | AX12: =AX9*'입력값'!E19/4 | AY12: =AY9*'입력값'!E19/4 | AZ12: =AZ9*'입력값'!E19/4 | BA12: =BA9*'입력값'!E19/4 | BB12: =BB9*'입력값'!E19/4 | BC12: =BC9*'입력값'!E19/4 | BD12: =BD9*'입력값'!E19/4 | BE12: =BE9*'입력값'!E19/4 | BF12: =BF9*'입력값'!E19/4 | BG12: =BG9*'입력값'!E19/4 | BH12: =BH9*'입력값'!E19/4 | BI12: =BI9*'입력값'!E19/4 | BJ12: =BJ9*'입력값'!E19/4 | BK12: =BK9*'입력값'!E19/4 | BL12: =BL9*'입력값'!E19/4 | BM12: =BM9*'입력값'!E19/4 | BN12: =BN9*'입력값'!E19/4 | BO12: =BO9*'입력값'!E19/4 | BP12: =BP9*'입력값'!E19/4 | BQ12: =BQ9*'입력값'!E19/4 | BR12: =BR9*'입력값'!E19/4 | BS12: =BS9*'입력값'!E19/4 | BT12: =BT9*'입력값'!E19/4 | BU12: =BU9*'입력값'!E19/4 | BV12: =BV9*'입력값'!E19/4 | BW12: =BW9*'입력값'!E19/4 | BX12: =BX9*'입력값'!E19/4 | BY12: =BY9*'입력값'!E19/4 | BZ12: =BZ9*'입력값'!E19/4 | CA12: =CA9*'입력값'!E19/4 | CB12: =CB9*'입력값'!E19/4 | CC12: =CC9*'입력값'!E19/4 | CD12: =CD9*'입력값'!E19/4 | CE12: =CE9*'입력값'!E19/4 | CF12: =CF9*'입력값'!E19/4 | CG12: =CG9*'입력값'!E19/4 | CH12: =CH9*'입력값'!E19/4 | CI12: =CI9*'입력값'!E19/4 | CJ12: =CJ9*'입력값'!E19/4 | CK12: =CK9*'입력값'!E19/4 | CL12: =CL9*'입력값'!E19/4
B13: 원금상환 | C13: [KRWm] | D13: 126069 | E13: 0 | F13: 0 | G13: 0 | H13: 0 | I13: 0 | J13: 0 | K13: 0 | L13: 0 | M13: 0 | N13: ='입력값'!C19*100/60 | O13: ='입력값'!C19*100/60 | P13: ='입력값'!C19*100/60 | Q13: ='입력값'!C19*100/60 | R13: ='입력값'!C19*100/60 | S13: ='입력값'!C19*100/60 | T13: ='입력값'!C19*100/60 | U13: ='입력값'!C19*100/60 | V13: ='입력값'!C19*100/60 | W13: ='입력값'!C19*100/60 | X13: ='입력값'!C19*100/60 | Y13: ='입력값'!C19*100/60 | Z13: ='입력값'!C19*100/60 | AA13: ='입력값'!C19*100/60 | AB13: ='입력값'!C19*100/60 | AC13: ='입력값'!C19*100/60 | AD13: ='입력값'!C19*100/60 | AE13: ='입력값'!C19*100/60 | AF13: ='입력값'!C19*100/60 | AG13: ='입력값'!C19*100/60 | AH13: ='입력값'!C19*100/60 | AI13: ='입력값'!C19*100/60 | AJ13: ='입력값'!C19*100/60 | AK13: ='입력값'!C19*100/60 | AL13: ='입력값'!C19*100/60 | AM13: ='입력값'!C19*100/60 | AN13: ='입력값'!C19*100/60 | AO13: ='입력값'!C19*100/60 | AP13: ='입력값'!C19*100/60 | AQ13: ='입력값'!C19*100/60 | AR13: ='입력값'!C19*100/60 | AS13: ='입력값'!C19*100/60 | AT13: ='입력값'!C19*100/60 | AU13: ='입력값'!C19*100/60 | AV13: ='입력값'!C19*100/60 | AW13: ='입력값'!C19*100/60 | AX13: ='입력값'!C19*100/60 | AY13: ='입력값'!C19*100/60 | AZ13: ='입력값'!C19*100/60 | BA13: ='입력값'!C19*100/60 | BB13: ='입력값'!C19*100/60 | BC13: ='입력값'!C19*100/60 | BD13: ='입력값'!C19*100/60 | BE13: ='입력값'!C19*100/60 | BF13: ='입력값'!C19*100/60 | BG13: ='입력값'!C19*100/60 | BH13: ='입력값'!C19*100/60 | BI13: ='입력값'!C19*100/60 | BJ13: ='입력값'!C19*100/60 | BK13: ='입력값'!C19*100/60 | BL13: ='입력값'!C19*100/60 | BM13: ='입력값'!C19*100/60 | BN13: ='입력값'!C19*100/60 | BO13: ='입력값'!C19*100/60 | BP13: ='입력값'!C19*100/60 | BQ13: ='입력값'!C19*100/60 | BR13: ='입력값'!C19*100/60 | BS13: ='입력값'!C19*100/60 | BT13: ='입력값'!C19*100/60 | BU13: ='입력값'!C19*100/60 | BV13: 0 | BW13: 0 | BX13: 0 | BY13: 0 | BZ13: 0 | CA13: 0 | CB13: 0 | CC13: 0 | CD13: 0 | CE13: 0 | CF13: 0 | CG13: 0 | CH13: 0 | CI13: 0 | CJ13: 0 | CK13: 0 | CL13: 0
B14: 기말잔액 | C14: [KRWm] | E14: =E9+E10-E13 | F14: =F9+F10-F13 | G14: =G9+G10-G13 | H14: =H9+H10-H13 | I14: =I9+I10-I13 | J14: =J9+J10-J13 | K14: =K9+K10-K13 | L14: =L9+L10-L13 | ... CL14: =CL9+CL10-CL13
B15: 미상환 잔액(검증용) | C15: [KRWm] | D15: 1.3005774e-10 | F15: 완전상환 확인 (OK)
B17: 선순위B
B18: 기초잔액 | C18: [KRWm] | E18: 0 | F18: =E23 | G18: =F23 | H18: =G23 | I18: =H23 | J18: =I23 | K18: =J23 | L18: =K23 | M18: =L23 | ... CL18: =CK23
B19: 인출 | C19: [KRWm] | D19: 0 | E19: 0 | F19: 0 | G19: 0 | H19: 0 | I19: 0 | J19: 0 | K19: 0 | L19: 0 | M19: 0 | N19: 0 | O19: 0 | P19: 0 | Q19: 0 | R19: 0 | S19: 0 | T19: 0 | U19: 0 | V19: 0 | W19: 0 | X19: 0 | Y19: 0 | Z19: 0 | AA19: 0 | AB19: 0 | AC19: 0 | AD19: 0 | AE19: 0 | AF19: 0 | AG19: 0 | AH19: 0 | AI19: 0 | AJ19: 0 | AK19: 0 | AL19: 0 | AM19: 0 | AN19: 0 | AO19: 0 | AP19: 0 | AQ19: 0 | AR19: 0 | AS19: 0 | AT19: 0 | AU19: 0 | AV19: 0 | AW19: 0 | AX19: 0 | AY19: 0 | AZ19: 0 | BA19: 0 | BB19: 0 | BC19: 0 | BD19: 0 | BE19: 0 | BF19: 0 | BG19: 0 | BH19: 0 | BI19: 0 | BJ19: 0 | BK19: 0 | BL19: 0 | BM19: 0 | BN19: 0 | BO19: 0 | BP19: 0 | BQ19: 0 | BR19: 0 | BS19: 0 | BT19: 0 | BU19: 0 | BV19: 0 | BW19: 0 | BX19: 0 | BY19: 0 | BZ19: 0 | CA19: 0 | CB19: 0 | CC19: 0 | CD19: 0 | CE19: 0 | CF19: 0 | CG19: 0 | CH19: 0 | CI19: 0 | CJ19: 0 | CK19: 0 | CL19: 0
B20: 건설이자(IDC) | C20: [KRWm] | D20: 0 | E20: 0 | F20: 0 | G20: 0 | H20: 0 | I20: 0 | J20: 0 | K20: 0 | L20: 0 | M20: 0 | N20: 0 | O20: 0 | P20: 0 | Q20: 0 | R20: 0 | S20: 0 | T20: 0 | U20: 0 | V20: 0 | W20: 0 | X20: 0 | Y20: 0 | Z20: 0 | AA20: 0 | AB20: 0 | AC20: 0 | AD20: 0 | AE20: 0 | AF20: 0 | AG20: 0 | AH20: 0 | AI20: 0 | AJ20: 0 | AK20: 0 | AL20: 0 | AM20: 0 | AN20: 0 | AO20: 0 | AP20: 0 | AQ20: 0 | AR20: 0 | AS20: 0 | AT20: 0 | AU20: 0 | AV20: 0 | AW20: 0 | AX20: 0 | AY20: 0 | AZ20: 0 | BA20: 0 | BB20: 0 | BC20: 0 | BD20: 0 | BE20: 0 | BF20: 0 | BG20: 0 | BH20: 0 | BI20: 0 | BJ20: 0 | BK20: 0 | BL20: 0 | BM20: 0 | BN20: 0 | BO20: 0 | BP20: 0 | BQ20: 0 | BR20: 0 | BS20: 0 | BT20: 0 | BU20: 0 | BV20: 0 | BW20: 0 | BX20: 0 | BY20: 0 | BZ20: 0 | CA20: 0 | CB20: 0 | CC20: 0 | CD20: 0 | CE20: 0 | CF20: 0 | CG20: 0 | CH20: 0 | CI20: 0 | CJ20: 0 | CK20: 0 | CL20: 0
B21: 이자(운영) | C21: [KRWm] | D21: 0 | E21: 0 | F21: 0 | G21: 0 | H21: 0 | I21: 0 | J21: 0 | K21: =K18*'입력값'!E20/4 | L21: =L18*'입력값'!E20/4 | M21: =M18*'입력값'!E20/4 | N21: =N18*'입력값'!E20/4 | O21: =O18*'입력값'!E20/4 | P21: =P18*'입력값'!E20/4 | Q21: =Q18*'입력값'!E20/4 | R21: =R18*'입력값'!E20/4 | S21: =S18*'입력값'!E20/4 | T21: =T18*'입력값'!E20/4 | U21: =U18*'입력값'!E20/4 | V21: =V18*'입력값'!E20/4 | W21: =W18*'입력값'!E20/4 | X21: =X18*'입력값'!E20/4 | Y21: =Y18*'입력값'!E20/4 | Z21: =Z18*'입력값'!E20/4 | AA21: =AA18*'입력값'!E20/4 | AB21: =AB18*'입력값'!E20/4 | AC21: =AC18*'입력값'!E20/4 | AD21: =AD18*'입력값'!E20/4 | AE21: =AE18*'입력값'!E20/4 | AF21: =AF18*'입력값'!E20/4 | AG21: =AG18*'입력값'!E20/4 | AH21: =AH18*'입력값'!E20/4 | AI21: =AI18*'입력값'!E20/4 | AJ21: =AJ18*'입력값'!E20/4 | AK21: =AK18*'입력값'!E20/4 | AL21: =AL18*'입력값'!E20/4 | AM21: =AM18*'입력값'!E20/4 | AN21: =AN18*'입력값'!E20/4 | AO21: =AO18*'입력값'!E20/4 | AP21: =AP18*'입력값'!E20/4 | AQ21: =AQ18*'입력값'!E20/4 | AR21: =AR18*'입력값'!E20/4 | AS21: =AS18*'입력값'!E20/4 | AT21: =AT18*'입력값'!E20/4 | AU21: =AU18*'입력값'!E20/4 | AV21: =AV18*'입력값'!E20/4 | AW21: =AW18*'입력값'!E20/4 | AX21: =AX18*'입력값'!E20/4 | AY21: =AY18*'입력값'!E20/4 | AZ21: =AZ18*'입력값'!E20/4 | BA21: =BA18*'입력값'!E20/4 | BB21: =BB18*'입력값'!E20/4 | BC21: =BC18*'입력값'!E20/4 | BD21: =BD18*'입력값'!E20/4 | BE21: =BE18*'입력값'!E20/4 | BF21: =BF18*'입력값'!E20/4 | BG21: =BG18*'입력값'!E20/4 | BH21: =BH18*'입력값'!E20/4 | BI21: =BI18*'입력값'!E20/4 | BJ21: =BJ18*'입력값'!E20/4 | BK21: =BK18*'입력값'!E20/4 | BL21: =BL18*'입력값'!E20/4 | BM21: =BM18*'입력값'!E20/4 | BN21: =BN18*'입력값'!E20/4 | BO21: =BO18*'입력값'!E20/4 | BP21: =BP18*'입력값'!E20/4 | BQ21: =BQ18*'입력값'!E20/4 | BR21: =BR18*'입력값'!E20/4 | BS21: =BS18*'입력값'!E20/4 | BT21: =BT18*'입력값'!E20/4 | BU21: =BU18*'입력값'!E20/4 | BV21: =BV18*'입력값'!E20/4 | BW21: =BW18*'입력값'!E20/4 | BX21: =BX18*'입력값'!E20/4 | BY21: =BY18*'입력값'!E20/4 | BZ21: =BZ18*'입력값'!E20/4 | CA21: =CA18*'입력값'!E20/4 | CB21: =CB18*'입력값'!E20/4 | CC21: =CC18*'입력값'!E20/4 | CD21: =CD18*'입력값'!E20/4 | CE21: =CE18*'입력값'!E20/4 | CF21: =CF18*'입력값'!E20/4 | CG21: =CG18*'입력값'!E20/4 | CH21: =CH18*'입력값'!E20/4 | CI21: =CI18*'입력값'!E20/4 | CJ21: =CJ18*'입력값'!E20/4 | CK21: =CK18*'입력값'!E20/4 | CL21: =CL18*'입력값'!E20/4
B22: 원금상환 | C22: [KRWm] | D22: 0 | E22: 0 | F22: 0 | G22: 0 | H22: 0 | I22: 0 | J22: 0 | K22: 0 | L22: 0 | M22: 0 | N22: 0 | O22: 0 | P22: 0 | Q22: 0 | R22: 0 | S22: 0 | T22: 0 | U22: 0 | V22: 0 | W22: 0 | X22: 0 | Y22: 0 | Z22: 0 | AA22: 0 | AB22: 0 | AC22: 0 | AD22: 0 | AE22: 0 | AF22: 0 | AG22: 0 | AH22: 0 | AI22: 0 | AJ22: 0 | AK22: 0 | AL22: 0 | AM22: 0 | AN22: 0 | AO22: 0 | AP22: 0 | AQ22: 0 | AR22: 0 | AS22: 0 | AT22: 0 | AU22: 0 | AV22: 0 | AW22: 0 | AX22: 0 | AY22: 0 | AZ22: 0 | BA22: 0 | BB22: 0 | BC22: 0 | BD22: 0 | BE22: 0 | BF22: 0 | BG22: 0 | BH22: 0 | BI22: 0 | BJ22: 0 | BK22: 0 | BL22: 0 | BM22: 0 | BN22: 0 | BO22: 0 | BP22: 0 | BQ22: 0 | BR22: 0 | BS22: 0 | BT22: 0 | BU22: 0 | BV22: 0 | BW22: 0 | BX22: 0 | BY22: 0 | BZ22: 0 | CA22: 0 | CB22: 0 | CC22: 0 | CD22: 0 | CE22: 0 | CF22: 0 | CG22: 0 | CH22: 0 | CI22: 0 | CJ22: 0 | CK22: 0 | CL22: 0
B23: 기말잔액 | C23: [KRWm] | E23: =E18+E19-E22 | F23: =F18+F19-F22 | G23: =G18+G19-G22 | H23: =H18+H19-H22 | I23: =I18+I19-I22 | J23: =J18+J19-J22 | K23: =K18+K19-K22 | L23: =L18+L19-L22 | ... CL23: =CL18+CL19-CL22
B24: 미상환 잔액(검증용) | C24: [KRWm] | D24: 0 | F24: 완전상환 확인 (OK) | H24: ※ 방식 3(직접 키인) 또는 미사용 트랜치 — 값(baked) 기준
B26: 선순위C
B27: 기초잔액 | C27: [KRWm] | E27: 0 | F27: =E32 | G27: =F32 | H27: =G32 | I27: =H32 | J27: =I32 | K27: =J32 | L27: =K32 | M27: =L32 | ... CL27: =CK32
B28: 인출 | C28: [KRWm] | D28: 0 | E28: 0 | F28: 0 | G28: 0 | H28: 0 | I28: 0 | J28: 0 | K28: 0 | L28: 0 | M28: 0 | N28: 0 | O28: 0 | P28: 0 | Q28: 0 | R28: 0 | S28: 0 | T28: 0 | U28: 0 | V28: 0 | W28: 0 | X28: 0 | Y28: 0 | Z28: 0 | AA28: 0 | AB28: 0 | AC28: 0 | AD28: 0 | AE28: 0 | AF28: 0 | AG28: 0 | AH28: 0 | AI28: 0 | AJ28: 0 | AK28: 0 | AL28: 0 | AM28: 0 | AN28: 0 | AO28: 0 | AP28: 0 | AQ28: 0 | AR28: 0 | AS28: 0 | AT28: 0 | AU28: 0 | AV28: 0 | AW28: 0 | AX28: 0 | AY28: 0 | AZ28: 0 | BA28: 0 | BB28: 0 | BC28: 0 | BD28: 0 | BE28: 0 | BF28: 0 | BG28: 0 | BH28: 0 | BI28: 0 | BJ28: 0 | BK28: 0 | BL28: 0 | BM28: 0 | BN28: 0 | BO28: 0 | BP28: 0 | BQ28: 0 | BR28: 0 | BS28: 0 | BT28: 0 | BU28: 0 | BV28: 0 | BW28: 0 | BX28: 0 | BY28: 0 | BZ28: 0 | CA28: 0 | CB28: 0 | CC28: 0 | CD28: 0 | CE28: 0 | CF28: 0 | CG28: 0 | CH28: 0 | CI28: 0 | CJ28: 0 | CK28: 0 | CL28: 0
B29: 건설이자(IDC) | C29: [KRWm] | D29: 0 | E29: 0 | F29: 0 | G29: 0 | H29: 0 | I29: 0 | J29: 0 | K29: 0 | L29: 0 | M29: 0 | N29: 0 | O29: 0 | P29: 0 | Q29: 0 | R29: 0 | S29: 0 | T29: 0 | U29: 0 | V29: 0 | W29: 0 | X29: 0 | Y29: 0 | Z29: 0 | AA29: 0 | AB29: 0 | AC29: 0 | AD29: 0 | AE29: 0 | AF29: 0 | AG29: 0 | AH29: 0 | AI29: 0 | AJ29: 0 | AK29: 0 | AL29: 0 | AM29: 0 | AN29: 0 | AO29: 0 | AP29: 0 | AQ29: 0 | AR29: 0 | AS29: 0 | AT29: 0 | AU29: 0 | AV29: 0 | AW29: 0 | AX29: 0 | AY29: 0 | AZ29: 0 | BA29: 0 | BB29: 0 | BC29: 0 | BD29: 0 | BE29: 0 | BF29: 0 | BG29: 0 | BH29: 0 | BI29: 0 | BJ29: 0 | BK29: 0 | BL29: 0 | BM29: 0 | BN29: 0 | BO29: 0 | BP29: 0 | BQ29: 0 | BR29: 0 | BS29: 0 | BT29: 0 | BU29: 0 | BV29: 0 | BW29: 0 | BX29: 0 | BY29: 0 | BZ29: 0 | CA29: 0 | CB29: 0 | CC29: 0 | CD29: 0 | CE29: 0 | CF29: 0 | CG29: 0 | CH29: 0 | CI29: 0 | CJ29: 0 | CK29: 0 | CL29: 0
B30: 이자(운영) | C30: [KRWm] | D30: 0 | E30: 0 | F30: 0 | G30: 0 | H30: 0 | I30: 0 | J30: 0 | K30: =K27*'입력값'!E21/4 | L30: =L27*'입력값'!E21/4 | M30: =M27*'입력값'!E21/4 | N30: =N27*'입력값'!E21/4 | O30: =O27*'입력값'!E21/4 | P30: =P27*'입력값'!E21/4 | Q30: =Q27*'입력값'!E21/4 | R30: =R27*'입력값'!E21/4 | S30: =S27*'입력값'!E21/4 | T30: =T27*'입력값'!E21/4 | U30: =U27*'입력값'!E21/4 | V30: =V27*'입력값'!E21/4 | W30: =W27*'입력값'!E21/4 | X30: =X27*'입력값'!E21/4 | Y30: =Y27*'입력값'!E21/4 | Z30: =Z27*'입력값'!E21/4 | AA30: =AA27*'입력값'!E21/4 | AB30: =AB27*'입력값'!E21/4 | AC30: =AC27*'입력값'!E21/4 | AD30: =AD27*'입력값'!E21/4 | AE30: =AE27*'입력값'!E21/4 | AF30: =AF27*'입력값'!E21/4 | AG30: =AG27*'입력값'!E21/4 | AH30: =AH27*'입력값'!E21/4 | AI30: =AI27*'입력값'!E21/4 | AJ30: =AJ27*'입력값'!E21/4 | AK30: =AK27*'입력값'!E21/4 | AL30: =AL27*'입력값'!E21/4 | AM30: =AM27*'입력값'!E21/4 | AN30: =AN27*'입력값'!E21/4 | AO30: =AO27*'입력값'!E21/4 | AP30: =AP27*'입력값'!E21/4 | AQ30: =AQ27*'입력값'!E21/4 | AR30: =AR27*'입력값'!E21/4 | AS30: =AS27*'입력값'!E21/4 | AT30: =AT27*'입력값'!E21/4 | AU30: =AU27*'입력값'!E21/4 | AV30: =AV27*'입력값'!E21/4 | AW30: =AW27*'입력값'!E21/4 | AX30: =AX27*'입력값'!E21/4 | AY30: =AY27*'입력값'!E21/4 | AZ30: =AZ27*'입력값'!E21/4 | BA30: =BA27*'입력값'!E21/4 | BB30: =BB27*'입력값'!E21/4 | BC30: =BC27*'입력값'!E21/4 | BD30: =BD27*'입력값'!E21/4 | BE30: =BE27*'입력값'!E21/4 | BF30: =BF27*'입력값'!E21/4 | BG30: =BG27*'입력값'!E21/4 | BH30: =BH27*'입력값'!E21/4 | BI30: =BI27*'입력값'!E21/4 | BJ30: =BJ27*'입력값'!E21/4 | BK30: =BK27*'입력값'!E21/4 | BL30: =BL27*'입력값'!E21/4 | BM30: =BM27*'입력값'!E21/4 | BN30: =BN27*'입력값'!E21/4 | BO30: =BO27*'입력값'!E21/4 | BP30: =BP27*'입력값'!E21/4 | BQ30: =BQ27*'입력값'!E21/4 | BR30: =BR27*'입력값'!E21/4 | BS30: =BS27*'입력값'!E21/4 | BT30: =BT27*'입력값'!E21/4 | BU30: =BU27*'입력값'!E21/4 | BV30: =BV27*'입력값'!E21/4 | BW30: =BW27*'입력값'!E21/4 | BX30: =BX27*'입력값'!E21/4 | BY30: =BY27*'입력값'!E21/4 | BZ30: =BZ27*'입력값'!E21/4 | CA30: =CA27*'입력값'!E21/4 | CB30: =CB27*'입력값'!E21/4 | CC30: =CC27*'입력값'!E21/4 | CD30: =CD27*'입력값'!E21/4 | CE30: =CE27*'입력값'!E21/4 | CF30: =CF27*'입력값'!E21/4 | CG30: =CG27*'입력값'!E21/4 | CH30: =CH27*'입력값'!E21/4 | CI30: =CI27*'입력값'!E21/4 | CJ30: =CJ27*'입력값'!E21/4 | CK30: =CK27*'입력값'!E21/4 | CL30: =CL27*'입력값'!E21/4
B31: 원금상환 | C31: [KRWm] | D31: 0 | E31: 0 | F31: 0 | G31: 0 | H31: 0 | I31: 0 | J31: 0 | K31: 0 | L31: 0 | M31: 0 | N31: 0 | O31: 0 | P31: 0 | Q31: 0 | R31: 0 | S31: 0 | T31: 0 | U31: 0 | V31: 0 | W31: 0 | X31: 0 | Y31: 0 | Z31: 0 | AA31: 0 | AB31: 0 | AC31: 0 | AD31: 0 | AE31: 0 | AF31: 0 | AG31: 0 | AH31: 0 | AI31: 0 | AJ31: 0 | AK31: 0 | AL31: 0 | AM31: 0 | AN31: 0 | AO31: 0 | AP31: 0 | AQ31: 0 | AR31: 0 | AS31: 0 | AT31: 0 | AU31: 0 | AV31: 0 | AW31: 0 | AX31: 0 | AY31: 0 | AZ31: 0 | BA31: 0 | BB31: 0 | BC31: 0 | BD31: 0 | BE31: 0 | BF31: 0 | BG31: 0 | BH31: 0 | BI31: 0 | BJ31: 0 | BK31: 0 | BL31: 0 | BM31: 0 | BN31: 0 | BO31: 0 | BP31: 0 | BQ31: 0 | BR31: 0 | BS31: 0 | BT31: 0 | BU31: 0 | BV31: 0 | BW31: 0 | BX31: 0 | BY31: 0 | BZ31: 0 | CA31: 0 | CB31: 0 | CC31: 0 | CD31: 0 | CE31: 0 | CF31: 0 | CG31: 0 | CH31: 0 | CI31: 0 | CJ31: 0 | CK31: 0 | CL31: 0
B32: 기말잔액 | C32: [KRWm] | E32: =E27+E28-E31 | F32: =F27+F28-F31 | G32: =G27+G28-G31 | H32: =H27+H28-H31 | I32: =I27+I28-I31 | J32: =J27+J28-J31 | K32: =K27+K28-K31 | L32: =L27+L28-L31 | ... CL32: =CL27+CL28-CL31
B33: 미상환 잔액(검증용) | C33: [KRWm] | D33: 0 | F33: 완전상환 확인 (OK) | H33: ※ 방식 3(직접 키인) 또는 미사용 트랜치 — 값(baked) 기준
B35: 선순위D
B36: 기초잔액 | C36: [KRWm] | E36: 0 | F36: =E41 | G36: =F41 | H36: =G41 | I36: =H41 | J36: =I41 | K36: =J41 | L36: =K41 | M36: =L41 | ... CL36: =CK41
B37: 인출 | C37: [KRWm] | D37: 0 | E37: 0 | F37: 0 | G37: 0 | H37: 0 | I37: 0 | J37: 0 | K37: 0 | L37: 0 | M37: 0 | N37: 0 | O37: 0 | P37: 0 | Q37: 0 | R37: 0 | S37: 0 | T37: 0 | U37: 0 | V37: 0 | W37: 0 | X37: 0 | Y37: 0 | Z37: 0 | AA37: 0 | AB37: 0 | AC37: 0 | AD37: 0 | AE37: 0 | AF37: 0 | AG37: 0 | AH37: 0 | AI37: 0 | AJ37: 0 | AK37: 0 | AL37: 0 | AM37: 0 | AN37: 0 | AO37: 0 | AP37: 0 | AQ37: 0 | AR37: 0 | AS37: 0 | AT37: 0 | AU37: 0 | AV37: 0 | AW37: 0 | AX37: 0 | AY37: 0 | AZ37: 0 | BA37: 0 | BB37: 0 | BC37: 0 | BD37: 0 | BE37: 0 | BF37: 0 | BG37: 0 | BH37: 0 | BI37: 0 | BJ37: 0 | BK37: 0 | BL37: 0 | BM37: 0 | BN37: 0 | BO37: 0 | BP37: 0 | BQ37: 0 | BR37: 0 | BS37: 0 | BT37: 0 | BU37: 0 | BV37: 0 | BW37: 0 | BX37: 0 | BY37: 0 | BZ37: 0 | CA37: 0 | CB37: 0 | CC37: 0 | CD37: 0 | CE37: 0 | CF37: 0 | CG37: 0 | CH37: 0 | CI37: 0 | CJ37: 0 | CK37: 0 | CL37: 0
B38: 건설이자(IDC) | C38: [KRWm] | D38: 0 | E38: 0 | F38: 0 | G38: 0 | H38: 0 | I38: 0 | J38: 0 | K38: 0 | L38: 0 | M38: 0 | N38: 0 | O38: 0 | P38: 0 | Q38: 0 | R38: 0 | S38: 0 | T38: 0 | U38: 0 | V38: 0 | W38: 0 | X38: 0 | Y38: 0 | Z38: 0 | AA38: 0 | AB38: 0 | AC38: 0 | AD38: 0 | AE38: 0 | AF38: 0 | AG38: 0 | AH38: 0 | AI38: 0 | AJ38: 0 | AK38: 0 | AL38: 0 | AM38: 0 | AN38: 0 | AO38: 0 | AP38: 0 | AQ38: 0 | AR38: 0 | AS38: 0 | AT38: 0 | AU38: 0 | AV38: 0 | AW38: 0 | AX38: 0 | AY38: 0 | AZ38: 0 | BA38: 0 | BB38: 0 | BC38: 0 | BD38: 0 | BE38: 0 | BF38: 0 | BG38: 0 | BH38: 0 | BI38: 0 | BJ38: 0 | BK38: 0 | BL38: 0 | BM38: 0 | BN38: 0 | BO38: 0 | BP38: 0 | BQ38: 0 | BR38: 0 | BS38: 0 | BT38: 0 | BU38: 0 | BV38: 0 | BW38: 0 | BX38: 0 | BY38: 0 | BZ38: 0 | CA38: 0 | CB38: 0 | CC38: 0 | CD38: 0 | CE38: 0 | CF38: 0 | CG38: 0 | CH38: 0 | CI38: 0 | CJ38: 0 | CK38: 0 | CL38: 0
B39: 이자(운영) | C39: [KRWm] | D39: 0 | E39: 0 | F39: 0 | G39: 0 | H39: 0 | I39: 0 | J39: 0 | K39: =K36*'입력값'!E22/4 | L39: =L36*'입력값'!E22/4 | M39: =M36*'입력값'!E22/4 | N39: =N36*'입력값'!E22/4 | O39: =O36*'입력값'!E22/4 | P39: =P36*'입력값'!E22/4 | Q39: =Q36*'입력값'!E22/4 | R39: =R36*'입력값'!E22/4 | S39: =S36*'입력값'!E22/4 | T39: =T36*'입력값'!E22/4 | U39: =U36*'입력값'!E22/4 | V39: =V36*'입력값'!E22/4 | W39: =W36*'입력값'!E22/4 | X39: =X36*'입력값'!E22/4 | Y39: =Y36*'입력값'!E22/4 | Z39: =Z36*'입력값'!E22/4 | AA39: =AA36*'입력값'!E22/4 | AB39: =AB36*'입력값'!E22/4 | AC39: =AC36*'입력값'!E22/4 | AD39: =AD36*'입력값'!E22/4 | AE39: =AE36*'입력값'!E22/4 | AF39: =AF36*'입력값'!E22/4 | AG39: =AG36*'입력값'!E22/4 | AH39: =AH36*'입력값'!E22/4 | AI39: =AI36*'입력값'!E22/4 | AJ39: =AJ36*'입력값'!E22/4 | AK39: =AK36*'입력값'!E22/4 | AL39: =AL36*'입력값'!E22/4 | AM39: =AM36*'입력값'!E22/4 | AN39: =AN36*'입력값'!E22/4 | AO39: =AO36*'입력값'!E22/4 | AP39: =AP36*'입력값'!E22/4 | AQ39: =AQ36*'입력값'!E22/4 | AR39: =AR36*'입력값'!E22/4 | AS39: =AS36*'입력값'!E22/4 | AT39: =AT36*'입력값'!E22/4 | AU39: =AU36*'입력값'!E22/4 | AV39: =AV36*'입력값'!E22/4 | AW39: =AW36*'입력값'!E22/4 | AX39: =AX36*'입력값'!E22/4 | AY39: =AY36*'입력값'!E22/4 | AZ39: =AZ36*'입력값'!E22/4 | BA39: =BA36*'입력값'!E22/4 | BB39: =BB36*'입력값'!E22/4 | BC39: =BC36*'입력값'!E22/4 | BD39: =BD36*'입력값'!E22/4 | BE39: =BE36*'입력값'!E22/4 | BF39: =BF36*'입력값'!E22/4 | BG39: =BG36*'입력값'!E22/4 | BH39: =BH36*'입력값'!E22/4 | BI39: =BI36*'입력값'!E22/4 | BJ39: =BJ36*'입력값'!E22/4 | BK39: =BK36*'입력값'!E22/4 | BL39: =BL36*'입력값'!E22/4 | BM39: =BM36*'입력값'!E22/4 | BN39: =BN36*'입력값'!E22/4 | BO39: =BO36*'입력값'!E22/4 | BP39: =BP36*'입력값'!E22/4 | BQ39: =BQ36*'입력값'!E22/4 | BR39: =BR36*'입력값'!E22/4 | BS39: =BS36*'입력값'!E22/4 | BT39: =BT36*'입력값'!E22/4 | BU39: =BU36*'입력값'!E22/4 | BV39: =BV36*'입력값'!E22/4 | BW39: =BW36*'입력값'!E22/4 | BX39: =BX36*'입력값'!E22/4 | BY39: =BY36*'입력값'!E22/4 | BZ39: =BZ36*'입력값'!E22/4 | CA39: =CA36*'입력값'!E22/4 | CB39: =CB36*'입력값'!E22/4 | CC39: =CC36*'입력값'!E22/4 | CD39: =CD36*'입력값'!E22/4 | CE39: =CE36*'입력값'!E22/4 | CF39: =CF36*'입력값'!E22/4 | CG39: =CG36*'입력값'!E22/4 | CH39: =CH36*'입력값'!E22/4 | CI39: =CI36*'입력값'!E22/4 | CJ39: =CJ36*'입력값'!E22/4 | CK39: =CK36*'입력값'!E22/4 | CL39: =CL36*'입력값'!E22/4
B40: 원금상환 | C40: [KRWm] | D40: 0 | E40: 0 | F40: 0 | G40: 0 | H40: 0 | I40: 0 | J40: 0 | K40: 0 | L40: 0 | M40: 0 | N40: 0 | O40: 0 | P40: 0 | Q40: 0 | R40: 0 | S40: 0 | T40: 0 | U40: 0 | V40: 0 | W40: 0 | X40: 0 | Y40: 0 | Z40: 0 | AA40: 0 | AB40: 0 | AC40: 0 | AD40: 0 | AE40: 0 | AF40: 0 | AG40: 0 | AH40: 0 | AI40: 0 | AJ40: 0 | AK40: 0 | AL40: 0 | AM40: 0 | AN40: 0 | AO40: 0 | AP40: 0 | AQ40: 0 | AR40: 0 | AS40: 0 | AT40: 0 | AU40: 0 | AV40: 0 | AW40: 0 | AX40: 0 | AY40: 0 | AZ40: 0 | BA40: 0 | BB40: 0 | BC40: 0 | BD40: 0 | BE40: 0 | BF40: 0 | BG40: 0 | BH40: 0 | BI40: 0 | BJ40: 0 | BK40: 0 | BL40: 0 | BM40: 0 | BN40: 0 | BO40: 0 | BP40: 0 | BQ40: 0 | BR40: 0 | BS40: 0 | BT40: 0 | BU40: 0 | BV40: 0 | BW40: 0 | BX40: 0 | BY40: 0 | BZ40: 0 | CA40: 0 | CB40: 0 | CC40: 0 | CD40: 0 | CE40: 0 | CF40: 0 | CG40: 0 | CH40: 0 | CI40: 0 | CJ40: 0 | CK40: 0 | CL40: 0
B41: 기말잔액 | C41: [KRWm] | E41: =E36+E37-E40 | F41: =F36+F37-F40 | G41: =G36+G37-G40 | H41: =H36+H37-H40 | I41: =I36+I37-I40 | J41: =J36+J37-J40 | K41: =K36+K37-K40 | L41: =L36+L37-L40 | ... CL41: =CL36+CL37-CL40
B42: 미상환 잔액(검증용) | C42: [KRWm] | D42: 0 | F42: 완전상환 확인 (OK) | H42: ※ 방식 3(직접 키인) 또는 미사용 트랜치 — 값(baked) 기준
B44: 후순위
B45: 기초잔액 | C45: [KRWm] | E45: 0 | F45: =E50 | G45: =F50 | H45: =G50 | I45: =H50 | J45: =I50 | K45: =J50 | L45: =K50 | M45: =L50 | ... CL45: =CK50
B46: 인출 | C46: [KRWm] | D46: 0 | E46: 0 | F46: 0 | G46: 0 | H46: 0 | I46: 0 | J46: 0 | K46: 0 | L46: 0 | M46: 0 | N46: 0 | O46: 0 | P46: 0 | Q46: 0 | R46: 0 | S46: 0 | T46: 0 | U46: 0 | V46: 0 | W46: 0 | X46: 0 | Y46: 0 | Z46: 0 | AA46: 0 | AB46: 0 | AC46: 0 | AD46: 0 | AE46: 0 | AF46: 0 | AG46: 0 | AH46: 0 | AI46: 0 | AJ46: 0 | AK46: 0 | AL46: 0 | AM46: 0 | AN46: 0 | AO46: 0 | AP46: 0 | AQ46: 0 | AR46: 0 | AS46: 0 | AT46: 0 | AU46: 0 | AV46: 0 | AW46: 0 | AX46: 0 | AY46: 0 | AZ46: 0 | BA46: 0 | BB46: 0 | BC46: 0 | BD46: 0 | BE46: 0 | BF46: 0 | BG46: 0 | BH46: 0 | BI46: 0 | BJ46: 0 | BK46: 0 | BL46: 0 | BM46: 0 | BN46: 0 | BO46: 0 | BP46: 0 | BQ46: 0 | BR46: 0 | BS46: 0 | BT46: 0 | BU46: 0 | BV46: 0 | BW46: 0 | BX46: 0 | BY46: 0 | BZ46: 0 | CA46: 0 | CB46: 0 | CC46: 0 | CD46: 0 | CE46: 0 | CF46: 0 | CG46: 0 | CH46: 0 | CI46: 0 | CJ46: 0 | CK46: 0 | CL46: 0
B47: 건설이자(IDC) | C47: [KRWm] | D47: 0 | E47: 0 | F47: 0 | G47: 0 | H47: 0 | I47: 0 | J47: 0 | K47: 0 | L47: 0 | M47: 0 | N47: 0 | O47: 0 | P47: 0 | Q47: 0 | R47: 0 | S47: 0 | T47: 0 | U47: 0 | V47: 0 | W47: 0 | X47: 0 | Y47: 0 | Z47: 0 | AA47: 0 | AB47: 0 | AC47: 0 | AD47: 0 | AE47: 0 | AF47: 0 | AG47: 0 | AH47: 0 | AI47: 0 | AJ47: 0 | AK47: 0 | AL47: 0 | AM47: 0 | AN47: 0 | AO47: 0 | AP47: 0 | AQ47: 0 | AR47: 0 | AS47: 0 | AT47: 0 | AU47: 0 | AV47: 0 | AW47: 0 | AX47: 0 | AY47: 0 | AZ47: 0 | BA47: 0 | BB47: 0 | BC47: 0 | BD47: 0 | BE47: 0 | BF47: 0 | BG47: 0 | BH47: 0 | BI47: 0 | BJ47: 0 | BK47: 0 | BL47: 0 | BM47: 0 | BN47: 0 | BO47: 0 | BP47: 0 | BQ47: 0 | BR47: 0 | BS47: 0 | BT47: 0 | BU47: 0 | BV47: 0 | BW47: 0 | BX47: 0 | BY47: 0 | BZ47: 0 | CA47: 0 | CB47: 0 | CC47: 0 | CD47: 0 | CE47: 0 | CF47: 0 | CG47: 0 | CH47: 0 | CI47: 0 | CJ47: 0 | CK47: 0 | CL47: 0
...

Sheet Revenue
A1: 태양광 발전사업
A2: 영업수익 추정
B4: 발전량 및 매출
B6: 구 분 | C6: unit | D6: 합 계 | E6: 2024-06-30 | F6: 2024-09-30 | G6: 2024-12-31 | H6: 2025-03-31 | I6: 2025-06-30 | J6: 2025-09-30 | K6: 2025-12-31 | L6: 2026-03-31 | M6: 2026-06-30 | N6: 2026-09-30 | O6: 2026-12-31 | P6: 2027-03-31 | Q6: 2027-06-30 | R6: 2027-09-30 | S6: 2027-12-31 | T6: 2028-03-31 | U6: 2028-06-30 | V6: 2028-09-30 | W6: 2028-12-31 | X6: 2029-03-31 | Y6: 2029-06-30 | Z6: 2029-09-30 | AA6: 2029-12-31 | AB6: 2030-03-31 | AC6: 2030-06-30 | AD6: 2030-09-30 | AE6: 2030-12-31 | AF6: 2031-03-31 | AG6: 2031-06-30 | AH6: 2031-09-30 | AI6: 2031-12-31 | AJ6: 2032-03-31 | AK6: 2032-06-30 | AL6: 2032-09-30 | AM6: 2032-12-31 | AN6: 2033-03-31 | AO6: 2033-06-30 | AP6: 2033-09-30 | AQ6: 2033-12-31 | AR6: 2034-03-31 | AS6: 2034-06-30 | AT6: 2034-09-30 | AU6: 2034-12-31 | AV6: 2035-03-31 | AW6: 2035-06-30 | AX6: 2035-09-30 | AY6: 2035-12-31 | AZ6: 2036-03-31 | BA6: 2036-06-30 | BB6: 2036-09-30 | BC6: 2036-12-31 | BD6: 2037-03-31 | BE6: 2037-06-30 | BF6: 2037-09-30 | BG6: 2037-12-31 | BH6: 2038-03-31 | BI6: 2038-06-30 | BJ6: 2038-09-30 | BK6: 2038-12-31 | BL6: 2039-03-31 | BM6: 2039-06-30 | BN6: 2039-09-30 | BO6: 2039-12-31 | BP6: 2040-03-31 | BQ6: 2040-06-30 | BR6: 2040-09-30 | BS6: 2040-12-31 | BT6: 2041-03-31 | BU6: 2041-06-30 | BV6: 2041-09-30 | BW6: 2041-12-31 | BX6: 2042-03-31 | BY6: 2042-06-30 | BZ6: 2042-09-30 | CA6: 2042-12-31 | CB6: 2043-03-31 | CC6: 2043-06-30 | CD6: 2043-09-30 | CE6: 2043-12-31 | CF6: 2044-03-31 | CG6: 2044-06-30 | CH6: 2044-09-30 | CI6: 2044-12-31 | CJ6: 2045-03-31 | CK6: 2045-06-30 | CL6: 2045-09-30
B9: 발전량 | C9: [MWh] | D9: 2621322.8 | E9: =('입력값'!C7*'입력값'!C14*365)*MAX(0,1-'입력값'!C12/100*0)*(1-'입력값'!C13/100)*0 | F9: =('입력값'!C7*'입력값'!C14*365)*MAX(0,1-'입력값'!C12/100*0)*(1-'입력값'!C13/100)*0 | G9: =('입력값'!C7*'입력값'!C14*365)*MAX(0,1-'입력값'!C12/100*0)*(1-'입력값'!C13/100)*0 | H9: =('입력값'!C7*'입력값'!C14*365)*MAX(0,1-'입력값'!C12/100*0)*(1-'입력값'!C13/100)*0 | I9: =('입력값'!C7*'입력값'!C14*365)*MAX(0,1-'입력값'!C12/100*0)*(1-'입력값'!C13/100)*0 | J9: =('입력값'!C7*'입력값'!C14*365)*MAX(0,1-'입력값'!C12/100*0)*(1-'입력값'!C13/100)*0 | K9: =('입력값'!C7*'입력값'!C14*365)*MAX(0,1-'입력값'!C12/100*0)*(1-'입력값'!C13/100)*0.25 | L9: =('입력값'!C7*'입력값'!C14*365)*MAX(0,1-'입력값'!C12/100*0)*(1-'입력값'!C13/100)*0.25 | M9: =('입력값'!C7*'입력값'!C14*365)*MAX(0,1-'입력값'!C12/100*0)*(1-'입력값'!C13/100)*0.25 | N9: =('입력값'!C7*'입력값'!C14*365)*MAX(0,1-'입력값'!C12/100*0)*(1-'입력값'!C13/100)*0.25 | O9: =('입력값'!C7*'입력값'!C14*365)*MAX(0,1-'입력값'!C12/100*1)*(1-'입력값'!C13/100)*0.25 | P9: =('입력값'!C7*'입력값'!C14*365)*MAX(0,1-'입력값'!C12/100*1)*(1-'입력값'!C13/100)*0.25 | Q9: =('입력값'!C7*'입력값'!C14*365)*MAX(0,1-'입력값'!C12/100*1)*(1-'입력값'!C13/100)*0.25 | R9: =('입력값'!C7*'입력값'!C14*365)*MAX(0,1-'입력값'!C12/100*1)*(1-'입력값'!C13/100)*0.25 | S9: =('입력값'!C7*'입력값'!C14*365)*MAX(0,1-'입력값'!C12/100*2)*(1-'입력값'!C13/100)*0.25 | T9: =('입력값'!C7*'입력값'!C14*365)*MAX(0,1-'입력값'!C12/100*2)*(1-'입력값'!C13/100)*0.25 | U9: =('입력값'!C7*'입력값'!C14*365)*MAX(0,1-'입력값'!C12/100*2)*(1-'입력값'!C13/100)*0.25 | V9: =('입력값'!C7*'입력값'!C14*365)*MAX(0,1-'입력값'!C12/100*2)*(1-'입력값'!C13/100)*0.25 | W9: =('입력값'!C7*'입력값'!C14*365)*MAX(0,1-'입력값'!C12/100*3)*(1-'입력값'!C13/100)*0.25 | X9: =('입력값'!C7*'입력값'!C14*365)*MAX(0,1-'입력값'!C12/100*3)*(1-'입력값'!C13/100)*0.25 | Y9: =('입력값'!C7*'입력값'!C14*365)*MAX(0,1-'입력값'!C12/100*3)*(1-'입력값'!C13/100)*0.25 | Z9: =('입력값'!C7*'입력값'!C14*365)*MAX(0,1-'입력값'!C12/100*3)*(1-'입력값'!C13/100)*0.25 | AA9: =('입력값'!C7*'입력값'!C14*365)*MAX(0,1-'입력값'!C12/100*4)*(1-'입력값'!C13/100)*0.25 | AB9: =('입력값'!C7*'입력값'!C14*365)*MAX(0,1-'입력값'!C12/100*4)*(1-'입력값'!C13/100)*0.25 | AC9: =('입력값'!C7*'입력값'!C14*365)*MAX(0,1-'입력값'!C12/100*4)*(1-'입력값'!C13/100)*0.25 | AD9: =('입력값'!C7*'입력값'!C14*365)*MAX(0,1-'입력값'!C12/100*4)*(1-'입력값'!C13/100)*0.25 | AE9: =('입력값'!C7*'입력값'!C14*365)*MAX(0,1-'입력값'!C12/100*5)*(1-'입력값'!C13/100)*0.25 | AF9: =('입력값'!C7*'입력값'!C14*365)*MAX(0,1-'입력값'!C12/100*5)*(1-'입력값'!C13/100)*0.25 | AG9: =('입력값'!C7*'입력값'!C14*365)*MAX(0,1-'입력값'!C12/100*5)*(1-'입력값'!C13/100)*0.25 | AH9: =('입력값'!C7*'입력값'!C14*365)*MAX(0,1-'입력값'!C12/100*5)*(1-'입력값'!C13/100)*0.25 | AI9: =('입력값'!C7*'입력값'!C14*365)*MAX(0,1-'입력값'!C12/100*6)*(1-'입력값'!C13/100)*0.25 | AJ9: =('입력값'!C7*'입력값'!C14*365)*MAX(0,1-'입력값'!C12/100*6)*(1-'입력값'!C13/100)*0.25 | AK9: =('입력값'!C7*'입력값'!C14*365)*MAX(0,1-'입력값'!C12/100*6)*(1-'입력값'!C13/100)*0.25 | AL9: =('입력값'!C7*'입력값'!C14*365)*MAX(0,1-'입력값'!C12/100*6)*(1-'입력값'!C13/100)*0.25 | AM9: =('입력값'!C7*'입력값'!C14*365)*MAX(0,1-'입력값'!C12/100*7)*(1-'입력값'!C13/100)*0.25 | AN9: =('입력값'!C7*'입력값'!C14*365)*MAX(0,1-'입력값'!C12/100*7)*(1-'입력값'!C13/100)*0.25 | AO9: =('입력값'!C7*'입력값'!C14*365)*MAX(0,1-'입력값'!C12/100*7)*(1-'입력값'!C13/100)*0.25 | AP9: =('입력값'!C7*'입력값'!C14*365)*MAX(0,1-'입력값'!C12/100*7)*(1-'입력값'!C13/100)*0.25 | AQ9: =('입력값'!C7*'입력값'!C14*365)*MAX(0,1-'입력값'!C12/100*8)*(1-'입력값'!C13/100)*0.25 | AR9: =('입력값'!C7*'입력값'!C14*365)*MAX(0,1-'입력값'!C12/100*8)*(1-'입력값'!C13/100)*0.25 | AS9: =('입력값'!C7*'입력값'!C14*365)*MAX(0,1-'입력값'!C12/100*8)*(1-'입력값'!C13/100)*0.25 | AT9: =('입력값'!C7*'입력값'!C14*365)*MAX(0,1-'입력값'!C12/100*8)*(1-'입력값'!C13/100)*0.25 | AU9: =('입력값'!C7*'입력값'!C14*365)*MAX(0,1-'입력값'!C12/100*9)*(1-'입력값'!C13/100)*0.25 | AV9: =('입력값'!C7*'입력값'!C14*365)*MAX(0,1-'입력값'!C12/100*9)*(1-'입력값'!C13/100)*0.25 | AW9: =('입력값'!C7*'입력값'!C14*365)*MAX(0,1-'입력값'!C12/100*9)*(1-'입력값'!C13/100)*0.25 | AX9: =('입력값'!C7*'입력값'!C14*365)*MAX(0,1-'입력값'!C12/100*9)*(1-'입력값'!C13/100)*0.25 | AY9: =('입력값'!C7*'입력값'!C14*365)*MAX(0,1-'입력값'!C12/100*10)*(1-'입력값'!C13/100)*0.25 | AZ9: =('입력값'!C7*'입력값'!C14*365)*MAX(0,1-'입력값'!C12/100*10)*(1-'입력값'!C13/100)*0.25 | BA9: =('입력값'!C7*'입력값'!C14*365)*MAX(0,1-'입력값'!C12/100*10)*(1-'입력값'!C13/100)*0.25 | BB9: =('입력값'!C7*'입력값'!C14*365)*MAX(0,1-'입력값'!C12/100*10)*(1-'입력값'!C13/100)*0.25 | BC9: =('입력값'!C7*'입력값'!C14*365)*MAX(0,1-'입력값'!C12/100*11)*(1-'입력값'!C13/100)*0.25 | BD9: =('입력값'!C7*'입력값'!C14*365)*MAX(0,1-'입력값'!C12/100*11)*(1-'입력값'!C13/100)*0.25 | BE9: =('입력값'!C7*'입력값'!C14*365)*MAX(0,1-'입력값'!C12/100*11)*(1-'입력값'!C13/100)*0.25 | BF9: =('입력값'!C7*'입력값'!C14*365)*MAX(0,1-'입력값'!C12/100*11)*(1-'입력값'!C13/100)*0.25 | BG9: =('입력값'!C7*'입력값'!C14*365)*MAX(0,1-'입력값'!C12/100*12)*(1-'입력값'!C13/100)*0.25 | BH9: =('입력값'!C7*'입력값'!C14*365)*MAX(0,1-'입력값'!C12/100*12)*(1-'입력값'!C13/100)*0.25 | BI9: =('입력값'!C7*'입력값'!C14*365)*MAX(0,1-'입력값'!C12/100*12)*(1-'입력값'!C13/100)*0.25 | BJ9: =('입력값'!C7*'입력값'!C14*365)*MAX(0,1-'입력값'!C12/100*12)*(1-'입력값'!C13/100)*0.25 | BK9: =('입력값'!C7*'입력값'!C14*365)*MAX(0,1-'입력값'!C12/100*13)*(1-'입력값'!C13/100)*0.25 | BL9: =('입력값'!C7*'입력값'!C14*365)*MAX(0,1-'입력값'!C12/100*13)*(1-'입력값'!C13/100)*0.25 | BM9: =('입력값'!C7*'입력값'!C14*365)*MAX(0,1-'입력값'!C12/100*13)*(1-'입력값'!C13/100)*0.25 | BN9: =('입력값'!C7*'입력값'!C14*365)*MAX(0,1-'입력값'!C12/100*13)*(1-'입력값'!C13/100)*0.25 | BO9: =('입력값'!C7*'입력값'!C14*365)*MAX(0,1-'입력값'!C12/100*14)*(1-'입력값'!C13/100)*0.25 | BP9: =('입력값'!C7*'입력값'!C14*365)*MAX(0,1-'입력값'!C12/100*14)*(1-'입력값'!C13/100)*0.25 | BQ9: =('입력값'!C7*'입력값'!C14*365)*MAX(0,1-'입력값'!C12/100*14)*(1-'입력값'!C13/100)*0.25 | BR9: =('입력값'!C7*'입력값'!C14*365)*MAX(0,1-'입력값'!C12/100*14)*(1-'입력값'!C13/100)*0.25 | BS9: =('입력값'!C7*'입력값'!C14*365)*MAX(0,1-'입력값'!C12/100*15)*(1-'입력값'!C13/100)*0.25 | BT9: =('입력값'!C7*'입력값'!C14*365)*MAX(0,1-'입력값'!C12/100*15)*(1-'입력값'!C13/100)*0.25 | BU9: =('입력값'!C7*'입력값'!C14*365)*MAX(0,1-'입력값'!C12/100*15)*(1-'입력값'!C13/100)*0.25 | BV9: =('입력값'!C7*'입력값'!C14*365)*MAX(0,1-'입력값'!C12/100*15)*(1-'입력값'!C13/100)*0.25 | BW9: =('입력값'!C7*'입력값'!C14*365)*MAX(0,1-'입력값'!C12/100*16)*(1-'입력값'!C13/100)*0.25 | BX9: =('입력값'!C7*'입력값'!C14*365)*MAX(0,1-'입력값'!C12/100*16)*(1-'입력값'!C13/100)*0.25 | BY9: =('입력값'!C7*'입력값'!C14*365)*MAX(0,1-'입력값'!C12/100*16)*(1-'입력값'!C13/100)*0.25 | BZ9: =('입력값'!C7*'입력값'!C14*365)*MAX(0,1-'입력값'!C12/100*16)*(1-'입력값'!C13/100)*0.25 | CA9: =('입력값'!C7*'입력값'!C14*365)*MAX(0,1-'입력값'!C12/100*17)*(1-'입력값'!C13/100)*0.25 | CB9: =('입력값'!C7*'입력값'!C14*365)*MAX(0,1-'입력값'!C12/100*17)*(1-'입력값'!C13/100)*0.25 | CC9: =('입력값'!C7*'입력값'!C14*365)*MAX(0,1-'입력값'!C12/100*17)*(1-'입력값'!C13/100)*0.25 | CD9: =('입력값'!C7*'입력값'!C14*365)*MAX(0,1-'입력값'!C12/100*17)*(1-'입력값'!C13/100)*0.25 | CE9: =('입력값'!C7*'입력값'!C14*365)*MAX(0,1-'입력값'!C12/100*18)*(1-'입력값'!C13/100)*0.25 | CF9: =('입력값'!C7*'입력값'!C14*365)*MAX(0,1-'입력값'!C12/100*18)*(1-'입력값'!C13/100)*0.25 | CG9: =('입력값'!C7*'입력값'!C14*365)*MAX(0,1-'입력값'!C12/100*18)*(1-'입력값'!C13/100)*0.25 | CH9: =('입력값'!C7*'입력값'!C14*365)*MAX(0,1-'입력값'!C12/100*18)*(1-'입력값'!C13/100)*0.25 | CI9: =('입력값'!C7*'입력값'!C14*365)*MAX(0,1-'입력값'!C12/100*19)*(1-'입력값'!C13/100)*0.25 | CJ9: =('입력값'!C7*'입력값'!C14*365)*MAX(0,1-'입력값'!C12/100*19)*(1-'입력값'!C13/100)*0.25 | CK9: =('입력값'!C7*'입력값'!C14*365)*MAX(0,1-'입력값'!C12/100*19)*(1-'입력값'!C13/100)*0.25 | CL9: =('입력값'!C7*'입력값'!C14*365)*MAX(0,1-'입력값'!C12/100*19)*(1-'입력값'!C13/100)*0.25
B10: 판매단가 | C10: [원/kWh] | K10: ='입력값'!C10*(1+'입력값'!C11/100)^0 | L10: ='입력값'!C10*(1+'입력값'!C11/100)^0 | M10: ='입력값'!C10*(1+'입력값'!C11/100)^0 | N10: ='입력값'!C10*(1+'입력값'!C11/100)^0 | O10: ='입력값'!C10*(1+'입력값'!C11/100)^1 | P10: ='입력값'!C10*(1+'입력값'!C11/100)^1 | Q10: ='입력값'!C10*(1+'입력값'!C11/100)^1 | R10: ='입력값'!C10*(1+'입력값'!C11/100)^1 | S10: ='입력값'!C10*(1+'입력값'!C11/100)^2 | T10: ='입력값'!C10*(1+'입력값'!C11/100)^2 | U10: ='입력값'!C10*(1+'입력값'!C11/100)^2 | V10: ='입력값'!C10*(1+'입력값'!C11/100)^2 | W10: ='입력값'!C10*(1+'입력값'!C11/100)^3 | X10: ='입력값'!C10*(1+'입력값'!C11/100)^3 | Y10: ='입력값'!C10*(1+'입력값'!C11/100)^3 | Z10: ='입력값'!C10*(1+'입력값'!C11/100)^3 | AA10: ='입력값'!C10*(1+'입력값'!C11/100)^4 | AB10: ='입력값'!C10*(1+'입력값'!C11/100)^4 | AC10: ='입력값'!C10*(1+'입력값'!C11/100)^4 | AD10: ='입력값'!C10*(1+'입력값'!C11/100)^4 | AE10: ='입력값'!C10*(1+'입력값'!C11/100)^5 | AF10: ='입력값'!C10*(1+'입력값'!C11/100)^5 | AG10: ='입력값'!C10*(1+'입력값'!C11/100)^5 | AH10: ='입력값'!C10*(1+'입력값'!C11/100)^5 | AI10: ='입력값'!C10*(1+'입력값'!C11/100)^6 | AJ10: ='입력값'!C10*(1+'입력값'!C11/100)^6 | AK10: ='입력값'!C10*(1+'입력값'!C11/100)^6 | AL10: ='입력값'!C10*(1+'입력값'!C11/100)^6 | AM10: ='입력값'!C10*(1+'입력값'!C11/100)^7 | AN10: ='입력값'!C10*(1+'입력값'!C11/100)^7 | AO10: ='입력값'!C10*(1+'입력값'!C11/100)^7 | AP10: ='입력값'!C10*(1+'입력값'!C11/100)^7 | AQ10: ='입력값'!C10*(1+'입력값'!C11/100)^8 | AR10: ='입력값'!C10*(1+'입력값'!C11/100)^8 | AS10: ='입력값'!C10*(1+'입력값'!C11/100)^8 | AT10: ='입력값'!C10*(1+'입력값'!C11/100)^8 | AU10: ='입력값'!C10*(1+'입력값'!C11/100)^9 | AV10: ='입력값'!C10*(1+'입력값'!C11/100)^9 | AW10: ='입력값'!C10*(1+'입력값'!C11/100)^9 | AX10: ='입력값'!C10*(1+'입력값'!C11/100)^9 | AY10: ='입력값'!C10*(1+'입력값'!C11/100)^10 | AZ10: ='입력값'!C10*(1+'입력값'!C11/100)^10 | BA10: ='입력값'!C10*(1+'입력값'!C11/100)^10 | BB10: ='입력값'!C10*(1+'입력값'!C11/100)^10 | BC10: ='입력값'!C10*(1+'입력값'!C11/100)^11 | BD10: ='입력값'!C10*(1+'입력값'!C11/100)^11 | BE10: ='입력값'!C10*(1+'입력값'!C11/100)^11 | BF10: ='입력값'!C10*(1+'입력값'!C11/100)^11 | BG10: ='입력값'!C10*(1+'입력값'!C11/100)^12 | BH10: ='입력값'!C10*(1+'입력값'!C11/100)^12 | BI10: ='입력값'!C10*(1+'입력값'!C11/100)^12 | BJ10: ='입력값'!C10*(1+'입력값'!C11/100)^12 | BK10: ='입력값'!C10*(1+'입력값'!C11/100)^13 | BL10: ='입력값'!C10*(1+'입력값'!C11/100)^13 | BM10: ='입력값'!C10*(1+'입력값'!C11/100)^13 | BN10: ='입력값'!C10*(1+'입력값'!C11/100)^13 | BO10: ='입력값'!C10*(1+'입력값'!C11/100)^14 | BP10: ='입력값'!C10*(1+'입력값'!C11/100)^14 | BQ10: ='입력값'!C10*(1+'입력값'!C11/100)^14 | BR10: ='입력값'!C10*(1+'입력값'!C11/100)^14 | BS10: ='입력값'!C10*(1+'입력값'!C11/100)^15 | BT10: ='입력값'!C10*(1+'입력값'!C11/100)^15 | BU10: ='입력값'!C10*(1+'입력값'!C11/100)^15 | BV10: ='입력값'!C10*(1+'입력값'!C11/100)^15 | BW10: ='입력값'!C10*(1+'입력값'!C11/100)^16 | BX10: ='입력값'!C10*(1+'입력값'!C11/100)^16 | BY10: ='입력값'!C10*(1+'입력값'!C11/100)^16 | BZ10: ='입력값'!C10*(1+'입력값'!C11/100)^16 | CA10: ='입력값'!C10*(1+'입력값'!C11/100)^17 | CB10: ='입력값'!C10*(1+'입력값'!C11/100)^17 | CC10: ='입력값'!C10*(1+'입력값'!C11/100)^17 | CD10: ='입력값'!C10*(1+'입력값'!C11/100)^17 | CE10: ='입력값'!C10*(1+'입력값'!C11/100)^18 | CF10: ='입력값'!C10*(1+'입력값'!C11/100)^18 | CG10: ='입력값'!C10*(1+'입력값'!C11/100)^18 | CH10: ='입력값'!C10*(1+'입력값'!C11/100)^18 | CI10: ='입력값'!C10*(1+'입력값'!C11/100)^19 | CJ10: ='입력값'!C10*(1+'입력값'!C11/100)^19 | CK10: ='입력값'!C10*(1+'입력값'!C11/100)^19 | CL10: ='입력값'!C10*(1+'입력값'!C11/100)^19
B12: 영업수익 | C12: [KRWm] | D12: 405780.77 | E12: 0 | F12: 0 | G12: 0 | H12: 0 | I12: 0 | J12: 0 | K12: =K9*K10/1000 | L12: =L9*L10/1000 | M12: =M9*M10/1000 | N12: =N9*N10/1000 | O12: =O9*O10/1000 | P12: =P9*P10/1000 | Q12: =Q9*Q10/1000 | R12: =R9*R10/1000 | ... CL12: =CL9*CL10/1000

Sheet Opex
A1: 태양광 발전사업
A2: 영업비용 추정
B4: 운영비용 (선순위/후순위 지급순위 반영)
B6: 구 분 | C6: unit | D6: 합 계 | E6: 2024-06-30 | F6: 2024-09-30 | G6: 2024-12-31 | H6: 2025-03-31 | I6: 2025-06-30 | J6: 2025-09-30 | K6: 2025-12-31 | L6: 2026-03-31 | M6: 2026-06-30 | N6: 2026-09-30 | O6: 2026-12-31 | P6: 2027-03-31 | Q6: 2027-06-30 | R6: 2027-09-30 | S6: 2027-12-31 | T6: 2028-03-31 | U6: 2028-06-30 | V6: 2028-09-30 | W6: 2028-12-31 | X6: 2029-03-31 | Y6: 2029-06-30 | Z6: 2029-09-30 | AA6: 2029-12-31 | AB6: 2030-03-31 | AC6: 2030-06-30 | AD6: 2030-09-30 | AE6: 2030-12-31 | AF6: 2031-03-31 | AG6: 2031-06-30 | AH6: 2031-09-30 | AI6: 2031-12-31 | AJ6: 2032-03-31 | AK6: 2032-06-30 | AL6: 2032-09-30 | AM6: 2032-12-31 | AN6: 2033-03-31 | AO6: 2033-06-30 | AP6: 2033-09-30 | AQ6: 2033-12-31 | AR6: 2034-03-31 | AS6: 2034-06-30 | AT6: 2034-09-30 | AU6: 2034-12-31 | AV6: 2035-03-31 | AW6: 2035-06-30 | AX6: 2035-09-30 | AY6: 2035-12-31 | AZ6: 2036-03-31 | BA6: 2036-06-30 | BB6: 2036-09-30 | BC6: 2036-12-31 | BD6: 2037-03-31 | BE6: 2037-06-30 | BF6: 2037-09-30 | BG6: 2037-12-31 | BH6: 2038-03-31 | BI6: 2038-06-30 | BJ6: 2038-09-30 | BK6: 2038-12-31 | BL6: 2039-03-31 | BM6: 2039-06-30 | BN6: 2039-09-30 | BO6: 2039-12-31 | BP6: 2040-03-31 | BQ6: 2040-06-30 | BR6: 2040-09-30 | BS6: 2040-12-31 | BT6: 2041-03-31 | BU6: 2041-06-30 | BV6: 2041-09-30 | BW6: 2041-12-31 | BX6: 2042-03-31 | BY6: 2042-06-30 | BZ6: 2042-09-30 | CA6: 2042-12-31 | CB6: 2043-03-31 | CC6: 2043-06-30 | CD6: 2043-09-30 | CE6: 2043-12-31 | CF6: 2044-03-31 | CG6: 2044-06-30 | CH6: 2044-09-30 | CI6: 2044-12-31 | CJ6: 2045-03-31 | CK6: 2045-06-30 | CL6: 2045-09-30
B8: 항목별 세부내역
B9: 부지임대료 | C9: [KRWm] | D9: -10000 | E9: 0 | F9: 0 | G9: 0 | H9: 0 | I9: 0 | J9: 0 | K9: =-('입력값'!C44*100*(3/12)) | L9: =-('입력값'!C44*100*(3/12)) | M9: =-('입력값'!C44*100*(3/12)) | N9: =-('입력값'!C44*100*(3/12)) | O9: =-('입력값'!C44*100*(3/12)) | P9: =-('입력값'!C44*100*(3/12)) | Q9: =-('입력값'!C44*100*(3/12)) | R9: =-('입력값'!C44*100*(3/12)) | S9: =-('입력값'!C44*100*(3/12)) | T9: =-('입력값'!C44*100*(3/12)) | U9: =-('입력값'!C44*100*(3/12)) | V9: =-('입력값'!C44*100*(3/12)) | W9: =-('입력값'!C44*100*(3/12)) | X9: =-('입력값'!C44*100*(3/12)) | Y9: =-('입력값'!C44*100*(3/12)) | Z9: =-('입력값'!C44*100*(3/12)) | AA9: =-('입력값'!C44*100*(3/12)) | AB9: =-('입력값'!C44*100*(3/12)) | AC9: =-('입력값'!C44*100*(3/12)) | AD9: =-('입력값'!C44*100*(3/12)) | AE9: =-('입력값'!C44*100*(3/12)) | AF9: =-('입력값'!C44*100*(3/12)) | AG9: =-('입력값'!C44*100*(3/12)) | AH9: =-('입력값'!C44*100*(3/12)) | AI9: =-('입력값'!C44*100*(3/12)) | AJ9: =-('입력값'!C44*100*(3/12)) | AK9: =-('입력값'!C44*100*(3/12)) | AL9: =-('입력값'!C44*100*(3/12)) | AM9: =-('입력값'!C44*100*(3/12)) | AN9: =-('입력값'!C44*100*(3/12)) | AO9: =-('입력값'!C44*100*(3/12)) | AP9: =-('입력값'!C44*100*(3/12)) | AQ9: =-('입력값'!C44*100*(3/12)) | AR9: =-('입력값'!C44*100*(3/12)) | AS9: =-('입력값'!C44*100*(3/12)) | AT9: =-('입력값'!C44*100*(3/12)) | AU9: =-('입력값'!C44*100*(3/12)) | AV9: =-('입력값'!C44*100*(3/12)) | AW9: =-('입력값'!C44*100*(3/12)) | AX9: =-('입력값'!C44*100*(3/12)) | AY9: =-('입력값'!C44*100*(3/12)) | AZ9: =-('입력값'!C44*100*(3/12)) | BA9: =-('입력값'!C44*100*(3/12)) | BB9: =-('입력값'!C44*100*(3/12)) | BC9: =-('입력값'!C44*100*(3/12)) | BD9: =-('입력값'!C44*100*(3/12)) | BE9: =-('입력값'!C44*100*(3/12)) | BF9: =-('입력값'!C44*100*(3/12)) | BG9: =-('입력값'!C44*100*(3/12)) | BH9: =-('입력값'!C44*100*(3/12)) | BI9: =-('입력값'!C44*100*(3/12)) | BJ9: =-('입력값'!C44*100*(3/12)) | BK9: =-('입력값'!C44*100*(3/12)) | BL9: =-('입력값'!C44*100*(3/12)) | BM9: =-('입력값'!C44*100*(3/12)) | BN9: =-('입력값'!C44*100*(3/12)) | BO9: =-('입력값'!C44*100*(3/12)) | BP9: =-('입력값'!C44*100*(3/12)) | BQ9: =-('입력값'!C44*100*(3/12)) | BR9: =-('입력값'!C44*100*(3/12)) | BS9: =-('입력값'!C44*100*(3/12)) | BT9: =-('입력값'!C44*100*(3/12)) | BU9: =-('입력값'!C44*100*(3/12)) | BV9: =-('입력값'!C44*100*(3/12)) | BW9: =-('입력값'!C44*100*(3/12)) | BX9: =-('입력값'!C44*100*(3/12)) | BY9: =-('입력값'!C44*100*(3/12)) | BZ9: =-('입력값'!C44*100*(3/12)) | CA9: =-('입력값'!C44*100*(3/12)) | CB9: =-('입력값'!C44*100*(3/12)) | CC9: =-('입력값'!C44*100*(3/12)) | CD9: =-('입력값'!C44*100*(3/12)) | CE9: =-('입력값'!C44*100*(3/12)) | CF9: =-('입력값'!C44*100*(3/12)) | CG9: =-('입력값'!C44*100*(3/12)) | CH9: =-('입력값'!C44*100*(3/12)) | CI9: =-('입력값'!C44*100*(3/12)) | CJ9: =-('입력값'!C44*100*(3/12)) | CK9: =-('입력값'!C44*100*(3/12)) | CL9: =-('입력값'!C44*100*(3/12))
B10: O&M | C10: [KRWm] | D10: -18498.934 | E10: 0 | F10: 0 | G10: 0 | H10: 0 | I10: 0 | J10: 0 | K10: =-('입력값'!C45*100*(3/12)*(1+'입력값'!D45/100)^0) | L10: =-('입력값'!C45*100*(3/12)*(1+'입력값'!D45/100)^0) | M10: =-('입력값'!C45*100*(3/12)*(1+'입력값'!D45/100)^0) | N10: =-('입력값'!C45*100*(3/12)*(1+'입력값'!D45/100)^0) | O10: =-('입력값'!C45*100*(3/12)*(1+'입력값'!D45/100)^1) | P10: =-('입력값'!C45*100*(3/12)*(1+'입력값'!D45/100)^1) | Q10: =-('입력값'!C45*100*(3/12)*(1+'입력값'!D45/100)^1) | R10: =-('입력값'!C45*100*(3/12)*(1+'입력값'!D45/100)^1) | S10: =-('입력값'!C45*100*(3/12)*(1+'입력값'!D45/100)^2) | T10: =-('입력값'!C45*100*(3/12)*(1+'입력값'!D45/100)^2) | U10: =-('입력값'!C45*100*(3/12)*(1+'입력값'!D45/100)^2) | V10: =-('입력값'!C45*100*(3/12)*(1+'입력값'!D45/100)^2) | W10: =-('입력값'!C45*100*(3/12)*(1+'입력값'!D45/100)^3) | X10: =-('입력값'!C45*100*(3/12)*(1+'입력값'!D45/100)^3) | Y10: =-('입력값'!C45*100*(3/12)*(1+'입력값'!D45/100)^3) | Z10: =-('입력값'!C45*100*(3/12)*(1+'입력값'!D45/100)^3) | AA10: =-('입력값'!C45*100*(3/12)*(1+'입력값'!D45/100)^4) | AB10: =-('입력값'!C45*100*(3/12)*(1+'입력값'!D45/100)^4) | AC10: =-('입력값'!C45*100*(3/12)*(1+'입력값'!D45/100)^4) | AD10: =-('입력값'!C45*100*(3/12)*(1+'입력값'!D45/100)^4) | AE10: =-('입력값'!C45*100*(3/12)*(1+'입력값'!D45/100)^5) | AF10: =-('입력값'!C45*100*(3/12)*(1+'입력값'!D45/100)^5) | AG10: =-('입력값'!C45*100*(3/12)*(1+'입력값'!D45/100)^5) | AH10: =-('입력값'!C45*100*(3/12)*(1+'입력값'!D45/100)^5) | AI10: =-('입력값'!C45*100*(3/12)*(1+'입력값'!D45/100)^6) | AJ10: =-('입력값'!C45*100*(3/12)*(1+'입력값'!D45/100)^6) | AK10: =-('입력값'!C45*100*(3/12)*(1+'입력값'!D45/100)^6) | AL10: =-('입력값'!C45*100*(3/12)*(1+'입력값'!D45/100)^6) | AM10: =-('입력값'!C45*100*(3/12)*(1+'입력값'!D45/100)^7) | AN10: =-('입력값'!C45*100*(3/12)*(1+'입력값'!D45/100)^7) | AO10: =-('입력값'!C45*100*(3/12)*(1+'입력값'!D45/100)^7) | AP10: =-('입력값'!C45*100*(3/12)*(1+'입력값'!D45/100)^7) | AQ10: =-('입력값'!C45*100*(3/12)*(1+'입력값'!D45/100)^8) | AR10: =-('입력값'!C45*100*(3/12)*(1+'입력값'!D45/100)^8) | AS10: =-('입력값'!C45*100*(3/12)*(1+'입력값'!D45/100)^8) | AT10: =-('입력값'!C45*100*(3/12)*(1+'입력값'!D45/100)^8) | AU10: =-('입력값'!C45*100*(3/12)*(1+'입력값'!D45/100)^9) | AV10: =-('입력값'!C45*100*(3/12)*(1+'입력값'!D45/100)^9) | AW10: =-('입력값'!C45*100*(3/12)*(1+'입력값'!D45/100)^9) | AX10: =-('입력값'!C45*100*(3/12)*(1+'입력값'!D45/100)^9) | AY10: =-('입력값'!C45*100*(3/12)*(1+'입력값'!D45/100)^10) | AZ10: =-('입력값'!C45*100*(3/12)*(1+'입력값'!D45/100)^10) | BA10: =-('입력값'!C45*100*(3/12)*(1+'입력값'!D45/100)^10) | BB10: =-('입력값'!C45*100*(3/12)*(1+'입력값'!D45/100)^10) | BC10: =-('입력값'!C45*100*(3/12)*(1+'입력값'!D45/100)^11) | BD10: =-('입력값'!C45*100*(3/12)*(1+'입력값'!D45/100)^11) | BE10: =-('입력값'!C45*100*(3/12)*(1+'입력값'!D45/100)^11) | BF10: =-('입력값'!C45*100*(3/12)*(1+'입력값'!D45/100)^11) | BG10: =-('입력값'!C45*100*(3/12)*(1+'입력값'!D45/100)^12) | BH10: =-('입력값'!C45*100*(3/12)*(1+'입력값'!D45/100)^12) | BI10: =-('입력값'!C45*100*(3/12)*(1+'입력값'!D45/100)^12) | BJ10: =-('입력값'!C45*100*(3/12)*(1+'입력값'!D45/100)^12) | BK10: =-('입력값'!C45*100*(3/12)*(1+'입력값'!D45/100)^13) | BL10: =-('입력값'!C45*100*(3/12)*(1+'입력값'!D45/100)^13) | BM10: =-('입력값'!C45*100*(3/12)*(1+'입력값'!D45/100)^13) | BN10: =-('입력값'!C45*100*(3/12)*(1+'입력값'!D45/100)^13) | BO10: =-('입력값'!C45*100*(3/12)*(1+'입력값'!D45/100)^14) | BP10: =-('입력값'!C45*100*(3/12)*(1+'입력값'!D45/100)^14) | BQ10: =-('입력값'!C45*100*(3/12)*(1+'입력값'!D45/100)^14) | BR10: =-('입력값'!C45*100*(3/12)*(1+'입력값'!D45/100)^14) | BS10: =-('입력값'!C45*100*(3/12)*(1+'입력값'!D45/100)^15) | BT10: =-('입력값'!C45*100*(3/12)*(1+'입력값'!D45/100)^15) | BU10: =-('입력값'!C45*100*(3/12)*(1+'입력값'!D45/100)^15) | BV10: =-('입력값'!C45*100*(3/12)*(1+'입력값'!D45/100)^15) | BW10: =-('입력값'!C45*100*(3/12)*(1+'입력값'!D45/100)^16) | BX10: =-('입력값'!C45*100*(3/12)*(1+'입력값'!D45/100)^16) | BY10: =-('입력값'!C45*100*(3/12)*(1+'입력값'!D45/100)^16) | BZ10: =-('입력값'!C45*100*(3/12)*(1+'입력값'!D45/100)^16) | CA10: =-('입력값'!C45*100*(3/12)*(1+'입력값'!D45/100)^17) | CB10: =-('입력값'!C45*100*(3/12)*(1+'입력값'!D45/100)^17) | CC10: =-('입력값'!C45*100*(3/12)*(1+'입력값'!D45/100)^17) | CD10: =-('입력값'!C45*100*(3/12)*(1+'입력값'!D45/100)^17) | CE10: =-('입력값'!C45*100*(3/12)*(1+'입력값'!D45/100)^18) | CF10: =-('입력값'!C45*100*(3/12)*(1+'입력값'!D45/100)^18) | CG10: =-('입력값'!C45*100*(3/12)*(1+'입력값'!D45/100)^18) | CH10: =-('입력값'!C45*100*(3/12)*(1+'입력값'!D45/100)^18) | CI10: =-('입력값'!C45*100*(3/12)*(1+'입력값'!D45/100)^19) | CJ10: =-('입력값'!C45*100*(3/12)*(1+'입력값'!D45/100)^19) | CK10: =-('입력값'!C45*100*(3/12)*(1+'입력값'!D45/100)^19) | CL10: =-('입력값'!C45*100*(3/12)*(1+'입력값'!D45/100)^19)
B11: 보험료 | C11: [KRWm] | D11: 0 | E11: 0 | F11: 0 | G11: 0 | H11: 0 | I11: 0 | J11: 0 | K11: =-('입력값'!C46*100*(3/12)) | L11: =-('입력값'!C46*100*(3/12)) | M11: =-('입력값'!C46*100*(3/12)) | N11: =-('입력값'!C46*100*(3/12)) | O11: =-('입력값'!C46*100*(3/12)) | P11: =-('입력값'!C46*100*(3/12)) | Q11: =-('입력값'!C46*100*(3/12)) | R11: =-('입력값'!C46*100*(3/12)) | S11: =-('입력값'!C46*100*(3/12)) | T11: =-('입력값'!C46*100*(3/12)) | U11: =-('입력값'!C46*100*(3/12)) | V11: =-('입력값'!C46*100*(3/12)) | W11: =-('입력값'!C46*100*(3/12)) | X11: =-('입력값'!C46*100*(3/12)) | Y11: =-('입력값'!C46*100*(3/12)) | Z11: =-('입력값'!C46*100*(3/12)) | AA11: =-('입력값'!C46*100*(3/12)) | AB11: =-('입력값'!C46*100*(3/12)) | AC11: =-('입력값'!C46*100*(3/12)) | AD11: =-('입력값'!C46*100*(3/12)) | AE11: =-('입력값'!C46*100*(3/12)) | AF11: =-('입력값'!C46*100*(3/12)) | AG11: =-('입력값'!C46*100*(3/12)) | AH11: =-('입력값'!C46*100*(3/12)) | AI11: =-('입력값'!C46*100*(3/12)) | AJ11: =-('입력값'!C46*100*(3/12)) | AK11: =-('입력값'!C46*100*(3/12)) | AL11: =-('입력값'!C46*100*(3/12)) | AM11: =-('입력값'!C46*100*(3/12)) | AN11: =-('입력값'!C46*100*(3/12)) | AO11: =-('입력값'!C46*100*(3/12)) | AP11: =-('입력값'!C46*100*(3/12)) | AQ11: =-('입력값'!C46*100*(3/12)) | AR11: =-('입력값'!C46*100*(3/12)) | AS11: =-('입력값'!C46*100*(3/12)) | AT11: =-('입력값'!C46*100*(3/12)) | AU11: =-('입력값'!C46*100*(3/12)) | AV11: =-('입력값'!C46*100*(3/12)) | AW11: =-('입력값'!C46*100*(3/12)) | AX11: =-('입력값'!C46*100*(3/12)) | AY11: =-('입력값'!C46*100*(3/12)) | AZ11: =-('입력값'!C46*100*(3/12)) | BA11: =-('입력값'!C46*100*(3/12)) | BB11: =-('입력값'!C46*100*(3/12)) | BC11: =-('입력값'!C46*100*(3/12)) | BD11: =-('입력값'!C46*100*(3/12)) | BE11: =-('입력값'!C46*100*(3/12)) | BF11: =-('입력값'!C46*100*(3/12)) | BG11: =-('입력값'!C46*100*(3/12)) | BH11: =-('입력값'!C46*100*(3/12)) | BI11: =-('입력값'!C46*100*(3/12)) | BJ11: =-('입력값'!C46*100*(3/12)) | BK11: =-('입력값'!C46*100*(3/12)) | BL11: =-('입력값'!C46*100*(3/12)) | BM11: =-('입력값'!C46*100*(3/12)) | BN11: =-('입력값'!C46*100*(3/12)) | BO11: =-('입력값'!C46*100*(3/12)) | BP11: =-('입력값'!C46*100*(3/12)) | BQ11: =-('입력값'!C46*100*(3/12)) | BR11: =-('입력값'!C46*100*(3/12)) | BS11: =-('입력값'!C46*100*(3/12)) | BT11: =-('입력값'!C46*100*(3/12)) | BU11: =-('입력값'!C46*100*(3/12)) | BV11: =-('입력값'!C46*100*(3/12)) | BW11: =-('입력값'!C46*100*(3/12)) | BX11: =-('입력값'!C46*100*(3/12)) | BY11: =-('입력값'!C46*100*(3/12)) | BZ11: =-('입력값'!C46*100*(3/12)) | CA11: =-('입력값'!C46*100*(3/12)) | CB11: =-('입력값'!C46*100*(3/12)) | CC11: =-('입력값'!C46*100*(3/12)) | CD11: =-('입력값'!C46*100*(3/12)) | CE11: =-('입력값'!C46*100*(3/12)) | CF11: =-('입력값'!C46*100*(3/12)) | CG11: =-('입력값'!C46*100*(3/12)) | CH11: =-('입력값'!C46*100*(3/12)) | CI11: =-('입력값'!C46*100*(3/12)) | CJ11: =-('입력값'!C46*100*(3/12)) | CK11: =-('입력값'!C46*100*(3/12)) | CL11: =-('입력값'!C46*100*(3/12))
B12: 환경모니터링비용 | C12: [KRWm] | D12: 0 | E12: 0 | F12: 0 | G12: 0 | H12: 0 | I12: 0 | J12: 0 | K12: =-('입력값'!C47*100*(3/12)) | L12: =-('입력값'!C47*100*(3/12)) | M12: =-('입력값'!C47*100*(3/12)) | N12: =-('입력값'!C47*100*(3/12)) | O12: =-('입력값'!C47*100*(3/12)) | P12: =-('입력값'!C47*100*(3/12)) | Q12: =-('입력값'!C47*100*(3/12)) | R12: =-('입력값'!C47*100*(3/12)) | S12: =-('입력값'!C47*100*(3/12)) | T12: =-('입력값'!C47*100*(3/12)) | U12: =-('입력값'!C47*100*(3/12)) | V12: =-('입력값'!C47*100*(3/12)) | W12: =-('입력값'!C47*100*(3/12)) | X12: =-('입력값'!C47*100*(3/12)) | Y12: =-('입력값'!C47*100*(3/12)) | Z12: =-('입력값'!C47*100*(3/12)) | AA12: =-('입력값'!C47*100*(3/12)) | AB12: =-('입력값'!C47*100*(3/12)) | AC12: =-('입력값'!C47*100*(3/12)) | AD12: =-('입력값'!C47*100*(3/12)) | AE12: =-('입력값'!C47*100*(3/12)) | AF12: =-('입력값'!C47*100*(3/12)) | AG12: =-('입력값'!C47*100*(3/12)) | AH12: =-('입력값'!C47*100*(3/12)) | AI12: =-('입력값'!C47*100*(3/12)) | AJ12: =-('입력값'!C47*100*(3/12)) | AK12: =-('입력값'!C47*100*(3/12)) | AL12: =-('입력값'!C47*100*(3/12)) | AM12: =-('입력값'!C47*100*(3/12)) | AN12: =-('입력값'!C47*100*(3/12)) | AO12: =-('입력값'!C47*100*(3/12)) | AP12: =-('입력값'!C47*100*(3/12)) | AQ12: =-('입력값'!C47*100*(3/12)) | AR12: =-('입력값'!C47*100*(3/12)) | AS12: =-('입력값'!C47*100*(3/12)) | AT12: =-('입력값'!C47*100*(3/12)) | AU12: =-('입력값'!C47*100*(3/12)) | AV12: =-('입력값'!C47*100*(3/12)) | AW12: =-('입력값'!C47*100*(3/12)) | AX12: =-('입력값'!C47*100*(3/12)) | AY12: =-('입력값'!C47*100*(3/12)) | AZ12: =-('입력값'!C47*100*(3/12)) | BA12: =-('입력값'!C47*100*(3/12)) | BB12: =-('입력값'!C47*100*(3/12)) | BC12: =-('입력값'!C47*100*(3/12)) | BD12: =-('입력값'!C47*100*(3/12)) | BE12: =-('입력값'!C47*100*(3/12)) | BF12: =-('입력값'!C47*100*(3/12)) | BG12: =-('입력값'!C47*100*(3/12)) | BH12: =-('입력값'!C47*100*(3/12)) | BI12: =-('입력값'!C47*100*(3/12)) | BJ12: =-('입력값'!C47*100*(3/12)) | BK12: =-('입력값'!C47*100*(3/12)) | BL12: =-('입력값'!C47*100*(3/12)) | BM12: =-('입력값'!C47*100*(3/12)) | BN12: =-('입력값'!C47*100*(3/12)) | BO12: =-('입력값'!C47*100*(3/12)) | BP12: =-('입력값'!C47*100*(3/12)) | BQ12: =-('입력값'!C47*100*(3/12)) | BR12: =-('입력값'!C47*100*(3/12)) | BS12: =-('입력값'!C47*100*(3/12)) | BT12: =-('입력값'!C47*100*(3/12)) | BU12: =-('입력값'!C47*100*(3/12)) | BV12: =-('입력값'!C47*100*(3/12)) | BW12: =-('입력값'!C47*100*(3/12)) | BX12: =-('입력값'!C47*100*(3/12)) | BY12: =-('입력값'!C47*100*(3/12)) | BZ12: =-('입력값'!C47*100*(3/12)) | CA12: =-('입력값'!C47*100*(3/12)) | CB12: =-('입력값'!C47*100*(3/12)) | CC12: =-('입력값'!C47*100*(3/12)) | CD12: =-('입력값'!C47*100*(3/12)) | CE12: =-('입력값'!C47*100*(3/12)) | CF12: =-('입력값'!C47*100*(3/12)) | CG12: =-('입력값'!C47*100*(3/12)) | CH12: =-('입력값'!C47*100*(3/12)) | CI12: =-('입력값'!C47*100*(3/12)) | CJ12: =-('입력값'!C47*100*(3/12)) | CK12: =-('입력값'!C47*100*(3/12)) | CL12: =-('입력값'!C47*100*(3/12))
B13: 소내전력비 | C13: [KRWm] | D13: 0 | E13: 0 | F13: 0 | G13: 0 | H13: 0 | I13: 0 | J13: 0 | K13: =-('입력값'!C48*100*(3/12)*(1+'입력값'!D48/100)^0) | L13: =-('입력값'!C48*100*(3/12)*(1+'입력값'!D48/100)^0) | M13: =-('입력값'!C48*100*(3/12)*(1+'입력값'!D48/100)^0) | N13: =-('입력값'!C48*100*(3/12)*(1+'입력값'!D48/100)^0) | O13: =-('입력값'!C48*100*(3/12)*(1+'입력값'!D48/100)^1) | P13: =-('입력값'!C48*100*(3/12)*(1+'입력값'!D48/100)^1) | Q13: =-('입력값'!C48*100*(3/12)*(1+'입력값'!D48/100)^1) | R13: =-('입력값'!C48*100*(3/12)*(1+'입력값'!D48/100)^1) | S13: =-('입력값'!C48*100*(3/12)*(1+'입력값'!D48/100)^2) | T13: =-('입력값'!C48*100*(3/12)*(1+'입력값'!D48/100)^2) | U13: =-('입력값'!C48*100*(3/12)*(1+'입력값'!D48/100)^2) | V13: =-('입력값'!C48*100*(3/12)*(1+'입력값'!D48/100)^2) | W13: =-('입력값'!C48*100*(3/12)*(1+'입력값'!D48/100)^3) | X13: =-('입력값'!C48*100*(3/12)*(1+'입력값'!D48/100)^3) | Y13: =-('입력값'!C48*100*(3/12)*(1+'입력값'!D48/100)^3) | Z13: =-('입력값'!C48*100*(3/12)*(1+'입력값'!D48/100)^3) | AA13: =-('입력값'!C48*100*(3/12)*(1+'입력값'!D48/100)^4) | AB13: =-('입력값'!C48*100*(3/12)*(1+'입력값'!D48/100)^4) | AC13: =-('입력값'!C48*100*(3/12)*(1+'입력값'!D48/100)^4) | AD13: =-('입력값'!C48*100*(3/12)*(1+'입력값'!D48/100)^4) | AE13: =-('입력값'!C48*100*(3/12)*(1+'입력값'!D48/100)^5) | AF13: =-('입력값'!C48*100*(3/12)*(1+'입력값'!D48/100)^5) | AG13: =-('입력값'!C48*100*(3/12)*(1+'입력값'!D48/100)^5) | AH13: =-('입력값'!C48*100*(3/12)*(1+'입력값'!D48/100)^5) | AI13: =-('입력값'!C48*100*(3/12)*(1+'입력값'!D48/100)^6) | AJ13: =-('입력값'!C48*100*(3/12)*(1+'입력값'!D48/100)^6) | AK13: =-('입력값'!C48*100*(3/12)*(1+'입력값'!D48/100)^6) | AL13: =-('입력값'!C48*100*(3/12)*(1+'입력값'!D48/100)^6) | AM13: =-('입력값'!C48*100*(3/12)*(1+'입력값'!D48/100)^7) | AN13: =-('입력값'!C48*100*(3/12)*(1+'입력값'!D48/100)^7) | AO13: =-('입력값'!C48*100*(3/12)*(1+'입력값'!D48/100)^7) | AP13: =-('입력값'!C48*100*(3/12)*(1+'입력값'!D48/100)^7) | AQ13: =-('입력값'!C48*100*(3/12)*(1+'입력값'!D48/100)^8) | AR13: =-('입력값'!C48*100*(3/12)*(1+'입력값'!D48/100)^8) | AS13: =-('입력값'!C48*100*(3/12)*(1+'입력값'!D48/100)^8) | AT13: =-('입력값'!C48*100*(3/12)*(1+'입력값'!D48/100)^8) | AU13: =-('입력값'!C48*100*(3/12)*(1+'입력값'!D48/100)^9) | AV13: =-('입력값'!C48*100*(3/12)*(1+'입력값'!D48/100)^9) | AW13: =-('입력값'!C48*100*(3/12)*(1+'입력값'!D48/100)^9) | AX13: =-('입력값'!C48*100*(3/12)*(1+'입력값'!D48/100)^9) | AY13: =-('입력값'!C48*100*(3/12)*(1+'입력값'!D48/100)^10) | AZ13: =-('입력값'!C48*100*(3/12)*(1+'입력값'!D48/100)^10) | BA13: =-('입력값'!C48*100*(3/12)*(1+'입력값'!D48/100)^10) | BB13: =-('입력값'!C48*100*(3/12)*(1+'입력값'!D48/100)^10) | BC13: =-('입력값'!C48*100*(3/12)*(1+'입력값'!D48/100)^11) | BD13: =-('입력값'!C48*100*(3/12)*(1+'입력값'!D48/100)^11) | BE13: =-('입력값'!C48*100*(3/12)*(1+'입력값'!D48/100)^11) | BF13: =-('입력값'!C48*100*(3/12)*(1+'입력값'!D48/100)^11) | BG13: =-('입력값'!C48*100*(3/12)*(1+'입력값'!D48/100)^12) | BH13: =-('입력값'!C48*100*(3/12)*(1+'입력값'!D48/100)^12) | BI13: =-('입력값'!C48*100*(3/12)*(1+'입력값'!D48/100)^12) | BJ13: =-('입력값'!C48*100*(3/12)*(1+'입력값'!D48/100)^12) | BK13: =-('입력값'!C48*100*(3/12)*(1+'입력값'!D48/100)^13) | BL13: =-('입력값'!C48*100*(3/12)*(1+'입력값'!D48/100)^13) | BM13: =-('입력값'!C48*100*(3/12)*(1+'입력값'!D48/100)^13) | BN13: =-('입력값'!C48*100*(3/12)*(1+'입력값'!D48/100)^13) | BO13: =-('입력값'!C48*100*(3/12)*(1+'입력값'!D48/100)^14) | BP13: =-('입력값'!C48*100*(3/12)*(1+'입력값'!D48/100)^14) | BQ13: =-('입력값'!C48*100*(3/12)*(1+'입력값'!D48/100)^14) | BR13: =-('입력값'!C48*100*(3/12)*(1+'입력값'!D48/100)^14) | BS13: =-('입력값'!C48*100*(3/12)*(1+'입력값'!D48/100)^15) | BT13: =-('입력값'!C48*100*(3/12)*(1+'입력값'!D48/100)^15) | BU13: =-('입력값'!C48*100*(3/12)*(1+'입력값'!D48/100)^15) | BV13: =-('입력값'!C48*100*(3/12)*(1+'입력값'!D48/100)^15) | BW13: =-('입력값'!C48*100*(3/12)*(1+'입력값'!D48/100)^16) | BX13: =-('입력값'!C48*100*(3/12)*(1+'입력값'!D48/100)^16) | BY13: =-('입력값'!C48*100*(3/12)*(1+'입력값'!D48/100)^16) | BZ13: =-('입력값'!C48*100*(3/12)*(1+'입력값'!D48/100)^16) | CA13: =-('입력값'!C48*100*(3/12)*(1+'입력값'!D48/100)^17) | CB13: =-('입력값'!C48*100*(3/12)*(1+'입력값'!D48/100)^17) | CC13: =-('입력값'!C48*100*(3/12)*(1+'입력값'!D48/100)^17) | CD13: =-('입력값'!C48*100*(3/12)*(1+'입력값'!D48/100)^17) | CE13: =-('입력값'!C48*100*(3/12)*(1+'입력값'!D48/100)^18) | CF13: =-('입력값'!C48*100*(3/12)*(1+'입력값'!D48/100)^18) | CG13: =-('입력값'!C48*100*(3/12)*(1+'입력값'!D48/100)^18) | CH13: =-('입력값'!C48*100*(3/12)*(1+'입력값'!D48/100)^18) | CI13: =-('입력값'!C48*100*(3/12)*(1+'입력값'!D48/100)^19) | CJ13: =-('입력값'!C48*100*(3/12)*(1+'입력값'!D48/100)^19) | CK13: =-('입력값'!C48*100*(3/12)*(1+'입력값'!D48/100)^19) | CL13: =-('입력값'!C48*100*(3/12)*(1+'입력값'!D48/100)^19)
